Workbook
Name body: '[1]资产负债表-2017'!$C$6:$H$36
Name grid: '[1]资产负债表-2017'!$C$6:$H$36
Name head: '[1]资产负债表-2017'!$A$4:$H$4
Name 合并科目名称: [2]Sheet1!$A$2:$A$908
Name 核算项目明细账: [3]核算项目明细账!$A$1:$K$157
Name 会计分录序时簿: #REF!
Name 科目余额表: #REF!
Name 明细分类账: #REF!
Name body: '[4]资产负债表-2017'!$C$6:$H$36
Name grid: '[4]资产负债表-2017'!$C$6:$H$36
Name head: '[4]资产负债表-2017'!$A$4:$H$4
Name 合并科目名称: [5]Sheet1!$A$2:$A$908
Name 核算项目明细账: [6]核算项目明细账!$A$1:$K$157
Name 会计分录序时簿: #REF!
Name 科目余额表: #REF!
Name 明细分类账: #REF!
Name body: '[4]资产负债表-2017'!$C$6:$H$36
Name grid: '[4]资产负债表-2017'!$C$6:$H$36
Name head: '[4]资产负债表-2017'!$A$4:$H$4
Name 合并科目名称: [5]Sheet1!$A$2:$A$908
Name 核算项目明细账: [6]核算项目明细账!$A$1:$K$157
Name 会计分录序时簿: #REF!
Name 科目余额表: #REF!
Name 明细分类账: #REF!
Name \555: [7]表三甲!#REF!
Name \a: [7]表三甲!#REF!
Name \b: #REF!
Name \bbb: #REF!
Name \E: #REF!
Name \k: [8]土建表三乙!#REF!
Name \kkk: [7]表三甲!#REF!
Name \m: #REF!
Name \o: [7]表三甲!#REF!
Name \p: [7]表三甲!#REF!
Name \q: [7]表三甲!#REF!
Name \r: [7]表三甲!#REF!
Name \x: [7]表三甲!#REF!
Name \xx: [7]表三甲!#REF!
Name \z: [7]表三甲!#REF!
Name \zz: [7]表三甲!#REF!
Name _: #REF!
Name _0.dbf: #REF!
Name _000.03.dbf: #REF!
Name _00103应收货款余额表.dbf: #REF!
Name _0月31日: #REF!
Name _1: #REF!
Name _1_: #REF!
Name _1_?: #REF!
Name _10_2004009P1: #REF!
Name _10Print_Area_00v00__00_00_\________0.00\_______損_鑼_T_R__z揻_?00_0_0_0__?Vo__000______000?T00000?_0_00000B0___0鞊?w_0000_0_斪_萟?00_000?_000?_0_?000000_0詶__????_?: #REF!
Name _11_2004012P1: #REF!
Name _12其他资产_开办费除外_明细表: #REF!
Name _2: #REF!
Name _2_??????: #REF!
Name _3: #REF!
Name _3_2003002K8: #REF!
Name _333: #REF!
Name _4: #REF!
Name _4_2003002KA: #REF!
Name _5: #REF!

Sheet GMV-战略需求
A1: 规模
A2: 结构 | B2: 品类
B3: 品牌
A5: 1、21年-22年商品大类增长波动 | J5: 年份 | K5: 游戏 | L5: 通信 | M5: 网娱 | N5: 网娱 | O5: 合计
J6: 43831
J7: 43862
J8: 43891
J9: 43922
J10: 43952
J11: 43983
J12: 44013
J13: 44044
J14: 44075
J15: 44105
J16: 44136
J17: 44166
... J23: 44348
A24: 2、21年-22年网娱、生活服务增长波动 | J24: 44378
J25: 44409
J26: 44440
J27: 44470
J28: 44501
J29: 44531
J30: 44562
J31: 44593
J32: 44621
J33: 44652
J34: 44682
J35: 44713
J36: 44743
... J40: 44866
A43: 3、品牌趋势波动，是否针对网娱、生活服务--22年数据波动做分析
A44: 网娱品牌 | B44: 影视会员、音频、视频直播、知识阅读
A45: 生活服务 | B45: 加油卡、网络工具、出行生活、餐饮、购物（优惠劵）、其他

Sheet 毛利-战略需求
A1: 1、收入构成 | B1: 代理 | C1: 虚拟商品采销差额收入+返点 | D1: 分商品大类-20年-22年
B2: 增值代运营 | C2: 代运营收入 | D2: 分商品大类-需要提供21年GMV
B3: 推广收入 | D3: 分商品大类-需要提供21年GMV
A8: 2、品类毛利21年-22年 | B8: 依赖第一条数据提供商品大类可以出
A18: 3、四大品类毛利/gmv
A25: 4、成长性品牌的毛利分析
A26: 生活服务
A27: 网娱
A30: 5、供应商毛利波动（前10）

Sheet 利润组成
A1: GMV | F1: 毛利收入（含税） | P1: 净利润 | AC1: 毛利率 | AH1: 净利润率 | AM1: 当月净利润 | AR1: 子公司提交资料
A2: 月份累计 | B2: 上市公司 | C2: 投资公司 | D2: 小计 | F2: 月份累计 | G2: 上市公司 | H2: 佣金手续费（元）（账面不含税金额） | I2: 佣金手续费（含税） | J2: 体内项目-衍生公司 | K2: 跨期返利(含税） | L2: 上市公司-扣除佣金手续费后、调整跨期返利后毛利收入 | M2: 投资公司 | N2: 集团小计 | P2: 月份累计 | Q2: 上市公司（审计口径） | R2: 跨期返利 | S2: 体内项目-衍生公司 | T2: H1项目分红 | U2: H1导师分红 | V2: 西藏福禄确认的上海灵盟投资损失 | W2: 上市公司调整后净利润小计 | X2: 投资公司调整前 | Y2: H1项目分红 | Z2: H1导师分红 | AA2: 集团小计 | AC2: 月份 | AD2: 上市公司（审计口径） | AE2: 投资公司 | AF2: 集团小计 | AH2: 月份 | AI2: 上市公司（审计口径） | AJ2: 投资公司 | AK2: 小计 | AM2: 月份 | AN2: 上市公司当月利润（核算）（元） | AO2: 调整跨期返利收入（元） | AP2: 调整投资公司(万元） | AR2: 月份累计 | AS2: 项目 | AT2: GMV | AU2: 毛利 | AV2: 净利润（决算口径） | AW2: 净利润（核算口径）
A3: 44562 | B3: 108052.9 | C3: 2374.0586 | D3: =B3+C3 -> 110426.96 | F3: 44562 | G3: ='毛利-收入组成'!AQ27 -> 2571.88 | H3: 2707835.9 | I3: =H3*1.06/10000 -> 287.03061 | J3: 655.10541 | K3: =R3*1.06 -> -486.04177 | L3: =G3-I3+J3-K3 -> 3425.9966 | M3: 1436.02 | N3: =L3+M3 -> 4862.0166 | P3: 44562 | Q3: 554.64112 | R3: =-4585299.71781625/10000 -> -458.52997 | S3: 160.39838 | W3: =Q3-R3+S3 -> 1173.5695 | X3: -1005.6133 | AA3: =W3+X3 -> 167.95616 | AC3: 44562 | AD3: =L3/B3 -> 0.03170666 | AE3: =M3/C3 -> 0.60487979 | AF3: =N3/D3 -> 0.044029254 | AH3: 44562 | AI3: =W3*1.06/L3 -> 0.36310125 | AJ3: =X3*1.06/M3 -> -0.74229474 | AK3: =AA3*1.06/N3 -> 0.03661722 | AM3: 44562 | AN3: 4419474.4 | AO3: =-12638207.1/3 -> -4212735.7 | AR3: 45931 | AS3: 灵工平台中心
A4: 44593 | B4: 194083.64 | C4: 4905.486 | D4: =B4+C4 -> 198989.13 | F4: 44593 | G4: ='毛利-收入组成'!AQ28 -> 4593.9912 | H4: 4898251.5 | I4: =H4*1.06/10000 -> 519.21466 | J4: 895.37 | K4: =R4*1.06 -> -952.56963 | L4: =G4-I4+J4-K4 -> 5922.7161 | M4: 3006.5654 | N4: =L4+M4 -> 8929.2816 | P4: 44593 | Q4: 632.65232 | R4: =-4585299.71781625/10000-4401206.19439752/10000 -> -898.65059 | S4: 103.02 | W4: =Q4-R4+S4 -> 1634.3229 | X4: -1072.18 | AA4: =W4+X4 -> 562.14291 | AC4: 44593 | AD4: =L4/B4 -> 0.030516307 | AE4: =M4/C4 -> 0.61289859 | AF4: =N4/D4 -> 0.044873213 | AH4: 44593 | AI4: =W4*1.06/L4 -> 0.29249794 | AJ4: =X4*1.06/M4 -> -0.37800967 | AK4: =AA4*1.06/N4 -> 0.066732299 | AM4: 44593 | AN4: 2602332.2 | AO4: =-12638207.1/3 -> -4212735.7 | AR4: 45931 | AS4: 海外权益中心
A5: 44621 | B5: 326827.75 | C5: 7834.875 | D5: =B5+C5 -> 334662.63 | F5: 44621 | G5: ='毛利-收入组成'!AQ29 -> 8008.37 | H5: 6963186.2 | I5: =H5*1.06/10000 -> 738.09774 | J5: 1265.12 | K5: =R5*1.06 -> -1339.65 | L5: =G5-I5+J5-K5 -> 9875.0423 | M5: 4720.6749 | N5: =L5+M5 -> 14595.717 | P5: 44621 | Q5: 1386.5289 | R5: -1263.8207 | S5: 203.79785 | W5: =Q5-R5+S5 -> 2854.1475 | X5: -1370.88 | AA5: =W5+X5 -> 1483.2675 | AC5: 44621 | AD5: =L5/B5 -> 0.030214822 | AE5: =M5/C5 -> 0.60252077 | AF5: =N5/D5 -> 0.043613227 | AH5: 44621 | AI5: =W5*1.06/L5 -> 0.30636794 | AJ5: =X5*1.06/M5 -> -0.3078231 | AK5: =AA5*1.06/N5 -> 0.10772088 | AM5: 44621 | AN5: 6160437 | AO5: =-12638207.1/3 -> -4212735.7 | AP5: 146.56785 | AR5: 45931 | AS5: 游戏生态电商中心 | AT5: 118797.22 | AU5: 3600.68 | AV5: 1573.3
A6: 44652 | B6: 448332.98 | C6: 8907.4138 | D6: =B6+C6 -> 457240.4 | F6: 44652 | G6: ='毛利-收入组成'!AQ30 -> 10700.565 | H6: 9273917.6 | I6: =H6*1.06/10000 -> 983.03526 | J6: 1531.8642 | K6: =R6*1.06 -> -1249.4227 | L6: =G6-I6+J6-K6 -> 12498.816 | M6: 6687.3105 | N6: =L6+M6 -> 19186.127 | P6: 44652 | Q6: 1630.6354 | R6: -1178.7007 | S6: 4.467404 | W6: =Q6-R6+S6 -> 2813.8034 | X6: -1783.2181 | AA6: =W6+X6 -> 1030.5853 | AC6: 44652 | AD6: =L6/B6 -> 0.027878423 | AE6: =M6/C6 -> 0.75075781 | AF6: =N6/D6 -> 0.0419607 | AH6: 44652 | AI6: =W6*1.06/L6 -> 0.23863313 | AJ6: =X6*1.06/M6 -> -0.28265641 | AK6: =AA6*1.06/N6 -> 0.05693804 | AM6: 44652 | AN6: 3124110.2 | AO6: 851200.46 | AP6: -11.900448
A7: 44682 | B7: 584617.02 | C7: 11251.915 | D7: =B7+C7 -> 595868.94 | F7: 44682 | G7: ='毛利-收入组成'!AQ31 -> 13310.057 | H7: 11902620 | I7: =H7*1.06/10000 -> 1261.6778 | J7: 1849.5439 | K7: =R7*1.06 -> -1388.9571 | L7: =G7-I7+J7-K7 -> 15286.88 | M7: 8601.3529 | N7: =L7+M7 -> 23888.233 | P7: 44682 | Q7: 1691.0027 | R7: =-13103368.83/10000 -> -1310.3369 | S7: 45.146767 | W7: =Q7-R7+S7 -> 3046.4863 | X7: -2102.6224 | AA7: =W7+X7 -> 943.86394 | AC7: 44682 | AD7: =L7/B7 -> 0.026148538 | AE7: =M7/C7 -> 0.76443456 | AF7: =N7/D7 -> 0.040089744 | AH7: 44682 | AI7: =W7*1.06/L7 -> 0.2112449 | AJ7: =X7*1.06/M7 -> -0.25911967 | AK7: =AA7*1.06/N7 -> 0.041882368 | AM7: 44682 | AN7: 603672.79 | AO7: =(R7-R6)*10000 -> -1316362.2 | AP7: 208.2226
A8: 44713 | B8: 727745.91 | C8: 13983.27 | D8: =B8+C8 -> 741729.18 | F8: 44713 | G8: ='毛利-收入组成'!AQ32 -> 17052.403 | H8: 15547055 | I8: =H8*1.06/10000 -> 1647.9879 | J8: 2173.8273 | K8: =R8*1.06 -> -1365.4349 | L8: =G8-I8+J8-K8 -> 18943.678 | M8: 10706.914 | N8: =L8+M8 -> 29650.592 | P8: 44713 | Q8: 3194.8382 | R8: =-12881461.65/10000 -> -1288.1462 | S8: -520.13564 | W8: =Q8-R8+S8 -> 3962.8487 | X8: -2258.997 | AA8: =W8+X8 -> 1703.8517 | AC8: 44713 | AD8: =L8/B8 -> 0.026030621 | AE8: =M8/C8 -> 0.76569461 | AF8: =N8/D8 -> 0.039974957 | AH8: 44713 | AI8: =W8*1.06/L8 -> 0.22174256 | AJ8: =X8*1.06/M8 -> -0.22364397 | AK8: =AA8*1.06/N8 -> 0.060912202 | AM8: 44713 | AN8: 15038356 | AO8: =(R8-R7)*10000 -> 221907.18 | AP8: -280.71317
A9: 44743 | B9: 850965.84 | C9: 16453.571 | D9: =B9+C9 -> 867419.41 | F9: 44743 | G9: ='毛利-收入组成'!AQ33 -> 20185.933 | H9: 18238988 | I9: =H9*1.06/10000 -> 1933.3327 | J9: 2432.4562 | K9: =R9*1.06 -> -1463.2248 | L9: =G9-I9+J9-K9 -> 22148.281 | M9: 13005.352 | N9: =L9+M9 -> 35153.633 | P9: 44743 | Q9: 3804.432 | R9: =-13804007.17/10000 -> -1380.4007 | S9: -820.04 | W9: =Q9-R9+S9 -> 4364.7927 | X9: -2988.73 | AA9: =W9+X9 -> 1376.0627 | AC9: 44743 | AD9: =L9/B9 -> 0.026027227 | AE9: =M9/C9 -> 0.79042731 | AF9: =N9/D9 -> 0.040526685 | AH9: 44743 | AI9: =W9*1.06/L9 -> 0.20889568 | AJ9: =X9*1.06/M9 -> -0.24359616 | AK9: =AA9*1.06/N9 -> 0.041492909 | AM9: 44743 | AN9: 6095938 | AO9: =(R9-R8)*10000 -> -922545.52 | AP9: 15.963167
A10: 44774 | B10: 985758.18 | C10: 19132.318 | D10: =B10+C10 -> 1004890.5 | F10: 44774 | G10: ='毛利-收入组成'!AQ34 -> 25497.365 | H10: 21451872 | I10: =H10*1.06/10000 -> 2273.8984 | J10: 3031.335 | K10: =R10*1.06 -> -1426.7573 | L10: =G10-I10+J10-K10 -> 27681.559 | M10: 15290.998 | N10: =L10+M10 -> 42972.557 | P10: 44774 | Q10: =54992357.66/10000 -> 5499.2358 | R10: =-13459974.9019033/10000 -> -1345.9975 | S10: -606.21 | W10: =Q10-R10+S10 -> 6239.0233 | X10: -3396.47 | AA10: =W10+X10 -> 2842.5533 | AC10: 44774 | AD10: =L10/B10 -> 0.02808149 | AE10: =M10/C10 -> 0.79922348 | AF10: =N10/D10 -> 0.042763423 | AH10: 44774 | AI10: =W10*1.06/L10 -> 0.23890868 | AJ10: =X10*1.06/M10 -> -0.23544952 | AK10: =AA10*1.06/N10 -> 0.070116992 | AM10: 44774 | AN10: 16948038 | AO10: =(R10-R9)*10000 -> 344032.27 | AP10: 302.64
A11: 44805 | B11: 1135221.8 | C11: 22645.071 | D11: =B11+C11 -> 1157866.9 | F11: 44805 | G11: ='毛利-收入组成'!AQ35 -> 28661.881 | H11: 24370597 | I11: =H11*1.06/10000 -> 2583.2833 | J11: 4014.432 | K11: =R11*1.06 -> -1269.1804 | L11: =G11-I11+J11-K11 -> 31362.211 | M11: 17952.319 | N11: =L11+M11 -> 49314.53 | P11: 44805 | Q11: =60424603.79/10000 -> 6042.4604 | R11: =-11973400.44662/10000 -> -1197.34 | S11: -844.98 | W11: =Q11-R11+S11 -> 6394.8204 | X11: -4007.97 | AA11: =W11+X11 -> 2386.8504 | AC11: 44805 | AD11: =L11/B11 -> 0.027626505 | AE11: =M11/C11 -> 0.79276938 | AF11: =N11/D11 -> 0.042590846 | AH11: 44805 | AI11: =W11*1.06/L11 -> 0.21613622 | AJ11: =X11*1.06/M11 -> -0.23665178 | AK11: =AA11*1.06/N11 -> 0.051304584 | AM11: 44805 | AN11: 5432246.1 | AO11: =(R11-R10)*10000 -> 1486574.5 | AP11: -155.56
A12: 44835 | B12: 1282791 | C12: 30802.29 | D12: =B12+C12 -> 1313593.3 | F12: 44835 | G12: ='毛利-收入组成'!AQ36 -> 31941.924 | H12: 27931645 | I12: =H12*1.06/10000 -> 2960.7544 | J12: 4527.9066 | K12: =R12*1.06 -> -1399.6803 | L12: =G12-I12+J12-K12 -> 34908.756 | M12: 20691.857 | N12: =L12+M12 -> 55600.613 | P12: 44835 | Q12: =70722471.56/10000 -> 7072.2472 | R12: =-13204531.4789889/10000 -> -1320.4531 | S12: -989.72 | W12: =Q12-R12+S12 -> 7402.9803 | X12: -3546.33 | AA12: =W12+X12 -> 3856.6503 | AC12: 44835 | AD12: =L12/B12 -> 0.027213129 | AE12: =M12/C12 -> 0.67176361 | AF12: =N12/D12 -> 0.042327115 | AH12: 44835 | AI12: =W12*1.06/L12 -> 0.22479057 | AJ12: =X12*1.06/M12 -> -0.18167097 | AK12: =AA12*1.06/N12 -> 0.073525256 | AM12: 44835 | AN12: 10297813 | AO12: =(R12-R11)*10000 -> -1231131 | AP12: -99.33
A13: 44866 | B13: 1458208.4 | C13: 28395.373 | D13: =B13+C13 -> 1486603.8 | F13: 44866 | G13: ='毛利-收入组成'!AQ37 -> 36141.231 | H13: 34940282 | I13: =H13*1.06/10000 -> 3703.6699 | J13: 5080.3998 | K13: =R13*1.06 -> -1487.864 | L13: =G13-I13+J13-K13 -> 39005.825 | M13: 23119.872 | N13: =L13+M13 -> 62125.697 | P13: 44866 | Q13: =75107451.42/10000 -> 7510.7451 | R13: =-14036452.5418712/10000 -> -1403.6453 | S13: -1132.02 | W13: =Q13-R13+S13 -> 7782.3704 | X13: -3545.53 | AA13: =W13+X13 -> 4236.8404 | AC13: 44866 | AD13: =L13/B13 -> 0.026749143 | AE13: =M13/C13 -> 0.81421265 | AF13: =N13/D13 -> 0.041790353 | AH13: 44866 | AI13: =W13*1.06/L13 -> 0.21148925 | AJ13: =X13*1.06/M13 -> -0.16255548 | AK13: =AA13*1.06/N13 -> 0.072289746 | AM13: 44866 | AN13: 3561925.3 | AO13: =(R13-R12)*10000 -> -831921.06 | AP13: -166.06
A14: 44896 | B14: 1630463.8 | C14: 43463.22 | D14: =B14+C14 -> 1673927 | F14: 44896 | G14: ='毛利-收入组成'!AQ38 -> 43520.124 | H14: 39830925 | I14: =H14*1.06/10000 -> 4222.0781 | J14: 6011.9066 | K14: =R14*1.06 -> -1190.8049 | L14: =G14-I14+J14-K14 -> 46500.757 | M14: 25043.454 | N14: =L14+M14 -> 71544.211 | P14: 44896 | Q14: =115027391.79/10000 -> 11502.739 | R14: =-11234008.655/10000 -> -1123.4009 | S14: -1269.48 | W14: =Q14-R14+S14 -> 11356.66 | X14: -4104.55 | AA14: =W14+X14 -> 7252.11 | AC14: 44896 | AD14: =L14/B14 -> 0.028519957 | AE14: =M14/C14 -> 0.57619877 | AF14: =N14/D14 -> 0.042740341 | AH14: 44896 | AI14: =W14*1.06/L14 -> 0.25887879 | AJ14: =X14*1.06/M14 -> -0.17373095 | AK14: =AA14*1.06/N14 -> 0.10744736 | AM14: 44896 | AN14: 18287190 | AO14: =(R14-R13)*10000 -> 2802443.9 | AP14: 184.5
A15: 44927 | B15: ='GMV表-商品大类'!T18+B71 -> 139899.12 | C15: 3494.7221 | D15: =B15+C15 -> 143393.84 | F15: 44927 | G15: ='毛利-收入组成'!AQ39 -> 4343.2834 | H15: 3630321.3 | I15: =H15*1.06/10000 -> 384.81406 | J15: 1931.3288 | K15: =R15*1.06 -> 206.06363 | L15: =G15-I15+J15-K15 -> 5683.7345 | M15: 2148.7773 | N15: =L15+M15 -> 7832.5118 | P15: 44927 | Q15: 1390.69 | R15: =1943996.50432941/10000 -> 194.39965 | S15: 785.578 | W15: =Q15-R15+S15 -> 1981.8684 | X15: 206.1331 | AA15: =W15+X15 -> 2188.0015 | AC15: 44927 | AD15: =L15/B15 -> 0.040627379 | AE15: =M15/C15 -> 0.61486355 | AF15: =N15/D15 -> 0.054622372 | AH15: 44927 | AI15: =W15*1.06/L15 -> 0.3696127 | AJ15: =X15*1.06/M15 -> 0.10168624 | AK15: =AA15*1.06/N15 -> 0.29610955 | AM15: 44927 | AN15: 13906900 | AO15: =R15*10000 -> 1943996.5 | AP15: 98.863
A16: 44958 | B16: ='GMV表-商品大类'!T19+B72 -> 273756.55 | C16: 6379.2112 | D16: =B16+C16 -> 280135.76 | F16: 44958 | G16: ='毛利-收入组成'!AQ40 -> 7467.2483 | H16: 6214995.1 | I16: =H16*1.06/10000 -> 658.78948 | J16: 2249.6399 | K16: =R16*1.06 -> -169.18257 | L16: =G16-I16+J16-K16 -> 9227.2813 | M16: 3659.1241 | N16: =L16+M16 -> 12886.405 | P16: 44958 | Q16: 2066.4314 | R16: =-1596061.9885538/10000 -> -159.6062 | S16: 597.92934 | W16: =Q16-R16+S16 -> 2823.967 | X16: 130.11791 | AA16: =W16+X16 -> 2954.0849 | AC16: 44958 | AD16: =L16/B16 -> 0.033706157 | AE16: =M16/C16 -> 0.57360134 | AF16: =N16/D16 -> 0.046000572 | AH16: 44958 | AI16: =W16*1.06/L16 -> 0.32440812 | AJ16: =X16*1.06/M16 -> 0.037693443 | AK16: =AA16*1.06/N16 -> 0.24299484 | AM16: 44958 | AN16: 6757414.1 | AO16: =(R16-R15)*10000 -> -3540058.5 | AP16: =S16-S15 -> -187.64866
A17: 44986 | B17: ='GMV表-商品大类'!T20+B73 -> 430030.64 | C17: 9120.9552 | D17: =B17+C17 -> 439151.59 | F17: 44986 | G17: ='毛利-收入组成'!AQ41 -> 10413.099 | H17: 9373428.8 | I17: =H17*1.06/10000 -> 993.58345 | J17: 2973.5557 | K17: =R17*1.06 -> 45.142784 | L17: =G17-I17+J17-K17 -> 12347.928 | M17: 5379.9146 | N17: =L17+M17 -> 17727.843 | P17: 44986 | Q17: 2269.4532 | R17: 42.587533 | S17: 365.21191 | W17: =Q17-R17+S17 -> 2592.0776 | X17: -140.70901 | AA17: =W17+X17 -> 2451.3686 | AC17: 44986 | AD17: =L17/B17 -> 0.028714067 | AE17: =M17/C17 -> 0.58984114 | AF17: =N17/D17 -> 0.04036839 | AH17: 44986 | AI17: =W17*1.06/L17 -> 0.22251524 | AJ17: =X17*1.06/M17 -> -0.027723776 | AK17: =AA17*1.06/N17 -> 0.14657455 | AM17: 44986 | AN17: 2030217.6 | AO17: =(R17-R16)*10000 -> 2021937.3 | AP17: =S17-S16 -> -232.71743
A18: 45017 | B18: ='GMV表-商品大类'!T21+B74 -> 562009.48 | C18: 11863.173 | D18: =B18+C18 -> 573872.65 | F18: 45017 | G18: ='毛利-收入组成'!AQ42 -> 12608.747 | H18: 12671634 | I18: =H18*1.06/10000 -> 1343.1932 | J18: 3381.6409 | K18: =R18*1.06 -> 39.369201 | L18: =G18-I18+J18-K18 -> 14607.826 | M18: 6902.0785 | N18: =L18+M18 -> 21509.904 | P18: 45017 | Q18: =24847709.2/10000 -> 2484.7709 | R18: =371407.553576133/10000 -> 37.140755 | S18: -115.89507 | W18: =Q18-R18+S18 -> 2331.7351 | X18: -310.77087 | AA18: =W18+X18 -> 2020.9642 | AC18: 45017 | AD18: =L18/B18 -> 0.025992134 | AE18: =M18/C18 -> 0.58180713 | AF18: =N18/D18 -> 0.037482017 | AH18: 45017 | AI18: =W18*1.06/L18 -> 0.16919966 | AJ18: =X18*1.06/M18 -> -0.047727235 | AK18: =AA18*1.06/N18 -> 0.099592357 | AM18: 45017 | AN18: 2153177.1 | AO18: =(R18-R17)*10000 -> -54467.771 | AP18: =S18-S17 -> -481.10697
A19: 45047 | B19: ='GMV表-商品大类'!T22+B75 -> 718524.9 | C19: 14129.51 | D19: =B19+C19 -> 732654.41 | F19: 45047 | G19: ='毛利-收入组成'!AQ43 -> 16236.986 | H19: 16554205 | I19: =H19*1.06/10000 -> 1754.7457 | J19: 3943.9878 | K19: =R19*1.06 -> 49.602631 | L19: =G19-I19+J19-K19 -> 18376.626 | M19: 8310.2133 | N19: =L19+M19 -> 26686.839 | P19: 45047 | Q19: =33865340.38/10000 -> 3386.534 | R19: =467949.353128217/10000 -> 46.794935 | S19: -480.00006 | W19: =Q19-R19+S19 -> 2859.739 | X19: -782.02193 | AA19: =W19+X19 -> 2077.7171 | AC19: 45047 | AD19: =L19/B19 -> 0.025575489 | AE19: =M19/C19 -> 0.58814591 | AF19: =N19/D19 -> 0.036424866 | AH19: 45047 | AI19: =W19*1.06/L19 -> 0.16495539 | AJ19: =X19*1.06/M19 -> -0.099749936 | AK19: =AA19*1.06/N19 -> 0.082526826 | AM19: 45047 | AN19: 9017631.2 | AO19: =(R19-R18)*10000 -> 96541.8 | AP19: =S19-S18 -> -364.105
A20: 45078 | B20: ='GMV表-商品大类'!T23+B76 -> 885719.33 | C20: 16876.623 | D20: =B20+C20 -> 902595.96 | F20: 45078 | G20: ='毛利-收入组成'!AQ44 -> 21479.88 | H20: 22188118 | I20: =H20*1.06/10000 -> 2351.9405 | J20: 4738.2533 | K20: =R20*1.06 -> 3.0884422 | L20: =G20-I20+J20-K20 -> 23863.104 | M20: 9775.2481 | N20: =L20+M20 -> 33638.353 | P20: 45078 | Q20: =56339633.83/10000 -> 5633.9634 | R20: =29136.2470234791/10000 -> 2.9136247 | S20: -606.53558 | W20: =Q20-R20+S20 -> 5024.5142 | X20: -595.02904 | AA20: =W20+X20 -> 4429.4851 | AC20: 45078 | AD20: =L20/B20 -> 0.026942061 | AE20: =M20/C20 -> 0.57921824 | AF20: =N20/D20 -> 0.03726845 | AH20: 45078 | AI20: =W20*1.06/L20 -> 0.22318911 | AJ20: =X20*1.06/M20 -> -0.064523251 | AK20: =AA20*1.06/N20 -> 0.13958039 | AM20: 45078 | AN20: 22474293 | AO20: =(R20-R19)*10000 -> -438813.11 | AP20: =S20-S19 -> -126.53552
A21: 45108 | B21: ='GMV表-商品大类'!T24+B77 -> 1031827.7 | C21: 19317.607 | D21: =B21+C21 -> 1051145.4 | F21: 45108 | G21: ='毛利-收入组成'!AQ45 -> 24896.668 | H21: 25343928 | I21: =H21*1.06/10000 -> 2686.4563 | J21: 5300.6635 | K21: =R21*1.06 -> 100.72932 | L21: =G21-I21+J21-K21 -> 27410.145 | M21: 11006.209 | N21: =L21+M21 -> 38416.354 | P21: 45108 | Q21: =64434719.82/10000 -> 6443.472 | R21: =950276.619611746/10000 -> 95.027662 | S21: -889.85281 | W21: =Q21-R21+S21 -> 5458.5915 | X21: -612.04319 | AA21: =W21+X21 -> 4846.5483 | AC21: 45108 | AD21: =L21/B21 -> 0.026564652 | AE21: =M21/C21 -> 0.56975012 | AF21: =N21/D21 -> 0.036547138 | AH21: 45108 | AI21: =W21*1.06/L21 -> 0.21109363 | AJ21: =X21*1.06/M21 -> -0.058945437 | AK21: =AA21*1.06/N21 -> 0.13372797 | AM21: 45108 | AN21: 8095086 | AO21: =(R21-R20)*10000 -> 921140.37 | AP21: =S21-S20 -> -283.31723
A22: 45139 | B22: ='GMV表-商品大类'!T25+B78 -> 1194307.4 | C22: 22430.295 | D22: =B22+C22 -> 1216737.7 | F22: 45139 | G22: ='毛利-收入组成'!AQ46 -> 29102.011 | H22: 29881459 | I22: =H22*1.06/10000 -> 3167.4347 | J22: 6106.3185 | K22: =R22*1.06 -> 89.892167 | L22: =G22-I22+J22-K22 -> 31951.003 | M22: 12594.133 | N22: =L22+M22 -> 44545.136 | P22: 45139 | Q22: =75519119.24/10000 -> 7551.9119 | R22: =848039.309164936/10000 -> 84.803931 | S22: -990.76869 | W22: =Q22-R22+S22 -> 6476.3393 | X22: -592.28631 | AA22: =W22+X22 -> 5884.053 | AC22: 45139 | AD22: =L22/B22 -> 0.026752747 | AE22: =M22/C22 -> 0.56147871 | AF22: =N22/D22 -> 0.036610304 | AH22: 45139 | AI22: =W22*1.06/L22 -> 0.21485772 | AJ22: =X22*1.06/M22 -> -0.049850472 | AK22: =AA22*1.06/N22 -> 0.14001745 | AM22: 45139 | AN22: 11084399 | AO22: =(R22-R21)*10000 -> -102237.31 | AP22: =S22-S21 -> -100.91588
A23: 45170 | B23: ='GMV表-商品大类'!T26+B79 -> 1339120.1 | C23: 25425.014 | D23: =B23+C23 -> 1364545.1 | F23: 45170 | G23: ='毛利-收入组成'!AQ47 -> 31954.748 | H23: 32816668 | I23: =H23*1.06/10000 -> 3478.5668 | J23: 7413.0762 | K23: =R23*1.06 -> -155.33227 | L23: =G23-I23+J23-K23 -> 36044.59 | M23: 14057.412 | N23: =L23+M23 -> 50102.002 | P23: 45170 | Q23: =83475621.39/10000 -> 8347.5621 | R23: =-1465398.79/10000 -> -146.53988 | S23: -698.13675 | W23: =Q23-R23+S23 -> 7795.9653 | X23: -570.92725 | AA23: =W23+X23 -> 7225.038 | AC23: 45170 | AD23: =L23/B23 -> 0.026916622 | AE23: =M23/C23 -> 0.55289692 | AF23: =N23/D23 -> 0.036716999 | AH23: 45170 | AI23: =W23*1.06/L23 -> 0.2292639 | AJ23: =X23*1.06/M23 -> -0.043050804 | AK23: =AA23*1.06/N23 -> 0.15285897 | AM23: 45170 | AN23: 7956502.2 | AO23: =(R23-R22)*10000 -> -2313438.1 | AP23: =S23-S22 -> 292.63194
A24: 45200 | B24: ='GMV表-商品大类'!T27+B80 -> 1446745 | C24: 28365.195 | D24: =B24+C24 -> 1475110.2 | F24: 45200 | G24: ='毛利-收入组成'!AQ48 -> 35384.217 | H24: 35555090 | I24: =H24*1.06/10000 -> 3768.8395 | J24: 8333.3067 | K24: =R24*1.06 -> 50.929116 | L24: =G24-I24+J24-K24 -> 39897.755 | M24: 15607.072 | N24: =L24+M24 -> 55504.827 | P24: 45200 | Q24: =89396323.84/10000 -> 8939.6324 | R24: =480463.357363195/10000 -> 48.046336 | S24: -747.08716 | W24: =Q24-R24+S24 -> 8144.4989 | X24: -460.83184 | AA24: =W24+X24 -> 7683.667 | AC24: 45200 | AD24: =L24/B24 -> 0.0275776 | AE24: =M24/C24 -> 0.5502191 | AF24: =N24/D24 -> 0.03762758 | AH24: 45200 | AI24: =W24*1.06/L24 -> 0.21638232 | AJ24: =X24*1.06/M24 -> -0.031298744 | AK24: =AA24*1.06/N24 -> 0.14673836 | AM24: 45200 | AN24: 5920702.5 | AO24: =(R24-R23)*10000 -> 1945862.1 | AP24: =S24-S23 -> -48.950403
A25: 45231 | B25: ='GMV表-商品大类'!T28+B81 -> 1573930.7 | C25: 32045.495 | D25: =B25+C25 -> 1605976.2 | F25: 45231 | G25: ='毛利-收入组成'!AQ49 -> 40497.763 | H25: 39818569 | I25: =H25*1.06/10000 -> 4220.7683 | J25: 9122.3132 | K25: =R25*1.06 -> -126.91095 | L25: =G25-I25+J25-K25 -> 45526.218 | M25: 16855.04 | N25: =L25+M25 -> 62381.259 | P25: 45231 | Q25: =105607329.35/10000 -> 10560.733 | R25: =-1197273.069527/10000 -> -119.72731 | S25: -669.69008 | W25: =Q25-R25+S25 -> 10010.77 | X25: -555.38892 | AA25: =W25+X25 -> 9455.3812 | AC25: 45231 | AD25: =L25/B25 -> 0.028925173 | AE25: =M25/C25 -> 0.52597222 | AF25: =N25/D25 -> 0.038843202 | AH25: 45231 | AI25: =W25*1.06/L25 -> 0.23308363 | AJ25: =X25*1.06/M25 -> -0.034927965 | AK25: =AA25*1.06/N25 -> 0.16066851 | AM25: 45231 | AN25: 16211006 | AO25: =(R25-R24)*10000 -> -1677736.4 | AP25: =S25-S24 -> 77.397076
A26: 45261 | B26: ='GMV表-商品大类'!T29+B82 -> 1683893.3 | C26: 35301.109 | D26: =B26+C26 -> 1719194.4 | F26: 45261 | G26: ='毛利-收入组成'!AQ50 -> 47538.618 | H26: 42529215 | I26: =H26*1.06/10000 -> 4508.0968 | J26: 10356.611 | K26: =R26*1.06 -> 116.10774 | L26: =G26-I26+J26-K26 -> 53271.024 | M26: 18153.929 | N26: =L26+M26 -> 71424.953 | P26: 45261 | Q26: =130338051.49/10000 -> 13033.805 | R26: =1095356.02364967/10000 -> 109.5356 | S26: -1547.2801 | W26: =Q26-R26+S26 -> 11376.989 | X26: -455.01694 | AA26: =W26+X26 -> 10921.973 | AC26: 45261 | AD26: =L26/B26 -> 0.03163563 | AE26: =M26/C26 -> 0.51425945 | AF26: =N26/D26 -> 0.041545594 | AH26: 45261 | AI26: =W26*1.06/L26 -> 0.22638215 | AJ26: =X26*1.06/M26 -> -0.026568242 | AK26: =AA26*1.06/N26 -> 0.16209028 | AM26: 45261 | AN26: 24730722 | AO26: =(R26-R25)*10000 -> 2292629.1 | AP26: =S26-S25 -> -877.58998
A27: 45292 | B27: ='GMV表-商品大类'!T30+B83 -> 101433.39 | C27: 2264.3271 | D27: =B27+C27 -> 103697.71 | F27: 45292 | G27: ='毛利-收入组成'!AQ51 -> 2786.2584 | H27: 2201641.7 | I27: =H27*1.06/10000 -> 233.37402 | J27: 1992.7764 | K27: =R27*1.06 -> -137.41391 | L27: =G27-I27+J27-K27 -> 4683.0747 | M27: 1641.7547 | N27: =L27+M27 -> 6324.8294 | P27: 45292 | Q27: =3364142.28/10000 -> 336.41423 | R27: =-1296357.68417/10000 -> -129.63577 | S27: 701.9994 | W27: =Q27-R27+S27 -> 1168.0494 | X27: 66.763345 | AA27: =W27+X27 -> 1234.8127 | AC27: 45292 | AD27: =L27/B27 -> 0.046168966 | AE27: =M27/C27 -> 0.72505193 | AF27: =N27/D27 -> 0.060992948 | AH27: 45292 | AI27: =W27*1.06/L27 -> 0.2643845 | AJ27: =X27*1.06/M27 -> 0.043105797 | AK27: =AA27*1.06/N27 -> 0.20694653 | AM27: 45292 | AN27: 3364142.3 | AO27: =R27*10000 -> -1296357.7 | AP27: =S27 -> 701.9994
A28: 45323 | B28: ='GMV表-商品大类'!T31+B84 -> 190089.48 | C28: 4490.9293 | D28: =B28+C28 -> 194580.41 | F28: 45323 | G28: ='毛利-收入组成'!AQ52 -> 5256.8072 | H28: 4535148.6 | I28: =H28*1.06/10000 -> 480.72575 | J28: 2470.0261 | K28: =R28*1.06 -> -236.35704 | L28: =G28-I28+J28-K28 -> 7482.4646 | M28: 3234.9687 | N28: =L28+M28 -> 10717.433 | P28: 45323 | Q28: 566.71745 | R28: =-2229783.36430365/10000 -> -222.97834 | S28: 664.82858 | W28: =Q28-R28+S28 -> 1454.5244 | X28: 318.4881 | AA28: =W28+X28 -> 1773.0125 | AC28: 45323 | AD28: =L28/B28 -> 0.039362855 | AE28: =M28/C28 -> 0.72033392 | AF28: =N28/D28 -> 0.055079714 | AH28: 45323 | AI28: =W28*1.06/L28 -> 0.20605454 | AJ28: =X28*1.06/M28 -> 0.10435878 | AK28: =AA28*1.06/N28 -> 0.17535852 | AM28: 45323 | AN28: 2303032.2 | AO28: =(R28-R27)*10000 -> -933425.68 | AP28: =S28-S27 -> -37.170824
A29: 45352 | B29: ='GMV表-商品大类'!T32+B85 -> 268614.84 | C29: 6554.9001 | D29: =B29+C29 -> 275169.74 | F29: 45352 | G29: ='毛利-收入组成'!AQ53 -> 8421.3423 | H29: 6411571.3 | I29: =H29*1.06/10000 -> 679.62655 | J29: 3319.7856 | K29: =R29*1.06 -> -625.33948 | L29: =G29-I29+J29-K29 -> 11686.841 | M29: 4047.3122 | N29: =L29+M29 -> 15734.153 | P29: 45352 | Q29: =19480246.9399998/10000 -> 1948.0247 | R29: =-5899429.04962477/10000 -> -589.9429 | S29: 484.12228 | W29: =Q29-R29+S29 -> 3022.0899 | X29: -142.42172 | AA29: =W29+X29 -> 2879.6682 | AC29: 45352 | AD29: =L29/B29 -> 0.043507801 | AE29: =M29/C29 -> 0.61744834 | AF29: =N29/D29 -> 0.057179809 | AH29: 45352 | AI29: =W29*1.06/L29 -> 0.27410447 | AJ29: =X29*1.06/M29 -> -0.037300564 | AK29: =AA29*1.06/N29 -> 0.19400143 | AM29: 45352 | AN29: =(Q29-Q28)*10000 -> 13813072 | AO29: =(R29-R28)*10000 -> -3669645.7 | AP29: =S29-S28 -> -180.7063
A30: 45383 | B30: ='GMV表-商品大类'!T33+B86 -> 329663.72 | C30: 7811.5825 | D30: =B30+C30 -> 337475.3 | F30: 45383 | G30: ='毛利-收入组成'!AQ54 -> 9720.5498 | H30: 8210403.3 | I30: =H30*1.06/10000 -> 870.30275 | J30: 3986.5078 | K30: =R30*1.06 -> -630.70441 | L30: =G30-I30+J30-K30 -> 13467.459 | M30: 4692.473 | N30: =L30+M30 -> 18159.932 | P30: 45383 | Q30: =17237592.6600001/10000 -> 1723.7593 | R30: =-5950041.59942243/10000 -> -595.00416 | S30: 527.01729 | W30: =Q30-R30+S30 -> 2845.7807 | X30: -364.30428 | AA30: =W30+X30 -> 2481.4764 | AC30: 45383 | AD30: =L30/B30 -> 0.040852112 | AE30: =M30/C30 -> 0.60070709 | AF30: =N30/D30 -> 0.053811144 | AH30: 45383 | AI30: =W30*1.06/L30 -> 0.22398639 | AJ30: =X30*1.06/M30 -> -0.082294036 | AK30: =AA30*1.06/N30 -> 0.14484443 | AM30: 45383 | AN30: =(Q30-Q29)*10000 -> -2242654.3 | AO30: =(R30-R29)*10000 -> -50612.55 | AP30: =S30-S29 -> 42.895009
A31: 45413 | B31: ='GMV表-商品大类'!T34+B87 -> 411711.95 | C31: 48484.603 | D31: =B31+C31 -> 460196.55 | F31: 45413 | G31: ='毛利-收入组成'!AQ55 -> 11948.968 | H31: 10009914 | I31: =H31*1.06/10000 -> 1061.0509 | J31: 4828.7836 | K31: =R31*1.06 -> -643.36516 | L31: =G31-I31+J31-K31 -> 16360.066 | M31: 5488.1957 | N31: =L31+M31 -> 21848.261 | P31: 45413 | Q31: =17363557.5599997/10000 -> 1736.3558 | R31: =-6069482.61294327/10000 -> -606.94826 | S31: 469.47202 | W31: =Q31-R31+S31 -> 2812.776 | X31: -520.88602 | AA31: =W31+X31 -> 2291.89 | AC31: 45413 | AD31: =L31/B31 -> 0.03973668 | AE31: =M31/C31 -> 0.11319461 | AF31: =N31/D31 -> 0.047475935 | AH31: 45413 | AI31: =W31*1.06/L31 -> 0.18224515 | AJ31: =X31*1.06/M31 -> -0.10060486 | AK31: =AA31*1.06/N31 -> 0.11119436 | AM31: 45413 | AN31: =(Q31-Q30)*10000 -> 125964.9 | AO31: =(R31-R30)*10000 -> -119441.01 | AP31: =S31-S30 -> -57.545267
A32: 45444 | B32: ='GMV表-商品大类'!T35+B88 -> 509385.36 | C32: 57933.49 | D32: =B32+C32 -> 567318.85 | F32: 45444 | G32: ='毛利-收入组成'!AQ56 -> 13920.387 | H32: 13079265 | I32: =H32*1.06/10000 -> 1386.402 | J32: 5206.9754 | K32: =R32*1.06 -> -648.29281 | L32: =G32-I32+J32-K32 -> 18389.253 | M32: 6076.524 | N32: =L32+M32 -> 24465.777 | P32: 45444 | Q32: =20545121.3099999/10000 -> 2054.5121 | R32: =-6115969.92496954/10000 -> -611.59699 | S32: 407.13856 | W32: =Q32-R32+S32 -> 3073.2477 | X32: -1234.8556 | AA32: =W32+X32 -> 1838.3921 | AC32: 45444 | AD32: =L32/B32 -> 0.036100867 | AE32: =M32/C32 -> 0.10488793 | AF32: =N32/D32 -> 0.043125267 | AH32: 45444 | AI32: =W32*1.06/L32 -> 0.17714926 | AJ32: =X32*1.06/M32 -> -0.21541047 | AK32: =AA32*1.06/N32 -> 0.079649857 | AM32: 45444 | AN32: =(Q32-Q31)*10000 -> 3181563.8 | AO32: =(R32-R31)*10000 -> -46487.312 | AP32: =S32-S31 -> -62.333461
A33: 45474 | B33: ='GMV表-商品大类'!T36+B89 -> 607746.8 | C33: 67786.587 | D33: =B33+C33 -> 675533.39 | F33: 45474 | G33: ='毛利-收入组成'!AQ57 -> 16860.607 | H33: 16583095 | I33: =H33*1.06/10000 -> 1757.8081 | J33: 4830.4436 | K33: =R33*1.06 -> 216.82817 | L33: =G33-I33+J33-K33 -> 19716.415 | M33: 7385.8469 | N33: =L33+M33 -> 27102.262 | P33: 45474 | Q33: =28247260.5499999/10000 -> 2824.7261 | R33: =2045548.79526134/10000 -> 204.55488 | S33: 345.70945 | W33: =Q33-R33+S33 -> 2965.8806 | X33: -914.54146 | AA33: =W33+X33 -> 2051.3392 | AC33: 45474 | AD33: =L33/B33 -> 0.032441824 | AE33: =M33/C33 -> 0.10895735 | AF33: =N33/D33 -> 0.040119796 | AH33: 45474 | AI33: =W33*1.06/L33 -> 0.15945259 | AJ33: =X33*1.06/M33 -> -0.13125292 | AK33: =AA33*1.06/N33 -> 0.080230187 | AM33: 45474 | AN33: =(Q33-Q32)*10000 -> 7702139.2 | AO33: =(R33-R32)*10000 -> 8161518.7 | AP33: =S33-S32 -> -61.429102
A34: 45505 | B34: ='GMV表-商品大类'!T37+B90 -> 688414.05 | C34: 77960.769 | D34: =B34+C34 -> 766374.82 | F34: 45505 | G34: ='毛利-收入组成'!AQ58 -> 19501.135 | H34: 17318463 | I34: =H34*1.06/10000 -> 1835.757 | J34: 6482.25 | K34: =R34*1.06 -> 163.1307 | L34: =G34-I34+J34-K34 -> 23984.497 | M34: 8433.5884 | N34: =L34+M34 -> 32418.085 | P34: 45505 | Q34: =31134501.7400001/10000 -> 3113.4502 | R34: =1538968.90630751/10000 -> 153.89689 | S34: 331.25371 | W34: =Q34-R34+S34 -> 3290.807 | X34: -916.40871 | AA34: =W34+X34 -> 2374.3983 | AC34: 45505 | AD34: =L34/B34 -> 0.03484022 | AE34: =M34/C34 -> 0.10817734 | AF34: =N34/D34 -> 0.042300562 | AH34: 45505 | AI34: =W34*1.06/L34 -> 0.14543792 | AJ34: =X34*1.06/M34 -> -0.11518148 | AK34: =AA34*1.06/N34 -> 0.077637595 | AM34: 45505 | AN34: =(Q34-Q33)*10000 -> 2887241.2 | AO34: =(R34-R33)*10000 -> -506579.89 | AP34: =S34-S33 -> -14.455746
A35: 45536 | B35: ='GMV表-商品大类'!T38+B91 -> 748878.18 | C35: 88041.301 | D35: =B35+C35 -> 836919.48 | F35: 45536 | G35: ='毛利-收入组成'!AQ59 -> 21218.058 | H35: 18819047 | I35: =H35*1.06/10000 -> 1994.819 | J35: 7755.0266 | K35: =R35*1.06 -> 163.32379 | L35: =G35-I35+J35-K35 -> 26814.942 | M35: 9463.4699 | N35: =L35+M35 -> 36278.412 | P35: 45536 | Q35: =36119147.9499995/10000 -> 3611.9148 | R35: =1540790.48672378/10000 -> 154.07905 | S35: 741.04432 | W35: =Q35-R35+S35 -> 4198.8801 | X35: -869.18632 | AA35: =W35+X35 -> 3329.6937 | AC35: 45536 | AD35: =L35/B35 -> 0.035806815 | AE35: =M35/C35 -> 0.10748898 | AF35: =N35/D35 -> 0.043347554 | AH35: 45536 | AI35: =W35*1.06/L35 -> 0.16598256 | AJ35: =X35*1.06/M35 -> -0.09735726 | AK35: =AA35*1.06/N35 -> 0.097288585 | AM35: 45536 | AN35: =(Q35-Q34)*10000 -> 4984646.2 | AO35: =(R35-R34)*10000 -> 1821.5804 | AP35: =S35-S34 -> 409.79062
A36: 45566 | B36: ='GMV表-商品大类'!T39+B92 -> 813677.8 | C36: 98052.555 | D36: =B36+C36 -> 911730.36 | F36: 45566 | G36: ='毛利-收入组成'!AQ60 -> 23238.672 | H36: 20057337 | I36: =H36*1.06/10000 -> 2126.0777 | J36: 8747.211 | K36: =R36*1.06 -> 259.79516 | L36: =G36-I36+J36-K36 -> 29600.01 | M36: 10528.913 | N36: =L36+M36 -> 40128.923 | P36: 45566 | Q36: =37390549.6399998/10000 -> 3739.055 | R36: =2450897.73613187/10000 -> 245.08977 | S36: 862.00698 | W36: =Q36-R36+S36 -> 4355.9722 | X36: -708.53098 | AA36: =W36+X36 -> 3647.4412 | AC36: 45566 | AD36: =L36/B36 -> 0.036378048 | AE36: =M36/C36 -> 0.1073803 | AF36: =N36/D36 -> 0.044014026 | AH36: 45566 | AI36: =W36*1.06/L36 -> 0.15599084 | AJ36: =X36*1.06/M36 -> -0.071331469 | AK36: =AA36*1.06/N36 -> 0.096346658 | AM36: 45566 | AN36: =(Q36-Q35)*10000 -> 1271401.7 | AO36: =(R36-R35)*10000 -> 910107.25 | AP36: =S36-S35 -> 120.96266
A37: 45597 | B37: ='GMV表-商品大类'!T40+B93 -> 882563.82 | C37: 108422.02 | D37: =B37+C37 -> 990985.84 | F37: 45597 | G37: ='毛利-收入组成'!AQ61 -> 25333.258 | H37: 19330114 | I37: =H37*1.06/10000 -> 2048.9921 | J37: 9819.6838 | K37: =R37*1.06 -> 46.743328 | L37: =G37-I37+J37-K37 -> 33057.207 | M37: 11601.376 | N37: =L37+M37 -> 44658.582 | P37: 45597 | Q37: =39282359.86/10000 -> 3928.236 | R37: =440974.792297676/10000 -> 44.097479 | S37: 1143.8451 | W37: =Q37-R37+S37 -> 5027.9836 | X37: -559.21109 | AA37: =W37+X37 -> 4468.7725 | AC37: 45597 | AD37: =L37/B37 -> 0.037455883 | AE37: =M37/C37 -> 0.10700202 | AF37: =N37/D37 -> 0.045064804 | AH37: 45597 | AI37: =W37*1.06/L37 -> 0.16122544 | AJ37: =X37*1.06/M37 -> -0.051094264 | AK37: =AA37*1.06/N37 -> 0.10606917 | AM37: 45597 | AN37: =(Q37-Q36)*10000 -> 1891810.2 | AO37: =(R37-R36)*10000 -> -2009922.9 | AP37: =S37-S36 -> 281.8381
A38: 45627 | B38: ='GMV表-商品大类'!T41+B94 -> 950049.95 | C38: 120473.04 | D38: =B38+C38 -> 1070523 | F38: 45627 | G38: ='毛利-收入组成'!AQ62 -> 28076.738 | H38: 20867964 | I38: =H38*1.06/10000 -> 2212.0042 | J38: 10371.365 | K38: =R38*1.06 -> -5.9447039 | L38: =G38-I38+J38-K38 -> 36242.044 | M38: 13216.352 | N38: =L38+M38 -> 49458.396 | P38: 45627 | Q38: =30259069.27/10000 -> 3025.9069 | R38: =-56082.1122934511/10000 -> -5.6082112 | S38: 799.44024 | W38: =Q38-R38+S38 -> 3830.9554 | X38: -191.65324 | AA38: =W38+X38 -> 3639.3021 | AC38: 45627 | AD38: =L38/B38 -> 0.038147514 | AE38: =M38/C38 -> 0.10970382 | AF38: =N38/D38 -> 0.046200219 | AH38: 45627 | AI38: =W38*1.06/L38 -> 0.11204701 | AJ38: =X38*1.06/M38 -> -0.015371294 | AK38: =AA38*1.06/N38 -> 0.077998087 | AM38: 45627 | AN38: =(Q38-Q37)*10000 -> -9023290.6 | AO38: =(R38-R37)*10000 -> -497056.9 | AP38: =S38-S37 -> -344.40485
A39: 45658 | B39: ='GMV表-商品大类'!T42+B95 -> 81145.313 | C39: 12379.049 | D39: =B39+C39 -> 93524.362 | F39: 45658 | G39: ='毛利-收入组成'!AQ63 -> 2087.8323 | H39: 1143231.9 | I39: =H39*1.06/10000 -> 121.18258 | J39: 2206.1643 | K39: =R39*1.06 -> -180.42851 | L39: =G39-I39+J39-K39 -> 4353.2426 | M39: 1241.357 | N39: =L39+M39 -> 5594.5996 | P39: 45658 | Q39: =2904342.15/10000 -> 290.43421 | R39: =-1702155.76979259/10000 -> -170.21558 | S39: 744.55228 | W39: =Q39-R39+S39 -> 1205.2021 | X39: 36.057099 | AA39: =W39+X39 -> 1241.2592 | AC39: 45658 | AD39: =L39/B39 -> 0.053647493 | AE39: =M39/C39 -> 0.10027887 | AF39: =N39/D39 -> 0.059819703 | AH39: 45658 | AI39: =W39*1.06/L39 -> 0.29346267 | AJ39: =X39*1.06/M39 -> 0.030789309 | AK39: =AA39*1.06/N39 -> 0.23517943 | AM39: 45658 | AN39: =Q39*10000 -> 2904342.1 | AO39: =R39*10000 -> -1702155.8 | AP39: =S39 -> 744.55228
A40: 45689 | B40: ='GMV表-商品大类'!T43+B96 -> 143043.59 | C40: 15190.545 | D40: =B40+C40 -> 158234.13 | F40: 45689 | G40: ='毛利-收入组成'!AQ64 -> 4874.4917 | H40: 2075803.2 | I40: =H40*1.06/10000 -> 220.03514 | J40: 2816.3186 | K40: =R40*1.06 -> -266.66127 | L40: =G40-I40+J40-K40 -> 7737.4364 | M40: 2372.3631 | N40: =L40+M40 -> 10109.8 | P40: 45689 | Q40: =14521013.01/10000 -> 1452.1013 | R40: =-2515672.38594156/10000 -> -251.56724 | S40: 771.90753 | W40: =Q40-R40+S40 -> 2475.5761 | X40: 26.999682 | AA40: =W40+X40 -> 2502.5757 | AC40: 45689 | AD40: =L40/B40 -> 0.054091459 | AE40: =M40/C40 -> 0.15617367 | AF40: =N40/D40 -> 0.063891395 | AH40: 45689 | AI40: =W40*1.06/L40 -> 0.33914471 | AJ40: =X40*1.06/M40 -> 0.012063778 | AK40: =AA40*1.06/N40 -> 0.26239198 | AM40: 45689 | AN40: =(Q40-Q39)*10000 -> 11616671 | AO40: =(R40-R39)*10000 -> -813516.62 | AP40: =(S40-S39) -> 27.355244
...

Sheet 投资公司
A1: 2025年
A2: 类别 | B2: 葫芦藤体内项目毛利 | C2: 累计净利润 | D2: 1月利润 | E2: 2月利润 | F2: 3月利润 | G2: 4月利润 | H2: 5月利润 | I2: 6月利润 | J2: 7月利润 | K2: 8月利润 | L2: 9月利润 | M2: 10月利润 | N2: 11月利润 | O2: 12月利润
A3: 1、手游 | B3: 游戏直播 | C3: =SUM(D3:O3) -> 5.464 | I3: 7.059 | J3: =-27.65-I3 -> -34.709 | K3: -0.037 | L3: 31.138 | M3: 2.012 | N3: 0 | O3: 0.001
A4: 2、网游 | C4: =SUM(D4:O4) -> 0 | M4: 0
A5: 3、通信 | C5: =SUM(D5:O5) -> 0 | M5: 0
A6: 4、网娱 | B6: 渠道线&游戏电商&直播中心 | C6: =SUM(D6:O6) -> 418.85566 | D6: 77.701 | E6: 6.228 | F6: 106.762 | G6: 78.746 | H6: 76.203 | I6: =281.088987-7.059-(38.674+377.647) -> -142.29101 | J6: =232.934-SUM(D6:I6) -> 29.585013 | K6: 132.251 | L6: 76.318 | M6: 83.93 | N6: -147.993 | O6: =(63.035-1217774/1.06/10000)+17.31+75.955 -> 41.41566
A7: 5、生活服务 | B7: 客户发展&灵活用工项目-推广 | C7: =SUM(D7:O7) -> 671.72952 | I7: =38.674+377.647 -> 416.321 | J7: =461.05-I7 -> 44.729 | K7: 64.544117 | L7: 29.013872 | M7: 84.95648 | N7: 7.982971 | O7: =11.968+12.21408 -> 24.18208
A8: 合计 | B8: =SUM(B3:B7) -> 0 | C8: =SUM(C3:C7) -> 1096.0492 | D8: =SUM(D3:D7) -> 77.701 | E8: =SUM(E3:E7) -> 6.228 | F8: =SUM(F3:F7) -> 106.762 | G8: =SUM(G3:G7) -> 78.746 | H8: =SUM(H3:H7) -> 76.203 | I8: =SUM(I3:I7) -> 281.08899 | ... O8: =SUM(O3:O7) -> 65.59874
A9: 含税金额 | C9: =C8*1.06 -> 1161.8121 | D9: =D8*1.06 -> 82.36306 | E9: =E8*1.06 -> 6.60168 | F9: =F8*1.06 -> 113.16772 | G9: =G8*1.06 -> 83.47076 | H9: =H8*1.06 -> 80.77518 | I9: =I8*1.06 -> 297.95433 | J9: =J8*1.06 -> 41.981314 | ... O9: =O8*1.06 -> 69.534665
A11: 2024年
A12: 类别 | B12: 调整博宽&黄石福桃等渠道电商毛利 | C12: 累计净利润 | D12: 1月利润 | E12: 2月利润 | F12: 3月利润 | G12: 4月利润 | H12: 5月利润 | I12: 6月利润 | J12: 7月利润 | K12: 8月利润 | L12: 9月利润 | M12: 10月利润 | N12: 11月利润 | O12: 12月利润
A13: 1、手游
A14: 2、网游
A15: 3、通信
A16: 4、网娱 | C16: =SUM(D16:O16) -> 366.107 | D16: =377.983-2659414.53/10000 -> 112.04155 | E16: =191.57-3869946.72/10000 -> -195.42467 | F16: =-429.26--5370695.59/10000 -> 107.80956 | G16: =-29.559-2165911.16/10000 -> -246.15012 | H16: 96.61 | I16: -3.44 | J16: 191.09 | K16: 71.15 | L16: 20.14 | M16: 57.43 | N16: 209.28868 | O16: -54.438
A17: 5、生活服务
A18: 合计 | B18: =SUM(B13:B17) -> 0 | C18: =SUM(C13:C17) -> 366.107 | D18: =SUM(D13:D17) -> 112.04155 | E18: =SUM(E13:E17) -> -195.42467 | F18: =SUM(F13:F17) -> 107.80956 | G18: =SUM(G13:G17) -> -246.15012 | H18: =SUM(H13:H17) -> 96.61 | I18: =SUM(I13:I17) -> -3.44 | ... O18: =SUM(O13:O17) -> -54.438
A19: 含税金额 | C19: =C18*1.06 -> 388.07342 | D19: =D18*1.06 -> 118.76404 | E19: =E18*1.06 -> -207.15015 | F19: =F18*1.06 -> 114.27813 | G19: =G18*1.06 -> -260.91912 | H19: =H18*1.06 -> 102.4066 | I19: =I18*1.06 -> -3.6464 | J19: =J18*1.06 -> 202.5554 | ... O19: =O18*1.06 -> -57.70428
A21: 2023年
A22: 类别 | B22: 调整博宽&黄石福桃等渠道电商毛利 | C22: 累计净利润 | D22: 1月利润 | E22: 2月利润 | F22: 3月利润 | G22: 4月利润 | H22: 5月利润 | I22: 6月利润 | J22: 7月利润 | K22: 8月利润 | L22: 9月利润 | M22: 10月利润 | N22: 11月利润 | O22: 12月利润
A23: 1、手游
A24: 2、网游
A25: 3、通信
A26: 4、网娱 | C26: =SUM(D26:O26) -> 219.71 | D26: 98.863 | E26: 88.266 | F26: 112.98 | G26: -111.401 | H26: -41.707 | I26: -100.897 | J26: 160.729 | K26: 125.174 | L26: -208.57 | M26: 179.757 | N26: 53.982 | O26: -137.466
A27: 5、生活服务
A28: 合计 | B28: =SUM(B23:B27) -> 0 | C28: =SUM(C23:C27) -> 219.71 | F28: =SUM(F23:F27) -> 112.98 | G28: =SUM(G23:G27) -> -111.401 | H28: =SUM(H23:H27) -> -41.707 | I28: =SUM(I23:I27) -> -100.897 | J28: =SUM(J23:J27) -> 160.729 | K28: =SUM(K23:K27) -> 125.174 | L28: =SUM(L23:L27) -> -208.57 | M28: =SUM(M23:M27) -> 179.757 | ... O28: =SUM(O23:O27) -> -137.466
A29: 含税金额 | C29: =C28*1.06 -> 232.8926 | D29: =D28*1.06 -> 0 | E29: =E28*1.06 -> 0 | F29: =F28*1.06 -> 119.7588 | G29: =G28*1.06 -> -118.08506 | H29: =H28*1.06 -> -44.20942 | I29: =I28*1.06 -> -106.95082 | J29: =J28*1.06 -> 170.37274 | ... O29: =O28*1.06 -> -145.71396

Sheet GMV销售额波动分析（分月、年）
A1: 2025年 | B1: SP0001-网游 | C1: SP0005-手游 | D1: SP0002-通信 | E1: SP0003-网娱 | F1: SP0004-卡劵 | G1: SP0006-生活服务 | H1: 总计（含税） | I1: 体内公司GMV | J1: 月份 | K1: 2025年GMV | L1: 2024年GMV | M1: 同期增长
A2: 1月 | B2: 45102810 | C2: 75000597 | D2: 9435812.5 | E2: 2.0356185e+08 | F2: 3.6554639e+08 | G2: 277292.49 | H2: =SUM(B2:G2) -> 6.9892476e+08 | I2: =H2/10000-GMV销售平台占比!B17 -> 6.9849193e-10 | J2: 1月 | K2: =H2/100000000 -> 6.9892476 | L2: =H17/100000000 -> 8.3841662 | M2: =(K2-L2)/L2 -> -0.16637536 | N2: =K2-L2 -> -1.3949187
A3: 2月 | B3: 29914547 | C3: 33284884 | D3: 12224513 | E3: 1.8650532e+08 | F3: 2.8944267e+08 | G3: 697463.75 | H3: =SUM(B3:G3) -> 5.5206939e+08 | J3: 2月 | K3: =H3/100000000 -> 5.5206939 | L3: =H18/100000000 -> 7.6218049 | M3: =(K3-L3)/L3 -> -0.27567105
A4: 3月 | B4: 23250822 | C4: 38931285 | D4: 4582458.6 | E4: 1.8891607e+08 | F4: 4.1025231e+08 | G4: 50935.907 | H4: =SUM(B4:G4) -> 6.6598388e+08 | J4: 3月 | K4: =H4/100000000 -> 6.6598388 | L4: =H19/100000000 -> 6.6832889 | M4: =(K4-L4)/L4 -> -0.0035087704
A5: 4月 | B5: 26883010 | C5: 46615668 | D5: 3360143.8 | E5: 1.7304789e+08 | F5: 3.5350825e+08 | G5: 45091.202 | H5: =SUM(B5:G5) -> 6.0346005e+08 | J5: 4月 | K5: =H5/100000000 -> 6.0346005 | L5: =H20/100000000 -> 5.0345297 | M5: =(K5-L5)/L5 -> 0.19864235
A6: 5月 | B6: 37315216 | C6: 1.0025681e+08 | D6: 3366603.9 | E6: 1.7290566e+08 | F6: 2.90837e+08 | G6: 36996.619 | H6: =SUM(B6:G6) -> 6.0471829e+08 | J6: 5月 | K6: =H6/100000000 -> 6.0471829 | L6: =H21/100000000 -> 7.0552966 | M6: =(K6-L6)/L6 -> -0.1428875
A7: 6月 | B7: 44748189 | C7: 41902247 | D7: 2880591.8 | E7: 1.2474516e+08 | F7: 3.5477031e+08 | G7: 93346.506 | H7: =SUM(B7:G7) -> 5.6913985e+08 | J7: 6月 | K7: =H7/100000000 -> 5.6913985 | L7: =H22/100000000 -> 8.3802748 | M7: =(K7-L7)/L7 -> -0.32085777
A8: 7月 | B8: 40140017 | C8: 47381046 | D8: 2957178.4 | E8: 75125965 | F8: 4.6261523e+08 | G8: 2103107.7 | H8: =SUM(B8:G8) -> 6.3032255e+08 | J8: 7月 | K8: =H8/100000000 -> 6.3032255 | L8: =H23/100000000 -> 8.2004978 | M8: =(K8-L8)/L8 -> -0.23136063
A9: 8月 | B9: 38764101 | C9: 57682762 | D9: 3647053.4 | E9: 84315661 | F9: 5.2488302e+08 | G9: 1186092.5 | H9: =SUM(B9:G9) -> 7.1047869e+08 | I9: =H9/10000-'GMV表-商品大类'!F49 -> 0 | J9: 8月 | K9: =H9/100000000 -> 7.1047869 | L9: =H24/100000000 -> 7.5165771 | M9: =(K9-L9)/L9 -> -0.054784265
A10: 9月 | B10: 28150837 | C10: 1.0835199e+08 | D10: 3315332.7 | E10: 87118571 | F10: 5.0121265e+08 | G10: 3348273.6 | H10: =SUM(B10:G10) -> 7.3149766e+08 | J10: 9月 | K10: =H10/100000000 -> 7.3149766 | L10: =H25/100000000 -> 5.2618104 | M10: =(K10-L10)/L10 -> 0.39020146
A11: 10月 | B11: 27253234 | C11: 1.0098886e+08 | D11: 3440109.1 | E11: 92681238 | F11: 3.9677189e+08 | G11: 529975.24 | H11: =SUM(B11:G11) -> 6.2166531e+08 | J11: 10月 | K11: =H11/100000000 -> 6.2166531 | L11: =H26/100000000 -> 5.901137 | M11: =(K11-L11)/L11 -> 0.053466991
A12: 11月 | B12: 36611701 | C12: 1.0402716e+08 | D12: 3413736 | E12: 1.0587371e+08 | F12: 4.0635999e+08 | G12: 186184.83 | H12: =SUM(B12:G12) -> 6.5647248e+08 | J12: 11月 | K12: =H12/100000000 -> 6.5647248 | L12: =H27/100000000 -> 6.1812962 | M12: =(K12-L12)/L12 -> 0.062030461
A13: 12月 | B13: 35827984 | C13: =101631883.7308+11608600.18-11608600.18 -> 1.0163188e+08 | D13: 3342888.6 | E13: 1.1975211e+08 | F13: 6.1052145e+08 | G13: 1025884.7 | H13: =SUM(B13:G13) -> 8.721022e+08 | J13: 12月 | K13: =H13/100000000 -> 8.721022 | L13: =H28/100000000 -> 6.0199264 | M13: =(K13-L13)/L13 -> 0.44869247
A14: 合计 | B14: =SUM(B2:B13) -> 4.1396247e+08 | C14: =SUM(C2:C13) -> 8.560552e+08 | D14: =SUM(D2:D13) -> 55966421 | E14: =SUM(E2:E13) -> 1.6145492e+09 | F14: =SUM(F2:F13) -> 4.9667212e+09 | G14: =SUM(G2:G13) -> 9580645.1 | H14: =SUM(H2:H13) -> 7.9168351e+09 | J14: 合计（亿元） | K14: =SUM(K2:K13) -> 79.168351 | L14: =SUM(L2:L13) -> 82.240606 | M14: =(K14-L14)/L14 -> -0.037356911 | N14: =K14-L14 -> -3.072255 | O14: =N14/L14 -> -0.037356911
J15: 累计数贴PPT37
A16: 2024年 | B16: SP0001-网游 | C16: SP0005-手游 | D16: SP0002-通信 | E16: SP0003-网娱 | F16: SP0004-卡劵 | G16: SP0006-生活服务 | H16: 总计（含税） | J16: 商品大类 | K16: 2024年 | L16: 2023年 | M16: 变动额 | N16: 变动率
A17: 1月 | B17: 1.6394352e+08 | C17: 72069322 | D17: 57651169 | E17: 2.2038104e+08 | F17: 3.2436856e+08 | G17: 3015.47 | H17: 8.3841662e+08 | J17: 网游 | K17: =B14/10000 -> 41396.247 | L17: =SUM(B32:B43)/10000 -> 204213.4 | M17: =K17-L17 -> -162817.16 | N17: =M17/L17 -> -0.79728928 | O17: =K17+K18 -> 127001.77 | P17: =L17+L18 -> 288229.3
A18: 2月 | B18: 1.2902059e+08 | C18: 78670926 | D18: 51869185 | E18: 2.0630623e+08 | F18: 2.9632854e+08 | G18: -14984.47 | H18: 7.6218049e+08 | J18: 手游 | K18: =C14/10000 -> 85605.52 | L18: =SUM(C32:C43)/10000 -> 84015.899 | M18: =K18-L18 -> 1589.6209 | N18: =M18/L18 -> 0.018920477 | P18: =(O17-P17)/P17 -> -0.55937247
A19: 3月 | B19: 40868843 | C19: 40313324 | D19: 61579069 | E19: 2.4007575e+08 | F19: 2.8386047e+08 | G19: 1631435.1 | H19: 6.6832889e+08 | J19: 通信 | K19: =D14/10000 -> 5596.6421 | L19: =SUM(D32:D43)/10000 -> 212342.83 | M19: =K19-L19 -> -206746.19 | N19: =M19/L19 -> -0.97364337
A20: 4月 | B20: 36836160 | C20: 30957288 | D20: 31064079 | E20: 2.3861802e+08 | F20: 1.659334e+08 | G20: 44022.467 | H20: 5.0345297e+08 | J20: 网娱 | K20: =E14/10000 -> 161454.92 | L20: =SUM(E32:E43)/10000 -> 505603.59 | M20: =K20-L20 -> -344148.67 | N20: =M20/L20 -> -0.68066896
A21: 5月 | B21: 36434632 | C21: 80871997 | D21: 23162770 | E21: 2.994851e+08 | F21: 2.6579687e+08 | G21: -221706.87 | H21: 7.0552966e+08 | J21: 生活服务 | K21: =(F14+G14)/10000 -> 497630.18 | L21: =SUM(F32:G43)/10000 -> 554277.85 | M21: =K21-L21 -> -56647.665 | N21: =M21/L21 -> -0.10220085
A22: 6月 | B22: 77715917 | C22: 92084688 | D22: 14168628 | E22: 3.4860498e+08 | F22: 3.052408e+08 | G22: 212456.67 | H22: 8.3802748e+08 | J22: 总计（万元） | K22: =SUM(K17:K21) -> 791683.51 | L22: =SUM(L17:L21) -> 1560453.6 | M22: =SUM(M17:M21) -> -768770.07 | N22: =M22/L22 -> -0.49265808
A23: 7月 | B23: 83089797 | C23: 1.3250714e+08 | D23: 14913498 | E23: 2.4546108e+08 | F23: 3.3679378e+08 | G23: 7284483.8 | H23: 8.2004978e+08
A24: 8月 | B24: 49122371 | C24: 66704878 | D24: 25481143 | E24: 3.0002115e+08 | F24: 3.0906987e+08 | G24: 1258291.4 | H24: 7.5165771e+08
A25: 9月 | B25: 29245115 | C25: 48236433 | D25: 12906205 | E25: 2.2928796e+08 | F25: 2.0652896e+08 | G25: -23631.13 | H25: 5.2618104e+08
A26: 10月 | B26: 30810565 | C26: 55595035 | D26: 9471714.6 | E26: 2.3255981e+08 | F26: 2.6141187e+08 | G26: 264707.59 | H26: 5.901137e+08
A27: 11月 | B27: 24768660 | C27: 61722499 | D27: 6958838.9 | E27: 2.5892265e+08 | F27: 2.656238e+08 | G27: 133170.18 | H27: 6.1812962e+08
A28: 12月 | B28: 17633355 | C28: 34982091 | D28: 6161395.9 | E28: 2.6412947e+08 | F28: 2.7877715e+08 | G28: 309180.8 | H28: 6.0199264e+08
A29: 合计 | B29: =SUM(B17:B28) -> 7.1948953e+08 | C29: =SUM(C17:C28) -> 7.9471562e+08 | D29: =SUM(D17:D28) -> 3.153877e+08 | E29: =SUM(E17:E28) -> 3.0838533e+09 | F29: =SUM(F17:F28) -> 3.2997341e+09 | G29: =SUM(G17:G28) -> 10880441 | H29: =SUM(H17:H28) -> 8.2240606e+09
A31: 2023年 | B31: SP0001-网游 | C31: SP0005-手游 | D31: SP0002-通信 | E31: SP0003-网娱 | F31: SP0004-卡劵 | G31: SP0006-生活服务 | H31: 总计（含税）
A32: 1月 | B32: 1.0755749e+08 | C32: 1.2230208e+08 | D32: 2.927875e+08 | E32: 4.8836984e+08 | F32: 3.2916948e+08 | G32: 5629439.6 | H32: =SUM(B32:G32) -> 1.3458158e+09
A33: 2月 | B33: 86491645 | C33: 48095782 | D33: 3.841738e+08 | E33: 4.5017964e+08 | F33: 3.5004372e+08 | G33: 7076.29 | H33: =SUM(B33:G33) -> 1.3189917e+09
A34: 3月 | B34: 1.088094e+08 | C34: 67960161 | D34: 4.0696017e+08 | E34: =481032330.11-13500000 -> 4.6753233e+08 | F34: 4.8239142e+08 | G34: -551189.73 | H34: =SUM(B34:G34) -> 1.5331023e+09
A35: 4月 | B35: 2.050828e+08 | C35: 45919678 | D35: 1.4908958e+08 | E35: =398767570-12500000 -> 386267570 | F35: 4.6616905e+08 | G35: 4267.31 | H35: =SUM(B35:G35) -> 1.2525329e+09
A36: 5月 | B36: 3.3263003e+08 | C36: 1.0672384e+08 | D36: 1.4554824e+08 | E36: 3.4806915e+08 | F36: 5.457605e+08 | G36: -17436.15 | H36: =SUM(B36:G36) -> 1.4787143e+09
A37: 6月 | B37: 2.8460326e+08 | C37: 38830643 | D37: 1.8696408e+08 | E37: 4.0582857e+08 | F37: 6.5744036e+08 | G37: 2100.07 | H37: =SUM(B37:G37) -> 1.573669e+09
A38: 7月 | B38: 2.1237629e+08 | C38: 68821147 | D38: 1.2591962e+08 | E38: 3.5418136e+08 | F38: 5.528262e+08 | G38: 10513.11 | H38: =SUM(B38:G38) -> 1.3141351e+09
A39: 8月 | B39: 2.0523625e+08 | C39: 1.1420637e+08 | D39: 1.234218e+08 | E39: 4.1823418e+08 | F39: 6.1102003e+08 | G39: 2183.91 | H39: =SUM(B39:G39) -> 1.4721208e+09
A40: 9月 | B40: 2.1353486e+08 | C40: 51971549 | D40: 97829884 | E40: 3.9707166e+08 | F40: 4.9935928e+08 | G40: 6539.06 | H40: =SUM(B40:G40) -> 1.2597738e+09
A41: 10月 | B41: 89061955 | C41: 36377220 | D41: 72310873 | E41: 3.9956302e+08 | F41: 3.6598322e+08 | G41: -70181.51 | H41: =SUM(B41:G41) -> 9.632261e+08
...

Sheet GMV销售平台占比
A1: 2025年
A2: 平台 | B2: 1月 | C2: 2月 | D2: 3月 | E2: 4月 | F2: 5月 | G2: 6月 | H2: 7月 | I2: 8月 | J2: 9月 | K2: 10月 | L2: 11月 | M2: 12月 | N2: 合计 | O2: 平台GMV占比 | Q2: 平台 | R2: 2025年 | S2: 2024年 | T2: 2023年 | U2: 2022年
A3: 福禄开放平台 | B3: 55063.067 | C3: 45120.512 | D3: 57418.92 | E3: 51803.522 | F3: 45322.133 | G3: 43295.323 | H3: 48615.93 | I3: =55589.0837440203+108.94/10000 -> 55589.095 | J3: 55216.189 | K3: 44896.934 | L3: 49122.948 | M3: =71166.6857643303+11608600.18/10000-11608600.18/10000 -> 71166.686 | N3: =(SUM(B3:M3)) -> 622631.26 | O3: =ROUND(N3/$N$17,4) -> 0.7864 | P3: =N3-N22 -> 22405.68 | Q3: TOB | R3: =R13/Y13 -> 0.84717978 | S3: =R14/Y14 -> 0.7298409 | T3: =R15/Y15 -> 0.69194426 | U3: =R16/Y16 -> 0.67893398 | AB3: =N3-N22 -> 22405.68 | AC3: =AB3/N22 -> 0.037328766
A4: 福游云平台 | E4: 31.579643 | F4: 705.67017 | G4: 2546.6727 | H4: 2700.307 | I4: 4142.5863 | J4: 9701.1453 | K4: 8663.3645 | L4: 9221.6356 | M4: 9515.0403 | N4: =(SUM(B4:M4)) -> 47228.001 | O4: =ROUND(N4/$N$17,4) -> 0.0597 | Q4: 京东 | R4: =S13/Y13 -> 0.0031510534 | S4: =S14/Y14 -> 0.060596688 | T4: =S15/Y15 -> 0.095458353 | U4: =S16/Y16 -> 0.12832323
A5: TOB平台 | L5: 178.4694 | M5: 715.99161 | N5: =(SUM(B5:M5)) -> 894.46101 | O5: =ROUND(N5/$N$17,4) -> 0.0011 | Q5: 天猫 | R5: =T13/Y13 -> 0.026382133 | S5: =T14/Y14 -> 0.049586303 | T5: =T15/Y15 -> 0.062372006 | U5: =T16/Y16 -> 0.063652707
A6: 京东 | B6: 190.33022 | C6: 199.69965 | D6: 194.03104 | E6: 183.95279 | F6: 467.27444 | G6: 658.6546 | H6: 1.0980527 | I6: 97.612906 | J6: 70.949964 | K6: 148.99086 | L6: 158.97491 | M6: 123.27384 | N6: =(SUM(B6:M6)) -> 2494.8433 | O6: =ROUND(N6/$N$17,4) -> 0.0032 | P6: =O6+O7+O8 -> 0.0331 | Q6: 拼多多 | R6: =U13/Y13 -> 0.0034954953 | S6: =U14/Y14 -> 0.0037359517 | T6: =U15/Y15 -> 0.0034942153 | U6: =U16/Y16 -> 0.013988165
A7: 天猫 | B7: 2049.7325 | C7: 1846.0403 | D7: 1706.0095 | E7: 1664.0018 | F7: 2202.8411 | G7: 1977.3084 | H7: 1709.1216 | I7: 1623.5382 | J7: 841.0991 | K7: 2493.3202 | L7: 1296.4332 | M7: 1478.581 | N7: =(SUM(B7:M7)) -> 20888.027 | O7: =ROUND(N7/$N$17,4) -> 0.0264 | Q7: 支付宝小程序 | R7: =V13/Y13 -> 0.079487559 | S7: =V14/Y14 -> 0.0902878 | T7: =V15/Y15 -> 0.068240155 | U7: =V16/Y16 -> 0.030087931
A8: 拼多多 | B8: 230.92896 | C8: 199.5126 | D8: 226.99423 | E8: 171.59552 | F8: 210.09979 | G8: 259.57187 | H8: 285.84206 | I8: 223.07519 | J8: 186.76374 | K8: 231.65394 | L8: 304.51737 | M8: 236.99954 | N8: =(SUM(B8:M8)) -> 2767.5548 | O8: =ROUND(N8/$N$17,4) -> 0.0035 | Q8: 抖快 | R8: =W13/Y13 -> 0.023426601 | S8: =W14/Y14 -> 0.035960964 | T8: =W15/Y15 -> 0.041035133 | U8: =W16/Y16 -> 0.024833133
A9: 支付宝小程序 | B9: 7907.5419 | C9: 5765.9562 | D9: 5728.9415 | E9: 4580.5479 | F9: 4494.4352 | G9: 6285.4866 | H9: 7367.2304 | I9: 7398.0521 | J9: 5078.521 | K9: 3301.592 | L9: 2872.1234 | M9: 2153.7649 | N9: =(SUM(B9:M9)) -> 62934.193 | O9: =ROUND(N9/$N$17,4) -> 0.0795 | Q9: 其他 | R9: =X13/Y13 -> 0.016877376 | S9: =X14/Y14 -> 0.029991394 | T9: =X15/Y15 -> 0.037455881 | U9: =X16/Y16 -> 0.32106602
A10: 抖音 | B10: 3623.411 | C10: 1339.3877 | D10: 547.55514 | E10: 899.18485 | F10: 6022.9674 | G10: 718.47917 | H10: 1363.9833 | I10: 867.92285 | J10: 900.60897 | K10: 920.27192 | L10: 794.15799 | M10: 292.8022 | N10: =(SUM(B10:M10)) -> 18290.732 | O10: =ROUND(N10/$N$17,4) -> 0.0231 | P10: =O10+O11 -> 0.0234 | Q10: 小计 | R10: =SUM(R3:R9) -> 1 | S10: =SUM(S3:S9) -> 1 | T10: =SUM(T3:T9) -> 1 | U10: =SUM(U3:U9) -> 1.2608852
A11: 快手 | B11: 0 | C11: 0 | D11: 0 | E11: 35.226567 | F11: 27.489975 | G11: 23.483136 | H11: 67.845025 | I11: 83.636968 | J11: 12.822216 | K11: 0.8307702 | L11: 5.5903112 | M11: 0.330229 | N11: =(SUM(B11:M11)) -> 257.2552 | O11: =ROUND(N11/$N$17,4) -> 0.0003
A12: 微信 | B12: 0.00845142 | C12: 0.00939968 | D12: 1.9206678 | E12: 3.5007104 | F12: 7.2964773 | G12: 3.3149819 | H12: 32.526796 | I12: 93.968823 | J12: 4.821247 | K12: 134.05461 | L12: 3.2586008 | M12: 3.0619577 | N12: =(SUM(B12:M12)) -> 287.74272 | O12: =ROUND(N12/$N$17,4) -> 0.0004 | Q12: 渠道大类 | R12: TOB | S12: 京东 | T12: 天猫 | U12: 拼多多 | V12: 支付宝小程序 | W12: 抖快 | X12: 第三方B2B2C | Y12: 合计（万元） | Z12: TOC | AA12: 验算
A13: 第三方平台 | B13: 790.75542 | C13: 704.81211 | D13: 742.65797 | E13: 935.42259 | F13: 969.39961 | G13: 1099.4609 | H13: 858.72859 | I13: 902.99937 | J13: 1110.287 | K13: 1415.7339 | L13: 1647.8698 | M13: 1466.3648 | N13: =(SUM(B13:M13)) -> 12644.492 | O13: =ROUND(N13/$N$17,4) -> 0.016 | Q13: 2025年 | R13: =N3+N4+N5 -> 670753.72 | S13: =N6 -> 2494.8433 | T13: =N7 -> 20888.027 | U13: =N8 -> 2767.5548 | V13: =N9 -> 62934.193 | W13: =N10+N11 -> 18547.988 | X13: =Y13-SUM(R13:W13) -> 13362.645 | Y13: =N17 -> 791748.97 | Z13: =Y13-R13 -> 120995.25 | AA13: =Y13-'GMV表-商品大类'!F61 -> 65.461797
A14: 充值频道 | B14: 22.783026 | C14: 19.475482 | D14: 20.449559 | E14: 20.691139 | F14: 16.109016 | G14: 29.63618 | H14: 18.880263 | I14: 19.177948 | J14: 21.060196 | K14: 18.389809 | L14: 34.353121 | M14: 44.106587 | N14: =(SUM(B14:M14)) -> 285.11233 | O14: =ROUND(N14/$N$17,4) -> 0.0004 | Q14: 2024年 | R14: =N22 -> 600225.58 | S14: =N23 -> 49835.083 | T14: =N24 -> 40780.076 | U14: =N25 -> 3072.4693 | V14: =N26 -> 74253.234 | W14: =N27+N28 -> 29574.515 | X14: =Y14-SUM(R14:W14) -> 24665.104 | Y14: =N35 -> 822406.06 | Z14: =Y14-R14 -> 222180.48 | AA14: =Y14-'GMV表-商品大类'!F60 -> -7.3341653e-09
A15: 百度小程序 | B15: 0.00039 | C15: 0.00499048 | D15: 0.00124 | E15: 0.0007 | F15: 0.00499048 | G15: 0 | H15: 0 | I15: 0 | J15: 0 | K15: 0 | L15: 0 | M15: 0 | N15: =(SUM(B15:M15)) -> 0.01231096 | O15: =ROUND(N15/$N$17,4) -> 0 | Q15: 2023年 | R15: =N40 -> 1079746.9 | S15: =N41 -> 148958.33 | T15: =N42 -> 97328.619 | U15: =N43 -> 5452.5608 | V15: =N44 -> 106485.59 | W15: =N45+N46 -> 64033.42 | X15: =Y15-SUM(R15:W15) -> 58448.164 | Y15: =N54 -> 1560453.6 | Z15: =Y15-R15 -> 480706.69 | AA15: =Y15-'GMV表-商品大类'!F59 -> 0.00060700113
A16: mall商城 | B16: 13.916859 | C16: 11.529193 | D16: 10.90678 | E16: 16.779002 | F16: 26.107432 | G16: 16.593748 | H16: 10.761049 | I16: 6.203813 | J16: 5.4977622 | K16: 6.8559693 | L16: 6.9168687 | M16: 13.217679 | N16: =(SUM(B16:M16)) -> 145.28615 | O16: =ROUND(N16/$N$17,4) -> 0.0002 | Q16: 2022年 | R16: =N58 -> 1095964.4 | S16: =N59 -> 207144.88 | T16: =N60 -> 102750.94 | U16: =N61 -> 22580.296 | V16: =N62 -> 48569.231 | W16: =N63+N64 -> 40086.711 | X16: =Y16-SUM(R16:R16) -> 518278.57 | Y16: =N72 -> 1614243 | Z16: =Y16-R16 -> 518278.57 | AA16: =Y16-'GMV表-商品大类'!F58 -> -2.4028122e-07
A17: 合计(单位：万元） | B17: =SUM(B3:B16) -> 69892.476 | C17: =SUM(C3:C16) -> 55206.939 | D17: =SUM(D3:D16) -> 66598.388 | E17: =SUM(E3:E16) -> 60346.005 | F17: =SUM(F3:F16) -> 60471.829 | G17: =SUM(G3:G16) -> 56913.985 | H17: =SUM(H3:H16) -> 63032.255 | I17: =SUM(I3:I16) -> 71047.869 | ... O17: =SUM(O3:O16) -> 1.0002 | Q17: 变动 | R17: =R13-R14 -> 70528.143 | S17: =S13-S14 -> -47340.24 | T17: =T13-T14 -> -19892.049 | U17: =U13-U14 -> -304.91453 | V17: =V13-V14 -> -11319.041 | W17: =W13-W14 -> -11026.527 | X17: =X13-X14 -> -11302.459 | Y17: =Y13-Y14 -> -30657.088
R18: =R17/R14 -> 0.11750273 | S18: =S17/S14 -> -0.94993801 | T18: =T17/T14 -> -0.48778843 | U18: =U17/U14 -> -0.099240871 | V18: =V17/V14 -> -0.15243836 | W18: =W17/W14 -> -0.37283882 | X18: =X17/X14 -> -0.45823682 | Y18: =Y17/Y14 -> -0.037277313
A20: 2024年 | Q20: 平台 | R20: TOB | S20: 京东 | T20: 天猫 | U20: 拼多多 | V20: 支付宝小程序 | W20: 抖快 | X20: 其他 | Y20: 小计
A21: 平台 | B21: 1月 | C21: 2月 | D21: 3月 | E21: 4月 | F21: 5月 | G21: 6月 | H21: 7月 | I21: 8月 | J21: 9月 | K21: 10月 | L21: 11月 | M21: 12月 | N21: 合计 | O21: 平台GMV占比 | Q21: 2025年 | R21: =R13/$Y$13 -> 0.84717978 | S21: =S13/$Y$13 -> 0.0031510534 | T21: =T13/$Y$13 -> 0.026382133 | U21: =U13/$Y$13 -> 0.0034954953 | V21: =V13/$Y$13 -> 0.079487559 | W21: =W13/$Y$13 -> 0.023426601 | X21: =X13/$Y$13 -> 0.016877376 | Y21: =SUM(R21:X21) -> 1
A22: 福禄开放平台 | B22: 57380.332 | C22: 49703.168 | D22: 52869.612 | E22: 39772.322 | F22: 48186.498 | G22: 55691.42 | H22: 50930.264 | I22: 57429.588 | J22: 43578.641 | K22: 46612.011 | L22: 47834.971 | M22: 50236.751 | N22: =SUM(B22:M22) -> 600225.58 | O22: =ROUND(N22/$N$35,4) -> 0.7298 | Q22: 2024年 | R22: =R14/$Y$14 -> 0.7298409 | S22: =S14/$Y$14 -> 0.060596688 | T22: =T14/$Y$14 -> 0.049586303 | U22: =U14/$Y$14 -> 0.0037359517 | V22: =V14/$Y$14 -> 0.0902878 | W22: =W14/$Y$14 -> 0.035960964 | X22: =X14/$Y$14 -> 0.029991394 | Y22: =SUM(R22:X22) -> 1
A23: 京东 | B23: 7436.1819 | C23: 4795.2709 | D23: 1573.2976 | E23: 1831.6988 | F23: 5229.3072 | G23: 11708.543 | H23: 12092.34 | I23: 2723.5818 | J23: 621.1785 | K23: 1282.8291 | L23: 354.24055 | M23: 186.61391 | N23: =SUM(B23:M23) -> 49835.083 | O23: =ROUND(N23/$N$35,4) -> 0.0606 | P23: =O23+O24+O25 -> 0.1139 | Q23: 2023年 | R23: =R15/$Y$15 -> 0.69194426 | S23: =S15/$Y$15 -> 0.095458353 | T23: =T15/$Y$15 -> 0.062372006 | U23: =U15/$Y$15 -> 0.0034942153 | V23: =V15/$Y$15 -> 0.068240155 | W23: =W15/$Y$15 -> 0.041035133 | X23: =X15/$Y$15 -> 0.037455881 | Y23: =SUM(R23:X23) -> 1
A24: 天猫 | B24: 7356.2745 | C24: 6826.9474 | D24: 3343.9349 | E24: 2639.3386 | F24: 2808.5516 | G24: 3292.1818 | H24: 2281.9778 | I24: 2542.949 | J24: 1620.5124 | K24: 2614.4508 | L24: 3180.461 | M24: 2272.4962 | N24: =SUM(B24:M24) -> 40780.076 | O24: =ROUND(N24/$N$35,4) -> 0.0496
A25: 拼多多 | B25: 169.63949 | C25: 258.59786 | D25: 201.96861 | E25: 209.87979 | F25: 245.2243 | G25: 301.85235 | H25: 306.39712 | I25: 303.30276 | J25: 270.23927 | K25: 255.92196 | L25: 287.69779 | M25: 261.74802 | N25: =SUM(B25:M25) -> 3072.4693 | O25: =ROUND(N25/$N$35,4) -> 0.0037
A26: 支付宝小程序 | B26: 4835.725 | C26: 6130.6306 | D26: 4249.5636 | E26: 3138.7858 | F26: 8496.6226 | G26: 8256.9594 | H26: 8340.9431 | I26: 9739.3838 | J26: 5159.344 | K26: 5454.6605 | L26: 5035.8439 | M26: 5414.7719 | N26: =SUM(B26:M26) -> 74253.234 | O26: =ROUND(N26/$N$35,4) -> 0.0903
A27: 抖音 | B27: 978.85206 | C27: 5589.2987 | D27: 1310.5839 | E27: 856.94885 | F27: 2235.5593 | G27: 3481.126 | H27: 7230.5858 | I27: 1241.067 | J27: 611.61683 | K27: 789.61794 | L27: 4306.1958 | M27: 900.78845 | N27: =SUM(B27:M27) -> 29532.241 | O27: =ROUND(N27/$N$35,4) -> 0.0359 | P27: =O27+O28 -> 0.036
A28: 快手 | B28: 7.955893 | C28: 8.04633 | D28: 5.182013 | E28: 5.71417 | F28: 4.99868 | G28: 0.3792994 | H28: 0.86430006 | I28: -2.4889971 | J28: 6.0944412 | K28: 0.782 | L28: 2.8899 | M28: 1.8559 | N28: =SUM(B28:M28) -> 42.27393 | O28: =ROUND(N28/$N$35,4) -> 0.0001
A29: 微信 | B29: 0.137637 | C29: 0.088062 | D29: 0.16190964 | E29: 0 | F29: -1.272e-05 | G29: 1.2955172 | L29: 0.02205672 | M29: 0.01564572 | N29: =SUM(B29:M29) -> 1.7208155 | O29: =ROUND(N29/$N$35,4) -> 0
A30: 第三方平台 | B30: 2608.1562 | C30: 2087.6476 | D30: 2307.5211 | E30: 1413.6205 | F30: 2168.5868 | G30: 876.27303 | H30: 683.92585 | I30: 876.53694 | J30: 673.27937 | K30: 965.75132 | L30: 723.18587 | M30: 819.06602 | N30: =SUM(B30:M30) -> 16203.551 | O30: =ROUND(N30/$N$35,4) -> 0.0197
A31: 充值频道 | B31: 1491.8645 | C31: 151.0234 | D31: 267.63107 | E31: 294.43465 | F31: 1160.9214 | G31: 180.26779 | H31: 120.31669 | I31: 289.59872 | J31: 73.440949 | K31: 1029.4009 | L31: 76.861941 | M31: 81.4073 | N31: =SUM(B31:M31) -> 5217.1693 | O31: =ROUND(N31/$N$35,4) -> 0.0063
A32: 短信分销平台 | B32: 2.656935 | C32: 1.945017 | D32: 1.73492 | E32: 1.742468 | F32: 1.632589 | G32: 3.857593 | H32: 1.6050478 | I32: 1.1173497 | J32: 0.012545 | K32: 0.11889592 | L32: 0.001748 | M32: 0.002504 | N32: =SUM(B32:M32) -> 16.427612 | O32: =ROUND(N32/$N$35,4) -> 0
A33: 百度小程序 | B33: 1.11333 | C33: 0.404225 | D33: 12.162652 | E33: 2.36439 | F33: 0.00255 | G33: 0.00751 | H33: 0.0134056 | I33: 0.000465 | J33: 0.00078204 | K33: 0.00155796 | L33: 0 | M33: 0.002955 | N33: =SUM(B33:M33) -> 16.073823 | O33: =ROUND(N33/$N$35,4) -> 0
A34: mall商城 | B34: 1572.7729 | C34: 664.98154 | D34: 689.53527 | E34: 178.44666 | F34: 15.061236 | G34: 8.584745 | H34: 15.744394 | I34: 21.133721 | J34: 3.7441439 | K34: 5.8240984 | L34: 10.589944 | M34: 23.743412 | N34: =SUM(B34:M34) -> 3210.1621 | O34: =ROUND(N34/$N$35,4) -> 0.0039
A35: 合计(单位：万元） | B35: =SUM(B22:B34) -> 83841.662 | C35: =SUM(C22:C34) -> 76218.049 | D35: =SUM(D22:D34) -> 66832.889 | E35: =SUM(E22:E34) -> 50345.297 | F35: =SUM(F22:F34) -> 70552.966 | G35: =SUM(G22:G34) -> 83802.748 | H35: =SUM(H22:H34) -> 82004.978 | I35: =SUM(I22:I34) -> 75165.771 | ... N35: =SUM(N22:N34) -> 822406.06 | O35: =N35/$N$35 -> 1
A38: 2023年
A39: 平台 | B39: 1月 | C39: 2月 | D39: 3月 | E39: 4月 | F39: 5月 | G39: 6月 | H39: 7月 | I39: 8月 | J39: 9月 | K39: 10月 | L39: 11月 | M39: 12月 | N39: 合计 | O39: 平台GMV占比
