Workbook
Name body: '[1]资产负债表-2017'!$C$6:$H$36
Name grid: '[1]资产负债表-2017'!$C$6:$H$36
Name head: '[1]资产负债表-2017'!$A$4:$H$4
Name 合并科目名称: [2]Sheet1!$A$2:$A$908
Name 核算项目明细账: [3]核算项目明细账!$A$1:$K$157
Name 会计分录序时簿: #REF!
Name 科目余额表: #REF!
Name 明细分类账: #REF!
Name 会计分录序时簿: #REF!
Name 科目余额表: #REF!
Name 明细分类账: #REF!
Name 会计分录序时簿: #REF!
Name 科目余额表: #REF!
Name 明细分类账: #REF!
Name body: '[4]资产负债表-2017'!$C$6:$H$36
Name grid: '[4]资产负债表-2017'!$C$6:$H$36
Name head: '[4]资产负债表-2017'!$A$4:$H$4
Name 合并科目名称: [5]Sheet1!$A$2:$A$908
Name 核算项目明细账: [6]核算项目明细账!$A$1:$K$157
Name 会计分录序时簿: #REF!
Name 科目余额表: #REF!
Name 明细分类账: #REF!
Name body: '[4]资产负债表-2017'!$C$6:$H$36
Name grid: '[4]资产负债表-2017'!$C$6:$H$36
Name head: '[4]资产负债表-2017'!$A$4:$H$4
Name 合并科目名称: [5]Sheet1!$A$2:$A$908
Name 核算项目明细账: [6]核算项目明细账!$A$1:$K$157
Name 会计分录序时簿: #REF!
Name 科目余额表: #REF!
Name 明细分类账: #REF!
Name body: '[4]资产负债表-2017'!$C$6:$H$36
Name grid: '[4]资产负债表-2017'!$C$6:$H$36
Name head: '[4]资产负债表-2017'!$A$4:$H$4
Name 合并科目名称: [5]Sheet1!$A$2:$A$908
Name 核算项目明细账: [6]核算项目明细账!$A$1:$K$157
Name 会计分录序时簿: #REF!
Name 科目余额表: #REF!
Name 明细分类账: #REF!
Name \555: [10]表三甲!#REF!
Name \a: [10]表三甲!#REF!
Name \b: #REF!
Name \bbb: #REF!
Name \E: #REF!
Name \k: [11]土建表三乙!#REF!
Name \kkk: [10]表三甲!#REF!
Name \m: #REF!
Name \o: [10]表三甲!#REF!
Name \p: [10]表三甲!#REF!
Name \q: [10]表三甲!#REF!
Name \r: [10]表三甲!#REF!
Name \x: [10]表三甲!#REF!
Name \xx: [10]表三甲!#REF!
Name \z: [10]表三甲!#REF!
Name \zz: [10]表三甲!#REF!
Name _: #REF!
Name _0.dbf: #REF!
Name _000.03.dbf: #REF!
Name _00103应收货款余额表.dbf: #REF!
Name _0月31日: #REF!
Name _1: #REF!

Sheet 范围确认
A1: 1、涉及业务线 | B1: 游戏电商、渠道线、业务发展
A2: 2、涉及年限 | B2: 2020年1-22年
A3: 3、5月13号提供数据
A4: 4、单位：万元

Sheet GMV-战略需求
A1: 规模
A2: 结构 | B2: 品类
B3: 品牌
A5: 1、21年-22年商品大类增长波动 | J5: 年份 | K5: 游戏 | L5: 通信 | M5: 网娱 | N5: 网娱 | O5: 合计
J6: 43831
J7: 43862
J8: 43891
J9: 43922
J10: 43952
J11: 43983
J12: 44013
J13: 44044
J14: 44075
J15: 44105
J16: 44136
J17: 44166
... J23: 44348
A24: 2、21年-22年网娱、生活服务增长波动 | J24: 44378
J25: 44409
J26: 44440
J27: 44470
J28: 44501
J29: 44531
J30: 44562
J31: 44593
J32: 44621
J33: 44652
J34: 44682
J35: 44713
J36: 44743
... J40: 44866
A43: 3、品牌趋势波动，是否针对网娱、生活服务--22年数据波动做分析
A44: 网娱品牌 | B44: 影视会员、音频、视频直播、知识阅读
A45: 生活服务 | B45: 加油卡、网络工具、出行生活、餐饮、购物（优惠劵）、其他

Sheet 毛利-战略需求
A1: 1、收入构成 | B1: 代理 | C1: 虚拟商品采销差额收入+返点 | D1: 分商品大类-20年-22年
B2: 增值代运营 | C2: 代运营收入 | D2: 分商品大类-需要提供21年GMV
B3: 推广收入 | D3: 分商品大类-需要提供21年GMV
A8: 2、品类毛利21年-22年 | B8: 依赖第一条数据提供商品大类可以出
A18: 3、四大品类毛利/gmv
A25: 4、成长性品牌的毛利分析
A26: 生活服务
A27: 网娱
A30: 5、供应商毛利波动（前10）

Sheet 上市公司经营概况
A1: 体系内公司经营概况整体变化情况
A2: 单位：万元
A3: 项目 | B3: 2022年1-6月体系内公司经营概况 | C3: 2021年1-6月体系内公司经营概况 | D3: 2020年1-6月体系内公司经营概况 | E3: 增长总数对比额
E4: 累计增长额 | F4: 增长比率
A5: 集团GMV | B5: ='GMV表-商品大类'!T35 -> 722480.29 | C5: ='GMV表-商品大类'!T23 -> 997949.58 | D5: ='GMV表-商品大类'!T11 -> 753470.03 | E5: =B5-C5 -> -275469.29 | F5: =E5/C5 -> -0.27603528
A6: 毛利收入（含税） | B6: =SUM('毛利-收入组成'!AH27:AH32) -> 17052.403 | C6: =SUM('毛利-收入组成'!AH15:AH20) -> 21665.327 | D6: =SUM('毛利-收入组成'!AH3:AH8) -> 17359.563 | E6: =B6-C6 -> -4612.9233 | F6: =E6/C6 -> -0.21291732
A7: 净利润（核算报表) | B7: ='[9]财务报表--EAS（原表）'!$S$53/10000+投资公司!C19 -> #REF! | C7: ='[9]财务报表--EAS（原表）'!$G$53/10000 -> #REF! | D7: =[8]经营概况整体变化情况!$C$7 -> #REF! | E7: =B7-C7 -> #REF! | F7: =E7/C7 -> #REF!
A8: 净利润（审计口径) | B8: =B7-(-12881461.65/10000) -> #REF! | C8: ='[9]权责制经营报表-EAS 2206（审计口径）'!$H$48/10000-766.444582 -> #REF! | D8: =[8]经营概况整体变化情况!$C$8 -> #REF! | E8: =B8-C8 -> #REF! | F8: =E8/C8 -> #REF! | G8: 合并报表-跨期返点收入+审计补计提在21年费用
A9: 净利润（扣非) | B9: =B8+'[9]权责制经营报表-EAS 2206（审计口径）'!$T$53/10000 -> #REF! | C9: =C8+'[9]权责制经营报表-EAS 2206（审计口径）'!$H$53/10000+'[9]权责制经营报表-EAS 2206（审计口径）'!$H$54/10000 -> #REF! | D9: =[8]经营概况整体变化情况!$C$9 -> #REF! | E9: =B9-C9 -> #REF! | F9: =E9/C9 -> #REF! | G9: 合并报表-跨期返点收入+调整IPO费用+调整汇兑损益+权益股份
A10: 留存率 | B10: =B6/B5 -> 0.023602586 | C10: =C6/C5 -> 0.021709841 | D10: =D6/D5 -> 0.023039487
A11: 利润率 | B11: =B8*1.06/B6 -> #REF! | C11: =C8*1.06/C6 -> #REF! | D11: =D8*1.06/D6 -> #REF!
B13: =B8-B9 -> #REF! | C13: =C8-C9 -> #REF! | D13: =E6-[7]成本费用分布!$AA$16 -> #REF!
A17: 调整项： | B17: 1、体内扣非、不扣给，都要调整采购返点未实现部分
B18: 2、体外岚晨，公会费用按总额法核算，同时调整收入和费用
A21: 项目 | B21: 管理报表数 | C21: 净利润（审计口径） | D21: 净利润（扣非）
A22: 2022年1-6月 | B22: =B7 -> #REF! | C22: =B8 -> #REF! | D22: =B9 -> #REF! | E22: =D22-B9 -> #REF!
A23: 2021年1-6月 | B23: =C7 -> #REF! | C23: =C8 -> #REF! | D23: =C9 -> #REF!
A24: 变动值 | B24: =B22-B23 -> #REF! | C24: =C22-C23 -> #REF! | D24: =D22-D23 -> #REF!
A25: 增长率 | B25: =B24/B23 -> #REF! | C25: =C24/C23 -> #REF! | D25: =D24/D23 -> #REF!

Sheet 利润调整

Sheet 利润组成
A1: GMV | F1: 毛利收入（含税） | P1: 净利润 | AB1: 毛利率 | AG1: 净利润率 | AL1: 当月净利润
A2: 月份累计 | B2: 上市公司 | C2: 投资公司 | D2: 小计 | F2: 月份累计 | G2: 上市公司 | H2: 佣金手续费（元）（账面不含税金额） | I2: 佣金手续费（含税） | J2: 体内项目-葫芦藤延伸公司 | K2: 跨期返利(含税） | L2: 上市公司-扣除佣金手续费后、调整跨期返利后毛利收入 | M2: 投资公司 | N2: 集团小计 | P2: 月份累计 | Q2: 上市公司（审计口径） | R2: 跨期返利 | S2: 体内项目-葫芦藤延伸公司 | T2: H1项目分红 | U2: H1导师分红 | V2: 上市公司调整后净利润小计 | W2: 投资公司调整前 | X2: H1项目分红 | Y2: H1导师分红 | Z2: 集团小计 | AB2: 月份 | AC2: 上市公司（审计口径） | AD2: 投资公司 | AE2: 集团小计 | AG2: 月份 | AH2: 上市公司（审计口径） | AI2: 投资公司 | AJ2: 小计 | AL2: 月份 | AM2: 上市公司当月利润（核算）（元） | AN2: 调整跨期返利收入（元） | AO2: 调整投资公司(万元）
A3: 43831 | B3: 108855.57 | C3: 0 | D3: =B3+C3 -> 108855.57 | F3: 43831 | G3: ='毛利-收入组成'!AP3 -> 3005.5532 | H3: 2267566.2 | I3: =H3*1.06/10000 -> 240.36202 | L3: =G3-I3+J3-K3 -> 2765.1912 | M3: 0 | N3: =L3+M3 -> 2765.1912 | P3: 43831 | Q3: 1461.1357 | V3: =Q3-R3+S3 -> 1461.1357 | W3: 0 | Z3: =V3+W3 -> 1461.1357 | AB3: 43831 | AC3: =L3/B3 -> 0.025402387 | AD3: =M3/C3 -> #DIV/0! | AE3: =N3/D3 -> 0.025402387 | AG3: 43831 | AH3: =V3*1.06/L3 -> 0.56010732 | AI3: =W3*1.06/M3 -> #DIV/0! | AJ3: =Z3*1.06/N3 -> 0.56010732 | AL3: 43831
A4: 43862 | B4: 234834.11 | C4: 0 | D4: =B4+C4 -> 234834.11 | F4: 43862 | G4: ='毛利-收入组成'!AP4 -> 5626.0416 | H4: 4138698.7 | I4: =H4*1.06/10000 -> 438.70206 | L4: =G4-I4+J4-K4 -> 5187.3395 | M4: 0 | N4: =L4+M4 -> 5187.3395 | P4: 43862 | Q4: 2772.2185 | V4: =Q4-R4+S4 -> 2772.2185 | W4: 0 | Z4: =V4+W4 -> 2772.2185 | AB4: 43862 | AC4: =L4/B4 -> 0.022089379 | AD4: =M4/C4 -> #DIV/0! | AE4: =N4/D4 -> 0.022089379 | AG4: 43862 | AH4: =V4*1.06/L4 -> 0.56648529 | AI4: =W4*1.06/M4 -> #DIV/0! | AJ4: =Z4*1.06/N4 -> 0.56648529 | AL4: 43862
A5: 43891 | B5: 371037.83 | C5: 0 | D5: =B5+C5 -> 371037.83 | F5: 43891 | G5: ='毛利-收入组成'!AP5 -> 9302.7749 | H5: 7022628.5 | I5: =H5*1.06/10000 -> 744.39862 | L5: =G5-I5+J5-K5 -> 8558.3762 | M5: 0 | N5: =L5+M5 -> 8558.3762 | P5: 43891 | Q5: 4900.3466 | V5: =Q5-R5+S5 -> 4900.3466 | W5: 0 | Z5: =V5+W5 -> 4900.3466 | AB5: 43891 | AC5: =L5/B5 -> 0.023066048 | AD5: =M5/C5 -> #DIV/0! | AE5: =N5/D5 -> 0.023066048 | AG5: 43891 | AH5: =V5*1.06/L5 -> 0.60693376 | AI5: =W5*1.06/M5 -> #DIV/0! | AJ5: =Z5*1.06/N5 -> 0.60693376 | AL5: 43891
A6: 43922 | B6: 499627.82 | C6: 1683.13 | D6: =B6+C6 -> 501310.95 | F6: 43922 | G6: ='毛利-收入组成'!AP6 -> 11563.258 | H6: 9398075.9 | I6: =H6*1.06/10000 -> 996.19605 | L6: =G6-I6+J6-K6 -> 10567.062 | M6: 985.5668 | N6: =L6+M6 -> 11552.628 | P6: 43922 | Q6: 5201.3962 | R6: -12.490192 | V6: =Q6-R6+S6 -> 5213.8864 | W6: 152.41 | Z6: =V6+W6 -> 5366.2964 | AB6: 43922 | AC6: =L6/B6 -> 0.021149866 | AD6: =M6/C6 -> 0.58555596 | AE6: =N6/D6 -> 0.023044835 | AG6: 43922 | AH6: =V6*1.06/L6 -> 0.52301386 | AI6: =W6*1.06/M6 -> 0.1639205 | AJ6: =Z6*1.06/N6 -> 0.49237923 | AL6: 43922
A7: 43952 | B7: 620327.46 | C7: 2274.839 | D7: =B7+C7 -> 622602.3 | F7: 43952 | G7: ='毛利-收入组成'!AP7 -> 14361.51 | H7: 12574211 | I7: =H7*1.06/10000 -> 1332.8664 | L7: =G7-I7+J7-K7 -> 13028.643 | M7: 1307.1454 | N7: =L7+M7 -> 14335.789 | P7: 43952 | Q7: 5946.4111 | R7: 262.44255 | V7: =Q7-R7+S7 -> 5683.9685 | W7: 263.82746 | Z7: =V7+W7 -> 5947.796 | AB7: 43952 | AC7: =L7/B7 -> 0.021002848 | AD7: =M7/C7 -> 0.57461004 | AE7: =N7/D7 -> 0.023025595 | AG7: 43952 | AH7: =V7*1.06/L7 -> 0.46244313 | AI7: =W7*1.06/M7 -> 0.21394492 | AJ7: =Z7*1.06/N7 -> 0.43978493 | AL7: 43952
A8: 43983 | B8: 753470.03 | C8: 2614.3009 | D8: =B8+C8 -> 756084.33 | F8: 43983 | G8: ='毛利-收入组成'!AP8 -> 17359.563 | H8: 16502507 | I8: =H8*1.06/10000 -> 1749.2657 | L8: =G8-I8+J8-K8 -> 15610.297 | M8: 1553.5218 | N8: =L8+M8 -> 17163.819 | P8: 43983 | Q8: =V8+R8 -> 7553.8477 | R8: 431.57644 | V8: =71222712.99/10000 -> 7122.2713 | W8: 299.95646 | Z8: =V8+W8 -> 7422.2278 | AB8: 43983 | AC8: =L8/B8 -> 0.020717874 | AD8: =M8/C8 -> 0.59423986 | AE8: =N8/D8 -> 0.022700932 | AG8: 43983 | AH8: =V8*1.06/L8 -> 0.48362996 | AI8: =W8*1.06/M8 -> 0.20466648 | AJ8: =Z8*1.06/N8 -> 0.45838058 | AL8: 43983
A9: 44013 | B9: 861281.71 | C9: 3169.0978 | D9: =B9+C9 -> 864450.8 | F9: 44013 | G9: ='毛利-收入组成'!AP9 -> 19620.865 | H9: 20753792 | I9: =H9*1.06/10000 -> 2199.902 | L9: =G9-I9+J9-K9 -> 17420.964 | M9: 1894.8863 | N9: =L9+M9 -> 19315.85 | P9: 44013 | Q9: 7363.7605 | R9: 150.29162 | V9: =Q9-R9+S9 -> 7213.4688 | W9: 392.87593 | Z9: =V9+W9 -> 7606.3448 | AB9: 44013 | AC9: =L9/B9 -> 0.020226789 | AD9: =M9/C9 -> 0.5979261 | AE9: =N9/D9 -> 0.022344649 | AG9: 44013 | AH9: =V9*1.06/L9 -> 0.4389124 | AI9: =W9*1.06/M9 -> 0.21977492 | AJ9: =Z9*1.06/N9 -> 0.417415 | AL9: 44013
A10: 44044 | B10: 963744.17 | C10: 3907.6229 | D10: =B10+C10 -> 967651.79 | F10: 44044 | G10: ='毛利-收入组成'!AP10 -> 22608.732 | H10: 24741203 | I10: =H10*1.06/10000 -> 2622.5675 | L10: =G10-I10+J10-K10 -> 19986.165 | M10: 2452.8894 | N10: =L10+M10 -> 22439.054 | P10: 44044 | Q10: 8315.3341 | R10: 149.08987 | V10: =Q10-R10+S10 -> 8166.2442 | W10: 655.03143 | Z10: =V10+W10 -> 8821.2757 | AB10: 44044 | AC10: =L10/B10 -> 0.02073804 | AD10: =M10/C10 -> 0.62771906 | AE10: =N10/D10 -> 0.023189183 | AG10: 44044 | AH10: =V10*1.06/L10 -> 0.43311055 | AI10: =W10*1.06/M10 -> 0.28306752 | AJ10: =Z10*1.06/N10 -> 0.41670884 | AL10: 44044
A11: 44075 | B11: 1071698.6 | C11: 4482.1392 | D11: =B11+C11 -> 1076180.7 | F11: 44075 | G11: ='毛利-收入组成'!AP11 -> 25599.175 | H11: 28841287 | I11: =H11*1.06/10000 -> 3057.1764 | L11: =G11-I11+J11-K11 -> 22541.998 | M11: 2887.029 | N11: =L11+M11 -> 25429.028 | P11: 44075 | Q11: 8938.9383 | R11: 197.12663 | V11: =Q11-R11+S11 -> 8741.8117 | W11: 570.89724 | Z11: =V11+W11 -> 9312.7089 | AB11: 44075 | AC11: =L11/B11 -> 0.021033898 | AD11: =M11/C11 -> 0.64411856 | AE11: =N11/D11 -> 0.023628957 | AG11: 44075 | AH11: =V11*1.06/L11 -> 0.41106916 | AI11: =W11*1.06/M11 -> 0.20961032 | AJ11: =Z11*1.06/N11 -> 0.38819697 | AL11: 44075
A12: 44105 | B12: 1192298.3 | C12: 5181.8237 | D12: =B12+C12 -> 1197480.1 | F12: 44105 | G12: ='毛利-收入组成'!AP12 -> 27955.57 | H12: 32592117 | I12: =H12*1.06/10000 -> 3454.7644 | L12: =G12-I12+J12-K12 -> 24500.805 | M12: 3471.1219 | N12: =L12+M12 -> 27971.927 | P12: 44105 | Q12: 9119.9746 | R12: 451.08295 | V12: =Q12-R12+S12 -> 8668.8917 | W12: 581.18029 | Z12: =V12+W12 -> 9250.072 | AB12: 44105 | AC12: =L12/B12 -> 0.020549225 | AD12: =M12/C12 -> 0.66986492 | AE12: =N12/D12 -> 0.023358991 | AG12: 44105 | AH12: =V12*1.06/L12 -> 0.37504992 | AI12: =W12*1.06/M12 -> 0.17747896 | AJ12: =Z12*1.06/N12 -> 0.35053274 | AL12: 44105
A13: 44136 | B13: 1323765.4 | C13: 5964.1379 | D13: =B13+C13 -> 1329729.5 | F13: 44136 | G13: ='毛利-收入组成'!AP13 -> 32152.429 | H13: 37425284 | I13: =H13*1.06/10000 -> 3967.0801 | L13: =G13-I13+J13-K13 -> 28185.349 | M13: 4022.961 | N13: =L13+M13 -> 32208.31 | P13: 44136 | Q13: 10096.153 | R13: 435.37173 | V13: =Q13-R13+S13 -> 9660.7811 | W13: 167.55656 | Z13: =V13+W13 -> 9828.3377 | AB13: 44136 | AC13: =L13/B13 -> 0.021291802 | AD13: =M13/C13 -> 0.67452514 | AE13: =N13/D13 -> 0.024221701 | AG13: 44136 | AH13: =V13*1.06/L13 -> 0.3633245 | AI13: =W13*1.06/M13 -> 0.044149061 | AJ13: =Z13*1.06/N13 -> 0.32345807 | AL13: 44136
A14: 44166 | B14: 1457884 | C14: 5878.4142 | D14: =B14+C14 -> 1463762.4 | F14: 44166 | G14: ='毛利-收入组成'!AP14 -> 36994.551 | H14: 42520356 | I14: =H14*1.06/10000 -> 4507.1578 | L14: =G14-I14+J14-K14 -> 32487.394 | M14: 4489.3097 | N14: =L14+M14 -> 36976.703 | P14: 44166 | Q14: 11872.702 | R14: 1082.9923 | V14: =Q14-R14+S14 -> 10789.71 | W14: -288.12588 | Z14: =V14+W14 -> 10501.584 | AB14: 44166 | AC14: =L14/B14 -> 0.022283936 | AD14: =M14/C14 -> 0.76369401 | AE14: =N14/D14 -> 0.025261411 | AG14: 44166 | AH14: =V14*1.06/L14 -> 0.35204708 | AI14: =W14*1.06/M14 -> -0.06803127 | AJ14: =Z14*1.06/N14 -> 0.30104573 | AL14: 44166
A15: 44197 | B15: 126572.29 | C15: 1250.12 | D15: =B15+C15 -> 127822.41 | F15: 44197 | G15: ='毛利-收入组成'!AP15 -> 3267.6274 | H15: 4151308 | I15: =H15*1.06/10000 -> 440.03865 | L15: =G15-I15+J15-K15 -> 2827.5887 | M15: 631.95525 | N15: =L15+M15 -> 3459.544 | P15: 44197 | Q15: 1259.6255 | R15: =2059085.54115382/10000 -> 205.90855 | V15: =Q15-R15+S15 -> 1053.717 | W15: -170.35 | Z15: =V15+W15 -> 883.36699 | AB15: 44197 | AC15: =L15/B15 -> 0.022339713 | AD15: =M15/C15 -> 0.50551567 | AE15: =N15/D15 -> 0.027065237 | AG15: 44197 | AH15: =V15*1.06/L15 -> 0.39501501 | AI15: =W15*1.06/M15 -> -0.28573384 | AJ15: =Z15*1.06/N15 -> 0.27066255 | AL15: 44197
A16: 44228 | B16: 253086.25 | C16: 2870.11 | D16: =B16+C16 -> 255956.36 | F16: 44228 | G16: ='毛利-收入组成'!AP16 -> 6453.35 | H16: 8209257.9 | I16: =H16*1.06/10000 -> 870.18133 | L16: =G16-I16+J16-K16 -> 5583.1687 | M16: 1530.8654 | N16: =L16+M16 -> 7114.0341 | P16: 44228 | Q16: 2643.0176 | R16: =2059085.54115382/10000+5981296.97843144/10000 -> 804.03825 | V16: =Q16-R16+S16 -> 1838.9794 | W16: -210.67 | Z16: =V16+W16 -> 1628.3094 | AB16: 44228 | AC16: =L16/B16 -> 0.02206034 | AD16: =M16/C16 -> 0.53338214 | AE16: =N16/D16 -> 0.027793934 | AG16: 44228 | AH16: =V16*1.06/L16 -> 0.3491419 | AI16: =W16*1.06/M16 -> -0.14587187 | AJ16: =Z16*1.06/N16 -> 0.24262014 | AL16: 44228
A17: 44256 | B17: 420256.07 | C17: 3989.14 | D17: =B17+C17 -> 424245.21 | F17: 44256 | G17: ='毛利-收入组成'!AP17 -> 11169.797 | H17: 12929115 | I17: =H17*1.06/10000 -> 1370.4861 | L17: =G17-I17+J17-K17 -> 9799.3112 | M17: 2212.245 | N17: =L17+M17 -> 12011.556 | P17: 44256 | Q17: 5626.5008 | R17: 1056.3554 | V17: =Q17-R17+S17 -> 4570.1454 | W17: -440.97 | Z17: =V17+W17 -> 4129.1754 | AB17: 44256 | AC17: =L17/B17 -> 0.023317477 | AD17: =M17/C17 -> 0.5545669 | AE17: =N17/D17 -> 0.028312768 | AG17: 44256 | AH17: =V17*1.06/L17 -> 0.49435659 | AI17: =W17*1.06/M17 -> -0.21129134 | AJ17: =Z17*1.06/N17 -> 0.36439291 | AL17: 44256
A18: 44287 | B18: 576778.07 | C18: 5126.1593 | D18: =B18+C18 -> 581904.23 | F18: 44287 | G18: ='毛利-收入组成'!AP18 -> 13446.163 | H18: 17509484 | I18: =H18*1.06/10000 -> 1856.0053 | L18: =G18-I18+J18-K18 -> 11590.157 | M18: 2770.0335 | N18: =L18+M18 -> 14360.191 | P18: 44287 | Q18: 5424.4488 | R18: 922.42937 | V18: =Q18-R18+S18 -> 4502.0194 | W18: -1136.0004 | Z18: =V18+W18 -> 3366.019 | AB18: 44287 | AC18: =L18/B18 -> 0.020094657 | AD18: =M18/C18 -> 0.5403721 | AE18: =N18/D18 -> 0.024677928 | AG18: 44287 | AH18: =V18*1.06/L18 -> 0.4117408 | AI18: =W18*1.06/M18 -> -0.43470972 | AJ18: =Z18*1.06/N18 -> 0.24846328 | AL18: 44287
A19: 44317 | B19: 771135.94 | C19: 5636.3654 | D19: =B19+C19 -> 776772.31 | F19: 44317 | G19: ='毛利-收入组成'!AP19 -> 16651.896 | H19: 22355194 | I19: =H19*1.06/10000 -> 2369.6505 | L19: =G19-I19+J19-K19 -> 14282.245 | M19: 3359.428 | N19: =L19+M19 -> 17641.673 | P19: 44317 | Q19: 5772.8294 | R19: 593.88748 | V19: =Q19-R19+S19 -> 5178.9419 | W19: -1642.0427 | Z19: =V19+W19 -> 3536.8992 | AB19: 44317 | AC19: =L19/B19 -> 0.018521047 | AD19: =M19/C19 -> 0.59602737 | AE19: =N19/D19 -> 0.022711511 | AG19: 44317 | AH19: =V19*1.06/L19 -> 0.38437083 | AI19: =W19*1.06/M19 -> -0.51811358 | AJ19: =Z19*1.06/N19 -> 0.2125146 | AL19: 44317
A20: 44348 | B20: 997949.58 | C20: 8217.612 | D20: =B20+C20 -> 1006167.2 | F20: 44348 | G20: ='毛利-收入组成'!AP20 -> 21665.327 | H20: 27674170 | I20: =H20*1.06/10000 -> 2933.4621 | L20: =G20-I20+J20-K20 -> 18731.865 | M20: 3775.6411 | N20: =L20+M20 -> 22507.506 | P20: 44348 | Q20: =V20+R20 -> 7603.2288 | R20: =3569650.9/10000 -> 356.96509 | V20: =Q20-R20+S20 -> 0 | W20: -2396.6821 | Z20: =V20+W20 -> 4849.5816 | AB20: 44348 | AC20: =L20/B20 -> 0.018770352 | AD20: =M20/C20 -> 0.45945721 | AE20: =N20/D20 -> 0.022369548 | AG20: 44348 | AH20: =V20*1.06/L20 -> 0.41005205 | AI20: =W20*1.06/M20 -> -0.67286138 | AJ20: =Z20*1.06/N20 -> 0.22839299 | AL20: 44348
A21: 44378 | B21: 1218182.5 | C21: 12572.54 | D21: =B21+C21 -> 1230755 | F21: 44378 | G21: ='毛利-收入组成'!AP21 -> 24096.859 | H21: 33458555 | I21: =H21*1.06/10000 -> 3546.6069 | L21: =G21-I21+J21-K21 -> 20550.252 | M21: 4601.6992 | N21: =L21+M21 -> 25151.951 | P21: 44378 | Q21: 7910.5746 | R21: 112.48696 | V21: =Q21-R21+S21 -> 7798.0877 | W21: -3142.9056 | Z21: =V21+W21 -> 4655.1821 | AB21: 44378 | AC21: =L21/B21 -> 0.0168696 | AD21: =M21/C21 -> 0.36601191 | AE21: =N21/D21 -> 0.020436196 | AG21: 44378 | AH21: =V21*1.06/L21 -> 0.4022322 | AI21: =W21*1.06/M21 -> -0.72396734 | AJ21: =Z21*1.06/N21 -> 0.19618729 | AL21: 44378
A22: 44409 | B22: 1486957.6 | C22: 17899.22 | D22: =B22+C22 -> 1504856.8 | F22: 44409 | G22: ='毛利-收入组成'!AP22 -> 28498.305 | H22: 38539023 | I22: =H22*1.06/10000 -> 4085.1365 | L22: =G22-I22+J22-K22 -> 24413.168 | M22: 5710.0711 | N22: =L22+M22 -> 30123.239 | P22: 44409 | Q22: 9563.2288 | R22: 887.64735 | V22: =Q22-R22+S22 -> 8675.5815 | W22: -4186.9176 | Z22: =V22+W22 -> 4488.6639 | AB22: 44409 | AC22: =L22/B22 -> 0.016418201 | AD22: =M22/C22 -> 0.3190123 | AE22: =N22/D22 -> 0.020017346 | AG22: 44409 | AH22: =V22*1.06/L22 -> 0.37668673 | AI22: =W22*1.06/M22 -> -0.77724647 | AJ22: =Z22*1.06/N22 -> 0.1579506 | AL22: 44409
A23: 44440 | B23: 1664670.2 | C23: 22068.8 | D23: =B23+C23 -> 1686739 | F23: 44440 | G23: ='毛利-收入组成'!AP23 -> 31841.635 | H23: 41417901 | I23: =H23*1.06/10000 -> 4390.2975 | L23: =G23-I23+J23-K23 -> 27451.338 | M23: 7194.8592 | N23: =L23+M23 -> 34646.197 | P23: 44440 | Q23: 10693.952 | R23: 777.15114 | V23: =Q23-R23+S23 -> 9916.8012 | W23: -4721.5095 | Z23: =V23+W23 -> 5195.2918 | AB23: 44440 | AC23: =L23/B23 -> 0.016490556 | AD23: =M23/C23 -> 0.3260195 | AE23: =N23/D23 -> 0.020540342 | AG23: 44440 | AH23: =V23*1.06/L23 -> 0.38292521 | AI23: =W23*1.06/M23 -> -0.69560778 | AJ23: =Z23*1.06/N23 -> 0.15894989 | AL23: 44440
A24: 44470 | B24: 1806282.5 | C24: 27398.839 | D24: =B24+C24 -> 1833681.4 | F24: 44470 | G24: ='毛利-收入组成'!AP24 -> 33988.698 | H24: 43956682 | I24: =H24*1.06/10000 -> 4659.4083 | L24: =G24-I24+J24-K24 -> 29329.29 | M24: 9048.694 | N24: =L24+M24 -> 38377.983 | P24: 44470 | Q24: 12165.082 | R24: 307.9756 | V24: =Q24-R24+S24 -> 11857.106 | W24: -6032.2274 | Z24: =V24+W24 -> 5824.8786 | AB24: 44470 | AC24: =L24/B24 -> 0.016237377 | AD24: =M24/C24 -> 0.3302583 | AE24: =N24/D24 -> 0.020929472 | AG24: 44470 | AH24: =V24*1.06/L24 -> 0.42853177 | AI24: =W24*1.06/M24 -> -0.70663911 | AJ24: =Z24*1.06/N24 -> 0.16088316 | AL24: 44470
A25: 44501 | B25: 1984677.8 | C25: 34131.113 | D25: =B25+C25 -> 2018808.9 | F25: 44501 | G25: ='毛利-收入组成'!AP25 -> 38643.159 | H25: 47344757 | I25: =H25*1.06/10000 -> 5018.5442 | J25: 0 | L25: =G25-I25+J25-K25 -> 33624.614 | M25: 9572.8058 | N25: =L25+M25 -> 43197.42 | P25: 44501 | Q25: 13533.2 | R25: 113.85843 | V25: =Q25-R25+S25 -> 13419.342 | W25: -6850.5275 | Z25: =V25+W25 -> 6568.8143 | AB25: 44501 | AC25: =L25/B25 -> 0.016942103 | AD25: =M25/C25 -> 0.28047154 | AE25: =N25/D25 -> 0.021397479 | AG25: 44501 | AH25: =V25*1.06/L25 -> 0.42303838 | AI25: =W25*1.06/M25 -> -0.75856122 | AJ25: =Z25*1.06/N25 -> 0.16118886 | AL25: 44501
A26: 44531 | B26: 2148731.6 | C26: 42339.291 | D26: =B26+C26 -> 2191070.9 | F26: 44531 | G26: ='毛利-收入组成'!AP26 -> 43403.164 | H26: 48802379 | I26: =H26*1.06/10000 -> 5173.0522 | J26: 0 | L26: =G26-I26+J26-K26 -> 38230.112 | M26: 11140.604 | N26: =L26+M26 -> 49370.716 | P26: 44531 | Q26: =151608372.83/10000 -> 15160.837 | R26: 1486.718 | V26: =Q26-R26+S26 -> 13674.119 | W26: -7655.0039 | Z26: =V26+W26 -> 6019.1155 | AB26: 44531 | AC26: =L26/B26 -> 0.017791944 | AD26: =M26/C26 -> 0.26312684 | AE26: =N26/D26 -> 0.022532688 | AG26: 44531 | AH26: =V26*1.06/L26 -> 0.37914005 | AI26: =W26*1.06/M26 -> -0.72835406 | AJ26: =Z26*1.06/N26 -> 0.12923172 | AL26: 44531
A27: 44562 | B27: 108052.9 | C27: 2374.0586 | D27: =B27+C27 -> 110426.96 | F27: 44562 | G27: ='毛利-收入组成'!AP27 -> 2571.88 | H27: 2707835.9 | I27: =H27*1.06/10000 -> 287.03061 | J27: 655.10541 | K27: =R27*1.06 -> -486.04177 | L27: =G27-I27+J27-K27 -> 3425.9966 | M27: 1436.02 | N27: =L27+M27 -> 4862.0166 | P27: 44562 | Q27: 554.64112 | R27: =-4585299.71781625/10000 -> -458.52997 | S27: 160.39838 | V27: =Q27-R27+S27 -> 1173.5695 | W27: -1005.6133 | Z27: =V27+W27 -> 167.95616 | AB27: 44562 | AC27: =L27/B27 -> 0.03170666 | AD27: =M27/C27 -> 0.60487979 | AE27: =N27/D27 -> 0.044029254 | AG27: 44562 | AH27: =V27*1.06/L27 -> 0.36310125 | AI27: =W27*1.06/M27 -> -0.74229474 | AJ27: =Z27*1.06/N27 -> 0.03661722 | AL27: 44562 | AM27: 4419474.4 | AN27: =-12638207.1/3 -> -4212735.7
A28: 44593 | B28: 194083.64 | C28: 4905.486 | D28: =B28+C28 -> 198989.13 | F28: 44593 | G28: ='毛利-收入组成'!AP28 -> 4593.9912 | H28: 4898251.5 | I28: =H28*1.06/10000 -> 519.21466 | J28: 895.37 | K28: =R28*1.06 -> -952.56963 | L28: =G28-I28+J28-K28 -> 5922.7161 | M28: 3006.5654 | N28: =L28+M28 -> 8929.2816 | P28: 44593 | Q28: 632.65232 | R28: =-4585299.71781625/10000-4401206.19439752/10000 -> -898.65059 | S28: 103.02 | V28: =Q28-R28+S28 -> 1634.3229 | W28: -1072.18 | Z28: =V28+W28 -> 562.14291 | AB28: 44593 | AC28: =L28/B28 -> 0.030516307 | AD28: =M28/C28 -> 0.61289859 | AE28: =N28/D28 -> 0.044873213 | AG28: 44593 | AH28: =V28*1.06/L28 -> 0.29249794 | AI28: =W28*1.06/M28 -> -0.37800967 | AJ28: =Z28*1.06/N28 -> 0.066732299 | AL28: 44593 | AM28: 2602332.2 | AN28: =-12638207.1/3 -> -4212735.7
A29: 44621 | B29: 326827.75 | C29: 7834.875 | D29: =B29+C29 -> 334662.63 | F29: 44621 | G29: ='毛利-收入组成'!AP29 -> 8008.37 | H29: 6963186.2 | I29: =H29*1.06/10000 -> 738.09774 | J29: 1265.12 | K29: =R29*1.06 -> -1339.65 | L29: =G29-I29+J29-K29 -> 9875.0423 | M29: 4720.6749 | N29: =L29+M29 -> 14595.717 | P29: 44621 | Q29: 1386.5289 | R29: -1263.8207 | S29: 203.79785 | V29: =Q29-R29+S29 -> 2854.1475 | W29: -1370.88 | Z29: =V29+W29 -> 1483.2675 | AB29: 44621 | AC29: =L29/B29 -> 0.030214822 | AD29: =M29/C29 -> 0.60252077 | AE29: =N29/D29 -> 0.043613227 | AG29: 44621 | AH29: =V29*1.06/L29 -> 0.30636794 | AI29: =W29*1.06/M29 -> -0.3078231 | AJ29: =Z29*1.06/N29 -> 0.10772088 | AL29: 44621 | AM29: 6160437 | AN29: =-12638207.1/3 -> -4212735.7 | AO29: 146.56785
A30: 44652 | B30: 448332.98 | C30: 8907.4138 | D30: =B30+C30 -> 457240.4 | F30: 44652 | G30: ='毛利-收入组成'!AP30 -> 10700.565 | H30: 9273917.6 | I30: =H30*1.06/10000 -> 983.03526 | J30: 1531.8642 | K30: =R30*1.06 -> -1249.4227 | L30: =G30-I30+J30-K30 -> 12498.816 | M30: 6687.3105 | N30: =L30+M30 -> 19186.127 | P30: 44652 | Q30: 1630.6354 | R30: -1178.7007 | S30: 4.467404 | V30: =Q30-R30+S30 -> 2813.8034 | W30: -1783.2181 | Z30: =V30+W30 -> 1030.5853 | AB30: 44652 | AC30: =L30/B30 -> 0.027878423 | AD30: =M30/C30 -> 0.75075781 | AE30: =N30/D30 -> 0.0419607 | AG30: 44652 | AH30: =V30*1.06/L30 -> 0.23863313 | AI30: =W30*1.06/M30 -> -0.28265641 | AJ30: =Z30*1.06/N30 -> 0.05693804 | AL30: 44652 | AM30: 3124110.2 | AN30: 851200.46 | AO30: -11.900448
A31: 44682 | B31: 584617.02 | C31: 11251.915 | D31: =B31+C31 -> 595868.94 | F31: 44682 | G31: ='毛利-收入组成'!AP31 -> 13310.057 | H31: 11902620 | I31: =H31*1.06/10000 -> 1261.6778 | J31: 1849.5439 | K31: =R31*1.06 -> -1388.9571 | L31: =G31-I31+J31-K31 -> 15286.88 | M31: 8601.3529 | N31: =L31+M31 -> 23888.233 | P31: 44682 | Q31: 1691.0027 | R31: =-13103368.83/10000 -> -1310.3369 | S31: 45.146767 | V31: =Q31-R31+S31 -> 3046.4863 | W31: -2102.6224 | Z31: =V31+W31 -> 943.86394 | AB31: 44682 | AC31: =L31/B31 -> 0.026148538 | AD31: =M31/C31 -> 0.76443456 | AE31: =N31/D31 -> 0.040089744 | AG31: 44682 | AH31: =V31*1.06/L31 -> 0.2112449 | AI31: =W31*1.06/M31 -> -0.25911967 | AJ31: =Z31*1.06/N31 -> 0.041882368 | AL31: 44682 | AM31: 603672.79 | AN31: =(R31-R30)*10000 -> -1316362.2 | AO31: 208.2226
A32: 44713 | B32: 727745.91 | C32: 13983.27 | D32: =B32+C32 -> 741729.18 | F32: 44713 | G32: ='毛利-收入组成'!AP32 -> 17052.403 | H32: 15547055 | I32: =H32*1.06/10000 -> 1647.9879 | J32: 2173.8273 | K32: =R32*1.06 -> -1365.4349 | L32: =G32-I32+J32-K32 -> 18943.678 | M32: 10706.914 | N32: =L32+M32 -> 29650.592 | P32: 44713 | Q32: 3194.8382 | R32: =-12881461.65/10000 -> -1288.1462 | S32: -520.13564 | V32: =Q32-R32+S32 -> 3962.8487 | W32: -2258.997 | Z32: =V32+W32 -> 1703.8517 | AB32: 44713 | AC32: =L32/B32 -> 0.026030621 | AD32: =M32/C32 -> 0.76569461 | AE32: =N32/D32 -> 0.039974957 | AG32: 44713 | AH32: =V32*1.06/L32 -> 0.22174256 | AI32: =W32*1.06/M32 -> -0.22364397 | AJ32: =Z32*1.06/N32 -> 0.060912202 | AL32: 44713 | AM32: 15038356 | AN32: =(R32-R31)*10000 -> 221907.18 | AO32: -280.71317
A33: 44743 | B33: 850965.84 | C33: 16453.571 | D33: =B33+C33 -> 867419.41 | F33: 44743 | G33: ='毛利-收入组成'!AP33 -> 20185.933 | H33: 18238988 | I33: =H33*1.06/10000 -> 1933.3327 | J33: 2432.4562 | K33: =R33*1.06 -> -1463.2248 | L33: =G33-I33+J33-K33 -> 22148.281 | M33: 13005.352 | N33: =L33+M33 -> 35153.633 | P33: 44743 | Q33: 3804.432 | R33: =-13804007.17/10000 -> -1380.4007 | S33: -820.04 | V33: =Q33-R33+S33 -> 4364.7927 | W33: -2988.73 | Z33: =V33+W33 -> 1376.0627 | AB33: 44743 | AC33: =L33/B33 -> 0.026027227 | AD33: =M33/C33 -> 0.79042731 | AE33: =N33/D33 -> 0.040526685 | AG33: 44743 | AH33: =V33*1.06/L33 -> 0.20889568 | AI33: =W33*1.06/M33 -> -0.24359616 | AJ33: =Z33*1.06/N33 -> 0.041492909 | AL33: 44743 | AM33: 6095938 | AN33: =(R33-R32)*10000 -> -922545.52 | AO33: 15.963167
A34: 44774 | B34: 985758.18 | C34: 19132.318 | D34: =B34+C34 -> 1004890.5 | F34: 44774 | G34: ='毛利-收入组成'!AP34 -> 25497.365 | H34: 21451872 | I34: =H34*1.06/10000 -> 2273.8984 | J34: 3031.335 | K34: =R34*1.06 -> -1426.7573 | L34: =G34-I34+J34-K34 -> 27681.559 | M34: 15290.998 | N34: =L34+M34 -> 42972.557 | P34: 44774 | Q34: =54992357.66/10000 -> 5499.2358 | R34: =-13459974.9019033/10000 -> -1345.9975 | S34: -606.21 | V34: =Q34-R34+S34 -> 6239.0233 | W34: -3396.47 | Z34: =V34+W34 -> 2842.5533 | AB34: 44774 | AC34: =L34/B34 -> 0.02808149 | AD34: =M34/C34 -> 0.79922348 | AE34: =N34/D34 -> 0.042763423 | AG34: 44774 | AH34: =V34*1.06/L34 -> 0.23890868 | AI34: =W34*1.06/M34 -> -0.23544952 | AJ34: =Z34*1.06/N34 -> 0.070116992 | AL34: 44774 | AM34: 16948038 | AN34: =(R34-R33)*10000 -> 344032.27 | AO34: 302.64
A35: 44805 | B35: 1135221.8 | C35: 22645.071 | D35: =B35+C35 -> 1157866.9 | F35: 44805 | G35: ='毛利-收入组成'!AP35 -> 28661.881 | H35: 24370597 | I35: =H35*1.06/10000 -> 2583.2833 | J35: 4014.432 | K35: =R35*1.06 -> -1269.1804 | L35: =G35-I35+J35-K35 -> 31362.211 | M35: 17952.319 | N35: =L35+M35 -> 49314.53 | P35: 44805 | Q35: =60424603.79/10000 -> 6042.4604 | R35: =-11973400.44662/10000 -> -1197.34 | S35: -844.98 | V35: =Q35-R35+S35 -> 6394.8204 | W35: -4007.97 | Z35: =V35+W35 -> 2386.8504 | AB35: 44805 | AC35: =L35/B35 -> 0.027626505 | AD35: =M35/C35 -> 0.79276938 | AE35: =N35/D35 -> 0.042590846 | AG35: 44805 | AH35: =V35*1.06/L35 -> 0.21613622 | AI35: =W35*1.06/M35 -> -0.23665178 | AJ35: =Z35*1.06/N35 -> 0.051304584 | AL35: 44805 | AM35: 5432246.1 | AN35: =(R35-R34)*10000 -> 1486574.5 | AO35: -155.56
A36: 44835 | B36: 1282791 | C36: 30802.29 | D36: =B36+C36 -> 1313593.3 | F36: 44835 | G36: ='毛利-收入组成'!AP36 -> 31941.924 | H36: 27931645 | I36: =H36*1.06/10000 -> 2960.7544 | J36: 4527.9066 | K36: =R36*1.06 -> -1399.6803 | L36: =G36-I36+J36-K36 -> 34908.756 | M36: 20691.857 | N36: =L36+M36 -> 55600.613 | P36: 44835 | Q36: =70722471.56/10000 -> 7072.2472 | R36: =-13204531.4789889/10000 -> -1320.4531 | S36: -989.72 | V36: =Q36-R36+S36 -> 7402.9803 | W36: -3546.33 | Z36: =V36+W36 -> 3856.6503 | AB36: 44835 | AC36: =L36/B36 -> 0.027213129 | AD36: =M36/C36 -> 0.67176361 | AE36: =N36/D36 -> 0.042327115 | AG36: 44835 | AH36: =V36*1.06/L36 -> 0.22479057 | AI36: =W36*1.06/M36 -> -0.18167097 | AJ36: =Z36*1.06/N36 -> 0.073525256 | AL36: 44835 | AM36: 10297813 | AN36: =(R36-R35)*10000 -> -1231131 | AO36: -99.33
A37: 44866 | B37: 1458208.4 | C37: 28395.373 | D37: =B37+C37 -> 1486603.8 | F37: 44866 | G37: ='毛利-收入组成'!AP37 -> 36141.231 | H37: 34940282 | I37: =H37*1.06/10000 -> 3703.6699 | J37: 5080.3998 | K37: =R37*1.06 -> -1487.864 | L37: =G37-I37+J37-K37 -> 39005.825 | M37: 23119.872 | N37: =L37+M37 -> 62125.697 | P37: 44866 | Q37: =75107451.42/10000 -> 7510.7451 | R37: =-14036452.5418712/10000 -> -1403.6453 | S37: -1132.02 | V37: =Q37-R37+S37 -> 7782.3704 | W37: -3545.53 | Z37: =V37+W37 -> 4236.8404 | AB37: 44866 | AC37: =L37/B37 -> 0.026749143 | AD37: =M37/C37 -> 0.81421265 | AE37: =N37/D37 -> 0.041790353 | AG37: 44866 | AH37: =V37*1.06/L37 -> 0.21148925 | AI37: =W37*1.06/M37 -> -0.16255548 | AJ37: =Z37*1.06/N37 -> 0.072289746 | AL37: 44866 | AM37: 3561925.3 | AN37: =(R37-R36)*10000 -> -831921.06 | AO37: -166.06
A38: 44896 | B38: 1630463.8 | C38: 43463.22 | D38: =B38+C38 -> 1673927 | F38: 44896 | G38: ='毛利-收入组成'!AP38 -> 43520.124 | H38: 39830925 | I38: =H38*1.06/10000 -> 4222.0781 | J38: 6011.9066 | K38: =R38*1.06 -> -1190.8049 | L38: =G38-I38+J38-K38 -> 46500.757 | M38: 25043.454 | N38: =L38+M38 -> 71544.211 | P38: 44896 | Q38: =115027391.79/10000 -> 11502.739 | R38: =-11234008.655/10000 -> -1123.4009 | S38: -1269.48 | V38: =Q38-R38+S38 -> 11356.66 | W38: -4104.55 | Z38: =V38+W38 -> 7252.11 | AB38: 44896 | AC38: =L38/B38 -> 0.028519957 | AD38: =M38/C38 -> 0.57619877 | AE38: =N38/D38 -> 0.042740341 | AG38: 44896 | AH38: =V38*1.06/L38 -> 0.25887879 | AI38: =W38*1.06/M38 -> -0.17373095 | AJ38: =Z38*1.06/N38 -> 0.10744736 | AL38: 44896 | AM38: 18287190 | AN38: =(R38-R37)*10000 -> 2802443.9 | AO38: 184.5
A39: 44927 | B39: ='GMV表-商品大类'!T42+B95 -> 139899.12 | C39: 3494.7221 | D39: =B39+C39 -> 143393.84 | F39: 44927 | G39: ='毛利-收入组成'!AP39 -> 4343.2834 | H39: 3630321.3 | I39: =H39*1.06/10000 -> 384.81406 | J39: 1931.3288 | K39: =R39*1.06 -> 206.06363 | L39: =G39-I39+J39-K39 -> 5683.7345 | M39: 2148.7773 | N39: =L39+M39 -> 7832.5118 | P39: 44927 | Q39: 1390.69 | R39: =1943996.50432941/10000 -> 194.39965 | S39: 785.578 | V39: =Q39-R39+S39 -> 1981.8684 | W39: 206.1331 | Z39: =V39+W39 -> 2188.0015 | AB39: 44927 | AC39: =L39/B39 -> 0.040627379 | AD39: =M39/C39 -> 0.61486355 | AE39: =N39/D39 -> 0.054622372 | AG39: 44927 | AH39: =V39*1.06/L39 -> 0.3696127 | AI39: =W39*1.06/M39 -> 0.10168624 | AJ39: =Z39*1.06/N39 -> 0.29610955 | AL39: 44927 | AM39: 13906900 | AN39: =R39*10000 -> 1943996.5 | AO39: 98.863
A40: 44958 | B40: ='GMV表-商品大类'!T43+B96 -> 273756.55 | C40: 6379.2112 | D40: =B40+C40 -> 280135.76 | F40: 44958 | G40: ='毛利-收入组成'!AP40 -> 7467.2483 | H40: 6214995.1 | I40: =H40*1.06/10000 -> 658.78948 | J40: 2249.6399 | K40: =R40*1.06 -> -169.18257 | L40: =G40-I40+J40-K40 -> 9227.2813 | M40: 3659.1241 | N40: =L40+M40 -> 12886.405 | P40: 44958 | Q40: 2066.4314 | R40: =-1596061.9885538/10000 -> -159.6062 | S40: 597.92934 | V40: =Q40-R40+S40 -> 2823.967 | W40: 130.11791 | Z40: =V40+W40 -> 2954.0849 | AB40: 44958 | AC40: =L40/B40 -> 0.033706157 | AD40: =M40/C40 -> 0.57360134 | AE40: =N40/D40 -> 0.046000572 | AG40: 44958 | AH40: =V40*1.06/L40 -> 0.32440812 | AI40: =W40*1.06/M40 -> 0.037693443 | AJ40: =Z40*1.06/N40 -> 0.24299484 | AL40: 44958 | AM40: 6757414.1 | AN40: =(R40-R39)*10000 -> -3540058.5 | AO40: =S40-S39 -> -187.64866
...

Sheet 投资公司
A1: 2025年
A2: 类别 | B2: 调整博宽&黄石福桃等渠道电商毛利 | C2: 累计净利润 | D2: 1月利润 | E2: 2月利润 | F2: 3月利润 | G2: 4月利润 | H2: 5月利润 | I2: 6月利润 | J2: 7月利润 | K2: 8月利润 | L2: 9月利润 | M2: 10月利润 | N2: 11月利润 | O2: 12月利润
A3: 1、手游 | C3: =SUM(D3:O3) -> -27.65 | I3: 7.059 | J3: =-27.65-I3 -> -34.709 | P3: -27.65
A4: 2、网游 | C4: =SUM(D4:O4) -> 0
A5: 3、通信 | C5: =SUM(D5:O5) -> 0
A6: 4、网娱 | C6: =SUM(D6:O6) -> 232.934 | D6: 77.701 | E6: 6.228 | F6: 106.762 | G6: 78.746 | H6: 76.203 | I6: =281.088987-7.059-(38.674+377.647) -> -142.29101 | J6: =232.934-SUM(D6:I6) -> 29.585013 | P6: 232.934
A7: 5、生活服务 | C7: =SUM(D7:O7) -> 461.05 | I7: =38.674+377.647 -> 416.321 | J7: =461.05-I7 -> 44.729 | P7: 461.05
A8: 合计 | B8: =SUM(B3:B7) -> 0 | C8: =SUM(C3:C7) -> 666.334 | D8: =SUM(D3:D7) -> 77.701 | E8: =SUM(E3:E7) -> 6.228 | F8: =SUM(F3:F7) -> 106.762 | G8: =SUM(G3:G7) -> 78.746 | H8: =SUM(H3:H7) -> 76.203 | I8: =SUM(I3:I7) -> 281.08899 | ... O8: =SUM(O3:O7) -> 0 | P8: ='[37]简表底稿 (万元)'!$L$2 -> 666.334 | Q8: =P8-C8 -> 0
A10: 含税金额 | C10: =C8*1.06 -> 706.31404 | D10: =D8*1.06 -> 82.36306 | E10: =E8*1.06 -> 6.60168 | F10: =F8*1.06 -> 113.16772 | G10: =G8*1.06 -> 83.47076 | H10: =H8*1.06 -> 80.77518 | I10: =I8*1.06 -> 297.95433 | J10: =J8*1.06 -> 41.981314 | ... O10: =O8*1.06 -> 0
A12: 2024年
A13: 类别 | B13: 调整博宽&黄石福桃等渠道电商毛利 | C13: 累计净利润 | D13: 1月利润 | E13: 2月利润 | F13: 3月利润 | G13: 4月利润 | H13: 5月利润 | I13: 6月利润 | J13: 7月利润 | K13: 8月利润 | L13: 9月利润 | M13: 10月利润 | N13: 11月利润 | O13: 12月利润
A14: 1、手游
A15: 2、网游
A16: 3、通信
A17: 4、网娱 | C17: =SUM(D17:O17) -> 366.107 | D17: =377.983-2659414.53/10000 -> 112.04155 | E17: =191.57-3869946.72/10000 -> -195.42467 | F17: =-429.26--5370695.59/10000 -> 107.80956 | G17: =-29.559-2165911.16/10000 -> -246.15012 | H17: 96.61 | I17: -3.44 | J17: 191.09 | K17: 71.15 | L17: 20.14 | M17: 57.43 | N17: 209.28868 | O17: -54.438
A18: 5、生活服务
A19: 合计 | B19: =SUM(B14:B18) -> 0 | C19: =SUM(C14:C18) -> 366.107 | D19: =SUM(D14:D18) -> 112.04155 | E19: =SUM(E14:E18) -> -195.42467 | F19: =SUM(F14:F18) -> 107.80956 | G19: =SUM(G14:G18) -> -246.15012 | H19: =SUM(H14:H18) -> 96.61 | I19: =SUM(I14:I18) -> -3.44 | ... O19: =SUM(O14:O18) -> -54.438
A21: 含税金额 | C21: =C19*1.06 -> 388.07342 | D21: =D19*1.06 -> 118.76404 | E21: =E19*1.06 -> -207.15015 | F21: =F19*1.06 -> 114.27813 | G21: =G19*1.06 -> -260.91912 | H21: =H19*1.06 -> 102.4066 | I21: =I19*1.06 -> -3.6464 | J21: =J19*1.06 -> 202.5554 | ... O21: =O19*1.06 -> -57.70428
A23: 2023年
A24: 类别 | B24: 调整博宽&黄石福桃等渠道电商毛利 | C24: 累计净利润 | D24: 1月利润 | E24: 2月利润 | F24: 3月利润 | G24: 4月利润 | H24: 5月利润 | I24: 6月利润 | J24: 7月利润 | K24: 8月利润 | L24: 9月利润 | M24: 10月利润 | N24: 11月利润 | O24: 12月利润
A25: 1、手游
A26: 2、网游
A27: 3、通信
A28: 4、网娱 | C28: =SUM(D28:O28) -> 219.71 | D28: 98.863 | E28: 88.266 | F28: 112.98 | G28: -111.401 | H28: -41.707 | I28: -100.897 | J28: 160.729 | K28: 125.174 | L28: -208.57 | M28: 179.757 | N28: 53.982 | O28: -137.466
A29: 5、生活服务
A30: 合计 | B30: =SUM(B25:B29) -> 0 | C30: =SUM(C25:C29) -> 219.71 | F30: =SUM(F25:F29) -> 112.98 | G30: =SUM(G25:G29) -> -111.401 | H30: =SUM(H25:H29) -> -41.707 | I30: =SUM(I25:I29) -> -100.897 | J30: =SUM(J25:J29) -> 160.729 | K30: =SUM(K25:K29) -> 125.174 | L30: =SUM(L25:L29) -> -208.57 | M30: =SUM(M25:M29) -> 179.757 | ... O30: =SUM(O25:O29) -> -137.466
A32: 含税金额 | C32: =C30*1.06 -> 232.8926 | D32: =D30*1.06 -> 0 | E32: =E30*1.06 -> 0 | F32: =F30*1.06 -> 119.7588 | G32: =G30*1.06 -> -118.08506 | H32: =H30*1.06 -> -44.20942 | I32: =I30*1.06 -> -106.95082 | J32: =J30*1.06 -> 170.37274 | ... O32: =O30*1.06 -> -145.71396
B39: 公司全称 | C39: 剔除后利润2410 | D39: 剔除后利润2411 | E39: 剔除后利润2412
B40: 北京萌桃网络科技有限公司 | C40: -1030348.8 | D40: -903225.23 | E40: 891317.98 | F40: =E40-D40 -> 1794543.2
B41: 黄石长驱网络科技有限公司 | C41: -101116.56 | D41: -121183.48 | E41: -159339.02 | F41: =E41-D41 -> -38155.54
B42: 南京梦澄网络科技有限公司 | C42: 39450.92 | D42: 36003.91 | E42: 27371.62 | F42: =E42-D42 -> -8632.29
B43: 南京逐电网络科技有限公司 | C43: -2854.26 | D43: -2898.17 | E43: -11201.47 | F43: =E43-D43 -> -8303.3
B44: 长沙雷厉网络科技有限公司 | C44: -2098.94 | D44: -2283.59 | E44: -2283.59 | F44: =E44-D44 -> 0
B45: 长沙星合网络科技有限公司 | C45: 118205.04 | D45: 232964.01 | E45: 154874.19 | F45: =E45-D45 -> -78089.82
B46: 武汉双立网络科技有限公司 | C46: -483876.71 | D46: -558336.91 | E46: -671481.83 | F46: =E46-D46 -> -113144.92
B47: 武汉铭柏网络科技有限公司 | C47: 1101715.3 | D47: 1529010.8 | E47: 451698.26 | F47: =E47-D47 -> -1077312.6
B48: 武汉市萌想家网络科技有限公司 | C48: 0 | D48: 0 | E48: -47112.72 | F48: =E48-D48 -> -47112.72
B49: 重分类调整 | C49: -442821.91 | D49: 8007.07 | E49: 6588.28 | F49: =E49-D49 -> -1418.79
B52: 客户发展中心 | C52: 47.351 | D52: 69.186 | E52: 92.599 | F52: =E52-D52 -> 23.413
B53: 渠道线项目 | C53: -80.375 | D53: 21.806 | E53: 64.043 | F53: =E53-D53 -> 42.237
...

Sheet GMV销售额波动分析（分月、年）
A1: 2025年 | B1: SP0001-网游 | C1: SP0005-手游 | D1: SP0002-通信 | E1: SP0003-网娱 | F1: SP0004-卡劵 | G1: SP0006-生活服务 | H1: 总计（含税） | I1: 体内公司GMV | J1: 月份 | K1: 2025年GMV | L1: 2024年GMV | M1: 同期增长
A2: 1月 | B2: 45102810 | C2: 75000597 | D2: 9435812.5 | E2: 2.0356185e+08 | F2: 3.6554639e+08 | G2: 277292.49 | H2: =SUM(B2:G2) -> 6.9892476e+08 | I2: =H2/10000-GMV销售平台占比!B16 -> 7.1304385e-10 | J2: 1月 | K2: =H2/100000000 -> 6.9892476 | L2: =H17/100000000 -> 8.3841662 | M2: =(K2-L2)/L2 -> -0.16637536 | N2: =K2-L2 -> -1.3949187
A3: 2月 | B3: 29914547 | C3: 33284884 | D3: 12224513 | E3: 1.8650532e+08 | F3: 2.8944267e+08 | G3: 697463.75 | H3: =SUM(B3:G3) -> 5.5206939e+08 | J3: 2月 | K3: =H3/100000000 -> 5.5206939 | L3: =H18/100000000 -> 7.6218049 | M3: =(K3-L3)/L3 -> -0.27567105
A4: 3月 | B4: 23250822 | C4: 38931285 | D4: 4582458.6 | E4: 1.8891607e+08 | F4: 4.1025231e+08 | G4: 50935.907 | H4: =SUM(B4:G4) -> 6.6598388e+08 | J4: 3月 | K4: =H4/100000000 -> 6.6598388 | L4: =H19/100000000 -> 6.6832889 | M4: =(K4-L4)/L4 -> -0.0035087704
A5: 4月 | B5: 26883010 | C5: 46615668 | D5: 3360143.8 | E5: 1.7304789e+08 | F5: 3.5350825e+08 | G5: 45091.202 | H5: =SUM(B5:G5) -> 6.0346005e+08 | J5: 4月 | K5: =H5/100000000 -> 6.0346005 | L5: =H20/100000000 -> 5.0345297 | M5: =(K5-L5)/L5 -> 0.19864235
A6: 5月 | B6: 37315216 | C6: 1.0025681e+08 | D6: 3366603.9 | E6: 1.7290566e+08 | F6: 2.90837e+08 | G6: 36996.619 | H6: =SUM(B6:G6) -> 6.0471829e+08 | J6: 5月 | K6: =H6/100000000 -> 6.0471829 | L6: =H21/100000000 -> 7.0552966 | M6: =(K6-L6)/L6 -> -0.1428875
A7: 6月 | B7: 44748189 | C7: 41902247 | D7: 2880591.8 | E7: 1.2474516e+08 | F7: 3.5477031e+08 | G7: 93346.506 | H7: =SUM(B7:G7) -> 5.6913985e+08 | J7: 6月 | K7: =H7/100000000 -> 5.6913985 | L7: =H22/100000000 -> 8.3802748 | M7: =(K7-L7)/L7 -> -0.32085777
A8: 7月 | B8: 40140017 | C8: 47381046 | D8: 2957178.4 | E8: 75125965 | F8: 4.6261523e+08 | G8: 2103107.7 | H8: =SUM(B8:G8) -> 6.3032255e+08 | J8: 7月 | K8: =H8/100000000 -> 6.3032255 | L8: =H23/100000000 -> 8.2004978 | M8: =(K8-L8)/L8 -> -0.23136063
A9: 8月 | H9: =SUM(B9:G9) -> 0 | J9: 8月 | K9: =H9/100000000 -> 0 | L9: =H24/100000000 -> 7.5165771 | M9: =(K9-L9)/L9 -> -1
A10: 9月 | H10: =SUM(B10:G10) -> 0 | J10: 9月 | K10: =H10/100000000 -> 0 | L10: =H25/100000000 -> 5.2618104 | M10: =(K10-L10)/L10 -> -1
A11: 10月 | H11: =SUM(B11:G11) -> 0 | J11: 10月 | K11: =H11/100000000 -> 0 | L11: =H26/100000000 -> 5.901137 | M11: =(K11-L11)/L11 -> -1
A12: 11月 | H12: =SUM(B12:G12) -> 0 | J12: 11月 | K12: =H12/100000000 -> 0 | L12: =H27/100000000 -> 6.1812962 | M12: =(K12-L12)/L12 -> -1
A13: 12月 | H13: =SUM(B13:G13) -> 0 | J13: 12月 | K13: =H13/100000000 -> 0 | L13: =H28/100000000 -> 6.0199264 | M13: =(K13-L13)/L13 -> -1
A14: 合计 | B14: =SUM(B2:B13) -> 2.4735461e+08 | C14: =SUM(C2:C13) -> 3.8337254e+08 | D14: =SUM(D2:D13) -> 38807302 | E14: =SUM(E2:E13) -> 1.1248079e+09 | F14: =SUM(F2:F13) -> 2.5269722e+09 | G14: =SUM(G2:G13) -> 3304234.2 | H14: =SUM(H2:H13) -> 4.3246188e+09 | J14: 合计（亿元） | K14: =SUM(K2:K13) -> 43.246188 | L14: =SUM(L2:L8) -> 51.359859 | M14: =(K14-L14)/L14 -> -0.1579769 | N14: =K14-L14 -> -8.1136713 | O14: =N14/L14 -> -0.1579769
J15: 累计数贴PPT37
A16: 2024年 | B16: SP0001-网游 | C16: SP0005-手游 | D16: SP0002-通信 | E16: SP0003-网娱 | F16: SP0004-卡劵 | G16: SP0006-生活服务 | H16: 总计（含税） | J16: 商品大类 | K16: 2024年 | L16: 2023年 | M16: 变动额 | N16: 变动率
A17: 1月 | B17: 1.6394352e+08 | C17: 72069322 | D17: 57651169 | E17: 2.2038104e+08 | F17: 3.2436856e+08 | G17: 3015.47 | H17: 8.3841662e+08 | J17: 网游 | K17: =B14/10000 -> 24735.461 | L17: =SUM(B32:B43)/10000 -> 204213.4 | M17: =K17-L17 -> -179477.94 | N17: =M17/L17 -> -0.87887445 | O17: =K17+K18 -> 63072.715 | P17: =L17+L18 -> 288229.3
A18: 2月 | B18: 1.2902059e+08 | C18: 78670926 | D18: 51869185 | E18: 2.0630623e+08 | F18: 2.9632854e+08 | G18: -14984.47 | H18: 7.6218049e+08 | J18: 手游 | K18: =C14/10000 -> 38337.254 | L18: =SUM(C32:C43)/10000 -> 84015.899 | M18: =K18-L18 -> -45678.645 | N18: =M18/L18 -> -0.54369049 | P18: =(O17-P17)/P17 -> -0.78117175
A19: 3月 | B19: 40868843 | C19: 40313324 | D19: 61579069 | E19: 2.4007575e+08 | F19: 2.8386047e+08 | G19: 1631435.1 | H19: 6.6832889e+08 | J19: 通信 | K19: =D14/10000 -> 3880.7302 | L19: =SUM(D32:D43)/10000 -> 212342.83 | M19: =K19-L19 -> -208462.1 | N19: =M19/L19 -> -0.98172422
A20: 4月 | B20: 36836160 | C20: 30957288 | D20: 31064079 | E20: 2.3861802e+08 | F20: 1.659334e+08 | G20: 44022.467 | H20: 5.0345297e+08 | J20: 网娱 | K20: =E14/10000 -> 112480.79 | L20: =SUM(E32:E43)/10000 -> 505603.59 | M20: =K20-L20 -> -393122.8 | N20: =M20/L20 -> -0.77753166
A21: 5月 | B21: 36434632 | C21: 80871997 | D21: 23162770 | E21: 2.994851e+08 | F21: 2.6579687e+08 | G21: -221706.87 | H21: 7.0552966e+08 | J21: 生活服务 | K21: =(F14+G14)/10000 -> 253027.64 | L21: =SUM(F32:G43)/10000 -> 554277.85 | M21: =K21-L21 -> -301250.21 | N21: =M21/L21 -> -0.54350036
A22: 6月 | B22: 77715917 | C22: 92084688 | D22: 14168628 | E22: 3.4860498e+08 | F22: 3.052408e+08 | G22: 212456.67 | H22: 8.3802748e+08 | J22: 总计（万元） | K22: =SUM(K17:K21) -> 432461.88 | L22: =SUM(L17:L21) -> 1560453.6 | M22: =SUM(M17:M21) -> -1127991.7 | N22: =M22/L22 -> -0.72286143
A23: 7月 | B23: 83089797 | C23: 1.3250714e+08 | D23: 14913498 | E23: 2.4546108e+08 | F23: 3.3679378e+08 | G23: 7284483.8 | H23: 8.2004978e+08
A24: 8月 | B24: 49122371 | C24: 66704878 | D24: 25481143 | E24: 3.0002115e+08 | F24: 3.0906987e+08 | G24: 1258291.4 | H24: 7.5165771e+08
A25: 9月 | B25: 29245115 | C25: 48236433 | D25: 12906205 | E25: 2.2928796e+08 | F25: 2.0652896e+08 | G25: -23631.13 | H25: 5.2618104e+08
A26: 10月 | B26: 30810565 | C26: 55595035 | D26: 9471714.6 | E26: 2.3255981e+08 | F26: 2.6141187e+08 | G26: 264707.59 | H26: 5.901137e+08
A27: 11月 | B27: 24768660 | C27: 61722499 | D27: 6958838.9 | E27: 2.5892265e+08 | F27: 2.656238e+08 | G27: 133170.18 | H27: 6.1812962e+08
A28: 12月 | B28: 17633355 | C28: 34982091 | D28: 6161395.9 | E28: 2.6412947e+08 | F28: 2.7877715e+08 | G28: 309180.8 | H28: 6.0199264e+08
A29: 合计 | B29: =SUM(B17:B28) -> 7.1948953e+08 | C29: =SUM(C17:C28) -> 7.9471562e+08 | D29: =SUM(D17:D28) -> 3.153877e+08 | E29: =SUM(E17:E28) -> 3.0838533e+09 | F29: =SUM(F17:F28) -> 3.2997341e+09 | G29: =SUM(G17:G28) -> 10880441 | H29: =SUM(H17:H28) -> 8.2240606e+09
A31: 2023年 | B31: SP0001-网游 | C31: SP0005-手游 | D31: SP0002-通信 | E31: SP0003-网娱 | F31: SP0004-卡劵 | G31: SP0006-生活服务 | H31: 总计（含税）
A32: 1月 | B32: 1.0755749e+08 | C32: 1.2230208e+08 | D32: 2.927875e+08 | E32: 4.8836984e+08 | F32: 3.2916948e+08 | G32: 5629439.6 | H32: =SUM(B32:G32) -> 1.3458158e+09
A33: 2月 | B33: 86491645 | C33: 48095782 | D33: 3.841738e+08 | E33: 4.5017964e+08 | F33: 3.5004372e+08 | G33: 7076.29 | H33: =SUM(B33:G33) -> 1.3189917e+09
A34: 3月 | B34: 1.088094e+08 | C34: 67960161 | D34: 4.0696017e+08 | E34: =481032330.11-13500000 -> 4.6753233e+08 | F34: 4.8239142e+08 | G34: -551189.73 | H34: =SUM(B34:G34) -> 1.5331023e+09
A35: 4月 | B35: 2.050828e+08 | C35: 45919678 | D35: 1.4908958e+08 | E35: =398767570-12500000 -> 386267570 | F35: 4.6616905e+08 | G35: 4267.31 | H35: =SUM(B35:G35) -> 1.2525329e+09
A36: 5月 | B36: 3.3263003e+08 | C36: 1.0672384e+08 | D36: 1.4554824e+08 | E36: 3.4806915e+08 | F36: 5.457605e+08 | G36: -17436.15 | H36: =SUM(B36:G36) -> 1.4787143e+09
A37: 6月 | B37: 2.8460326e+08 | C37: 38830643 | D37: 1.8696408e+08 | E37: 4.0582857e+08 | F37: 6.5744036e+08 | G37: 2100.07 | H37: =SUM(B37:G37) -> 1.573669e+09
A38: 7月 | B38: 2.1237629e+08 | C38: 68821147 | D38: 1.2591962e+08 | E38: 3.5418136e+08 | F38: 5.528262e+08 | G38: 10513.11 | H38: =SUM(B38:G38) -> 1.3141351e+09
A39: 8月 | B39: 2.0523625e+08 | C39: 1.1420637e+08 | D39: 1.234218e+08 | E39: 4.1823418e+08 | F39: 6.1102003e+08 | G39: 2183.91 | H39: =SUM(B39:G39) -> 1.4721208e+09
A40: 9月 | B40: 2.1353486e+08 | C40: 51971549 | D40: 97829884 | E40: 3.9707166e+08 | F40: 4.9935928e+08 | G40: 6539.06 | H40: =SUM(B40:G40) -> 1.2597738e+09
A41: 10月 | B41: 89061955 | C41: 36377220 | D41: 72310873 | E41: 3.9956302e+08 | F41: 3.6598322e+08 | G41: -70181.51 | H41: =SUM(B41:G41) -> 9.632261e+08
...

Sheet GMV销售平台占比
A1: 2025年
A2: 平台 | B2: 1月 | C2: 2月 | D2: 3月 | E2: 4月 | F2: 5月 | G2: 6月 | H2: 7月 | I2: 8月 | J2: 9月 | K2: 10月 | L2: 11月 | M2: 12月 | N2: 合计 | O2: 平台GMV占比 | Q2: 平台 | R2: 2025年 | S2: 2024年 | T2: 2023年 | U2: 2022年
A3: 福禄开放平台 | B3: 55063.067 | C3: 45120.512 | D3: 57418.92 | E3: 51803.522 | F3: 45322.133 | G3: 43295.323 | H3: 48615.93 | N3: =(SUM(B3:M3)) -> 346639.41 | O3: =ROUND(N3/$N$16,4) -> 0.8015 | Q3: TOB | R3: =R13/Y13 -> 0.81538664 | S3: =R14/Y14 -> 0.6902932 | T3: =R15/Y15 -> 0.69689837 | U3: =R16/Y16 -> 0.67893398
A4: 福游云平台 | E4: 31.579643 | F4: 705.67017 | G4: 2546.6727 | H4: 2700.307 | N4: =(SUM(B4:M4)) -> 5984.2295 | O4: =ROUND(N4/$N$16,4) -> 0.0138 | Q4: 京东 | R4: =S13/Y13 -> 0.0043819835 | S4: =S14/Y14 -> 0.086967994 | T4: =S15/Y15 -> 0.10181272 | U4: =S16/Y16 -> 0.12832323
A5: 京东 | B5: 190.33022 | C5: 199.69965 | D5: 194.03104 | E5: 183.95279 | F5: 467.27444 | G5: 658.6546 | H5: 1.0980527 | N5: =(SUM(B5:M5)) -> 1895.0408 | O5: =ROUND(N5/$N$16,4) -> 0.0044 | P5: =O5+O6+O7 -> 0.0385 | Q5: 天猫 | R5: =T13/Y13 -> 0.030418994 | S5: =T14/Y14 -> 0.055586614 | T5: =T15/Y15 -> 0.051617994 | U5: =T16/Y16 -> 0.063652707
A6: 天猫 | B6: 2049.7325 | C6: 1846.0403 | D6: 1706.0095 | E6: 1664.0018 | F6: 2202.8411 | G6: 1977.3084 | H6: 1709.1216 | N6: =(SUM(B6:M6)) -> 13155.055 | O6: =ROUND(N6/$N$16,4) -> 0.0304 | Q6: 拼多多 | R6: =U13/Y13 -> 0.0036640109 | S6: =U14/Y14 -> 0.003297438 | T6: =U15/Y15 -> 0.0036902897 | U6: =U16/Y16 -> 0.013988165
A7: 拼多多 | B7: 230.92896 | C7: 199.5126 | D7: 226.99423 | E7: 171.59552 | F7: 210.09979 | G7: 259.57187 | H7: 285.84206 | N7: =(SUM(B7:M7)) -> 1584.545 | O7: =ROUND(N7/$N$16,4) -> 0.0037 | Q7: 支付宝小程序 | R7: =V13/Y13 -> 0.097419315 | S7: =V14/Y14 -> 0.084597643 | T7: =V15/Y15 -> 0.067331178 | U7: =V16/Y16 -> 0.030087931
A8: 支付宝小程序 | B8: 7907.5419 | C8: 5765.9562 | D8: 5728.9415 | E8: 4580.5479 | F8: 4494.4352 | G8: 6285.4866 | H8: 7367.2304 | N8: =(SUM(B8:M8)) -> 42130.14 | O8: =ROUND(N8/$N$16,4) -> 0.0974 | Q8: 抖快 | R8: =W13/Y13 -> 0.033919783 | S8: =W14/Y14 -> 0.042282233 | T8: =W15/Y15 -> 0.044596246 | U8: =W16/Y16 -> 0.024833133
A9: 抖音 | B9: 3623.411 | C9: 1339.3877 | D9: 547.55514 | E9: 899.18485 | F9: 6022.9674 | G9: 718.47917 | H9: 1363.9833 | N9: =(SUM(B9:M9)) -> 14514.968 | O9: =ROUND(N9/$N$16,4) -> 0.0336 | P9: =O9+O10 -> 0.034 | Q9: 其他 | R9: =X13/Y13 -> 0.014809272 | S9: =X14/Y14 -> 0.036974874 | T9: =X15/Y15 -> 0.0340532 | U9: =X16/Y16 -> 0.32106602
A10: 快手 | B10: 0 | C10: 0 | D10: 0 | E10: 35.226567 | F10: 27.489975 | G10: 23.483136 | H10: 67.845025 | N10: =(SUM(B10:M10)) -> 154.0447 | O10: =ROUND(N10/$N$16,4) -> 0.0004 | Q10: 小计 | R10: =SUM(R3:R9) -> 1 | S10: =SUM(S3:S9) -> 1 | T10: =SUM(T3:T9) -> 1 | U10: =SUM(U3:U9) -> 1.2608852
A11: 微信 | B11: 0.00845142 | C11: 0.00939968 | D11: 1.9206678 | E11: 3.5007104 | F11: 7.2964773 | G11: 3.3149819 | H11: 32.526796 | N11: =(SUM(B11:M11)) -> 48.577485 | O11: =ROUND(N11/$N$16,4) -> 0.0001
A12: 第三方平台 | B12: 790.75542 | C12: 704.81211 | D12: 742.65797 | E12: 935.42259 | F12: 969.39961 | G12: 1099.4609 | H12: 858.72859 | N12: =(SUM(B12:M12)) -> 6101.2371 | O12: =ROUND(N12/$N$16,4) -> 0.0141 | Q12: 渠道大类 | R12: TOB | S12: 京东 | T12: 天猫 | U12: 拼多多 | V12: 支付宝小程序 | W12: 抖快 | X12: 第三方B2B2C | Y12: 合计（万元） | Z12: TOC | AA12: 验算
A13: 充值频道 | B13: 22.783026 | C13: 19.475482 | D13: 20.449559 | E13: 20.691139 | F13: 16.109016 | G13: 29.63618 | H13: 18.880263 | N13: =(SUM(B13:M13)) -> 148.02466 | O13: =ROUND(N13/$N$16,4) -> 0.0003 | Q13: 2025年 | R13: =N3+N4 -> 352623.64 | S13: =N5 -> 1895.0408 | T13: =N6 -> 13155.055 | U13: =N7 -> 1584.545 | V13: =N8 -> 42130.14 | W13: =N9+N10 -> 14669.013 | X13: =Y13-SUM(R13:W13) -> 6404.4457 | Y13: =N16 -> 432461.88 | Z13: =Y13-R13 -> 79838.239 | AA13: =Y13-'GMV表-商品大类'!F85 -> -5.0058588e-09
A14: 百度小程序 | B14: 0.00039 | C14: 0.00499048 | D14: 0.00124 | E14: 0.0007 | F14: 0.00499048 | G14: 0 | H14: 0 | N14: =(SUM(B14:M14)) -> 0.01231096 | O14: =ROUND(N14/$N$16,4) -> 0 | Q14: 2024年 | R14: =N21 -> 354533.62 | S14: =N22 -> 44666.639 | T14: =N23 -> 28549.207 | U14: =N24 -> 1693.5595 | V14: =N25 -> 43449.23 | W14: =N26+N27 -> 21716.095 | X14: =Y14-SUM(R14:W14) -> 18990.243 | Y14: =N34 -> 513598.59 | Z14: =Y14-R14 -> 159064.97 | AA14: =Y14-'GMV表-商品大类'!F84 -> 1.9790605e-09
A15: mall商城 | B15: 13.916859 | C15: 11.529193 | D15: 10.90678 | E15: 16.779002 | F15: 26.107432 | G15: 16.593748 | H15: 10.761049 | N15: =(SUM(B15:M15)) -> 106.59406 | O15: =ROUND(N15/$N$16,4) -> 0.0002 | Q15: 2023年 | R15: =N39 -> 684142.42 | S15: =N40 -> 99949.157 | T15: =N41 -> 50673.185 | U15: =N42 -> 3622.7431 | V15: =N43 -> 66098.756 | W15: =N44+N45 -> 43779.962 | X15: =Y15-SUM(R15:W15) -> 33429.895 | Y15: =N53 -> 981696.12 | Z15: =Y15-R15 -> 297553.7 | AA15: =Y15-'GMV表-商品大类'!F83 -> 0.00060700206
A16: 合计(单位：万元） | B16: =SUM(B3:B15) -> 69892.476 | C16: =SUM(C3:C15) -> 55206.939 | D16: =SUM(D3:D15) -> 66598.388 | E16: =SUM(E3:E15) -> 60346.005 | F16: =SUM(F3:F15) -> 60471.829 | G16: =SUM(G3:G15) -> 56913.985 | H16: =SUM(H3:H15) -> 63032.255 | I16: =SUM(I3:I15) -> 0 | ... O16: =SUM(O3:O15) -> 0.9999 | Q16: 2022年 | R16: =N57 -> 1095964.4 | S16: =N58 -> 207144.88 | T16: =N59 -> 102750.94 | U16: =N60 -> 22580.296 | V16: =N61 -> 48569.231 | W16: =N62+N63 -> 40086.711 | X16: =Y16-SUM(R16:R16) -> 518278.57 | Y16: =N71 -> 1614243 | Z16: =Y16-R16 -> 518278.57 | AA16: =Y16-'GMV表-商品大类'!F82 -> -2.4028122e-07
Q17: 变动 | R17: =R13-R14 -> -1909.9784 | S17: =S13-S14 -> -42771.598 | T17: =T13-T14 -> -15394.151 | U17: =U13-U14 -> -109.0145 | V17: =V13-V14 -> -1319.0906 | W17: =W13-W14 -> -7047.0822 | X17: =X13-X14 -> -12585.798 | Y17: =Y13-Y14 -> -81136.713
R18: =R17/R14 -> -0.0053872986 | S18: =S17/S14 -> -0.95757369 | T18: =T17/T14 -> -0.53921468 | U18: =U17/U14 -> -0.064370041 | V18: =V17/V14 -> -0.030359354 | W18: =W17/W14 -> -0.32450963 | X18: =X17/X14 -> -0.66275073 | Y18: =Y17/Y14 -> -0.1579769
A19: 2024年
A20: 平台 | B20: 1月 | C20: 2月 | D20: 3月 | E20: 4月 | F20: 5月 | G20: 6月 | H20: 7月 | I20: 8月 | J20: 9月 | K20: 10月 | L20: 11月 | M20: 12月 | N20: 合计 | O20: 平台GMV占比 | Q20: 平台 | R20: TOB | S20: 京东 | T20: 天猫 | U20: 拼多多 | V20: 支付宝小程序 | W20: 抖快 | X20: 其他 | Y20: 小计
A21: 福禄开放平台 | B21: 57380.332 | C21: 49703.168 | D21: 52869.612 | E21: 39772.322 | F21: 48186.498 | G21: 55691.42 | H21: 50930.264 | I21: 57429.588 | J21: 43578.641 | K21: 46612.011 | L21: 47834.971 | M21: 50236.751 | N21: =SUM(B21:H21) -> 354533.62 | O21: =ROUND(N21/$N$34,4) -> 0.6903 | Q21: 2025年 | R21: =R13/$Y$13 -> 0.81538664 | S21: =S13/$Y$13 -> 0.0043819835 | T21: =T13/$Y$13 -> 0.030418994 | U21: =U13/$Y$13 -> 0.0036640109 | V21: =V13/$Y$13 -> 0.097419315 | W21: =W13/$Y$13 -> 0.033919783 | X21: =X13/$Y$13 -> 0.014809272 | Y21: =SUM(R21:X21) -> 1
A22: 京东 | B22: 7436.1819 | C22: 4795.2709 | D22: 1573.2976 | E22: 1831.6988 | F22: 5229.3072 | G22: 11708.543 | H22: 12092.34 | I22: 2723.5818 | J22: 621.1785 | K22: 1282.8291 | L22: 354.24055 | M22: 186.61391 | N22: =SUM(B22:H22) -> 44666.639 | O22: =ROUND(N22/$N$34,4) -> 0.087 | P22: =O22+O23+O24 -> 0.1459 | Q22: 2024年 | R22: =R14/$Y$14 -> 0.6902932 | S22: =S14/$Y$14 -> 0.086967994 | T22: =T14/$Y$14 -> 0.055586614 | U22: =U14/$Y$14 -> 0.003297438 | V22: =V14/$Y$14 -> 0.084597643 | W22: =W14/$Y$14 -> 0.042282233 | X22: =X14/$Y$14 -> 0.036974874 | Y22: =SUM(R22:X22) -> 1
A23: 天猫 | B23: 7356.2745 | C23: 6826.9474 | D23: 3343.9349 | E23: 2639.3386 | F23: 2808.5516 | G23: 3292.1818 | H23: 2281.9778 | I23: 2542.949 | J23: 1620.5124 | K23: 2614.4508 | L23: 3180.461 | M23: 2272.4962 | N23: =SUM(B23:H23) -> 28549.207 | O23: =ROUND(N23/$N$34,4) -> 0.0556 | Q23: 2023年 | R23: =R15/$Y$15 -> 0.69689837 | S23: =S15/$Y$15 -> 0.10181272 | T23: =T15/$Y$15 -> 0.051617994 | U23: =U15/$Y$15 -> 0.0036902897 | V23: =V15/$Y$15 -> 0.067331178 | W23: =W15/$Y$15 -> 0.044596246 | X23: =X15/$Y$15 -> 0.0340532 | Y23: =SUM(R23:X23) -> 1
A24: 拼多多 | B24: 169.63949 | C24: 258.59786 | D24: 201.96861 | E24: 209.87979 | F24: 245.2243 | G24: 301.85235 | H24: 306.39712 | I24: 303.30276 | J24: 270.23927 | K24: 255.92196 | L24: 287.69779 | M24: 261.74802 | N24: =SUM(B24:H24) -> 1693.5595 | O24: =ROUND(N24/$N$34,4) -> 0.0033
A25: 支付宝小程序 | B25: 4835.725 | C25: 6130.6306 | D25: 4249.5636 | E25: 3138.7858 | F25: 8496.6226 | G25: 8256.9594 | H25: 8340.9431 | I25: 9739.3838 | J25: 5159.344 | K25: 5454.6605 | L25: 5035.8439 | M25: 5414.7719 | N25: =SUM(B25:H25) -> 43449.23 | O25: =ROUND(N25/$N$34,4) -> 0.0846
A26: 抖音 | B26: 978.85206 | C26: 5589.2987 | D26: 1310.5839 | E26: 856.94885 | F26: 2235.5593 | G26: 3481.126 | H26: 7230.5858 | I26: 1241.067 | J26: 611.61683 | K26: 789.61794 | L26: 4306.1958 | M26: 900.78845 | N26: =SUM(B26:H26) -> 21682.955 | O26: =ROUND(N26/$N$34,4) -> 0.0422 | P26: =O26+O27 -> 0.0423
A27: 快手 | B27: 7.955893 | C27: 8.04633 | D27: 5.182013 | E27: 5.71417 | F27: 4.99868 | G27: 0.3792994 | H27: 0.86430006 | I27: -2.4889971 | J27: 6.0944412 | K27: 0.782 | L27: 2.8899 | M27: 1.8559 | N27: =SUM(B27:H27) -> 33.140685 | O27: =ROUND(N27/$N$34,4) -> 0.0001
A28: 微信 | B28: 0.137637 | C28: 0.088062 | D28: 0.16190964 | E28: 0 | F28: -1.272e-05 | G28: 1.2955172 | L28: 0.02205672 | M28: 0.01564572 | N28: =SUM(B28:H28) -> 1.6831131 | O28: =ROUND(N28/$N$34,4) -> 0
A29: 第三方平台 | B29: 2608.1562 | C29: 2087.6476 | D29: 2307.5211 | E29: 1413.6205 | F29: 2168.5868 | G29: 876.27303 | H29: 683.92585 | I29: 876.53694 | J29: 673.27937 | K29: 965.75132 | L29: 723.18587 | M29: 819.06602 | N29: =SUM(B29:H29) -> 12145.731 | O29: =ROUND(N29/$N$34,4) -> 0.0236
A30: 充值频道 | B30: 1491.8645 | C30: 151.0234 | D30: 267.63107 | E30: 294.43465 | F30: 1160.9214 | G30: 180.26779 | H30: 120.31669 | I30: 289.59872 | J30: 73.440949 | K30: 1029.4009 | L30: 76.861941 | M30: 81.4073 | N30: =SUM(B30:H30) -> 3666.4595 | O30: =ROUND(N30/$N$34,4) -> 0.0071
A31: 短信分销平台 | B31: 2.656935 | C31: 1.945017 | D31: 1.73492 | E31: 1.742468 | F31: 1.632589 | G31: 3.857593 | H31: 1.6050478 | I31: 1.1173497 | J31: 0.012545 | K31: 0.11889592 | L31: 0.001748 | M31: 0.002504 | N31: =SUM(B31:H31) -> 15.17457 | O31: =ROUND(N31/$N$34,4) -> 0
A32: 百度小程序 | B32: 1.11333 | C32: 0.404225 | D32: 12.162652 | E32: 2.36439 | F32: 0.00255 | G32: 0.00751 | H32: 0.0134056 | I32: 0.000465 | J32: 0.00078204 | K32: 0.00155796 | L32: 0 | M32: 0.002955 | N32: =SUM(B32:H32) -> 16.068063 | O32: =ROUND(N32/$N$34,4) -> 0
A33: mall商城 | B33: 1572.7729 | C33: 664.98154 | D33: 689.53527 | E33: 178.44666 | F33: 15.061236 | G33: 8.584745 | H33: 15.744394 | I33: 21.133721 | J33: 3.7441439 | K33: 5.8240984 | L33: 10.589944 | M33: 23.743412 | N33: =SUM(B33:H33) -> 3145.1268 | O33: =ROUND(N33/$N$34,4) -> 0.0061
A34: 合计(单位：万元） | B34: =SUM(B21:B33) -> 83841.662 | C34: =SUM(C21:C33) -> 76218.049 | D34: =SUM(D21:D33) -> 66832.889 | E34: =SUM(E21:E33) -> 50345.297 | F34: =SUM(F21:F33) -> 70552.966 | G34: =SUM(G21:G33) -> 83802.748 | H34: =SUM(H21:H33) -> 82004.978 | I34: =SUM(I21:I33) -> 75165.771 | ... N34: =SUM(N21:N33) -> 513598.59 | O34: =N34/$N$34 -> 1
A37: 2023年
A38: 平台 | B38: 1月 | C38: 2月 | D38: 3月 | E38: 4月 | F38: 5月 | G38: 6月 | H38: 7月 | I38: 8月 | J38: 9月 | K38: 10月 | L38: 11月 | M38: 12月 | N38: 合计 | O38: 平台GMV占比
A39: 福禄开放平台 | B39: 91365.673 | C39: 99354.621 | D39: 115570.26 | E39: 90538.163 | F39: 94368.671 | G39: =101515.297081+9043.9/10000 -> 101516.2 | H39: =91428.439399+0.39521 -> 91428.835 | I39: 98871.924 | J39: 87871.175 | K39: 67975.954 | L39: 70601.928 | M39: 70283.486 | N39: =SUM(B39:H39) -> 684142.42 | O39: =ROUND(N39/$N$53,4) -> 0.6969
A40: 京东 | B40: 9976.2347 | C40: 7563.0608 | D40: 8790.9438 | E40: 13731.851 | F40: 21460.735 | G40: 25014.187 | H40: 13412.145 | I40: 11064.822 | J40: 10148.357 | K40: 8363.7859 | L40: 12780.064 | M40: 6652.1429 | N40: =SUM(B40:H40) -> 99949.157 | O40: =ROUND(N40/$N$53,4) -> 0.1018 | P40: =O40+O41+O42 -> 0.1571
A41: 天猫 | B41: 8600.3923 | C41: 6026.2335 | D41: =8710.422622-1350 -> 7360.4226 | E41: =8490.906362-1250 -> 7240.9064 | F41: 7482.9904 | G41: 7613.8731 | H41: 6348.3664 | I41: 8622.117 | J41: 11432.224 | K41: 7610.1162 | L41: 12712.985 | M41: 6277.992 | N41: =SUM(B41:H41) -> 50673.185 | O41: =ROUND(N41/$N$53,4) -> 0.0516
A42: 拼多多 | B42: 491.15028 | C42: 405.34202 | D42: 531.36978 | E42: 595.40474 | F42: 656.21552 | G42: 444.78814 | H42: 498.47264 | I42: 564.60724 | J42: 413.99637 | K42: 340.67903 | L42: 295.47328 | M42: 215.06176 | N42: =SUM(B42:H42) -> 3622.7431 | O42: =ROUND(N42/$N$53,4) -> 0.0037
...

Sheet GMV表-商品大类
A1: 支撑分析数据
A2: 1、21年-22年商品大类增长波动
A3: 2、21年-22年网娱、生活服务增长波动
A4: 代理商品大类 | H4: 代运营GMV
A5: 年份 | B5: 游戏 | C5: 通信 | D5: 网娱 | E5: 生活服务 | F5: 合计（单位：万元） | H5: 年份 | I5: 游戏 | J5: 通信 | K5: 网娱 | L5: 生活服务 | M5: 合计（单位：万元） | O5: 代理GMV年度累计 | P5: 游戏 | Q5: 通信 | R5: 网娱 | S5: 生活服务 | T5: 合计（单位：万元）
A6: 43831 | B6: 26733.731 | C6: 68544.632 | D6: 10654.409 | E6: 2922.7941 | F6: =SUM(B6:E6) -> 108855.57 | H6: 43831 | I6: 4766.0089 | J6: 0 | K6: 1558.2318 | L6: 0 | M6: =SUM(I6:L6) -> 6324.2407 | O6: 20.1月累计 | P6: =B6 -> 26733.731 | Q6: =C6 -> 68544.632 | R6: =D6 -> 10654.409 | S6: =E6 -> 2922.7941 | T6: =SUM(P6:S6) -> 108855.57 | U6: =F6-T6 -> 0
A7: 43862 | B7: 19821.24 | C7: 92007.291 | D7: 12820.087 | E7: 1329.9212 | F7: =SUM(B7:E7) -> 125978.54 | H7: 43862 | I7: 1147.842 | J7: 0 | K7: 1533.8891 | L7: 0 | M7: =SUM(I7:L7) -> 2681.731 | O7: 20.2月累计 | P7: =SUM(B6:B7) -> 46554.971 | Q7: =SUM(C6:C7) -> 160551.92 | R7: =SUM(D6:D7) -> 23474.497 | S7: =SUM(E6:E7) -> 4252.7153 | T7: =SUM(P7:S7) -> 234834.11 | U7: =F6+F7-T7 -> 0
A8: 43891 | B8: 17486.651 | C8: 97094.875 | D8: 15877.69 | E8: 5744.5058 | F8: =SUM(B8:E8) -> 136203.72 | H8: 43891 | I8: 9868.8997 | J8: 0 | K8: 1669.5443 | L8: 0 | M8: =SUM(I8:L8) -> 11538.444 | O8: 20.3月累计 | P8: =SUM(B6:B8) -> 64041.622 | Q8: =SUM(C6:C8) -> 257646.8 | R8: =SUM(D6:D8) -> 39352.186 | S8: =SUM(E6:E8) -> 9997.221 | T8: =SUM(P8:S8) -> 371037.83 | U8: =F6+F7+F8-T8 -> 0
A9: 43922 | B9: 15860.841 | C9: 93890.904 | D9: 15845.447 | E9: 2992.8043 | F9: =SUM(B9:E9) -> 128590 | H9: 43922 | I9: 6360.5902 | J9: 0 | K9: 1162.3167 | L9: 0 | M9: =SUM(I9:L9) -> 7522.9069 | O9: 20.4月累计 | P9: =SUM(B6:B9) -> 79902.463 | Q9: =SUM(C6:C9) -> 351537.7 | R9: =SUM(D6:D9) -> 55197.633 | S9: =SUM(E6:E9) -> 12990.025 | T9: =SUM(F6:F9) -> 499627.82 | U9: =F6+F7+F8+F9-T9 -> 0
A10: 43952 | B10: 16779.883 | C10: 83018.52 | D10: 17482.749 | E10: 3418.4836 | F10: =SUM(B10:E10) -> 120699.64 | H10: 43952 | I10: 5036.9338 | J10: 0 | K10: 1174.8589 | L10: 0 | M10: =SUM(I10:L10) -> 6211.7926 | O10: 20.5月累计 | P10: =SUM(B6:B10) -> 96682.346 | Q10: =SUM(C6:C10) -> 434556.22 | R10: =SUM(D6:D10) -> 72680.382 | S10: =SUM(E6:E10) -> 16408.509 | T10: =SUM(P10:S10) -> 620327.46 | U10: =F6+F7+F8+F9+F10-T10 -> 0
A11: 43983 | B11: 14015.746 | C11: 85266.828 | D11: 26479.396 | E11: 7380.6022 | F11: =SUM(B11:E11) -> 133142.57 | H11: 43983 | I11: 3440.8604 | J11: 0 | K11: 2146.6143 | L11: 0.7181 | M11: =SUM(I11:L11) -> 5588.1928 | O11: 20.6月累计 | P11: =SUM(B6:B11) -> 110698.09 | Q11: =SUM(C6:C11) -> 519823.05 | R11: =SUM(D6:D11) -> 99159.778 | S11: =SUM(E6:E11) -> 23789.111 | T11: =SUM(P11:S11) -> 753470.03 | U11: =F6+F7+F8+F9+F10+F11-T11 -> 0
A12: 44013 | B12: 16231.545 | C12: 64424.976 | D12: 22574.644 | E12: 4580.5085 | F12: =SUM(B12:E12) -> 107811.67 | H12: 44013 | I12: 4053.8244 | J12: 0 | K12: 1813.2527 | L12: 3.5087 | M12: =SUM(I12:L12) -> 5870.5857 | O12: 20.7月累计 | P12: =SUM(B6:B12) -> 126929.64 | Q12: =SUM(C6:C12) -> 584248.03 | R12: =SUM(D6:D12) -> 121734.42 | S12: =SUM(E6:E12) -> 28369.62 | T12: =SUM(P12:S12) -> 861281.71 | U12: =F6+F7+F8+F9+F10+F11+F12-T12 -> 0
A13: 44044 | B13: 14517.382 | C13: 57241.885 | D13: 26337.265 | E13: 4365.9292 | F13: =SUM(B13:E13) -> 102462.46 | H13: 44044 | I13: 4469.0221 | J13: 0 | K13: 2259.0279 | L13: 1.6854 | M13: =SUM(I13:L13) -> 6729.7354 | O13: 20.8月累计 | P13: =SUM(B6:B13) -> 141447.02 | Q13: =SUM(C6:C13) -> 641489.91 | R13: =SUM(D6:D13) -> 148071.69 | S13: =SUM(E6:E13) -> 32735.549 | T13: =SUM(P13:S13) -> 963744.17 | U13: =F6+F7+F8+F9+F10+F11+F12+F13-T13 -> 0
A14: 44075 | B14: 13843.132 | C14: 67326.285 | D14: 21292.801 | E14: 5492.1823 | F14: =SUM(B14:E14) -> 107954.4 | H14: 44075 | I14: 7806.3313 | J14: 0 | K14: 2382.1591 | L14: 8.0147 | M14: =SUM(I14:L14) -> 10196.505 | O14: 20.9月累计 | P14: =SUM(B6:B14) -> 155290.15 | Q14: =SUM(C6:C14) -> 708816.2 | R14: =SUM(D6:D14) -> 169364.49 | S14: =SUM(E6:E14) -> 38227.731 | T14: =SUM(P14:S14) -> 1071698.6 | U14: =F6+F7+F8+F9+F10+F11+F12+F13+F14-T14 -> 0
