Workbook
Name 合并科目名称: [1]Sheet1!$A$2:$A$908
Name 科目余额表: #REF!
Name body: '[2]资产负债表-2017'!$C$6:$H$36
Name grid: '[2]资产负债表-2017'!$C$6:$H$36
Name head: '[2]资产负债表-2017'!$A$4:$H$4
Name 核算项目明细账: [3]核算项目明细账!$A$1:$K$157
Name 会计分录序时簿: #REF!

Sheet 权责制经营报表-EAS 2512（审计口径）
A1: 利润表
A2: 编制单位：武汉福禄网络科技有限公司（汇总报表） 2024年度 单位：元
A3: 序号 | B3: 项目 | C3: 2021年1月 | D3: 2021年1-2月 | E3: 2021年Q1 | F3: 2021年1-4月 | G3: 2021年1-5月 | H3: 2021年Q2 | I3: 2021年1-7月 | J3: 2021年1-8月 | K3: 2021年Q3 | L3: 2021年1-10月 | M3: 2021年1-11月 | N3: 2021年1-12月 | O3: 2022年1月 | P3: 2022年1-2月 | Q3: 2022年Q1 | R3: 2022年1-4月 | S3: 2022年1-5月 | T3: 2022年Q2 | U3: 2022年1-7月 | V3: 2022年1-8月 | W3: 2022年Q3 | X3: 2022年1-10月 | Y3: 2022年1-11月 | Z3: 2022年 | AA3: 2023年1月 | AB3: 2023年1-2月 | AC3: 2023年Q1 | AD3: 2023年1-4月 | AE3: 2023年1-5月 | AF3: 2023年Q2 | AG3: 2023年1-7月 | AH3: 2023年1-8月 | AI3: 2023年Q3 | AJ3: 2023年1-10月 | AK3: 2023年1-11月 | AL3: 2023年 | AM3: 45292 | AN3: 45323 | AO3: 45352 | AP3: 45383 | AQ3: 45413 | AR3: 45444 | AS3: 45474 | AT3: 45505 | AU3: 45536 | AV3: 45566 | AW3: 45597 | AX3: 45627 | AY3: 45658 | AZ3: 45689 | BA3: 45717 | BB3: 45748 | BC3: 45778 | BD3: 45809 | BE3: 45839 | BF3: 45870 | BG3: 45901 | BH3: 45931 | BI3: 45962 | BJ3: 45992 | BL3: 变动
A4: 一 | B4: 订单销售收入 | C4: =#REF!-C7-C8-C9-C10-C11-C12-C13 -> #REF! | D4: =#REF!-D7-D8-D9-D10-D11-D12-D13 -> #REF! | E4: =#REF!-E7-E8-E9-E10-E11-E12-E13 -> #REF! | F4: =#REF!-F7-F8-F9-F10-F11-F12-F13 -> #REF! | G4: =#REF!-G7-G8-G9-G10-G11-G12-G13 -> #REF! | H4: =#REF!-H7-H8-H9-H10-H11-H12-H13 -> #REF! | I4: =#REF!-I7-I8-I9-I10-I11-I12-I13 -> #REF! | J4: =#REF!-J7-J8-J9-J10-J11-J12-J13 -> #REF! | ... AK4: =#REF!-AK7-AK8-AK9-AK10-AK11-AK12-AK13 -> #REF! | AL4: 5.5234211e+09 | AM4: =#REF!-AM7-AM8-AM9-AM10-AM11-AM12-AM13 -> #REF! | AN4: =#REF!-AN7-AN8-AN9-AN10-AN11-AN12-AN13 -> #REF! | AO4: =#REF!-AO7-AO8-AO9-AO10-AO11-AO12-AO13 -> #REF! | AP4: =#REF!-AP7-AP8-AP9-AP10-AP11-AP12-AP13 -> #REF! | AQ4: =#REF!-AQ7-AQ8-AQ9-AQ10-AQ11-AQ12-AQ13 -> #REF! | AR4: =#REF!-AR7-AR8-AR9-AR10-AR11-AR12-AR13 -> #REF! | AS4: =#REF!-AS7-AS8-AS9-AS10-AS11-AS12-AS13 -> #REF! | AT4: =#REF!-AT7-AT8-AT9-AT10-AT11-AT12-AT13 -> #REF! | ... AW4: =#REF!-AW7-AW8-AW9-AW10-AW11-AW12-AW13 -> #REF! | AX4: 2.982496e+09 | AY4: =#REF!-AY7-AY8-AY9-AY10-AY11-AY12-AY13 -> #REF! | AZ4: =#REF!-AZ7-AZ8-AZ9-AZ10-AZ11-AZ12-AZ13 -> #REF! | BA4: =#REF!-BA7-BA8-BA9-BA10-BA11-BA12-BA13 -> #REF! | BB4: 9.2791889e+08 | BC4: =#REF!-BC7-BC8-BC9-BC10-BC11-BC12-BC13 -> #REF! | BD4: =#REF!-BD7-BD8-BD9-BD10-BD11-BD12-BD13 -> #REF! | BE4: =#REF!-BE7-BE8-BE9-BE10-BE11-BE12-BE13 -> #REF! | BF4: =#REF!-BF7-BF8-BF9-BF10-BF11-BF12-BF13 -> #REF! | BG4: =#REF!-BG7-BG8-BG9-BG10-BG11-BG12-BG13 -> #REF! | BH4: 2.5195953e+09 | BI4: 2.7494254e+09 | BJ4: =3199126091.27-11125101.41 -> 3.188001e+09 | BL4: =BJ4-AX4 -> 2.0550499e+08
A5: 二 | B5: 减：销售成本额 | C5: =#REF! -> #REF! | D5: =#REF! -> #REF! | E5: =#REF! -> #REF! | F5: =#REF! -> #REF! | G5: =#REF! -> #REF! | H5: =#REF! -> #REF! | I5: =#REF! -> #REF! | J5: =#REF! -> #REF! | ... AK5: =#REF! -> #REF! | AL5: 5.5806166e+09 | AM5: =#REF! -> #REF! | AN5: =#REF! -> #REF! | AO5: =#REF! -> #REF! | AP5: =#REF! -> #REF! | AQ5: =#REF! -> #REF! | AR5: =#REF! -> #REF! | AS5: =#REF! -> #REF! | AT5: =#REF! -> #REF! | ... AW5: =#REF! -> #REF! | AX5: 3.0392126e+09 | AY5: =#REF! -> #REF! | AZ5: =#REF! -> #REF! | BA5: =#REF! -> #REF! | BB5: 9.1724876e+08 | BC5: =#REF! -> #REF! | BD5: =#REF! -> #REF! | BE5: =#REF! -> #REF! | BF5: =#REF! -> #REF! | BG5: =#REF! -> #REF! | BH5: 2.4505005e+09 | BI5: 2.6707478e+09 | BJ5: 3.1003635e+09 | BK5: =AP5-'[12]2404成本费用（EAS）'!$AU$30 -> #REF! | BL5: =BJ5-AX5 -> 61150899
A6: 三 | B6: 销售订单毛利 | C6: =C4-C5 -> #REF! | D6: =D4-D5 -> #REF! | E6: =E4-E5 -> #REF! | F6: =F4-F5 -> #REF! | G6: =G4-G5 -> #REF! | H6: =H4-H5 -> #REF! | I6: =I4-I5 -> #REF! | J6: =J4-J5 -> #REF! | ... AK6: =AK4-AK5 -> #REF! | AL6: -57195463 | AM6: =AM4-AM5 -> #REF! | AN6: =AN4-AN5 -> #REF! | AO6: =AO4-AO5 -> #REF! | AP6: =AP4-AP5 -> #REF! | AQ6: =AQ4-AQ5 -> #REF! | AR6: =AR4-AR5 -> #REF! | AS6: =AS4-AS5 -> #REF! | AT6: =AT4-AT5 -> #REF! | ... AW6: =AW4-AW5 -> #REF! | AX6: -56716552 | AY6: =AY4-AY5 -> #REF! | AZ6: =AZ4-AZ5 -> #REF! | BA6: =BA4-BA5 -> #REF! | BB6: 10670137 | BC6: =BC4-BC5 -> #REF! | BD6: =BD4-BD5 -> #REF! | BE6: =BE4-BE5 -> #REF! | BF6: =BF4-BF5 -> #REF! | BG6: =BG4-BG5 -> #REF! | BH6: 69094838 | BI6: 78677561 | BJ6: =BJ4-BJ5 -> 87637538 | BL6: =BJ6-AX6 -> 1.4435409e+08
A7: 四 | B7: 返佣收入 | C7: 15633096 | D7: 41034940 | E7: =74010097.4796227+ROUND(2853900/1.06,2) -> 76702456 | F7: =83298774.6+ROUND(2853900/1.06,2) -> 85991133 | G7: 1.0551614e+08 | H7: 1.5372603e+08 | I7: 1.6531903e+08 | J7: 1.9515517e+08 | K7: 2.1906692e+08 | L7: 2.3021969e+08 | M7: 2.8352399e+08 | N7: =326387655.05+ROUND(3299000/1.06,2) -> 3.2949992e+08 | O7: 19274684 | P7: 32120843 | Q7: 56020714 | R7: 72209454 | S7: 1.0084105e+08 | T7: 1.3630105e+08 | U7: 1.6290203e+08 | V7: 2.0954635e+08 | W7: 2.4144495e+08 | X7: 2.7580949e+08 | Y7: 3.3435345e+08 | Z7: 4.0288976e+08 | AA7: 44769657 | AB7: 75071978 | AC7: 1.0092354e+08 | AD7: 1.2294119e+08 | AE7: 1.5805113e+08 | AF7: 2.116887e+08 | AG7: 2.4485422e+08 | AH7: 2.8042536e+08 | AI7: 3.0682196e+08 | AJ7: 3.3437143e+08 | AK7: 3.814382e+08 | AL7: 4.2488856e+08 | AM7: =22558107.88 -> 22558108 | AN7: =22558107.88+23405244.17 -> 45963352 | AO7: =22558107.88+23405244.17+27007463.62 -> 72970816 | AP7: =22558107.88+23405244.17+27007463.62+20429764.16 -> 93400580 | AQ7: =22558107.88+23405244.17+27007463.62+20429764.16+19532060.94 -> 1.1293264e+08 | AR7: =22558107.88+23405244.17+27007463.62+20429764.16+19532060.94+21729930.21 -> 1.3466257e+08 | AS7: =22558107.88+23405244.17+27007463.62+20429764.16+19532060.94+21729930.21+15580356.73 -> 1.5024293e+08 | AT7: =22558107.88+23405244.17+27007463.62+20429764.16+19532060.94+21729930.21+15580356.73+13245739.73 -> 1.6348867e+08 | AU7: =22558107.88+23405244.17+27007463.62+20429764.16+19532060.94+21729930.21+15580356.73+13245739.73+12054353.46 -> 1.7554302e+08 | AV7: 1.8459053e+08 | AW7: 1.9787641e+08 | AX7: 2.1116519e+08 | AY7: 16855930 | AZ7: =16855931.17+12357833.71 -> 29213765 | BA7: =16855931.17+12357833.71+5507586.85 -> 34721352 | BB7: =16855931.17+12357833.71+5507586.85+4912591.66 -> 39633943 | BC7: =16855931.17+12357833.71+5507586.85+4912591.66+7057089.46 -> 46691033 | BD7: =16855931.17+12357833.71+5507586.85+4912591.66+7057089.46+9695356.65 -> 56386390 | BE7: =16855931.17+12357833.71+5507586.85+4912591.66+7057089.46+9695356.65+4741411.74 -> 61127801 | BF7: =16855931.17+12357833.71+5507586.85+4912591.66+7057089.46+9695356.65+4741411.74+6817429.75 -> 67945231 | BG7: =16855931.17+12357833.71+5507586.85+4912591.66+7057089.46+9695356.65+4741411.74+6817429.75 -> 67945231 | BH7: 55204501 | BI7: 57566742 | BJ7: 64941628 | BL7: =BJ7-AX7 -> -1.4622356e+08
A8: 五 | B8: 平台服务收入 | C8: 486.75 | D8: 2741.35 | E8: 21768.89 | F8: 31028.79 | G8: 41045.84 | H8: 103974.84 | I8: 158604.28 | J8: 223616 | K8: 255513.16 | L8: 309456.6 | M8: ='[4]2111成本费用（EAS）'!$AC$7 -> 380790.25 | N8: ='[5]2112成本费用（EAS）'!$AC$7 -> 448282.35 | O8: 83713.35 | P8: 181153.95 | Q8: 340015.12 | R8: 353629.51 | S8: ='[7]分月收入成本汇总（未抵消）'!$H$8-'[7]分月收入成本汇总（未抵消）'!$H$27 -> 439332.64 | T8: 1805447.1 | U8: 1901414.8 | V8: 2598026.1 | W8: 2697546.3 | X8: 3509809.2 | Y8: 3662954 | Z8: ='[10]2212成本费用（EAS）'!$AL$7 -> 4000421.5 | AA8: 114658.58 | AB8: 146154.09 | AC8: 427507.84 | AD8: 707085.11 | AE8: 1745620.9 | AF8: 2342559.8 | AG8: 2782841.2 | AH8: 2799611.7 | AI8: 4470624.8 | AJ8: 4647384.8 | AK8: 4856503.9 | AL8: 7001451.6 | AM8: 1294761 | AN8: 1781125.9 | AO8: 1781125.9 | AP8: 2709893.2 | AQ8: 3250251.9 | AR8: 3718929.8 | AS8: 3988718.4 | AT8: 4502549.5 | AU8: 5225028.7 | AV8: 5313866.1 | AW8: 5528449.9 | AX8: 9951032.3 | AY8: 530188.69 | AZ8: 1150018.4 | BA8: ='[13]2503成本费用（EAS）'!$BB$7 -> 1746396.3 | BB8: 2195894.7 | BC8: =#REF! -> #REF! | BD8: =#REF! -> #REF! | BE8: =#REF! -> #REF! | BF8: =#REF! -> #REF! | BG8: =#REF! -> #REF! | BH8: 12636672 | BI8: 12861808 | BJ8: 13300586 | BK8: =AP8-'[12]2404成本费用（EAS）'!$AU$7 -> 0 | BL8: =BJ8-AX8 -> 3349553.5
A9: 六 | B9: 游戏开发收入 | C9: 0 | D9: 12264.15 | E9: 12264.15 | F9: 532867.92 | G9: 545132.07 | H9: 2615629.2 | I9: 2615629.2 | J9: 2615629.2 | K9: 2672233 | L9: 2813742.5 | M9: ='[4]2111成本费用（EAS）'!$AC$9 -> 2813742.5 | N9: ='[5]2112成本费用（EAS）'!$AC$9 -> 2983553.8 | O9: 0 | P9: 0 | Q9: 200807.55 | R9: 200807.55 | S9: ='[7]分月收入成本汇总（未抵消）'!$H$9-'[7]分月收入成本汇总（未抵消）'!$H$28 -> 314015.1 | T9: 370618.87 | U9: 483826.42 | V9: 540430.19 | W9: 709864.15 | X9: 755147.17 | Y9: 868267.98 | Z9: ='[10]2212成本费用（EAS）'!$AL$8 -> 874400.04 | AA9: 0 | AB9: 0 | AC9: 50471.7 | AD9: 50471.7 | AE9: -7763.27 | AF9: 121785.79 | AG9: 140653.71 | AH9: 140653.71 | AI9: 485936.73 | AJ9: 485936.73 | AK9: 485936.73 | AL9: 485936.73 | AM9: -94339.62 | AN9: -94339.62 | AO9: -94339.62 | AP9: -94339.62 | AQ9: -94339.62 | AR9: -94339.62 | AS9: -94339.62 | AT9: -94339.62 | AU9: -94339.62 | AV9: -94339.62 | AW9: -94339.62 | AX9: -94339.62 | AY9: 0 | AZ9: 0 | BA9: ='[13]2503成本费用（EAS）'!$BB$8 -> 0 | BB9: 0 | BC9: 0 | BD9: 0 | BE9: 0 | BF9: 0 | BG9: 0 | BH9: 0 | BI9: 0 | BJ9: 0 | BL9: =BJ9-AX9 -> 94339.62
A10: 七 | B10: 代运营服务收入 | C10: 2328230.3 | D10: 10653516 | E10: 16845357 | F10: 19271756 | G10: 23948263 | H10: 32215540 | I10: 35803422 | J10: 39540461 | K10: 45813911 | L10: 49724099 | M10: ='[4]2111成本费用（EAS）'!$AC$10 -> 63941726 | N10: ='[5]2112成本费用（EAS）'!$AC$10 -> 69150571 | O10: 1982299.4 | P10: 10556838 | Q10: 13303592 | R10: 14998977 | S10: ='[7]分月收入成本汇总（未抵消）'!$H$10-'[7]分月收入成本汇总（未抵消）'!$H$29 -> 18113103 | T10: 30075246 | U10: 35690770 | V10: 42237237 | W10: 44615722 | X10: 53573141 | Y10: 67984515 | Z10: ='[10]2212成本费用（EAS）'!$AL$9 -> 76464810 | AA10: 7335310.3 | AB10: 10686805 | AC10: 14326969 | AD10: 20319447 | AE10: 24429710 | AF10: 35910234 | AG10: 42048406 | AH10: 46765042 | AI10: 54671482 | AJ10: 62125227 | AK10: 76278364 | AL10: 89465419 | AM10: 6199246.2 | AN10: 18108806 | AO10: 18108806 | AP10: 38640965 | AQ10: 52134930 | AR10: 66253107 | AS10: 71792549 | AT10: 80077861 | AU10: 86549260 | AV10: 94807853 | AW10: 1.088726e+08 | AX10: 1.1942592e+08 | AY10: 7086067.9 | AZ10: 15452219 | BA10: ='[13]2503成本费用（EAS）'!$BB$9 -> 21108796 | BB10: 25095398 | BC10: =#REF! -> #REF! | BD10: =#REF! -> #REF! | BE10: =#REF! -> #REF! | BF10: =#REF! -> #REF! | BG10: =#REF! -> #REF! | BH10: 81121926 | BI10: 99685568 | BJ10: 1.1250655e+08 | BL10: =BJ10-AX10 -> -6919367.5
A11: 八 | B11: 推广服务收入 | C11: 1513546.1 | D11: 1823265.1 | E11: 3454050.5 | F11: 7715000.6 | G11: 12576755 | H11: 21588037 | I11: 29608849 | J11: 33886794 | K11: 41912997 | L11: 54566053 | M11: ='[4]2111成本费用（EAS）'!$AC$11 -> 75146885 | N11: ='[5]2112成本费用（EAS）'!$AC$11 -> 95935276 | O11: 16924670 | P11: 22694334 | Q11: 31883396 | R11: 35678369 | S11: ='[7]分月收入成本汇总（未抵消）'!$H$11-'[7]分月收入成本汇总（未抵消）'!$H$30 -> 37746656 | T11: ='[9]2206成本费用（EAS）'!$AD$10 -> 42375813 | U11: 47930124 | V11: 53884497 | W11: 59801624 | X11: 64013977 | Y11: 69016797 | Z11: ='[10]2212成本费用（EAS）'!$AL$10 -> 71226103 | AA11: 722863.54 | AB11: 2158416.5 | AC11: 7390194.8 | AD11: 22626600 | AE11: 25636958 | AF11: 30906800 | AG11: 37509534 | AH11: 44109063 | AI11: 48118312 | AJ11: 53496482 | AK11: 65597876 | AL11: 77824807 | AM11: 16653371 | AN11: 21305204 | AO11: 21305204 | AP11: 33026963 | AQ11: 35048612 | AR11: 37006387 | AS11: 40535794 | AT11: 42821210 | AU11: 43364196 | AV11: 47240823 | AW11: 53934310 | AX11: 59780432 | AY11: 3532679.8 | AZ11: 7149503.8 | BA11: ='[13]2503成本费用（EAS）'!$BB$10 -> 12413080 | BB11: 24626486 | BC11: =#REF! -> #REF! | BD11: =#REF! -> #REF! | BE11: =#REF! -> #REF! | BF11: =#REF! -> #REF! | BG11: =#REF! -> #REF! | BH11: 84014114 | BI11: 90771979 | BJ11: 94946250 | BL11: =BJ11-AX11 -> 35165818
A12: 九 | B12: 信息、经纪服务收入 | C12: 784 | D12: 44441.5 | E12: 44441.5 | F12: 44441.5 | G12: 44441.5 | H12: 44441.5 | I12: 44441.5 | J12: 44441.5 | K12: 44441.5 | L12: 44441.5 | M12: ='[4]2111成本费用（EAS）'!$AC$13 -> 44441.5 | N12: ='[5]2112成本费用（EAS）'!$AC$13 -> 44441.5 | O12: 0 | P12: 0 | Q12: 0 | R12: 0 | S12: 0 | T12: 0.02 | U12: 0.04 | V12: 0.04 | W12: 28301.93 | X12: 28301.93 | Y12: 28301.93 | Z12: ='[10]2212成本费用（EAS）'!$AL$11+'[10]2212成本费用（EAS）'!$AL$12 -> 471396.85 | AA12: 311603.78 | AB12: 545566.04 | AC12: 833663.71 | AD12: 1260879.2 | AE12: 1553721.1 | AF12: 2625951.3 | AG12: 3216205.8 | AH12: 5943072.7 | AI12: 43788556 | AJ12: 73681439 | AK12: 1.2363987e+08 | AL12: 2.0101867e+08 | AM12: 68951639 | AN12: 132437570 | AO12: 132437570 | AP12: 2.4029257e+08 | AQ12: 2.914008e+08 | AR12: 3.7110927e+08 | AS12: 5.1385631e+08 | AT12: 5.3988215e+08 | AU12: 5.7600497e+08 | AV12: 6.0325463e+08 | AW12: 6.2385842e+08 | AX12: 6.4135468e+08 | AY12: 12779642 | AZ12: 24808694 | BA12: ='[13]2503成本费用（EAS）'!$BB$11+'[13]2503成本费用（EAS）'!$BB$12 -> 39677900 | BB12: 56391494 | BC12: =#REF! -> #REF! | BD12: =#REF! -> #REF! | BE12: =#REF! -> #REF! | BF12: =#REF! -> #REF! | BG12: =#REF! -> #REF! | BH12: 2.7206028e+08 | BI12: 3.0806262e+08 | BJ12: 3.1259978e+08 | BL12: =BJ12-AX12 -> -3.2875491e+08
A13: 十 | B13: 逾期权益收入 | C13: 0 | D13: 0 | E13: 0 | F13: 0 | G13: 0 | H13: 897733.18 | I13: 897733.18 | J13: 897733.18 | K13: 897733.18 | L13: 897733.18 | M13: ='[4]2111成本费用（EAS）'!$AC$15 -> 897733.18 | N13: ='[5]2112成本费用（EAS）'!$AC$15 -> 897733.18 | O13: 0 | P13: 0 | Q13: 0 | R13: 0 | S13: 0 | T13: ='[8]2206成本费用（EAS）'!$AD$14 -> 0 | U13: 0 | V13: 0 | W13: 0 | X13: 0 | Y13: 0 | Z13: 0 | AA13: 0 | AB13: 0 | AC13: 0 | AD13: 0 | AE13: 0 | AF13: 0 | AG13: 0 | AH13: 0 | AI13: 0 | AJ13: 0 | AK13: 0 | AL13: 9253417.1 | AM13: 0 | AN13: 0 | AO13: 0 | AP13: 203861.36 | AQ13: 675753.59 | AR13: 1349977.9 | AS13: 2393905.8 | AT13: 2945750.6 | AU13: 3597370.7 | AV13: 3956033 | AW13: 4378236 | AX13: 6917353.4 | AY13: 630250.41 | AZ13: 1067938.6 | BA13: ='[13]2503成本费用（EAS）'!$BB$14 -> 1956049.9 | BB13: 3239926 | BC13: =#REF! -> #REF! | BD13: =#REF! -> #REF! | BE13: =#REF! -> #REF! | BF13: =#REF! -> #REF! | BG13: =#REF! -> #REF! | BH13: 8332382 | BI13: 9496029.8 | BJ13: 12186028 | BL13: =BJ13-AX13 -> 5268674.8
A14: 十一 | B14: 其他收益-税收返还 | BJ14: 28815803 | BL14: =BJ14-AX14 -> 28815803
A15: 十三 | B15: 减：业务直接成本 | C15: =SUM(C16:C21) -> #REF! | D15: =SUM(D16:D21) -> #REF! | E15: =SUM(E16:E21) -> #REF! | F15: =SUM(F16:F21) -> #REF! | G15: =SUM(G16:G21) -> #REF! | H15: =SUM(H16:H21) -> #REF! | I15: =SUM(I16:I21) -> #REF! | J15: =SUM(J16:J21) -> #REF! | ... AK15: =SUM(AK16:AK21) -> #REF! | AL15: 3.4178237e+08 | AM15: =SUM(AM16:AM21) -> #REF! | AN15: =SUM(AN16:AN21) -> #REF! | AO15: =SUM(AO16:AO21) -> #REF! | AP15: =SUM(AP16:AP21) -> #REF! | AQ15: =SUM(AQ16:AQ21) -> #REF! | AR15: =SUM(AR16:AR21) -> #REF! | AS15: =SUM(AS16:AS21) -> #REF! | AT15: =SUM(AT16:AT21) -> #REF! | ... AW15: =SUM(AW16:AW21) -> #REF! | AX15: 7.5561627e+08 | AY15: =SUM(AY16:AY21) -> #REF! | AZ15: =SUM(AZ16:AZ21) -> #REF! | BA15: =SUM(BA16:BA21) -> #REF! | BB15: =SUM(BB16:BB21) -> #REF! | BC15: =SUM(BC16:BC21) -> #REF! | BD15: =SUM(BD16:BD21) -> #REF! | BE15: =SUM(BE16:BE21) -> #REF! | BF15: =SUM(BF16:BF21) -> #REF! | BG15: =SUM(BG16:BG21) -> #REF! | BH15: 4.0460428e+08 | BI15: 4.5489015e+08 | BJ15: 4.7280531e+08 | BL15: =BJ15-AX15 -> -2.8281096e+08
A16: 1.1 | B16: 佣金服务费 | C16: =#REF! -> #REF! | D16: =#REF! -> #REF! | E16: =#REF! -> #REF! | F16: =#REF! -> #REF! | G16: =#REF! -> #REF! | H16: =#REF! -> #REF! | I16: =#REF! -> #REF! | J16: =#REF! -> #REF! | ... AK16: =#REF! -> #REF! | AL16: 42529215 | AM16: =#REF! -> #REF! | AN16: =#REF! -> #REF! | AO16: =#REF! -> #REF! | AP16: =#REF! -> #REF! | AQ16: =#REF! -> #REF! | AR16: =#REF! -> #REF! | AS16: =#REF! -> #REF! | AT16: =#REF! -> #REF! | ... AW16: =#REF! -> #REF! | AX16: 20867964 | AY16: =#REF! -> #REF! | AZ16: =#REF! -> #REF! | BA16: =#REF! -> #REF! | BB16: 5009720.8 | BC16: =#REF! -> #REF! | BD16: =#REF! -> #REF! | BE16: =#REF! -> #REF! | BF16: =#REF! -> #REF! | BG16: =#REF! -> #REF! | BH16: 16310003 | BI16: 18481225 | BJ16: 20453484 | BL16: =BJ16-AX16 -> -414480.36
A17: 1.2 | B17: 平台服务费 | O17: =#REF! -> #REF! | P17: =#REF! -> #REF! | Q17: =#REF! -> #REF! | R17: =#REF! -> #REF! | S17: =#REF! -> #REF! | T17: =#REF! -> #REF! | U17: =#REF! -> #REF! | V17: =#REF! -> #REF! | ... AK17: =#REF! -> #REF! | AL17: 8377888.2 | AM17: =#REF! -> #REF! | AN17: =#REF! -> #REF! | AO17: =#REF! -> #REF! | AP17: =#REF! -> #REF! | AQ17: =#REF! -> #REF! | AR17: =#REF! -> #REF! | AS17: =#REF! -> #REF! | AT17: =#REF! -> #REF! | ... AW17: =#REF! -> #REF! | AX17: 14264535 | AY17: =#REF! -> #REF! | AZ17: =#REF! -> #REF! | BA17: =#REF! -> #REF! | BB17: 1135344.2 | BC17: =#REF! -> #REF! | BD17: =#REF! -> #REF! | BE17: =#REF! -> #REF! | BF17: =#REF! -> #REF! | BG17: =#REF! -> #REF! | BH17: 12455179 | BI17: 12725141 | BJ17: 17536835 | BL17: =BJ17-AX17 -> 3272299.5
A18: 1.3 | B18: 游戏开发服务费 | C18: =#REF! -> #REF! | D18: =#REF! -> #REF! | E18: =#REF! -> #REF! | F18: =#REF! -> #REF! | G18: =#REF! -> #REF! | H18: =#REF! -> #REF! | I18: =#REF! -> #REF! | J18: =#REF! -> #REF! | ... AK18: =#REF! -> #REF! | AL18: 431818.16 | AM18: =#REF! -> #REF! | AN18: =#REF! -> #REF! | AO18: =#REF! -> #REF! | AP18: =#REF! -> #REF! | AQ18: =#REF! -> #REF! | AR18: =#REF! -> #REF! | AS18: =#REF! -> #REF! | AT18: =#REF! -> #REF! | ... AW18: =#REF! -> #REF! | AX18: 0 | AY18: =#REF! -> #REF! | AZ18: =#REF! -> #REF! | BA18: =#REF! -> #REF! | BH18: 0 | BI18: 0 | BJ18: 0 | BL18: =BJ18-AX18 -> 0
A19: 1.4 | B19: 代运营服务费 | C19: =#REF! -> #REF! | D19: =#REF! -> #REF! | E19: =#REF! -> #REF! | F19: =#REF! -> #REF! | G19: =#REF! -> #REF! | H19: =#REF! -> #REF! | I19: =#REF! -> #REF! | J19: =#REF! -> #REF! | ... AK19: =#REF! -> #REF! | AL19: 13488649 | AM19: =#REF! -> #REF! | AN19: =#REF! -> #REF! | AO19: =#REF! -> #REF! | AP19: =#REF! -> #REF! | AQ19: =#REF! -> #REF! | AR19: =#REF! -> #REF! | AS19: =#REF! -> #REF! | AT19: =#REF! -> #REF! | ... AW19: =#REF! -> #REF! | AX19: 17762841 | AY19: =#REF! -> #REF! | AZ19: =#REF! -> #REF! | BA19: =#REF! -> #REF! | BB19: =#REF! -> #REF! | BC19: =#REF! -> #REF! | BD19: =#REF! -> #REF! | BE19: =#REF! -> #REF! | BF19: =#REF! -> #REF! | BG19: =#REF! -> #REF! | BH19: 19683073 | BI19: 24855795 | BJ19: 27259155 | BL19: =BJ19-AX19 -> 9496314.3
A20: 1.5 | B20: 推广服务费 | C20: =#REF! -> #REF! | D20: =#REF! -> #REF! | E20: =#REF! -> #REF! | F20: =#REF! -> #REF! | G20: =#REF! -> #REF! | H20: =#REF! -> #REF! | I20: =#REF! -> #REF! | J20: =#REF! -> #REF! | ... AK20: =#REF! -> #REF! | AL20: 73092714 | AM20: =#REF! -> #REF! | AN20: =#REF! -> #REF! | AO20: =#REF! -> #REF! | AP20: =#REF! -> #REF! | AQ20: =#REF! -> #REF! | AR20: =#REF! -> #REF! | AS20: =#REF! -> #REF! | AT20: =#REF! -> #REF! | ... AW20: =#REF! -> #REF! | AX20: 54754108 | AY20: =#REF! -> #REF! | AZ20: =#REF! -> #REF! | BA20: =#REF! -> #REF! | BB20: 22736621 | BC20: =#REF! -> #REF! | BD20: =#REF! -> #REF! | BE20: =#REF! -> #REF! | BF20: =#REF! -> #REF! | BG20: =#REF! -> #REF! | BH20: 84889333 | BI20: 91846765 | BJ20: 96169770 | BL20: =BJ20-AX20 -> 41415662
A21: 1.6 | B21: 信息、经纪服务费 | C21: =#REF! -> #REF! | D21: =#REF! -> #REF! | E21: =#REF! -> #REF! | F21: =#REF! -> #REF! | G21: =#REF! -> #REF! | H21: =#REF! -> #REF! | I21: =#REF! -> #REF! | J21: =#REF! -> #REF! | ... AK21: =#REF! -> #REF! | AL21: 2.0386208e+08 | AM21: =#REF! -> #REF! | AN21: =#REF! -> #REF! | AO21: =#REF! -> #REF! | AP21: =#REF! -> #REF! | AQ21: =#REF! -> #REF! | AR21: =#REF! -> #REF! | AS21: =#REF! -> #REF! | AT21: =#REF! -> #REF! | ... AW21: =#REF! -> #REF! | AX21: 6.4796682e+08 | AY21: =#REF! -> #REF! | AZ21: =#REF! -> #REF! | BA21: =#REF! -> #REF! | BB21: 56143939 | BC21: =#REF! -> #REF! | BD21: =#REF! -> #REF! | BE21: =#REF! -> #REF! | BF21: =#REF! -> #REF! | BG21: =#REF! -> #REF! | BH21: 2.7126669e+08 | BI21: 3.0698122e+08 | BJ21: 3.1138607e+08 | BL21: =BJ21-AX21 -> -3.3658076e+08
A22: 十四 | B22: 业务毛利 | C22: =C6+C7+C8+C9+C10+C11+C12+C13-C15 -> #REF! | D22: =D6+D7+D8+D9+D10+D11+D12+D13-D15 -> #REF! | E22: =E6+E7+E8+E9+E10+E11+E12+E13-E15 -> #REF! | F22: =F6+F7+F8+F9+F10+F11+F12+F13-F15 -> #REF! | G22: =G6+G7+G8+G9+G10+G11+G12+G13-G15 -> #REF! | H22: =H6+H7+H8+H9+H10+H11+H12+H13-H15 -> #REF! | I22: =I6+I7+I8+I9+I10+I11+I12+I13-I15 -> #REF! | J22: =J6+J7+J8+J9+J10+J11+J12+J13-J15 -> #REF! | ... AK22: =AK6+AK7+AK8+AK9+AK10+AK11+AK12+AK13-AK15 -> #REF! | AL22: 4.1096043e+08 | AM22: =AM6+AM7+AM8+AM9+AM10+AM11+AM12+AM13-AM15 -> #REF! | AN22: =AN6+AN7+AN8+AN9+AN10+AN11+AN12+AN13-AN15 -> #REF! | AO22: =AO6+AO7+AO8+AO9+AO10+AO11+AO12+AO13-AO15 -> #REF! | AP22: =AP6+AP7+AP8+AP9+AP10+AP11+AP12+AP13-AP15 -> #REF! | AQ22: =AQ6+AQ7+AQ8+AQ9+AQ10+AQ11+AQ12+AQ13-AQ15 -> #REF! | AR22: =AR6+AR7+AR8+AR9+AR10+AR11+AR12+AR13-AR15 -> #REF! | AS22: =AS6+AS7+AS8+AS9+AS10+AS11+AS12+AS13-AS15 -> #REF! | AT22: =AT6+AT7+AT8+AT9+AT10+AT11+AT12+AT13-AT15 -> #REF! | ... AW22: =AW6+AW7+AW8+AW9+AW10+AW11+AW12+AW13-AW15 -> #REF! | AX22: 2.3616745e+08 | AY22: =AY6+AY7+AY8+AY9+AY10+AY11+AY12+AY13-AY15 -> #REF! | AZ22: =AZ6+AZ7+AZ8+AZ9+AZ10+AZ11+AZ12+AZ13-AZ15 -> #REF! | BA22: =BA6+BA7+BA8+BA9+BA10+BA11+BA12+BA13-BA15 -> #REF! | BB22: 71749082 | BC22: =BC6+BC7+BC8+BC9+BC10+BC11+BC12+BC13-BC15 -> #REF! | BD22: =BD6+BD7+BD8+BD9+BD10+BD11+BD12+BD13-BD15 -> #REF! | BE22: =BE6+BE7+BE8+BE9+BE10+BE11+BE12+BE13-BE15 -> #REF! | BF22: =BF6+BF7+BF8+BF9+BF10+BF11+BF12+BF13-BF15 -> #REF! | BG22: =BG6+BG7+BG8+BG9+BG10+BG11+BG12+BG13-BG15 -> #REF! | BH22: 1.7786043e+08 | BI22: 2.0223216e+08 | BJ22: =BJ6+BJ7+BJ8+BJ9+BJ10+BJ11+BJ12+BJ13+BJ14-BJ15 -> 2.5412885e+08 | BK22: =BJ22+BJ16-BJ14 -> 2.4576653e+08 | BL22: =BJ22-AX22 -> 17961405 | BM22: =BL22-BL23-BL38 -> 71820623
A23: 十五 | B23: 减：业务直接费用 | C23: =C24+C27+C35+C36 -> #REF! | D23: =D24+D27+D35+D36 -> #REF! | E23: =E24+E27+E35+E36 -> #REF! | F23: =F24+F27+F35+F36 -> #REF! | G23: =G24+G27+G35+G36 -> #REF! | H23: =H24+H27+H35+H36 -> #REF! | I23: =I24+I27+I35+I36 -> #REF! | J23: =J24+J27+J35+J36 -> #REF! | ... AK23: =AK24+AK27+AK35+AK36 -> #REF! | AL23: 2.3881085e+08 | AM23: =AM24+AM27+AM35+AM36 -> #REF! | AN23: =AN24+AN27+AN35+AN36 -> #REF! | AO23: =AO24+AO27+AO35+AO36 -> #REF! | AP23: =AP24+AP27+AP35+AP36 -> #REF! | AQ23: =AQ24+AQ27+AQ35+AQ36 -> #REF! | AR23: =AR24+AR27+AR35+AR36 -> #REF! | AS23: =AS24+AS27+AS35+AS36 -> #REF! | AT23: =AT24+AT27+AT35+AT36 -> #REF! | ... AW23: =AW24+AW27+AW35+AW36 -> #REF! | AX23: 1.6342039e+08 | AY23: =AY24+AY27+AY35+AY36 -> #REF! | AZ23: =AZ24+AZ27+AZ35+AZ36 -> #REF! | BA23: =BA24+BA27+BA35+BA36 -> #REF! | BB23: 37678367 | BC23: =BC24+BC27+BC35+BC36 -> #REF! | BD23: =BD24+BD27+BD35+BD36 -> #REF! | BE23: =BE24+BE27+BE35+BE36 -> #REF! | BF23: =BF24+BF27+BF35+BF36 -> #REF! | BG23: =BG24+BG27+BG35+BG36 -> #REF! | BH23: 89271194 | BI23: 98327631 | BJ23: =125550481.87-0.01-11125101.41+323310 -> 1.1474869e+08 | BK23: =BK22*1.06/10000 -> 26051.252 | BL23: =BJ23-AX23 -> -48671703
A24: 1 | B24: 直接人工 | C24: =C25+C26 -> #REF! | D24: =D25+D26 -> #REF! | E24: =E25+E26 -> #REF! | F24: =F25+F26 -> #REF! | G24: =G25+G26 -> #REF! | H24: =H25+H26 -> #REF! | I24: =I25+I26 -> #REF! | J24: =J25+J26 -> #REF! | ... AK24: =AK25+AK26 -> #REF! | AL24: 1.304238e+08 | AM24: =AM25+AM26 -> #REF! | AN24: =AN25+AN26 -> #REF! | AO24: =AO25+AO26 -> #REF! | AP24: =AP25+AP26 -> #REF! | AQ24: =AQ25+AQ26 -> #REF! | AR24: =AR25+AR26 -> #REF! | AS24: =AS25+AS26 -> #REF! | AT24: =AT25+AT26 -> #REF! | ... AW24: =AW25+AW26 -> #REF! | AX24: 1.0104668e+08 | AY24: =AY25+AY26 -> #REF! | AZ24: =AZ25+AZ26 -> #REF! | BA24: =BA25+BA26 -> #REF! | BB24: 26758678 | BC24: =BC25+BC26 -> #REF! | BD24: =BD25+BD26 -> #REF! | BE24: =BE25+BE26 -> #REF! | BF24: =BF25+BF26 -> #REF! | BG24: =BG25+BG26 -> #REF! | BH24: 62377260 | BI24: 68314325 | BJ24: 80877269 | BL24: =BJ24-AX24 -> -20169415
A25: 1.1 | B25: 其中：运营/客服人工 | C25: =#REF!+#REF! -> #REF! | D25: =#REF!+#REF! -> #REF! | E25: =#REF!+#REF! -> #REF! | F25: =#REF!+#REF! -> #REF! | G25: =#REF!+#REF! -> #REF! | H25: =#REF!+#REF! -> #REF! | I25: =#REF!+#REF! -> #REF! | J25: =#REF!+#REF! -> #REF! | ... AK25: =#REF!+#REF! -> #REF! | AL25: 90779938 | AM25: =#REF!+#REF! -> #REF! | AN25: =#REF!+#REF! -> #REF! | AO25: =#REF!+#REF! -> #REF! | AP25: =#REF!+#REF! -> #REF! | AQ25: =#REF!+#REF! -> #REF! | AR25: =#REF!+#REF! -> #REF! | AS25: =#REF!+#REF! -> #REF! | AT25: =#REF!+#REF! -> #REF! | ... AW25: =#REF!+#REF! -> #REF! | AX25: 70391753 | AY25: =#REF!+#REF! -> #REF! | AZ25: =#REF!+#REF! -> #REF! | BA25: =#REF!+#REF! -> #REF! | BB25: 19935261 | BC25: =#REF!+#REF! -> #REF! | BD25: =#REF!+#REF! -> #REF! | BE25: =#REF!+#REF! -> #REF! | BF25: =#REF!+#REF! -> #REF! | BG25: =#REF!+#REF! -> #REF! | BH25: 44928021 | BI25: 49173721 | BJ25: 57548353 | BL25: =BJ25-AX25 -> -12843399
A26: 1.2 | B26: 研发人工 | C26: =#REF! -> #REF! | D26: =#REF! -> #REF! | E26: =#REF! -> #REF! | F26: =#REF! -> #REF! | G26: =#REF! -> #REF! | H26: =#REF! -> #REF! | I26: =#REF! -> #REF! | J26: =#REF! -> #REF! | ... AK26: =#REF! -> #REF! | AL26: 39643864 | AM26: =#REF! -> #REF! | AN26: =#REF! -> #REF! | AO26: =#REF! -> #REF! | AP26: =#REF! -> #REF! | AQ26: =#REF! -> #REF! | AR26: =#REF! -> #REF! | AS26: =#REF! -> #REF! | AT26: =#REF! -> #REF! | ... AW26: =#REF! -> #REF! | AX26: 30654931 | AY26: =#REF! -> #REF! | AZ26: =#REF! -> #REF! | BA26: =#REF! -> #REF! | BB26: 6823417.3 | BC26: =#REF! -> #REF! | BD26: =#REF! -> #REF! | BE26: =#REF! -> #REF! | BF26: =#REF! -> #REF! | BG26: =#REF! -> #REF! | BH26: 17449238 | BI26: 19140604 | BJ26: 23328915 | BL26: =BJ26-AX26 -> -7326016
A27: 2 | B27: 直接运营费用 | C27: =SUM(C28:C34) -> #REF! | D27: =SUM(D28:D34) -> #REF! | E27: =SUM(E28:E34) -> #REF! | F27: =SUM(F28:F34) -> #REF! | G27: =SUM(G28:G34) -> #REF! | H27: =SUM(H28:H34) -> #REF! | I27: =SUM(I28:I34) -> #REF! | J27: =SUM(J28:J34) -> #REF! | ... AK27: =SUM(AK28:AK34) -> #REF! | AL27: 99286505 | AM27: =SUM(AM28:AM34) -> #REF! | AN27: =SUM(AN28:AN34) -> #REF! | AO27: =SUM(AO28:AO34) -> #REF! | AP27: =SUM(AP28:AP34) -> #REF! | AQ27: =SUM(AQ28:AQ34) -> #REF! | AR27: =SUM(AR28:AR34) -> #REF! | AS27: =SUM(AS28:AS34) -> #REF! | AT27: =SUM(AT28:AT34) -> #REF! | ... AW27: =SUM(AW28:AW34) -> #REF! | AX27: 53858655 | AY27: =SUM(AY28:AY34) -> #REF! | AZ27: =SUM(AZ28:AZ34) -> #REF! | BA27: =SUM(BA28:BA34) -> #REF! | BB27: =SUM(BB28:BB34) -> 9741892.5 | BC27: =SUM(BC28:BC34) -> #REF! | BD27: =SUM(BD28:BD34) -> #REF! | BE27: =SUM(BE28:BE34) -> #REF! | BF27: =SUM(BF28:BF34) -> #REF! | BG27: =SUM(BG28:BG34) -> #REF! | BH27: 22315018 | BI27: 24770878 | BJ27: =40911850.25-0.01-11125101.41 -> 29786749 | BL27: =BJ27-AX27 -> -24071906
A28: 1.3 | B28: 其中：平台服务费（直接服务费） | C28: =#REF! -> #REF! | D28: =#REF! -> #REF! | E28: =#REF! -> #REF! | F28: =#REF! -> #REF! | G28: =#REF! -> #REF! | H28: =#REF! -> #REF! | I28: =#REF! -> #REF! | J28: =#REF! -> #REF! | ... AK28: =#REF! -> #REF! | AL28: 3089902.6 | AM28: =#REF! -> #REF! | AN28: =#REF! -> #REF! | AO28: =#REF! -> #REF! | AP28: =#REF! -> #REF! | AQ28: =#REF! -> #REF! | AR28: =#REF! -> #REF! | AS28: =#REF! -> #REF! | AT28: =#REF! -> #REF! | ... AW28: =#REF! -> #REF! | AX28: 1194300.1 | AY28: =#REF! -> #REF! | AZ28: =#REF! -> #REF! | BA28: =#REF! -> #REF! | BB28: 309823.16 | BC28: =#REF! -> #REF! | BD28: =#REF! -> #REF! | BE28: =#REF! -> #REF! | BF28: =#REF! -> #REF! | BG28: =#REF! -> #REF! | BH28: 542950.63 | BI28: 549506.9 | BJ28: 721915.64 | BL28: =BJ28-AX28 -> -472384.41
A29: 1.1 | B29: 平台推广服务费 | C29: =#REF! -> #REF! | D29: =#REF! -> #REF! | E29: =#REF! -> #REF! | F29: =#REF! -> #REF! | G29: =#REF! -> #REF! | H29: =#REF! -> #REF! | I29: =#REF! -> #REF! | J29: =#REF! -> #REF! | ... AK29: =#REF! -> #REF! | AL29: 50391209 | AM29: =#REF! -> #REF! | AN29: =#REF! -> #REF! | AO29: =#REF! -> #REF! | AP29: =#REF! -> #REF! | AQ29: =#REF! -> #REF! | AR29: =#REF! -> #REF! | AS29: =#REF! -> #REF! | AT29: =#REF! -> #REF! | ... AW29: =#REF! -> #REF! | AX29: 19379441 | AY29: =#REF! -> #REF! | AZ29: =#REF! -> #REF! | BA29: =#REF! -> #REF! | BB29: 2931380.1 | BC29: =#REF! -> #REF! | BD29: =#REF! -> #REF! | BE29: =#REF! -> #REF! | BF29: =#REF! -> #REF! | BG29: =#REF! -> #REF! | BH29: 7659793.2 | BI29: 8919872.7 | BJ29: 10617480 | BL29: =BJ29-AX29 -> -8761961.3
A30: 1.4 | B30: 市场推广服务费 | C30: =#REF! -> #REF! | D30: =#REF! -> #REF! | E30: =#REF! -> #REF! | F30: =#REF! -> #REF! | G30: =#REF! -> #REF! | H30: =#REF! -> #REF! | I30: =#REF! -> #REF! | J30: =#REF! -> #REF! | ... AK30: =#REF! -> #REF! | AL30: 7860607.1 | AM30: =#REF! -> #REF! | AN30: =#REF! -> #REF! | AO30: =#REF! -> #REF! | AP30: =#REF! -> #REF! | AQ30: =#REF! -> #REF! | AR30: =#REF! -> #REF! | AS30: =#REF! -> #REF! | AT30: =#REF! -> #REF! | ... AW30: =#REF! -> #REF! | AX30: 1615711.3 | AY30: =#REF! -> #REF! | AZ30: =#REF! -> #REF! | BA30: =#REF! -> #REF! | BB30: 227029.47 | BC30: =#REF! -> #REF! | BD30: =#REF! -> #REF! | BE30: =#REF! -> #REF! | BF30: =#REF! -> #REF! | BG30: =#REF! -> #REF! | BH30: 669463.01 | BI30: 704257.25 | BJ30: =13745066.38-11125101.41 -> 2619965 | BL30: =BJ30-AX30 -> 1004253.7
A31: 2.1 | B31: 软件服务费 | C31: =#REF!+#REF!+#REF! -> #REF! | D31: =#REF!+#REF!+#REF! -> #REF! | E31: =#REF!+#REF!+#REF! -> #REF! | F31: =#REF!+#REF!+#REF! -> #REF! | G31: =#REF!+#REF!+#REF! -> #REF! | H31: =#REF!+#REF!+#REF! -> #REF! | I31: =#REF!+#REF!+#REF! -> #REF! | J31: =#REF!+#REF!+#REF! -> #REF! | ... AK31: =#REF!+#REF!+#REF! -> #REF! | AL31: 1434426.4 | AM31: =#REF!+#REF!+#REF! -> #REF! | AN31: =#REF!+#REF!+#REF! -> #REF! | AO31: =#REF!+#REF!+#REF! -> #REF! | AP31: =#REF!+#REF!+#REF! -> #REF! | AQ31: =#REF!+#REF!+#REF! -> #REF! | AR31: =#REF!+#REF!+#REF! -> #REF! | AS31: =#REF!+#REF!+#REF! -> #REF! | AT31: =#REF!+#REF!+#REF! -> #REF! | ... AW31: =#REF!+#REF!+#REF! -> #REF! | AX31: 629978.8 | AY31: =#REF!+#REF!+#REF! -> #REF! | AZ31: =#REF!+#REF!+#REF! -> #REF! | BA31: =#REF!+#REF!+#REF! -> #REF! | BB31: 239047.94 | BC31: =#REF!+#REF!+#REF! -> #REF! | BD31: =#REF!+#REF!+#REF! -> #REF! | BE31: =#REF!+#REF!+#REF! -> #REF! | BF31: =#REF!+#REF!+#REF! -> #REF! | BG31: =#REF!+#REF!+#REF! -> #REF! | BH31: 505581.8 | BI31: 558888.42 | BJ31: 650882.58 | BL31: =BJ31-AX31 -> 20903.78
A32: 2.4 | B32: 服务器托管费 | C32: =#REF!+#REF! -> #REF! | D32: =#REF!+#REF! -> #REF! | E32: =#REF!+#REF! -> #REF! | F32: =#REF!+#REF! -> #REF! | G32: =#REF!+#REF! -> #REF! | H32: =#REF!+#REF! -> #REF! | I32: =#REF!+#REF! -> #REF! | J32: =#REF!+#REF! -> #REF! | ... AK32: =#REF!+#REF! -> #REF! | AL32: 5924275.5 | AM32: =#REF!+#REF! -> #REF! | AN32: =#REF!+#REF! -> #REF! | AO32: =#REF!+#REF! -> #REF! | AP32: =#REF!+#REF! -> #REF! | AQ32: =#REF!+#REF! -> #REF! | AR32: =#REF!+#REF! -> #REF! | AS32: =#REF!+#REF! -> #REF! | AT32: =#REF!+#REF! -> #REF! | ... AW32: =#REF!+#REF! -> #REF! | AX32: 4852838.6 | AY32: =#REF!+#REF! -> #REF! | AZ32: =#REF!+#REF! -> #REF! | BA32: =#REF!+#REF! -> #REF! | BB32: 1371743.6 | BC32: =#REF!+#REF! -> #REF! | BD32: =#REF!+#REF! -> #REF! | BE32: =#REF!+#REF! -> #REF! | BF32: =#REF!+#REF! -> #REF! | BG32: =#REF!+#REF! -> #REF! | BH32: 3204807.7 | BI32: 3525317 | BJ32: =3711620.25-0.01 -> 3711620.2 | BL32: =BJ32-AX32 -> -1141218.4
A33: 2.2 | B33: 办公费 | C33: =#REF!+#REF! -> #REF! | D33: =#REF!+#REF! -> #REF! | E33: =#REF!+#REF! -> #REF! | F33: =#REF!+#REF! -> #REF! | G33: =#REF!+#REF! -> #REF! | H33: =#REF!+#REF! -> #REF! | I33: =#REF!+#REF! -> #REF! | J33: =#REF!+#REF! -> #REF! | ... AK33: =#REF!+#REF! -> #REF! | AL33: 9482713.3 | AM33: =#REF!+#REF! -> #REF! | AN33: =#REF!+#REF! -> #REF! | AO33: =#REF!+#REF! -> #REF! | AP33: =#REF!+#REF! -> #REF! | AQ33: =#REF!+#REF! -> #REF! | AR33: =#REF!+#REF! -> #REF! | AS33: =#REF!+#REF! -> #REF! | AT33: =#REF!+#REF! -> #REF! | ... AW33: =#REF!+#REF! -> #REF! | AX33: 8633920.9 | AY33: =#REF!+#REF! -> #REF! | AZ33: =#REF!+#REF! -> #REF! | BA33: =#REF!+#REF! -> #REF! | BB33: 1979584.7 | BC33: =#REF!+#REF! -> #REF! | BD33: =#REF!+#REF! -> #REF! | BE33: =#REF!+#REF! -> #REF! | BF33: =#REF!+#REF! -> #REF! | BG33: =#REF!+#REF! -> #REF! | BH33: 4565051.5 | BI33: 4992321.7 | BJ33: 5709873.2 | BL33: =BJ33-AX33 -> -2924047.7
A34: 2.3 | B34: 中介咨询服务费 | C34: =#REF! -> #REF! | D34: =#REF! -> #REF! | E34: =#REF! -> #REF! | F34: =#REF! -> #REF! | G34: =#REF! -> #REF! | H34: =#REF! -> #REF! | I34: =#REF! -> #REF! | J34: =#REF! -> #REF! | ... AK34: =#REF! -> #REF! | AL34: 21103371 | AM34: =#REF! -> #REF! | AN34: =#REF! -> #REF! | AO34: =#REF! -> #REF! | AP34: =#REF! -> #REF! | AQ34: =#REF! -> #REF! | AR34: =#REF! -> #REF! | AS34: =#REF! -> #REF! | AT34: =#REF! -> #REF! | ... AW34: =#REF! -> #REF! | AX34: 17552464 | AY34: =#REF! -> #REF! | AZ34: =#REF! -> #REF! | BA34: =#REF! -> #REF! | BB34: 2683283.5 | BC34: =#REF! -> #REF! | BD34: =#REF! -> #REF! | BE34: =#REF! -> #REF! | BF34: =#REF! -> #REF! | BG34: =#REF! -> #REF! | BH34: 5167370 | BI34: 5520714.1 | BJ34: 5755012 | BL34: =BJ34-AX34 -> -11797452
A35: 3 | B35: 直接税费 | C35: =#REF! -> #REF! | D35: =#REF! -> #REF! | E35: =#REF! -> #REF! | F35: =#REF! -> #REF! | G35: =#REF! -> #REF! | H35: =#REF! -> #REF! | I35: =#REF! -> #REF! | J35: =#REF! -> #REF! | ... AK35: =#REF! -> #REF! | AL35: 7934025.7 | AM35: =#REF! -> #REF! | AN35: =#REF! -> #REF! | AO35: =#REF! -> #REF! | AP35: =#REF! -> #REF! | AQ35: =#REF! -> #REF! | AR35: =#REF! -> #REF! | AS35: =#REF! -> #REF! | AT35: =#REF! -> #REF! | ... AW35: =#REF! -> #REF! | AX35: 7054225.5 | AY35: =#REF! -> #REF! | AZ35: =#REF! -> #REF! | BA35: =#REF! -> #REF! | BB35: =#REF! -> #REF! | BC35: =#REF! -> #REF! | BD35: =#REF! -> #REF! | BE35: =#REF! -> #REF! | BF35: =#REF! -> #REF! | BG35: =#REF! -> #REF! | BH35: 6209905.3 | BI35: 6988162.8 | BJ35: 8312685.5 | BL35: =BJ35-AX35 -> 1258460
A36: 4 | B36: 直接借款利息费用 | C36: =#REF! -> #REF! | D36: =#REF! -> #REF! | E36: =#REF! -> #REF! | F36: =#REF! -> #REF! | G36: =#REF! -> #REF! | H36: =#REF! -> #REF! | I36: =#REF! -> #REF! | J36: =#REF! -> #REF! | ... AK36: =#REF! -> #REF! | AL36: 1166520.8 | AM36: =#REF! -> #REF! | AN36: =#REF! -> #REF! | AO36: =#REF! -> #REF! | AP36: =#REF! -> #REF! | AQ36: =#REF! -> #REF! | AR36: =#REF! -> #REF! | AS36: =#REF! -> #REF! | AT36: =#REF! -> #REF! | ... AW36: =#REF! -> #REF! | AX36: 1460829.4 | AY36: =#REF! -> #REF! | AZ36: =#REF! -> #REF! | BA36: =#REF! -> #REF! | BB36: =#REF! -> #REF! | BC36: =#REF! -> #REF! | BD36: =#REF! -> #REF! | BE36: =#REF! -> #REF! | BF36: =#REF! -> #REF! | BG36: =#REF! -> #REF! | BH36: -1630988.2 | BI36: -1745734.2 | BJ36: =-4551322.49+323310 -> -4228012.5 | BL36: =BJ36-AX36 -> -5688841.9
A37: 十六 | B37: 业务直接利润 | C37: =C22-C23 -> #REF! | D37: =D22-D23 -> #REF! | E37: =E22-E23 -> #REF! | F37: =F22-F23 -> #REF! | G37: =G22-G23 -> #REF! | H37: =H22-H23 -> #REF! | I37: =I22-I23 -> #REF! | J37: =J22-J23 -> #REF! | ... AK37: =AK22-AK23 -> #REF! | AL37: 1.7214958e+08 | AM37: =AM22-AM23 -> #REF! | AN37: =AN22-AN23 -> #REF! | AO37: =AO22-AO23 -> #REF! | AP37: =AP22-AP23 -> #REF! | AQ37: =AQ22-AQ23 -> #REF! | AR37: =AR22-AR23 -> #REF! | AS37: =AS22-AS23 -> #REF! | AT37: =AT22-AT23 -> #REF! | ... AW37: =AW22-AW23 -> #REF! | AX37: 72747053 | AY37: =AY22-AY23 -> #REF! | AZ37: =AZ22-AZ23 -> #REF! | BA37: =BA22-BA23 -> #REF! | BB37: 34070715 | BC37: =BC22-BC23 -> #REF! | BD37: =BD22-BD23 -> #REF! | BE37: =BE22-BE23 -> #REF! | BF37: =BF22-BF23 -> #REF! | BG37: =BG22-BG23 -> #REF! | BH37: 88589240 | BI37: 1.0390453e+08 | BJ37: =BJ22-BJ23 -> 1.3938016e+08 | BK37: =BJ22-BJ23 -> 1.3938016e+08 | BL37: =BJ37-AX37 -> 66633108
A38: 十七 | B38: 减：支撑部门费用 | C38: =SUM(C39:C44) -> #REF! | D38: =SUM(D39:D44) -> #REF! | E38: =SUM(E39:E44) -> #REF! | F38: =SUM(F39:F44) -> #REF! | G38: =SUM(G39:G44) -> #REF! | H38: =SUM(H39:H44) -> #REF! | I38: =SUM(I39:I44) -> #REF! | J38: =SUM(J39:J44) -> #REF! | ... AK38: =SUM(AK39:AK44) -> #REF! | AL38: 69311790 | AM38: =SUM(AM39:AM44) -> #REF! | AN38: =SUM(AN39:AN44) -> #REF! | AO38: =SUM(AO39:AO44) -> #REF! | AP38: =SUM(AP39:AP44) -> #REF! | AQ38: =SUM(AQ39:AQ44) -> #REF! | AR38: =SUM(AR39:AR44) -> #REF! | AS38: =SUM(AS39:AS44) -> #REF! | AT38: =SUM(AT39:AT44) -> #REF! | ... AW38: =SUM(AW39:AW44) -> #REF! | AX38: 68015355 | AY38: =SUM(AY39:AY44) -> #REF! | AZ38: =SUM(AZ39:AZ44) -> #REF! | BA38: =SUM(BA39:BA44) -> #REF! | BB38: 16109885 | BC38: =SUM(BC39:BC44) -> #REF! | BD38: =SUM(BD39:BD44) -> #REF! | BE38: =SUM(BE39:BE44) -> #REF! | BF38: =SUM(BF39:BF44) -> #REF! | BG38: =SUM(BG39:BG44) -> #REF! | BH38: 41463013 | BI38: 45579366 | BJ38: 62827840 | BL38: =BJ38-AX38 -> -5187514.9
A39: 1 | B39: 支撑部门人工成本 | C39: =#REF! -> #REF! | D39: =#REF! -> #REF! | E39: =#REF! -> #REF! | F39: =#REF! -> #REF! | G39: =#REF! -> #REF! | H39: =#REF! -> #REF! | I39: =#REF! -> #REF! | J39: =#REF! -> #REF! | ... AK39: =#REF! -> #REF! | AL39: 36877571 | AM39: =#REF! -> #REF! | AN39: =#REF! -> #REF! | AO39: =#REF! -> #REF! | AP39: =#REF! -> #REF! | AQ39: =#REF! -> #REF! | AR39: =#REF! -> #REF! | AS39: =#REF! -> #REF! | AT39: =#REF! -> #REF! | ... AW39: =#REF! -> #REF! | AX39: 39774916 | AY39: =#REF! -> #REF! | AZ39: =#REF! -> #REF! | BA39: =#REF! -> #REF! | BB39: 8646056.4 | BC39: =#REF! -> #REF! | BD39: =#REF! -> #REF! | BE39: =#REF! -> #REF! | BF39: =#REF! -> #REF! | BG39: =#REF! -> #REF! | BH39: 21638075 | BI39: 23826792 | BJ39: 33978074 | BL39: =BJ39-AX39 -> -5796842.1
A40: 2 | B40: 房租物业、水电费 | C40: =#REF! -> #REF! | D40: =#REF! -> #REF! | E40: =#REF! -> #REF! | F40: =#REF!-#REF! -> #REF! | G40: =#REF!-#REF! -> #REF! | H40: =#REF!-#REF! -> #REF! | I40: =#REF!-#REF! -> #REF! | J40: =#REF!-#REF! -> #REF! | K40: =#REF!-#REF! -> #REF! | L40: =#REF!-#REF! -> #REF! | M40: =#REF!-#REF! -> #REF! | ... AK40: =#REF!-#REF! -> #REF! | AL40: 7145135 | AM40: =#REF!-#REF! -> #REF! | AN40: =#REF!-#REF! -> #REF! | AO40: =#REF!-#REF! -> #REF! | AP40: 2319166.6 | AQ40: =#REF!-#REF! -> #REF! | AR40: =#REF!-#REF! -> #REF! | AS40: =#REF!-#REF! -> #REF! | AT40: =#REF!-#REF! -> #REF! | AU40: =#REF!-#REF! -> #REF! | AV40: =#REF!-#REF! -> #REF! | AW40: =#REF!-#REF! -> #REF! | AX40: 6392907.4 | AY40: =#REF!-#REF! -> #REF! | AZ40: =#REF!-#REF! -> #REF! | BA40: =#REF!-#REF! -> #REF! | BB40: 1501893.3 | BC40: =#REF!-#REF! -> #REF! | BD40: =#REF!-#REF! -> #REF! | BE40: =#REF!-#REF! -> #REF! | BF40: =#REF!-#REF! -> #REF! | BG40: =#REF!-#REF! -> #REF! | BH40: 4224841.1 | BI40: 4527129.4 | BJ40: 4798634.8 | BL40: =BJ40-AX40 -> -1594272.6
...

Sheet 成本费用分布（EAS）
A1: 费用项目 | B1: 2023年1月费用 | C1: 2023年1-2费用 | D1: 2023年1-3费用 | E1: 2023年1-4费用 | F1: 2023年1-5费用 | G1: 2023年1-6费用 | H1: 2023年1-7费用 | I1: 2023年1-8费用 | J1: 2023年1-9费用 | K1: 2023年1-10费用 | L1: 2023年1-11费用 | M1: 2023年1-12费用 | N1: 2024年1月费用 | O1: 2024年1-2月费用 | P1: 2024年1-3月费用 | Q1: 2024年1-4月费用 | R1: 2024年1-5月费用 | S1: 2024年1-6月费用 | T1: 2024年1-7月费用 | U1: 2024年1-8月费用 | V1: 2024年1-9月费用 | W1: 2024年1-10月费用 | X1: 2024年1-11月费用 | Y1: 2024年1-12月费用 | Z1: 2025年1月费用 | AA1: 2025年1-2月费用 | AB1: 2025年1-3月费用 | AC1: 2025年1-4月费用 | AD1: 2025年1-5月费用 | AE1: 2025年1-6月费用 | AF1: 2025年1-7月费用 | AG1: 2025年1-8月费用 | AH1: 2025年1-9月费用 | AI1: 2025年1-10月费用 | AJ1: 2025年1-11月费用 | AK1: 2025年1-12月费用 | AL1: 2025年费用分布占比 | AM1: 同期增长额度 | AN1: 同期费用增长率 | AO1: 备注 | AR1: 费用项目 | AS1: 2021年1-1月费用 | AT1: 2021年1-2月费用 | AU1: 2021年1-3月费用 | AV1: 2021年1-4月费用 | AW1: 2021年1-5月费用 | AX1: 2021年1-6月费用 | AY1: 2021年1-7月费用 | AZ1: 2021年1-8月费用 | BA1: 2021年1-9月费用 | BB1: 2021年1-10月费用 | BC1: 2021年1-11月费用 | BD1: 2021年1-12月费用 | BE1: 2022年1-1月费用 | BF1: 2022年1-2月费用 | BG1: 2022年1-3月费用 | BH1: 2022年1-10月费用 | BI1: 2022年1-5月费用 | BJ1: 2022年1-7月费用 | BK1: 2022年1-7月费用 | BL1: 2022年1-8月费用 | BM1: 2022年1-10月费用 | BN1: 2022年1-10月费用 | BO1: 2022年1-11月费用 | BP1: 2022年1-12月费用 | BQ1: 2023年1月费用 | BR1: 2023年1-2月费用 | BS1: 2023年1-3月费用 | BT1: 2023年1-5月费用 | BU1: 2023年1-5月费用 | BV1: 2023年1-6月费用 | BW1: 2023年1-7月费用 | BX1: 2023年1-8月费用 | BY1: 2023年1-9月费用 | BZ1: 2023年1-10月费用 | CA1: 2023年1-11月费用 | CB1: 2023年1-12月费用 | CC1: 2024年1月费用 | CD1: 2024年1-2月费用 | CE1: 2024年1-3月费用 | CF1: 2024年1-5月费用 | CG1: 2024年1-5月费用 | CH1: 2024年1-6月费用 | CI1: 2024年1-7月费用 | CJ1: 2024年1-8月费用 | CK1: 2024年1-9月费用 | CL1: 2024年1-10月费用 | CM1: 2024年1-11月费用 | CN1: 2024年1-12月费用 | CO1: 2025年1月费用 | CP1: 2025年1-2月费用 | CQ1: 2025年1-3月费用 | CR1: 2025年1-5月费用 | CS1: 2025年1-5月费用 | CT1: 2025年1-6月费用 | CU1: 2025年1-7月费用 | CV1: 2025年1-8月费用 | CW1: 2025年1-9月费用 | CX1: 2025年1-10月费用 | CY1: 2025年1-11月费用 | CZ1: 2025年1-12月费用 | DB1: 费用项目 | DC1: 直接运营费用 | DD1: 人事费用 | DE1: 咨询服务费用 | DF1: 办公费用 | DG1: 小计
A2: 人工成本-58.42% | B2: =('权责制经营报表-EAS 2512（审计口径）'!AA24+'权责制经营报表-EAS 2512（审计口径）'!AA39)/10000+B28/10000 -> #REF! | C2: =('权责制经营报表-EAS 2512（审计口径）'!AB24+'权责制经营报表-EAS 2512（审计口径）'!AB39)/10000+C28/10000 -> #REF! | D2: =('权责制经营报表-EAS 2512（审计口径）'!AC24+'权责制经营报表-EAS 2512（审计口径）'!AC39)/10000+D28/10000 -> #REF! | E2: =('权责制经营报表-EAS 2512（审计口径）'!AD24+'权责制经营报表-EAS 2512（审计口径）'!AD39)/10000+E28/10000 -> #REF! | F2: =('权责制经营报表-EAS 2512（审计口径）'!AE24+'权责制经营报表-EAS 2512（审计口径）'!AE39)/10000+F28/10000 -> #REF! | G2: =('权责制经营报表-EAS 2512（审计口径）'!AF24+'权责制经营报表-EAS 2512（审计口径）'!AF39)/10000+G28/10000 -> #REF! | H2: =('权责制经营报表-EAS 2512（审计口径）'!AG24+'权责制经营报表-EAS 2512（审计口径）'!AG39)/10000+H28/10000 -> #REF! | I2: =('权责制经营报表-EAS 2512（审计口径）'!AH24+'权责制经营报表-EAS 2512（审计口径）'!AH39)/10000+I28/10000 -> #REF! | ... R2: =('权责制经营报表-EAS 2512（审计口径）'!AQ24+'权责制经营报表-EAS 2512（审计口径）'!AQ39)/10000+R28/10000 -> #REF! | S2: =('权责制经营报表-EAS 2512（审计口径）'!AS24+'权责制经营报表-EAS 2512（审计口径）'!AS39)/10000+S28/10000 -> #REF! | T2: =('权责制经营报表-EAS 2512（审计口径）'!AS24+'权责制经营报表-EAS 2512（审计口径）'!AS39)/10000+U28/10000 -> #REF! | U2: =('权责制经营报表-EAS 2512（审计口径）'!AT24+'权责制经营报表-EAS 2512（审计口径）'!AT39)/10000+U28/10000 -> #REF! | V2: =('权责制经营报表-EAS 2512（审计口径）'!AU24+'权责制经营报表-EAS 2512（审计口径）'!AU39)/10000+V28/10000 -> #REF! | W2: =('权责制经营报表-EAS 2512（审计口径）'!AV24+'权责制经营报表-EAS 2512（审计口径）'!AV39)/10000+W28/10000 -> #REF! | X2: =('权责制经营报表-EAS 2512（审计口径）'!AW24+'权责制经营报表-EAS 2512（审计口径）'!AW39)/10000+X28/10000 -> #REF! | Y2: =('权责制经营报表-EAS 2512（审计口径）'!AX24+'权责制经营报表-EAS 2512（审计口径）'!AX39)/10000+Y28/10000 -> 15801.611 | Z2: =('权责制经营报表-EAS 2512（审计口径）'!AY24+'权责制经营报表-EAS 2512（审计口径）'!AY39)/10000+Z28/10000 -> #REF! | AA2: =('权责制经营报表-EAS 2512（审计口径）'!AZ24+'权责制经营报表-EAS 2512（审计口径）'!AZ39)/10000+AA28/10000 -> #REF! | AB2: =('权责制经营报表-EAS 2512（审计口径）'!BA24+'权责制经营报表-EAS 2512（审计口径）'!BA39)/10000+AB28/10000 -> #REF! | ... AK2: =('权责制经营报表-EAS 2512（审计口径）'!BJ24+'权责制经营报表-EAS 2512（审计口径）'!BJ39)/10000+AK28/10000 -> 12059.388 | AL2: =ROUND(AK2/$AK$14,4) -> 0.6357 | AM2: =AK2-Y2 -> -3742.2233 | AN2: =AM2/AK2 -> -0.3103162 | AO2: 人工成本增长1302万，主要是业务人工增加503万、研发人工增加77万、支撑部门人工增加622万；岗位外包费用120万； | AP2: 人事 | AR2: 直接运营费用 | AS2: =#REF!+#REF!+#REF!+#REF!+#REF!+#REF! -> #REF! | AT2: =#REF!+#REF!+#REF!+#REF!+#REF!+#REF! -> #REF! | AU2: =#REF!+#REF!+#REF!+#REF!+#REF!+#REF! -> #REF! | AV2: =#REF!+#REF!+#REF!+#REF!+#REF!+#REF! -> #REF! | AW2: =#REF!+#REF!+#REF!+#REF!+#REF!+#REF! -> #REF! | AX2: =#REF!+#REF!+#REF!+#REF!+#REF!+#REF! -> #REF! | AY2: =#REF!+#REF!+#REF!+#REF!+#REF!+#REF! -> #REF! | AZ2: =#REF!+#REF!+#REF!+#REF!+#REF!+#REF! -> #REF! | ... BP2: =#REF!+#REF!+#REF!+#REF!+#REF!+#REF! -> #REF! | BQ2: =B3+B4+B5+B6+B7+B8 -> #REF! | BR2: =C3+C4+C5+C6+C7+C8 -> #REF! | BS2: =D3+D4+D5+D6+D7+D8 -> #REF! | BT2: =F3+F4+F5+F6+F7+F8 -> #REF! | BU2: =F3+F4+F5+F6+F7+F8 -> #REF! | BV2: =G3+G4+G5+G6+G7+G8 -> #REF! | BW2: =H3+H4+H5+H6+H7+H8 -> #REF! | BX2: =I3+I4+I5+I6+I7+I8 -> #REF! | BY2: =J3+J4+J5+J6+J7+J8 -> #REF! | BZ2: =K3+K4+K5+K6+K7+K8 -> #REF! | CA2: =L3+L4+L5+L6+L7+L8 -> #REF! | CB2: =M3+M4+M5+M6+M7+M8 -> 11122.964 | ... CE2: =P3+P4+P5+P6+P7+P8 -> #REF! | CF2: =R3+R4+R5+R6+R7+R8 -> #REF! | CG2: =R3+R4+R5+R6+R7+R8 -> #REF! | CH2: =S3+S4+S5+S6+S7+S8 -> #REF! | CI2: =T3+T4+T5+T6+T7+T8 -> #REF! | CJ2: =U3+U4+U5+U6+U7+U8 -> #REF! | CK2: =V3+V4+V5+V6+V7+V8 -> #REF! | CL2: =W3+W4+W5+W6+W7+W8 -> #REF! | CM2: =X3+X4+X5+X6+X7+X8 -> #REF! | CN2: =Y3+Y4+Y5+Y6+Y7+Y8 -> 4854.0234 | ... CQ2: =AB3+AB4+AB5+AB6+AB7+AB8 -> #REF! | CR2: =AD3+AD4+AD5+AD6+AD7+AD8 -> #REF! | CS2: =AD3+AD4+AD5+AD6+AD7+AD8 -> #REF! | CT2: =AE3+AE4+AE5+AE6+AE7+AE8 -> #REF! | CU2: =AF3+AF4+AF5+AF6+AF7+AF8 -> #REF! | CV2: =AG3+AG4+AG5+AG6+AG7+AG8 -> #REF! | CW2: =AH3+AH4+AH5+AH6+AH7+AH8 -> #REF! | CX2: =AI3+AI4+AI5+AI6+AI7+AI8 -> 2889.2599 | CY2: =AJ3+AJ4+AJ5+AJ6+AJ7+AJ8 -> 3273.9067 | CZ2: =AK3+AK4+AK5+AK6+AK7+AK8 -> 3877.5347 | DB2: 45261 | DC2: =CB2 -> 11122.964 | DD2: =CB3 -> 18770.074 | DE2: =CB4 -> 1062.9966 | DF2: =CB5 -> 3315.7494 | DG2: =SUM(DC2:DF2) -> 34271.783
A3: 佣金服务费-10.8% | B3: ='权责制经营报表-EAS 2512（审计口径）'!AA16/10000 -> #REF! | C3: ='权责制经营报表-EAS 2512（审计口径）'!AB16/10000 -> #REF! | D3: ='权责制经营报表-EAS 2512（审计口径）'!AC16/10000 -> #REF! | E3: ='权责制经营报表-EAS 2512（审计口径）'!AD16/10000 -> #REF! | F3: ='权责制经营报表-EAS 2512（审计口径）'!AE16/10000 -> #REF! | G3: ='权责制经营报表-EAS 2512（审计口径）'!AF16/10000 -> #REF! | H3: ='权责制经营报表-EAS 2512（审计口径）'!AG16/10000 -> #REF! | I3: ='权责制经营报表-EAS 2512（审计口径）'!AH16/10000 -> #REF! | ... R3: ='权责制经营报表-EAS 2512（审计口径）'!AQ16/10000 -> #REF! | S3: ='权责制经营报表-EAS 2512（审计口径）'!AS16/10000 -> #REF! | T3: ='权责制经营报表-EAS 2512（审计口径）'!AS16/10000 -> #REF! | U3: ='权责制经营报表-EAS 2512（审计口径）'!AT16/10000 -> #REF! | V3: ='权责制经营报表-EAS 2512（审计口径）'!AU16/10000 -> #REF! | W3: ='权责制经营报表-EAS 2512（审计口径）'!AV16/10000 -> #REF! | X3: ='权责制经营报表-EAS 2512（审计口径）'!AW16/10000 -> #REF! | Y3: ='权责制经营报表-EAS 2512（审计口径）'!AX16/10000 -> 2086.7964 | Z3: ='权责制经营报表-EAS 2512（审计口径）'!AY16/10000 -> #REF! | AA3: ='权责制经营报表-EAS 2512（审计口径）'!AZ16/10000 -> #REF! | ... AK3: ='权责制经营报表-EAS 2512（审计口径）'!BJ16/10000 -> 2045.3484 | AL3: =ROUND(AK3/$AK$14,4) -> 0.1078 | AM3: =AK3-Y3 -> -41.448036 | AN3: =AM3/AK3 -> -0.020264536 | AO3: 京东拼购业务、京东话费充值店业务影响较大，GMV下降导致佣金手续减少474万；搜卡手游专营店减少93万；天猫+福禄网游数卡专营店下降63万； | AP3: 直接运营费用 | AR3: 人事费用 | AS3: =#REF! -> #REF! | AT3: =#REF! -> #REF! | AU3: =#REF! -> #REF! | AV3: =#REF! -> #REF! | AW3: =#REF! -> #REF! | AX3: =#REF! -> #REF! | AY3: =#REF! -> #REF! | AZ3: =#REF! -> #REF! | ... BP3: =#REF! -> #REF! | BQ3: =B2 -> #REF! | BR3: =C2 -> #REF! | BS3: =D2 -> #REF! | BT3: =F2 -> #REF! | BU3: =F2 -> #REF! | BV3: =G2 -> #REF! | BW3: =H2 -> #REF! | BX3: =I2 -> #REF! | BY3: =J2 -> #REF! | BZ3: =K2 -> #REF! | CA3: =L2 -> #REF! | CB3: =M2 -> 18770.074 | ... CE3: =P2 -> #REF! | CF3: =R2 -> #REF! | CG3: =R2 -> #REF! | CH3: =S2 -> #REF! | CI3: =T2 -> #REF! | CJ3: =U2 -> #REF! | CK3: =V2 -> #REF! | CL3: =W2 -> #REF! | CM3: =X2 -> #REF! | CN3: =Y2 -> 15801.611 | ... CQ3: =AB2 -> #REF! | CR3: =AD2 -> #REF! | CS3: =AD2 -> #REF! | CT3: =AE2 -> #REF! | CU3: =AF2 -> #REF! | CV3: =AG2 -> #REF! | CW3: =AH2 -> #REF! | CX3: =AI2 -> 8920.7393 | CY3: =AJ2 -> 9766.1249 | CZ3: =AK2 -> 12059.388 | DB3: 45627 | DC3: =CN2 -> 4854.0234 | DD3: =CN3 -> 15801.611 | DE3: =CN4 -> 845.79409 | DF3: =CN5 -> 3023.5203 | DG3: =SUM(DC3:DF3) -> 24524.949
A4: 平台服务费-1.38% | B4: ='权责制经营报表-EAS 2512（审计口径）'!AA28/10000 -> #REF! | C4: ='权责制经营报表-EAS 2512（审计口径）'!AB28/10000 -> #REF! | D4: ='权责制经营报表-EAS 2512（审计口径）'!AC28/10000 -> #REF! | E4: ='权责制经营报表-EAS 2512（审计口径）'!AD28/10000 -> #REF! | F4: ='权责制经营报表-EAS 2512（审计口径）'!AE28/10000 -> #REF! | G4: ='权责制经营报表-EAS 2512（审计口径）'!AF28/10000 -> #REF! | H4: ='权责制经营报表-EAS 2512（审计口径）'!AG28/10000 -> #REF! | I4: ='权责制经营报表-EAS 2512（审计口径）'!AH28/10000 -> #REF! | ... R4: ='权责制经营报表-EAS 2512（审计口径）'!AQ28/10000 -> #REF! | S4: ='权责制经营报表-EAS 2512（审计口径）'!AS28/10000 -> #REF! | T4: ='权责制经营报表-EAS 2512（审计口径）'!AS28/10000 -> #REF! | U4: ='权责制经营报表-EAS 2512（审计口径）'!AT28/10000 -> #REF! | V4: ='权责制经营报表-EAS 2512（审计口径）'!AU28/10000 -> #REF! | W4: ='权责制经营报表-EAS 2512（审计口径）'!AV28/10000 -> #REF! | X4: ='权责制经营报表-EAS 2512（审计口径）'!AW28/10000 -> #REF! | Y4: ='权责制经营报表-EAS 2512（审计口径）'!AX28/10000 -> 119.43 | Z4: ='权责制经营报表-EAS 2512（审计口径）'!AY28/10000 -> #REF! | AA4: ='权责制经营报表-EAS 2512（审计口径）'!AZ28/10000 -> #REF! | ... AK4: ='权责制经营报表-EAS 2512（审计口径）'!BJ28/10000 -> 72.191564 | AL4: =ROUND(AK4/$AK$14,4) -> 0.0038 | AM4: =AK4-Y4 -> -47.238441 | AN4: =AM4/AK4 -> -0.65434849 | AO4: 新增店铺的费用，今年较去年同期新增约56家店铺（53%）（22年162家、20年106家）；主要新增店铺的费用、以及店铺工具费用支出； | AR4: 咨询服务费用 | AS4: =#REF! -> #REF! | AT4: =#REF! -> #REF! | AU4: =#REF! -> #REF! | AV4: =#REF! -> #REF! | AW4: =#REF! -> #REF! | AX4: =#REF! -> #REF! | AY4: =#REF! -> #REF! | AZ4: =#REF! -> #REF! | ... BP4: =#REF! -> #REF! | BQ4: =B13 -> #REF! | BR4: =C13 -> #REF! | BS4: =D13 -> #REF! | BT4: =F13 -> #REF! | BU4: =F13 -> #REF! | BV4: =G13 -> #REF! | BW4: =H13 -> #REF! | BX4: =I13 -> #REF! | BY4: =J13 -> #REF! | BZ4: =K13 -> #REF! | CA4: =L13 -> #REF! | CB4: =M13 -> 1062.9966 | ... CE4: =P13 -> #REF! | CF4: =R13 -> #REF! | CG4: =R13 -> #REF! | CH4: =S13 -> #REF! | CI4: =T13 -> #REF! | CJ4: =U13 -> #REF! | CK4: =V13 -> #REF! | CL4: =W13 -> #REF! | CM4: =X13 -> #REF! | CN4: =Y13 -> 845.79409 | ... CQ4: =AB13 -> #REF! | CR4: =AD13 -> #REF! | CS4: =AD13 -> #REF! | CT4: =AE13 -> #REF! | CU4: =AF13 -> #REF! | CV4: =AG13 -> #REF! | CW4: =AH13 -> #REF! | CX4: =AI13 -> 491.4639 | CY4: =AJ13 -> 558.59551 | CZ4: =AK13 -> 1136.6434 | DB4: 45992 | DC4: =CZ2 -> 3877.5347 | DD4: =CZ3 -> 12059.388 | DE4: =CZ4 -> 1136.6434 | DF4: =CZ5 -> 1898.1671 | DG4: =SUM(DC4:DF4) -> 18971.733
A5: 平台推广费-15.56% | B5: ='权责制经营报表-EAS 2512（审计口径）'!AA29/10000 -> #REF! | C5: ='权责制经营报表-EAS 2512（审计口径）'!AB29/10000 -> #REF! | D5: ='权责制经营报表-EAS 2512（审计口径）'!AC29/10000 -> #REF! | E5: ='权责制经营报表-EAS 2512（审计口径）'!AD29/10000 -> #REF! | F5: ='权责制经营报表-EAS 2512（审计口径）'!AE29/10000 -> #REF! | G5: ='权责制经营报表-EAS 2512（审计口径）'!AF29/10000 -> #REF! | H5: ='权责制经营报表-EAS 2512（审计口径）'!AG29/10000 -> #REF! | I5: ='权责制经营报表-EAS 2512（审计口径）'!AH29/10000 -> #REF! | ... R5: ='权责制经营报表-EAS 2512（审计口径）'!AQ29/10000 -> #REF! | S5: ='权责制经营报表-EAS 2512（审计口径）'!AS29/10000 -> #REF! | T5: ='权责制经营报表-EAS 2512（审计口径）'!AS29/10000 -> #REF! | U5: ='权责制经营报表-EAS 2512（审计口径）'!AT29/10000 -> #REF! | V5: ='权责制经营报表-EAS 2512（审计口径）'!AU29/10000 -> #REF! | W5: ='权责制经营报表-EAS 2512（审计口径）'!AV29/10000 -> #REF! | X5: ='权责制经营报表-EAS 2512（审计口径）'!AW29/10000 -> #REF! | Y5: ='权责制经营报表-EAS 2512（审计口径）'!AX29/10000 -> 1937.9441 | Z5: ='权责制经营报表-EAS 2512（审计口径）'!AY29/10000 -> #REF! | AA5: ='权责制经营报表-EAS 2512（审计口径）'!AZ29/10000 -> #REF! | ... AK5: ='权责制经营报表-EAS 2512（审计口径）'!BJ29/10000 -> 1061.748 | AL5: =ROUND(AK5/$AK$14,4) -> 0.056 | AM5: =AK5-Y5 -> -876.19613 | AN5: =AM5/AK5 -> -0.82523924 | AO5: 平台店铺的推广支出下降了40万，主要是天猫网游数卡专营店直通车费用下降66万；京东+腾讯视频VIP会员专卖店下降111万、京东+福禄视频会员专营店下降52万；天猫+搜卡手游专营店下降96万；拼多多+腾讯视频官方旗舰店增加81万；抖音平台发生支出188万； | AR5: 办公费用 | AS5: =#REF!+#REF!+#REF!+#REF! -> #REF! | AT5: =#REF!+#REF!+#REF!+#REF! -> #REF! | AU5: =#REF!+#REF!+#REF!+#REF! -> #REF! | AV5: =#REF!+#REF!+#REF!+#REF! -> #REF! | AW5: =#REF!+#REF!+#REF!+#REF! -> #REF! | AX5: =#REF!+#REF!+#REF!+#REF! -> #REF! | AY5: =#REF!+#REF!+#REF!+#REF! -> #REF! | AZ5: =#REF!+#REF!+#REF!+#REF! -> #REF! | ... BP5: =#REF!+#REF!+#REF!+#REF! -> #REF! | BQ5: =B9+B10+B11+B12 -> #REF! | BR5: =C9+C10+C11+C12 -> #REF! | BS5: =D9+D10+D11+D12 -> #REF! | BT5: =F9+F10+F11+F12 -> #REF! | BU5: =F9+F10+F11+F12 -> #REF! | BV5: =G9+G10+G11+G12 -> #REF! | BW5: =H9+H10+H11+H12 -> #REF! | BX5: =I9+I10+I11+I12 -> #REF! | BY5: =J9+J10+J11+J12 -> #REF! | BZ5: =K9+K10+K11+K12 -> #REF! | CA5: =L9+L10+L11+L12 -> #REF! | CB5: =M9+M10+M11+M12 -> 3315.7494 | ... CE5: =P9+P10+P11+P12 -> #REF! | CF5: =R9+R10+R11+R12 -> #REF! | CG5: =R9+R10+R11+R12 -> #REF! | CH5: =S9+S10+S11+S12 -> #REF! | CI5: =T9+T10+T11+T12 -> #REF! | CJ5: =U9+U10+U11+U12 -> #REF! | CK5: =V9+V10+V11+V12 -> #REF! | CL5: =W9+W10+W11+W12 -> #REF! | CM5: =X9+X10+X11+X12 -> #REF! | CN5: =Y9+Y10+Y11+Y12 -> 3023.5203 | ... CQ5: =AB9+AB10+AB11+AB12 -> #REF! | CR5: =AD9+AD10+AD11+AD12 -> #REF! | CS5: =AD9+AD10+AD11+AD12 -> #REF! | CT5: =AE9+AE10+AE11+AE12 -> #REF! | CU5: =AF9+AF10+AF11+AF12 -> #REF! | CV5: =AG9+AG10+AG11+AG12 -> #REF! | CW5: =AH9+AH10+AH11+AH12 -> #REF! | CX5: =AI9+AI10+AI11+AI12 -> 1781.9674 | CY5: =AJ9+AJ10+AJ11+AJ12 -> 1941.3788 | CZ5: =AK9+AK10+AK11+AK12 -> 1898.1671 | DC5: =DC4-DC3 -> -976.4887 | DD5: =DD4-DD3 -> -3742.2233 | DE5: =DE4-DE3 -> 290.84933 | DF5: =DF4-DF3 -> -1125.3532 | DG5: =SUM(DC5:DF5) -> -5553.2159
A6: 市场推广费-2.12% | B6: ='权责制经营报表-EAS 2512（审计口径）'!AA30/10000+B29/10000 -> #REF! | C6: ='权责制经营报表-EAS 2512（审计口径）'!AB30/10000+C29/10000 -> #REF! | D6: ='权责制经营报表-EAS 2512（审计口径）'!AC30/10000+D29/10000 -> #REF! | E6: ='权责制经营报表-EAS 2512（审计口径）'!AD30/10000+E29/10000 -> #REF! | F6: ='权责制经营报表-EAS 2512（审计口径）'!AE30/10000+F29/10000 -> #REF! | G6: ='权责制经营报表-EAS 2512（审计口径）'!AF30/10000+G29/10000 -> #REF! | H6: ='权责制经营报表-EAS 2512（审计口径）'!AG30/10000+H29/10000 -> #REF! | I6: ='权责制经营报表-EAS 2512（审计口径）'!AH30/10000+I29/10000 -> #REF! | ... R6: ='权责制经营报表-EAS 2512（审计口径）'!AQ30/10000+R29/10000 -> #REF! | S6: ='权责制经营报表-EAS 2512（审计口径）'!AS30/10000+S29/10000 -> #REF! | T6: ='权责制经营报表-EAS 2512（审计口径）'!AS30/10000+U29/10000 -> #REF! | U6: ='权责制经营报表-EAS 2512（审计口径）'!AT30/10000+U29/10000 -> #REF! | V6: ='权责制经营报表-EAS 2512（审计口径）'!AU30/10000+V29/10000 -> #REF! | W6: ='权责制经营报表-EAS 2512（审计口径）'!AV30/10000+W29/10000 -> #REF! | X6: ='权责制经营报表-EAS 2512（审计口径）'!AW30/10000+X29/10000 -> #REF! | Y6: ='权责制经营报表-EAS 2512（审计口径）'!AX30/10000+Y29/10000 -> 161.57113 | Z6: ='权责制经营报表-EAS 2512（审计口径）'!AY30/10000+Z29/10000 -> #REF! | AA6: ='权责制经营报表-EAS 2512（审计口径）'!AZ30/10000+AA29/10000 -> #REF! | AB6: ='权责制经营报表-EAS 2512（审计口径）'!BA30/10000+AB29/10000 -> #REF! | ... AK6: ='权责制经营报表-EAS 2512（审计口径）'!BJ30/10000+AK29/10000 -> 261.9965 | AL6: =ROUND(AK6/$AK$14,4) -> 0.0138 | AM6: =AK6-Y6 -> 100.42536 | AN6: =AM6/AK6 -> 0.38330804 | AR6: 合计（单位：万元） | AS6: =SUM(AS2:AS5) -> #REF! | AT6: =SUM(AT2:AT5) -> #REF! | AU6: =SUM(AU2:AU5) -> #REF! | AV6: =SUM(AV2:AV5) -> #REF! | AW6: =SUM(AW2:AW5) -> #REF! | AX6: =SUM(AX2:AX5) -> #REF! | AY6: =SUM(AY2:AY5) -> #REF! | AZ6: =SUM(AZ2:AZ5) -> #REF! | ... CZ6: =SUM(CZ2:CZ5) -> 18971.733 | DC6: =DC5/DC3 -> -0.20117099 | DD6: =DD5/DD3 -> -0.23682543 | DE6: =DE5/DE3 -> 0.34387724 | DF6: =DF5/DF3 -> -0.37219965 | DG6: =DG5/DG3 -> -0.22643129
A7: 服务器托管费-2.07% | B7: ='权责制经营报表-EAS 2512（审计口径）'!AA32/10000 -> #REF! | C7: ='权责制经营报表-EAS 2512（审计口径）'!AB32/10000 -> #REF! | D7: ='权责制经营报表-EAS 2512（审计口径）'!AC32/10000 -> #REF! | E7: ='权责制经营报表-EAS 2512（审计口径）'!AD32/10000 -> #REF! | F7: ='权责制经营报表-EAS 2512（审计口径）'!AE32/10000 -> #REF! | G7: ='权责制经营报表-EAS 2512（审计口径）'!AF32/10000 -> #REF! | H7: ='权责制经营报表-EAS 2512（审计口径）'!AG32/10000 -> #REF! | I7: ='权责制经营报表-EAS 2512（审计口径）'!AH32/10000 -> #REF! | ... R7: ='权责制经营报表-EAS 2512（审计口径）'!AQ32/10000 -> #REF! | S7: ='权责制经营报表-EAS 2512（审计口径）'!AS32/10000 -> #REF! | T7: ='权责制经营报表-EAS 2512（审计口径）'!AS32/10000 -> #REF! | U7: ='权责制经营报表-EAS 2512（审计口径）'!AT32/10000 -> #REF! | V7: ='权责制经营报表-EAS 2512（审计口径）'!AU32/10000 -> #REF! | W7: ='权责制经营报表-EAS 2512（审计口径）'!AV32/10000 -> #REF! | X7: ='权责制经营报表-EAS 2512（审计口径）'!AW32/10000 -> #REF! | Y7: ='权责制经营报表-EAS 2512（审计口径）'!AX32/10000 -> 485.28386 | Z7: ='权责制经营报表-EAS 2512（审计口径）'!AY32/10000 -> #REF! | AA7: ='权责制经营报表-EAS 2512（审计口径）'!AZ32/10000 -> #REF! | ... AK7: ='权责制经营报表-EAS 2512（审计口径）'!BJ32/10000 -> 371.16202 | AL7: =ROUND(AK7/$AK$14,4) -> 0.0196 | AM7: =AK7-Y7 -> -114.12184 | AN7: =AM7/AK7 -> -0.30747176 | AO7: 订单量增加，新业务增加（例如海外业务）
A8: 软件服务费-0.6% | B8: ='权责制经营报表-EAS 2512（审计口径）'!AA31/10000 -> #REF! | C8: ='权责制经营报表-EAS 2512（审计口径）'!AB31/10000 -> #REF! | D8: ='权责制经营报表-EAS 2512（审计口径）'!AC31/10000 -> #REF! | E8: ='权责制经营报表-EAS 2512（审计口径）'!AD31/10000 -> #REF! | F8: ='权责制经营报表-EAS 2512（审计口径）'!AE31/10000 -> #REF! | G8: ='权责制经营报表-EAS 2512（审计口径）'!AF31/10000 -> #REF! | H8: ='权责制经营报表-EAS 2512（审计口径）'!AG31/10000 -> #REF! | I8: ='权责制经营报表-EAS 2512（审计口径）'!AH31/10000 -> #REF! | ... R8: ='权责制经营报表-EAS 2512（审计口径）'!AQ31/10000 -> #REF! | S8: ='权责制经营报表-EAS 2512（审计口径）'!AS31/10000 -> #REF! | T8: ='权责制经营报表-EAS 2512（审计口径）'!AS31/10000 -> #REF! | U8: ='权责制经营报表-EAS 2512（审计口径）'!AT31/10000 -> #REF! | V8: ='权责制经营报表-EAS 2512（审计口径）'!AU31/10000 -> #REF! | W8: ='权责制经营报表-EAS 2512（审计口径）'!AV31/10000 -> #REF! | X8: ='权责制经营报表-EAS 2512（审计口径）'!AW31/10000 -> #REF! | Y8: ='权责制经营报表-EAS 2512（审计口径）'!AX31/10000 -> 62.99788 | Z8: ='权责制经营报表-EAS 2512（审计口径）'!AY31/10000 -> #REF! | AA8: ='权责制经营报表-EAS 2512（审计口径）'!AZ31/10000 -> #REF! | ... AK8: ='权责制经营报表-EAS 2512（审计口径）'!BJ31/10000 -> 65.088258 | AL8: =ROUND(AK8/$AK$14,4) -> 0.0034 | AM8: =AK8-Y8 -> 2.090378 | AN8: =AM8/AK8 -> 0.032116054 | BH8: =BH6-AV6 -> #REF! | BR8: 146191.16
A9: 办公费-4.07% | B9: =('权责制经营报表-EAS 2512（审计口径）'!AA33+'权责制经营报表-EAS 2512（审计口径）'!AA41)/10000 -> #REF! | C9: =('权责制经营报表-EAS 2512（审计口径）'!AB33+'权责制经营报表-EAS 2512（审计口径）'!AB41)/10000 -> #REF! | D9: =('权责制经营报表-EAS 2512（审计口径）'!AC33+'权责制经营报表-EAS 2512（审计口径）'!AC41)/10000 -> #REF! | E9: =('权责制经营报表-EAS 2512（审计口径）'!AD33+'权责制经营报表-EAS 2512（审计口径）'!AD41)/10000 -> #REF! | F9: =('权责制经营报表-EAS 2512（审计口径）'!AE33+'权责制经营报表-EAS 2512（审计口径）'!AE41)/10000 -> #REF! | G9: =('权责制经营报表-EAS 2512（审计口径）'!AF33+'权责制经营报表-EAS 2512（审计口径）'!AF41)/10000 -> #REF! | H9: =('权责制经营报表-EAS 2512（审计口径）'!AG33+'权责制经营报表-EAS 2512（审计口径）'!AG41)/10000 -> #REF! | I9: =('权责制经营报表-EAS 2512（审计口径）'!AH33+'权责制经营报表-EAS 2512（审计口径）'!AH41)/10000 -> #REF! | ... R9: =('权责制经营报表-EAS 2512（审计口径）'!AQ33+'权责制经营报表-EAS 2512（审计口径）'!AQ41)/10000 -> #REF! | S9: =('权责制经营报表-EAS 2512（审计口径）'!AS33+'权责制经营报表-EAS 2512（审计口径）'!AS41)/10000 -> #REF! | T9: =('权责制经营报表-EAS 2512（审计口径）'!AS33+'权责制经营报表-EAS 2512（审计口径）'!AS41)/10000 -> #REF! | U9: =('权责制经营报表-EAS 2512（审计口径）'!AT33+'权责制经营报表-EAS 2512（审计口径）'!AT41)/10000 -> #REF! | V9: =('权责制经营报表-EAS 2512（审计口径）'!AU33+'权责制经营报表-EAS 2512（审计口径）'!AU41)/10000 -> #REF! | W9: =('权责制经营报表-EAS 2512（审计口径）'!AV33+'权责制经营报表-EAS 2512（审计口径）'!AV41)/10000 -> #REF! | X9: =('权责制经营报表-EAS 2512（审计口径）'!AW33+'权责制经营报表-EAS 2512（审计口径）'!AW41)/10000 -> #REF! | Y9: =('权责制经营报表-EAS 2512（审计口径）'!AX33+'权责制经营报表-EAS 2512（审计口径）'!AX41)/10000 -> 1376.7932 | Z9: =('权责制经营报表-EAS 2512（审计口径）'!AY33+'权责制经营报表-EAS 2512（审计口径）'!AY41)/10000 -> #REF! | AA9: =('权责制经营报表-EAS 2512（审计口径）'!AZ33+'权责制经营报表-EAS 2512（审计口径）'!AZ41)/10000 -> #REF! | ... AK9: =('权责制经营报表-EAS 2512（审计口径）'!BJ33+'权责制经营报表-EAS 2512（审计口径）'!BJ41)/10000 -> 1000.6447 | AL9: =ROUND(AK9/$AK$14,4) -> 0.0527 | AM9: =AK9-Y9 -> -376.14851 | AN9: =AM9/AK9 -> -0.37590617 | AO9: 主要是办公用品增加28.8万、会议费增加24万、招待费增加34.5万； | AP9: 办公费
A10: 房租、物业水电费-1.72% | B10: ='权责制经营报表-EAS 2512（审计口径）'!AA40/10000 -> #REF! | C10: ='权责制经营报表-EAS 2512（审计口径）'!AB40/10000 -> #REF! | D10: ='权责制经营报表-EAS 2512（审计口径）'!AC40/10000 -> #REF! | E10: ='权责制经营报表-EAS 2512（审计口径）'!AD40/10000 -> #REF! | F10: ='权责制经营报表-EAS 2512（审计口径）'!AE40/10000 -> #REF! | G10: ='权责制经营报表-EAS 2512（审计口径）'!AF40/10000 -> #REF! | H10: ='权责制经营报表-EAS 2512（审计口径）'!AG40/10000 -> #REF! | I10: ='权责制经营报表-EAS 2512（审计口径）'!AH40/10000 -> #REF! | ... R10: ='权责制经营报表-EAS 2512（审计口径）'!AQ40/10000 -> #REF! | S10: ='权责制经营报表-EAS 2512（审计口径）'!AS40/10000 -> #REF! | T10: ='权责制经营报表-EAS 2512（审计口径）'!AS40/10000 -> #REF! | U10: ='权责制经营报表-EAS 2512（审计口径）'!AT40/10000 -> #REF! | V10: ='权责制经营报表-EAS 2512（审计口径）'!AU40/10000 -> #REF! | W10: ='权责制经营报表-EAS 2512（审计口径）'!AV40/10000 -> #REF! | X10: ='权责制经营报表-EAS 2512（审计口径）'!AW40/10000 -> #REF! | Y10: ='权责制经营报表-EAS 2512（审计口径）'!AX40/10000 -> 639.29074 | Z10: ='权责制经营报表-EAS 2512（审计口径）'!AY40/10000 -> #REF! | AA10: ='权责制经营报表-EAS 2512（审计口径）'!AZ40/10000 -> #REF! | ... AK10: ='权责制经营报表-EAS 2512（审计口径）'!BJ40/10000 -> 479.86348 | AL10: =ROUND(AK10/$AK$14,4) -> 0.0253 | AM10: =AK10-Y10 -> -159.42726 | AN10: =AM10/AK10 -> -0.33223461
A11: 折旧摊销费-0.99% | B11: =('权责制经营报表-EAS 2512（审计口径）'!AA43+'权责制经营报表-EAS 2512（审计口径）'!AA44)/10000 -> #REF! | C11: =('权责制经营报表-EAS 2512（审计口径）'!AB43+'权责制经营报表-EAS 2512（审计口径）'!AB44)/10000 -> #REF! | D11: =('权责制经营报表-EAS 2512（审计口径）'!AC43+'权责制经营报表-EAS 2512（审计口径）'!AC44)/10000 -> #REF! | E11: =('权责制经营报表-EAS 2512（审计口径）'!AD43+'权责制经营报表-EAS 2512（审计口径）'!AD44)/10000 -> #REF! | F11: =('权责制经营报表-EAS 2512（审计口径）'!AE43+'权责制经营报表-EAS 2512（审计口径）'!AE44)/10000 -> #REF! | G11: =('权责制经营报表-EAS 2512（审计口径）'!AF43+'权责制经营报表-EAS 2512（审计口径）'!AF44)/10000 -> #REF! | H11: =('权责制经营报表-EAS 2512（审计口径）'!AG43+'权责制经营报表-EAS 2512（审计口径）'!AG44)/10000 -> #REF! | I11: =('权责制经营报表-EAS 2512（审计口径）'!AH43+'权责制经营报表-EAS 2512（审计口径）'!AH44)/10000 -> #REF! | ... R11: =('权责制经营报表-EAS 2512（审计口径）'!AQ43+'权责制经营报表-EAS 2512（审计口径）'!AQ44)/10000 -> #REF! | S11: =('权责制经营报表-EAS 2512（审计口径）'!AS43+'权责制经营报表-EAS 2512（审计口径）'!AS44)/10000 -> #REF! | T11: =('权责制经营报表-EAS 2512（审计口径）'!AS43+'权责制经营报表-EAS 2512（审计口径）'!AS44)/10000 -> #REF! | U11: =('权责制经营报表-EAS 2512（审计口径）'!AT43+'权责制经营报表-EAS 2512（审计口径）'!AT44)/10000 -> #REF! | V11: =('权责制经营报表-EAS 2512（审计口径）'!AU43+'权责制经营报表-EAS 2512（审计口径）'!AU44)/10000 -> #REF! | W11: =('权责制经营报表-EAS 2512（审计口径）'!AV43+'权责制经营报表-EAS 2512（审计口径）'!AV44)/10000 -> #REF! | X11: =('权责制经营报表-EAS 2512（审计口径）'!AW43+'权责制经营报表-EAS 2512（审计口径）'!AW44)/10000 -> #REF! | Y11: =('权责制经营报表-EAS 2512（审计口径）'!AX43+'权责制经营报表-EAS 2512（审计口径）'!AX44)/10000 -> 861.35339 | Z11: =('权责制经营报表-EAS 2512（审计口径）'!AY43+'权责制经营报表-EAS 2512（审计口径）'!AY44)/10000 -> #REF! | AA11: =('权责制经营报表-EAS 2512（审计口径）'!AZ43+'权责制经营报表-EAS 2512（审计口径）'!AZ44)/10000 -> #REF! | ... AK11: =('权责制经营报表-EAS 2512（审计口径）'!BJ43+'权责制经营报表-EAS 2512（审计口径）'!BJ44)/10000 -> 840.46017 | AL11: =ROUND(AK11/$AK$14,4) -> 0.0443 | AM11: =AK11-Y11 -> -20.893227 | AN11: =AM11/AK11 -> -0.024859271
