Workbook

Sheet 备忘录
A1: 被审计单位：福禄福擎网络科技有限公司 | E1: 项目 | F1: 名称 | G1: 链接 | H1: 问题描述 | I1: 相关支撑资料 | J1: 问题定性 | K1: 管理层回应/整改措施 | L1: 状态(已解决/持续监控)
A2: 财务报表截止日：2025/9/30 | C2: 日期：2025/10/30 | E2: 货币资金 | F2: 货币资金明细表 | G2: HBZJ-1
A3: 财务报表期间：2025.1-2025.9 | C3: 日期：2025/10/31 | F3: 流水分析 | G3: LSFX-1
E4: 库存商品 | F4: 库存商品明细表 | G4: KCSP-1
F5: 库存商品分析表 | G5: KCSPFX-1
E6: 固定资产 | F6: 固定资产明细表 | G6: GDZC-1
F7: 固定资产测算表 | G7: GDZCCS-1
E8: 无形资产 | F8: 无形资产明细表 | G8: WXZC-1
F9: 无形资产测算表 | G9: WXZCCS-1
E10: 其他流动资产 | F10: 其他流动资产明细表 | G10: QTLDZC-1
E11: 往来 | F11: 应收账款明细表 | G11: YSZK-1
F12: 预付账款明细表 | G12: YFZK-1
F13: 其他应收款明细表 | G13: QTYSK-1
F14: 应付账款明细表 | G14: YFZK-1
F15: 预收账款明细表 | G15: YSZK-1
F16: 其他应付款明细表 | G16: QTYFK-1
F17: 关联方交易核对 | G17: GLFJY-1
E18: 应付职工薪酬 | F18: 应付职工薪酬明细表 | G18: YFZGXCMX-1
F19: 应付职工薪酬检查表 | G19: YFZGXCJC-1
E20: 应交税费 | F20: 应交税费明细表 | G20: YJSF-1
F21: 应交增值税明细表 | G21: YJSF-2
E22: 收入、成本 | F22: 营业收入明细表 | G22: YYSR-1
F23: 营业成本明细表 | G23: YYCB-1
F24: 毛利率分析表 | G24: MLLFX-1
E25: 费用 | F25: 销售费用明细表 | G25: XSFY-1
F26: 销售费用比例分析 | G26: XSFY-2
F27: 管理费用明细表 | G27: GLFY-1
F28: 管理费用比例分析 | G28: GLFY-2
F29: 财务费用明细表 | G29: CWFY-1

Sheet 实际执行程序表（资产负债）
A1: 序号 | B1: 科目名称 | C1: 计划实施的实质性程序 | D1: 审计结论 | E1: 财务报表认定
E2: 存在/发生 | F2: 完整性 | G2: 权利/义务 | H2: 计价 | I2: 列报
A3: 1 | B3: 货币资金 | C3: 获取或编制货币资金明细表 | H3: √
A4: 2 | B4: 货币资金 | C4: 取得被审计单位银行存款及其他货币资金的银行余额对账单，检查被审计单位提供的银行对账单是否存在涂改或修改的情况，确定银行对账单金额的正确性，并与账面余额核对，确认是否一致； | E4: √ | F4: √ | H4: √
A5: 3 | B5: 货币资金 | C5: 抽查大额库存现金收支。检查原始凭证是否齐全、记账凭证与原始凭证是否相符、账务处理是否正确、是否记录于恰当的会计期间、是否经过授权批准等项内容。 | E5: √ | H5: √
A6: 4 | B6: 货币资金 | C6: 抽查大额银行存款收支的原始凭证，检查原始凭证是否齐全、有无授权批准、记账凭证与原始凭证是否相符、账务处理是否正确、是否记录于恰当的会计期间等项内容。 检查是否存在非营业目的的大额货币资金转移，并核对相关账户的进账情况；如有与被审计单位生产经营无关的收支事项，应查明原因并作相应的记录。 | E6: √ | H6: √
A7: 5 | B7: 货币资金 | C7: 抽查大额其他货币资金收付记录。检查原始凭证是否齐全、记账凭证与原始凭证是否相符、账务处理是否正确、是否记录于恰当的会计期间等项内容。 | E7: √ | H7: √
A8: 6 | B8: 货币资金 | C8: 关注是否有质押、冻结等对变现有限制、或存放在境外、或有潜在回收风险的款项，并已恰当披露。 | I8: √
A9: 7 | B9: 库存商品 | C9: 获取或编制库存商品的明细表，复核加计是否正确，并与总账数、明细账合计数核对是否相符。 检查库存商品明细表中是否有异常或负余额（包括数量为负或金额为负）的项目 | E9: √ | F9: √ | H9: √
A10: 8 | B10: 库存商品 | C10: 如发生关联方交易：(1)了解交易的商业理由；(检查与关联方的购销业务是否正常) (2)检查证实交易的支持性文件；（例如发票、合同、协议及入库单据等相关文件，并关注交易价格、交易金额的真实性及合理性) | E10: √ | F10: √ | G10: √ | H10: √
A11: 9 | B11: 库存商品 | C11: 审阅库存商品明细账，检查有无长期挂账的库存商品，如有，应查明原因并作适当处理。 | E11: √ | H11: √
A12: 10 | B12: 固定资产 | C12: 获取或编制固定资产、累计折旧、减值准备明细表，复核加计是否正确，并与总账数和明细账合计数、报表数核对是否相符，结合累计折旧和固定资产减值准备与报表数核对是否相符。 | H12: √
A13: 11 | B13: 固定资产 | C13: 检查固定资产的所有权或控制权：(1)对外购的机器设备等固定资产，审核采购发票、采购合同等； (2)对于房地产类固定资产，查阅有关的合同、产权证明、财产税单、抵押借款的还款凭据、保险单等书面文件； (3)对汽车等运输设备，检查有关运营证件等； | G13: √
A14: 12 | B14: 固定资产 | C14: 检查累计折旧：(1)获取或编制累计折旧分类汇总表，复核加计正确，并与总账数和明细合计数核对。 (2)复核本期折旧费用的计提是否正确 (3)检查累计折旧的减少是否合理，会计处理是否正确 | H14: √
A15: 13 | B15: 无形资产 | C15: 获取或编制无形资产明细表，复核加计是否正确，并与总账数和明细账合计数核对是否相符；结合累计摊销、无形资产减值准备科目与报表数核对是否相符。 | H15: √
A16: 14 | B16: 无形资产 | C16: 检查无形资产的权属证书原件、非专利技术的持有和保密状况等，并获取有关协议和董事会纪要等文件、资料，检查无形资产的性质、构成内容、计价依据、使用状况和受益期限，确定无形资产是否存在，并由被审计单位拥有或控制。 | E16: √ | G16: √
A17: 15 | B17: 无形资产 | C17: 检查使用寿命有限的无形资产的摊销：(1)获取或编制无形资产累计摊销明细表，复核加计正确，并与总账数和明细账合计数核对相符。 (2)检查无形资产摊销政策是否符合有关规定，是否与上期一致，若改变摊销政策，检查其依据是否充分。 (3)复核本期摊销是否正确。 | H17: √
A18: 16 | B18: 应收账款 | C18: 获取或编制应收账款明细表：复核加计是否正确，并与总账数和明细账合计数核对是否相符；结合坏账准备科目与报表数核对是否相符；分析有贷方余额的项目，查明原因，必要时，作重分类调整； | H18: √
A19: 17 | B19: 应收账款 | C19: 结合其他应收款、预收账款等往来项目的明细余额，调查有无同一客户多处挂账、异常余额或与销售无关的其他款项。如有，应做出记录，必要时作调整； | H19: √
A20: 18 | B20: 应收账款 | C20: 获取或编制应收账款账龄分析表，对重要客户的主要信息进行背景调查； | H20: √
A21: 19 | B21: 应收账款 | C21: 对重大应收账款余额进行核对。 | E21: √ | G21: √ | H21: √
A22: 20 | B22: 预付账款 | C22: 获取或编制预付款项明细表：复核加计是否正确，并与总账数和明细账合计数核对是否相符，结合坏账准备科目与报表数核对是否相符；分析出现贷方余额的项目，查明原因，必要的建议进行重新分类调整； | H22: √
A23: 21 | B23: 预付账款 | C23: 结合应付账款明细账审计，查核有无重复付款情况或在收到由预付款项购买的物资时未冲减预付款项而增加应付款项的情况（即在预付款项和应付账款两个科目中同时挂账)； | H23: √
A24: 22 | B24: 预付账款 | C24: 获取或编制预付账款账龄分析表，对重要客户的主要信息进行背景调查； | H24: √
A25: 23 | B25: 预付账款 | C25: 对重大预付账款余额进行核对。 | E25: √ | G25: √ | H25: √
A26: 24 | B26: 其他应收款 | C26: 获取或编制其他应收款明细表：复核加计正确，并与总账数和明细账合计数核对是否相符，结合坏账准备科目与报表数核对是否相符；分析有贷方余额的项目，查明原因，必要时，作重分类调整； | H26: √
A27: 25 | B27: 其他应收款 | C27: 结合其他应收款、其他应付款等明细余额，检查是否有同时挂账的项目，核算内容是否重复，必要时作出适当调整； | H27: √
A28: 26 | B28: 其他应收款 | C28: 获取或编制其他应收款账龄分析表，对重要客户的主要信息进行背景调查； | H28: √
A29: 27 | B29: 其他应收款 | C29: 对重大其他应收款余额进行核对。 | E29: √ | G29: √ | H29: √
A30: 28 | B30: 应付账款 | C30: 获取或编制应付账款明细表：复核加计正确，并与报表数、总账数和明细账合计数核对是否相符；分析出现借方余额的项目，查明原因，必要时，作重分类调整； | H30: √
A31: 29 | B31: 应付账款 | C31: 结合预付账款等往来项目的明细余额，调查有无同挂的项目、异常余额或与购货无关的其他款项（如关联方账户或雇员账户），如有，应做出记录，必要时作调整； | H31: √
A32: 30 | B32: 应付账款 | C32: 获取被审计单位与其供应商之间的对账单，以及被审计单位编制的差异调节表，确定应付账款金额的正确性。 应考虑从非财务部门获取上述资料，如：采购部门。查找有无未入账的应付账款，确定是否表明存在错报。 | H32: √
A33: 31 | B33: 应付账款 | C33: 如存在应付关联方的款项：（1）了解交易的商业理由；（2）检查证实交易的支持性文件（例如发票、合同、协议及入库等相关文件）。 | H33: √
A34: 32 | B34: 应付账款 | C34: 获取或编制应付账款账龄分析表，对重要客户的主要信息进行背景调查； | H34: √
A35: 33 | B35: 应付账款 | C35: 对重大应付账款余额进行核对。 | E35: √ | G35: √ | H35: √
A36: 34 | B36: 预收账款 | C36: 获取或编制预收款项明细表：复核加计是否正确，并与报表数、总账数和明细账合计数核对是否相符；比较期初、期末预收款项余额，分析其变动原因；检查是否存在借方余额，必要时进行重分类调整； | H36: √
A37: 35 | B37: 预收账款 | C37: 结合应收账款等往来款项目的明细余额，检查是否存在应收、预收两方挂账的项目，必要时做出调整； | H37: √
A38: 36 | B38: 预收账款 | C38: 获取或编制预收款项账龄分析表，并对期末账龄在上年账龄基础上递增的合理性进行分析，并检查预收款项长期挂账的原因，并作出记录，必要时提请被审计单位予以调整。 | H38: √
A39: 37 | B39: 预收账款 | C39: 如存在预收关联方[包括持股5%以上(含5%)股东]的款项：（1）了解交易的商业理由、交易类型、交易定价政策等，形成必要记录。（2）检查证实交易的支持性文件；例如发票、合同、协议、入库单等文件 | H39: √
A40: 38 | B40: 预收账款 | C40: 获取或编制预收账款账龄分析表，对重要客户的主要信息进行背景调查； | H40: √
...

Sheet 实际执行程序表（利润）
A1: 序号 | B1: 科目名称 | C1: 计划实施的实质性程序 | D1: 审计结论 | E1: 财务报表认定
E2: 发生 | F2: 完整性 | G2: 准确性 | H2: 截止 | I2: 分类 | J2: 列报
A3: 1 | B3: 营业收入 | C3: 获取或编制主营业务收入明细表：(1)复核加计是否正确，并与总账数和明细账合计数核对是否相符，结合其他业务收入科目与报表数核对是否相符； | G3: √
A4: 2 | B4: 营业收入 | C4: (1)按收入类别或产品名称对销售数量、主营业务收入、毛利率等进行趋势分析、结构分析和价格变动分析，确定异常或应关注的领域或区间，并查明重大波动原因； | E4: √ | F4: √ | G4: √
A5: 3 | B5: 营业收入 | C5: (2)按月度对本期和上期毛利率进行比较分析，检查是否存在异常，各期之间是否存在重大波动，查明原因； | E5: √ | F5: √ | G5: √
A6: 4 | B6: 营业收入 | C6: (3)比较本期各月各类主营业务收入的波动情况，分析其变动趋势是否正常，是否符合被审计单位季节性、周期性的经营规律，查明异常现象和重大波动的原因； | E6: √ | F6: √ | G6: √
A7: 5 | B7: 营业收入 | C7: 检查收入确认会计政策及会计估计的判断是否恰当：(1)了解被审计单位的销售模式或经营模式，结合在了解被审计单位及其环境时获取的信息，并结合合同检查主营业务收入的确认条件、方法是否符合企业会计准则规定；前后期是否一致； | E7: √ | F7: √ | G7: √ | H7: √
A8: 6 | B8: 营业收入 | C8: 获取产品价格目录，抽查售价是否符合价格政策，并注意销售给关联方或关系密切的重要客户的产品价格是否合理，有无以低价或高价结算的方法，相互之间有无转移利润的现象。 | G8: √
A9: 7 | B9: 营业收入 | C9: 如发生关联方交易：检查证实交易的支持性文件（例如发票、合同、协议及入库等相关文件）。 将关联方交易的频率、规模、价格和账款结算条件，与非关联方对比，确定关联交易价格是否远远高于或低于非关联方交易价格，分析被审计单位利用关联方交易虚构业务或调节利润或利益输送的可能性。 | E9: √ | G9: √
A10: 8 | B10: 营业收入 | C10: 获取或编制其他业务收入明细表，复核加计是否正确，并与总账数和明细账合计数核对是否相符，结合主营业务收入科目与营业收入报表数核对是否相符。 | G10: √
A11: 9 | B11: 营业收入 | C11: 检查营业收入是否已按照企业会计准则的规定在财务报表中作出恰当列报。 | J11: √
A12: 10 | B12: 营业成本 | C12: 获取或编制主营业务成本明细表，复核加计是否正确，并与总账数和明细账合计数核对是否相符，结合其他业务成本科目与营业成本报表数核对是否相符。 | E12: √ | F12: √ | G12: √
A13: 11 | B13: 营业成本 | C13: 对主营业务成本进行分析：（1）将本期和上期主营业务成本按月度进行比较分析 （2）将本期和上期的主要产品单位成本进行比较分析 （3）对异常情况的项目做进一步的调查 | F13: √ | G13: √ | H13: √
A14: 12 | B14: 营业成本 | C14: 抽查月主营业务成本结转明细清单，比较计入主营业务成本的品种、规格、数量和主营业务收入的口径是否一致，是否符合配比原则。 | E14: √ | F14: √
A15: 13 | B15: 营业成本 | C15: 检查营业成本是否已按照企业会计准则的规定在财务报表中作出恰当列报。 | J15: √
A16: 14 | B16: 销售费用 | C16: 获取或编制销售费用明细表： (1)复核其加计数是否正确，并与报表数、总账数和明细账合计数核对是否相符； (2)将销售费用中的工资、折旧等与相关的资产、负债科目核对，检查其勾稽关系的合理性。
A17: 15 | B17: 销售费用 | C17: 对销售费用进行分析：(1)计算分析各个月份销售费用总额及主要项目金额占主营业务收入的比率，并与上一年度进行比较，判断变动的合理性；(2)计算分析各个月份销售费用中主要项目发生额及占销售费用总额的比率，并与上一年度进行比较，判断其变动的合理性。
A18: 16 | B18: 销售费用 | C18: 对本期发生的销售费用，选取样本，检查其支付性文件，确定原始凭证是否齐全，记账凭证与原始凭证是否相符以及账务处理是否正确。
A19: 17 | B19: 销售费用 | C19: （1）检查销售佣金支出是否符合规定，审批手续是否健全，是否取得有效的原始凭证；如超过规定，是否按规定进行了纳税调整。
A20: 18 | B20: 销售费用 | C20: （2）检查广告费、宣传费、业务招待费的支出是否合理，审批手续是否健全，是否取得有效的原始凭证；如超过规定限额，应在计算应纳税所得额时调整。
A21: 19 | B21: 销售费用 | C21: （3）选择重要或异常的销售费用，检查销售费用各项目开支标准是否符合有关规定，开支内容是否与被审计单位的产品销售或专设销售机构的经费有关，计算是否正确，原始凭证是否合法，会计处理是否正确。
A22: 20 | B22: 销售费用 | C22: 检查销售费用是否已按照企业会计准则在财务报表中作出恰当的列报和披露。
A23: 21 | B23: 管理费用 | C23: 获取或编制管理费用明细表：(1)复核加计是否正确，并与报表数、总账数及明细账合计数核对是否相符。(2)将管理费用中的职工薪酬、无形资产摊销、长期待摊费用摊销额等项目与各有关账户进行核对，分析其勾稽关系的合理性，并作出相应记录。 | G23: √
A24: 22 | B24: 管理费用 | C24: 对管理费用进行分析，并汇总并评价差异结果：(1)计算分析管理费用中各项目发生额及占费用总额的比率，将本期、上期管理费用各主要明细项目作比较分析，判断其变动的合理性。(2)比较本期各月份管理费用，对有重大波动和异常情况的项目应查明原因，必要时作适当处理。 | E24: √ | F24: √ | G24: √
A25: 23 | B25: 管理费用 | C25: 对本期发生的管理费用，选取样本，检查其支付性文件，确定原始凭证是否齐全，记账凭证与原始凭证是否相符以及账务处理是否正确。 | E25: √ | G25: √ | H25: √ | I25: √
A26: 24 | B26: 管理费用 | C26: (1)检查公司经费(包括行政管理部门职工薪酬、物料消耗、低值易耗品摊销、办公费和差旅费)是否系经营管理中发生或应由公司统一负担，检查相关费用报销内部管理办法，是否有合法原始凭证支持。 | E26: √ | G26: √ | H26: √ | I26: √
A27: 25 | B27: 管理费用 | C27: (2)检查董事会费(包括董事会成员津贴、会议费和差旅费等)，检查相关董事会及股东会决议，是否在合规范围内开支费用。 | E27: √ | G27: √ | H27: √ | I27: √
A28: 26 | B28: 管理费用 | C28: (3)检查聘请中介机构费、咨询费(含顾问费)，检查是否按合同规定支付费用，有无涉及到诉讼及赔偿款项支出。 | E28: √ | G28: √ | H28: √ | I28: √
A29: 27 | B29: 管理费用 | C29: (4)检查业务招待费的支出是否合理，如超过规定限额，应在计算应纳税所得额时调整。 | E29: √ | G29: √ | H29: √ | I29: √
A30: 28 | B30: 管理费用 | C30: 检查诉讼费用并结合或有事项审计,检查涉及的相关重大诉讼事项是否已在附注中进行披露，还需进一步关注诉讼状态，判断有无或有负债，或是否存在损失已发生而未入账的事项。如发生诉讼和索赔费用，完成“诉讼和索赔事项”工作底稿。 | E30: √ | F30: √ | G30: √
A31: 29 | B31: 管理费用 | C31: 根据评估的舞弊风险等因素增加的其他审计程序。（1）检查大额或异常费用开支的适当性 （2）检查高层管理人员提交的费用报告的适当性和金额 | E31: √ | F31: √ | G31: √
A32: 30 | B32: 管理费用 | C32: 确定管理费用是否已按照企业会计准则的规定在财务报表中作出恰当的列报和披露。 | J32: √
A33: 31 | B33: 财务费用 | C33: 获取或编制财务费用明细表，复核其加计数是否正确，并与报表数、总账数和明细账合计数核对是否相符。 | G33: √
A34: 32 | B34: 财务费用 | C34: 将本期财务费用各明细项目与上期进行对比，必要时比较本期各月份财务费用，如有重大波动和异常情况应追查原因； | E34: √ | F34: √ | G34: √
A35: 33 | B35: 财务费用 | C35: 检查财务费用明细项目的设置是否符合规定的核算内容与范围，是否划清财务费用与其他费用的界限。 | J35: √
A36: 34 | B36: 财务费用 | C36: 检查财务费用是否已按照企业会计准则的规定在财务报表中作出恰当的列报。 | J36: √

Sheet 细节测试汇总
A1: 细节测试汇总表
A2: =备忘录!$A$1 -> 被审计单位：福禄福擎网络科技有限公司 | F2: 编制人：刘喜琴 | K2: =备忘录!$C$2 -> 日期：2025/10/30
A3: =备忘录!$A$2 -> 财务报表截止日：2025/9/30 | F3: 复核人：赵玮 | K3: =备忘录!$C$3 -> 日期：2025/10/31
A4: 序号 | B4: 记账日期 | C4: 凭证号 | D4: 摘要 | E4: 科目名称 | F4: 借方 | G4: 贷方 | H4: 对账单数据 | I4: 差异 | J4: 附件及支持性文件说明 | K4: 备注
A6: 1
A7: 2
A8: 3
A9: 4
A10: 5
A11: 6
A12: 7
A13: 8
A14: 9
A15: 10
A16: 11
A17: 12
... A30: 25
A31: 测试金额小计 | G31: =SUM(G6:G30) -> 0 | H31: =SUM(H6:H30) -> 0 | I31: =SUM(I6:I30) -> 0
A36: 备注：抽样明细内容来自序时账

Sheet 货币资金
A1: 货币资金明细表
A2: =备忘录!$A$1 -> 被审计单位：福禄福擎网络科技有限公司 | E2: 编制人：刘喜琴 | H2: =备忘录!$C$2 -> 日期：2025/10/30
A3: =备忘录!$A$2 -> 财务报表截止日：2025/9/30 | E3: 复核人：赵玮 | H3: =备忘录!$C$3 -> 日期：2025/10/31
A4: 序号 | B4: 科目名称 | C4: 核算项目 | D4: 账面数据 | H4: 银行对账单金额 | I4: 差异 | J4: 账户性质 | K4: 备注
D5: 期初金额 | E5: 本期借方 | F5: 本期贷方 | G5: 期末金额
A6: 库存现金 | D6: =ROUND(SUM(D7),2) -> 0 | E6: =ROUND(SUM(E7),2) -> 0 | F6: =ROUND(SUM(F7),2) -> 0 | G6: =ROUND(SUM(G7),2) -> 0 | H6: =ROUND(SUM(H7),2) -> 0
A7: 1 | G7: =ROUND(D7+E7-F7,2) -> 0 | I7: =ROUND(G7-H7,2) -> 0
A8: 银行存款_活期存款 | D8: =ROUND(SUM(D9:D17),2) -> 0 | E8: =ROUND(SUM(E9:E17),2) -> 0 | F8: =ROUND(SUM(F9:F17),2) -> 0 | G8: =ROUND(SUM(G9:G17),2) -> 0 | H8: =ROUND(SUM(H9:H17),2) -> 0 | I8: =ROUND(SUM(I9:I17),2) -> 0
A9: 1 | G9: =ROUND(D9+E9-F9,2) -> 0 | I9: =ROUND(G9-H9,2) -> 0
A10: 2 | G10: =ROUND(D10+E10-F10,2) -> 0 | I10: =ROUND(G10-H10,2) -> 0
A11: 3 | G11: =ROUND(D11+E11-F11,2) -> 0 | I11: =ROUND(G11-H11,2) -> 0
A12: 4 | G12: =ROUND(D12+E12-F12,2) -> 0 | I12: =ROUND(G12-H12,2) -> 0
A13: 5 | G13: =ROUND(D13+E13-F13,2) -> 0 | I13: =ROUND(G13-H13,2) -> 0
A14: 6 | G14: =ROUND(D14+E14-F14,2) -> 0 | I14: =ROUND(G14-H14,2) -> 0
A15: 7 | G15: =ROUND(D15+E15-F15,2) -> 0 | I15: =ROUND(G15-H15,2) -> 0
A16: 8 | G16: =ROUND(D16+E16-F16,2) -> 0 | I16: =ROUND(G16-H16,2) -> 0
A17: 9 | G17: =ROUND(D17+E17-F17,2) -> 0 | I17: =ROUND(G17-H17,2) -> 0
A18: 其他货币资金 | D18: =ROUND(SUM(D19:D30),2) -> 0 | E18: =ROUND(SUM(E19:E30),2) -> 0 | F18: =ROUND(SUM(F19:F30),2) -> 0 | G18: =ROUND(SUM(G19:G30),2) -> 0 | H18: =ROUND(SUM(H19:H30),2) -> 0 | I18: =ROUND(SUM(I19:I30),2) -> 0
A19: 1 | G19: =ROUND(D19+E19-F19,2) -> 0 | I19: =ROUND(G19-H19,2) -> 0
A20: 2 | G20: =ROUND(D20+E20-F20,2) -> 0 | I20: =ROUND(G20-H20,2) -> 0
A21: 3 | G21: =ROUND(D21+E21-F21,2) -> 0 | I21: =ROUND(G21-H21,2) -> 0
A22: 4 | G22: =ROUND(D22+E22-F22,2) -> 0 | I22: =ROUND(G22-H22,2) -> 0
A23: 5 | G23: =ROUND(D23+E23-F23,2) -> 0 | I23: =ROUND(G23-H23,2) -> 0
A24: 6 | G24: =ROUND(D24+E24-F24,2) -> 0 | I24: =ROUND(G24-H24,2) -> 0
A25: 7 | G25: =ROUND(D25+E25-F25,2) -> 0 | I25: =ROUND(G25-H25,2) -> 0
A26: 8 | G26: =ROUND(D26+E26-F26,2) -> 0 | I26: =ROUND(G26-H26,2) -> 0
A27: 9 | G27: =ROUND(D27+E27-F27,2) -> 0 | I27: =ROUND(G27-H27,2) -> 0
A28: 10 | G28: =ROUND(D28+E28-F28,2) -> 0 | I28: =ROUND(G28-H28,2) -> 0
A29: 11 | G29: =ROUND(D29+E29-F29,2) -> 0 | I29: =ROUND(G29-H29,2) -> 0
A30: 12 | G30: =ROUND(D30+E30-F30,2) -> 0 | I30: =ROUND(G30-H30,2) -> 0
A31: 合计 | D31: =ROUND(D6+D8+D18,2) -> 0 | E31: =ROUND(E6+E8+E18,2) -> 0 | F31: =ROUND(F6+F8+F18,2) -> 0 | G31: =ROUND(G6+G8+G18,2) -> 0 | H31: =ROUND(H6+H8+H18,2) -> 0 | I31: =ROUND(I6+I8+I18,2) -> 0
B33: 审计说明：

Sheet 流水分析-银行1
A1: 对账单流水与银行日记账流水月度核对分析
A2: =备忘录!$A$1 -> 被审计单位：福禄福擎网络科技有限公司 | E2: 编制人：刘喜琴 | H2: =备忘录!$C$2 -> 日期：2025/10/30
A3: =备忘录!$A$2 -> 财务报表截止日：2025/9/30 | E3: 复核人：赵玮 | H3: =备忘录!$C$3 -> 日期：2025/10/31
A4: 开户行 | D4: 账号
A5: 项目 | B5: 银行对账单 | F5: 银行日记账 | J5: 核对差异
B6: 月初金额 | C6: 借方发生额 本月汇总 | D6: 贷方发生额 本月汇总 | E6: 月末金额 | F6: 月初金额 | G6: 借方发生额 | H6: 贷方发生额 | I6: 月末金额 | J6: 借方发生额 | K6: 贷方发生额 | L6: 差异分析
A7: 1月 | E7: =ROUND(B7+C7-D7,2) -> 0 | I7: =ROUND(F7+G7-H7,2) -> 0 | J7: =C7-G7 -> 0 | K7: =D7-H7 -> 0
A8: 2月 | B8: =E7 -> 0 | E8: =ROUND(B8+C8-D8,2) -> 0 | F8: =I7 -> 0 | I8: =ROUND(F8+G8-H8,2) -> 0 | J8: =C8-G8 -> 0 | K8: =D8-H8 -> 0
A9: 3月 | B9: =E8 -> 0 | E9: =ROUND(B9+C9-D9,2) -> 0 | F9: =I8 -> 0 | I9: =ROUND(F9+G9-H9,2) -> 0 | J9: =C9-G9 -> 0 | K9: =D9-H9 -> 0
A10: 4月 | B10: =E9 -> 0 | E10: =ROUND(B10+C10-D10,2) -> 0 | F10: =I9 -> 0 | I10: =ROUND(F10+G10-H10,2) -> 0 | J10: =C10-G10 -> 0 | K10: =D10-H10 -> 0
A11: 5月 | B11: =E10 -> 0 | E11: =ROUND(B11+C11-D11,2) -> 0 | F11: =I10 -> 0 | I11: =ROUND(F11+G11-H11,2) -> 0 | J11: =C11-G11 -> 0 | K11: =D11-H11 -> 0
A12: 6月 | B12: =E11 -> 0 | E12: =ROUND(B12+C12-D12,2) -> 0 | F12: =I11 -> 0 | I12: =ROUND(F12+G12-H12,2) -> 0 | J12: =C12-G12 -> 0 | K12: =D12-H12 -> 0
A13: 7月 | B13: =E12 -> 0 | E13: =ROUND(B13+C13-D13,2) -> 0 | F13: =I12 -> 0 | I13: =ROUND(F13+G13-H13,2) -> 0 | J13: =C13-G13 -> 0 | K13: =D13-H13 -> 0
A14: 8月 | B14: =E13 -> 0 | E14: =ROUND(B14+C14-D14,2) -> 0 | F14: =I13 -> 0 | I14: =ROUND(F14+G14-H14,2) -> 0 | J14: =C14-G14 -> 0 | K14: =D14-H14 -> 0
A15: 9月 | B15: =E14 -> 0 | E15: =ROUND(B15+C15-D15,2) -> 0 | F15: =I14 -> 0 | I15: =ROUND(F15+G15-H15,2) -> 0 | J15: =C15-G15 -> 0 | K15: =D15-H15 -> 0
A16: 10月 | B16: =E15 -> 0 | E16: =ROUND(B16+C16-D16,2) -> 0 | F16: =I15 -> 0 | I16: =ROUND(F16+G16-H16,2) -> 0 | J16: =C16-G16 -> 0 | K16: =D16-H16 -> 0
A17: 11月 | B17: =E16 -> 0 | E17: =ROUND(B17+C17-D17,2) -> 0 | F17: =I16 -> 0 | I17: =ROUND(F17+G17-H17,2) -> 0 | J17: =C17-G17 -> 0 | K17: =D17-H17 -> 0
A18: 12月 | B18: =E17 -> 0 | E18: =ROUND(B18+C18-D18,2) -> 0 | F18: =I17 -> 0 | I18: =ROUND(F18+G18-H18,2) -> 0 | J18: =C18-G18 -> 0 | K18: =D18-H18 -> 0
A19: 合计 | B19: =B7 -> 0 | C19: =SUM(C7:C18) -> 0 | D19: =SUM(D7:D18) -> 0 | E19: =ROUND(B19+C19-D19,2) -> 0 | F19: =F7 -> 0 | G19: =SUM(G7:G18) -> 0 | H19: =SUM(H7:H18) -> 0 | I19: =ROUND(F19+G19-H19,2) -> 0 | J19: =SUM(J7:J18) -> 0 | K19: =SUM(K7:K18) -> 0
A20: 核对差异 | G20: =C19-G19 -> 0 | H20: =D19-H19 -> 0

Sheet 流水分析-银行2
A1: 对账单流水与银行日记账流水月度核对分析
A2: =备忘录!$A$1 -> 被审计单位：福禄福擎网络科技有限公司 | E2: 编制人：刘喜琴 | H2: =备忘录!$C$2 -> 日期：2025/10/30
A3: =备忘录!$A$2 -> 财务报表截止日：2025/9/30 | E3: 复核人：赵玮 | H3: =备忘录!$C$3 -> 日期：2025/10/31
A4: 开户行 | D4: 账号
A5: 项目 | B5: 银行对账单 | F5: 银行日记账 | J5: 核对差异
B6: 月初金额 | C6: 借方发生额 本月汇总 | D6: 贷方发生额 本月汇总 | E6: 月末金额 | F6: 月初金额 | G6: 借方发生额 | H6: 贷方发生额 | I6: 月末金额 | J6: 借方发生额 | K6: 贷方发生额 | L6: 差异分析
A7: 1月 | E7: =ROUND(B7+C7-D7,2) -> 0 | I7: =ROUND(F7+G7-H7,2) -> 0 | J7: =C7-G7 -> 0 | K7: =D7-H7 -> 0
A8: 2月 | B8: =E7 -> 0 | E8: =ROUND(B8+C8-D8,2) -> 0 | F8: =I7 -> 0 | I8: =ROUND(F8+G8-H8,2) -> 0 | J8: =C8-G8 -> 0 | K8: =D8-H8 -> 0
A9: 3月 | B9: =E8 -> 0 | E9: =ROUND(B9+C9-D9,2) -> 0 | F9: =I8 -> 0 | I9: =ROUND(F9+G9-H9,2) -> 0 | J9: =C9-G9 -> 0 | K9: =D9-H9 -> 0
A10: 4月 | B10: =E9 -> 0 | E10: =ROUND(B10+C10-D10,2) -> 0 | F10: =I9 -> 0 | I10: =ROUND(F10+G10-H10,2) -> 0 | J10: =C10-G10 -> 0 | K10: =D10-H10 -> 0
A11: 5月 | B11: =E10 -> 0 | E11: =ROUND(B11+C11-D11,2) -> 0 | F11: =I10 -> 0 | I11: =ROUND(F11+G11-H11,2) -> 0 | J11: =C11-G11 -> 0 | K11: =D11-H11 -> 0
A12: 6月 | B12: =E11 -> 0 | E12: =ROUND(B12+C12-D12,2) -> 0 | F12: =I11 -> 0 | I12: =ROUND(F12+G12-H12,2) -> 0 | J12: =C12-G12 -> 0 | K12: =D12-H12 -> 0
A13: 7月 | B13: =E12 -> 0 | E13: =ROUND(B13+C13-D13,2) -> 0 | F13: =I12 -> 0 | I13: =ROUND(F13+G13-H13,2) -> 0 | J13: =C13-G13 -> 0 | K13: =D13-H13 -> 0
A14: 8月 | B14: =E13 -> 0 | E14: =ROUND(B14+C14-D14,2) -> 0 | F14: =I13 -> 0 | I14: =ROUND(F14+G14-H14,2) -> 0 | J14: =C14-G14 -> 0 | K14: =D14-H14 -> 0
A15: 9月 | B15: =E14 -> 0 | E15: =ROUND(B15+C15-D15,2) -> 0 | F15: =I14 -> 0 | I15: =ROUND(F15+G15-H15,2) -> 0 | J15: =C15-G15 -> 0 | K15: =D15-H15 -> 0
A16: 10月 | B16: =E15 -> 0 | E16: =ROUND(B16+C16-D16,2) -> 0 | F16: =I15 -> 0 | I16: =ROUND(F16+G16-H16,2) -> 0 | J16: =C16-G16 -> 0 | K16: =D16-H16 -> 0
A17: 11月 | B17: =E16 -> 0 | E17: =ROUND(B17+C17-D17,2) -> 0 | F17: =I16 -> 0 | I17: =ROUND(F17+G17-H17,2) -> 0 | J17: =C17-G17 -> 0 | K17: =D17-H17 -> 0
A18: 12月 | B18: =E17 -> 0 | E18: =ROUND(B18+C18-D18,2) -> 0 | F18: =I17 -> 0 | I18: =ROUND(F18+G18-H18,2) -> 0 | J18: =C18-G18 -> 0 | K18: =D18-H18 -> 0
A19: 合计 | B19: =B7 -> 0 | C19: =SUM(C7:C18) -> 0 | D19: =SUM(D7:D18) -> 0 | E19: =ROUND(B19+C19-D19,2) -> 0 | F19: =F7 -> 0 | G19: =SUM(G7:G18) -> 0 | H19: =SUM(H7:H18) -> 0 | I19: =ROUND(F19+G19-H19,2) -> 0 | J19: =SUM(J7:J18) -> 0 | K19: =SUM(K7:K18) -> 0
A20: 核对差异 | G20: =C19-G19 -> 0 | H20: =D19-H19 -> 0

Sheet 流水分析-银行3
A1: 对账单流水与银行日记账流水月度核对分析
A2: =备忘录!$A$1 -> 被审计单位：福禄福擎网络科技有限公司 | E2: 编制人：刘喜琴 | H2: =备忘录!$C$2 -> 日期：2025/10/30
A3: =备忘录!$A$2 -> 财务报表截止日：2025/9/30 | E3: 复核人：赵玮 | H3: =备忘录!$C$3 -> 日期：2025/10/31
A4: 开户行 | D4: 账号
A5: 项目 | B5: 银行对账单 | F5: 银行日记账 | J5: 核对差异
B6: 月初金额 | C6: 借方发生额 本月汇总 | D6: 贷方发生额 本月汇总 | E6: 月末金额 | F6: 月初金额 | G6: 借方发生额 | H6: 贷方发生额 | I6: 月末金额 | J6: 借方发生额 | K6: 贷方发生额 | L6: 差异分析
A7: 1月 | E7: =ROUND(B7+C7-D7,2) -> 0 | I7: =ROUND(F7+G7-H7,2) -> 0 | J7: =C7-G7 -> 0 | K7: =D7-H7 -> 0
A8: 2月 | B8: =E7 -> 0 | E8: =ROUND(B8+C8-D8,2) -> 0 | F8: =I7 -> 0 | I8: =ROUND(F8+G8-H8,2) -> 0 | J8: =C8-G8 -> 0 | K8: =D8-H8 -> 0
A9: 3月 | B9: =E8 -> 0 | E9: =ROUND(B9+C9-D9,2) -> 0 | F9: =I8 -> 0 | I9: =ROUND(F9+G9-H9,2) -> 0 | J9: =C9-G9 -> 0 | K9: =D9-H9 -> 0
A10: 4月 | B10: =E9 -> 0 | E10: =ROUND(B10+C10-D10,2) -> 0 | F10: =I9 -> 0 | I10: =ROUND(F10+G10-H10,2) -> 0 | J10: =C10-G10 -> 0 | K10: =D10-H10 -> 0
A11: 5月 | B11: =E10 -> 0 | E11: =ROUND(B11+C11-D11,2) -> 0 | F11: =I10 -> 0 | I11: =ROUND(F11+G11-H11,2) -> 0 | J11: =C11-G11 -> 0 | K11: =D11-H11 -> 0
A12: 6月 | B12: =E11 -> 0 | E12: =ROUND(B12+C12-D12,2) -> 0 | F12: =I11 -> 0 | I12: =ROUND(F12+G12-H12,2) -> 0 | J12: =C12-G12 -> 0 | K12: =D12-H12 -> 0
A13: 7月 | B13: =E12 -> 0 | E13: =ROUND(B13+C13-D13,2) -> 0 | F13: =I12 -> 0 | I13: =ROUND(F13+G13-H13,2) -> 0 | J13: =C13-G13 -> 0 | K13: =D13-H13 -> 0
A14: 8月 | B14: =E13 -> 0 | E14: =ROUND(B14+C14-D14,2) -> 0 | F14: =I13 -> 0 | I14: =ROUND(F14+G14-H14,2) -> 0 | J14: =C14-G14 -> 0 | K14: =D14-H14 -> 0
A15: 9月 | B15: =E14 -> 0 | E15: =ROUND(B15+C15-D15,2) -> 0 | F15: =I14 -> 0 | I15: =ROUND(F15+G15-H15,2) -> 0 | J15: =C15-G15 -> 0 | K15: =D15-H15 -> 0
A16: 10月 | B16: =E15 -> 0 | E16: =ROUND(B16+C16-D16,2) -> 0 | F16: =I15 -> 0 | I16: =ROUND(F16+G16-H16,2) -> 0 | J16: =C16-G16 -> 0 | K16: =D16-H16 -> 0
A17: 11月 | B17: =E16 -> 0 | E17: =ROUND(B17+C17-D17,2) -> 0 | F17: =I16 -> 0 | I17: =ROUND(F17+G17-H17,2) -> 0 | J17: =C17-G17 -> 0 | K17: =D17-H17 -> 0
A18: 12月 | B18: =E17 -> 0 | E18: =ROUND(B18+C18-D18,2) -> 0 | F18: =I17 -> 0 | I18: =ROUND(F18+G18-H18,2) -> 0 | J18: =C18-G18 -> 0 | K18: =D18-H18 -> 0
A19: 合计 | B19: =B7 -> 0 | C19: =SUM(C7:C18) -> 0 | D19: =SUM(D7:D18) -> 0 | E19: =ROUND(B19+C19-D19,2) -> 0 | F19: =F7 -> 0 | G19: =SUM(G7:G18) -> 0 | H19: =SUM(H7:H18) -> 0 | I19: =ROUND(F19+G19-H19,2) -> 0 | J19: =SUM(J7:J18) -> 0 | K19: =SUM(K7:K18) -> 0
A20: 核对差异 | G20: =C19-G19 -> 0 | H20: =D19-H19 -> 0

Sheet 开户清单核对
A1: 银行账户清单与已开立银行结算账户清单核对
A2: =备忘录!$A$1 -> 被审计单位：福禄福擎网络科技有限公司 | E2: 编制人：刘喜琴 | H2: =备忘录!$C$2 -> 日期：2025/10/30
A3: =备忘录!$A$2 -> 财务报表截止日：2025/9/30 | E3: 复核人：赵玮 | H3: =备忘录!$C$3 -> 日期：2025/10/31
A4: 序号 | B4: 企业提供的银行账户实际信息 | G4: 与已开立银行结算账户清单核对 | M4: 是否由被审计单位实际使用 | N4: 备注
B5: 开户银行 | C5: 银行账号 | D5: 币种 | E5: 账户性质 | F5: 账户状态 | G5: 开户银行是否相符 | H5: 银行账号是否相符 | I5: 账户性质是否相符 | J5: 账户状态是否相符 | K5: 销户日期 | L5: 久悬日期
A6: 一、银行存款账户
A7: 1 | B7: =货币资金!B9 -> 0 | C7: =货币资金!C9 -> 0
A8: 2 | B8: =货币资金!B10 -> 0 | C8: =货币资金!C10 -> 0
A9: 3 | B9: =货币资金!B11 -> 0 | C9: =货币资金!C11 -> 0
A10: 4 | B10: =货币资金!B12 -> 0 | C10: =货币资金!C12 -> 0
A11: 5 | B11: =货币资金!B13 -> 0 | C11: =货币资金!C13 -> 0
A12: 6 | B12: =货币资金!B14 -> 0 | C12: =货币资金!C14 -> 0
A13: 7 | B13: =货币资金!B15 -> 0 | C13: =货币资金!C15 -> 0
A14: 8 | B14: =货币资金!B16 -> 0 | C14: =货币资金!C16 -> 0
A15: 9 | B15: =货币资金!B17 -> 0 | C15: =货币资金!C17 -> 0
A16: 二、其他货币资金账户
A17: 1 | B17: =货币资金!B19 -> 0 | C17: =货币资金!C19 -> 0
A18: 2 | B18: =货币资金!B20 -> 0 | C18: =货币资金!C20 -> 0
A19: 3 | B19: =货币资金!B21 -> 0 | C19: =货币资金!C21 -> 0
A20: 4 | B20: =货币资金!B22 -> 0 | C20: =货币资金!C22 -> 0
A21: 5 | B21: =货币资金!B23 -> 0 | C21: =货币资金!C23 -> 0
A22: 6 | B22: =货币资金!B24 -> 0 | C22: =货币资金!C24 -> 0
A23: 7 | B23: =货币资金!B25 -> 0 | C23: =货币资金!C25 -> 0
A24: 8 | B24: =货币资金!B26 -> 0 | C24: =货币资金!C26 -> 0
A25: 9 | B25: =货币资金!B27 -> 0 | C25: =货币资金!C27 -> 0
A26: 10 | B26: =货币资金!B28 -> 0 | C26: =货币资金!C28 -> 0
A27: 11 | B27: =货币资金!B29 -> 0 | C27: =货币资金!C29 -> 0
A28: 12 | B28: =货币资金!B30 -> 0 | C28: =货币资金!C30 -> 0
A30: 审计说明：
A31: 1、被审计单位未提供但开户信息上存在的银行账户情况：
A32: 序号 | B32: 开户银行 | C32: 银行账号 | D32: 币种 | E32: 账户性质 | F32: 账户状态 | G32: 处理意见及依据
A33: 1
A35: 2、被审计单位账户清单上存在但开户信息上不存在的银行账户情况：
A38: 3、开户银行截图：

Sheet 库存商品
A1: 库存商品明细表
A2: =备忘录!$A$1 -> 被审计单位：福禄福擎网络科技有限公司 | F2: 编制人：刘喜琴 | I2: =备忘录!$C$2 -> 日期：2025/10/30
A3: =备忘录!$A$2 -> 财务报表截止日：2025/9/30 | F3: 复核人：赵玮 | I3: =备忘录!$C$3 -> 日期：2025/10/31
A4: 序号 | B4: 科目名称 | C4: 核算项目1 | D4: 核算项目2 | E4: 账面数据 | K4: 审计调整 | L4: 期末审定数 | M4: 备注
E5: 期初金额 | F5: 本期借方 | G5: 本期贷方 | H5: 期末金额 | I5: 企业调整 | J5: 期末报表列报
A6: 一、外购库存商品
A7: 1 | B7: 库存商品_直充 | H7: =E7+F7-G7 -> 0 | J7: =H7+I7 -> 0 | L7: =J7+K7 -> 0
A8: 2 | B8: 库存商品_卡密 | H8: =E8+F8-G8 -> 0 | J8: =H8+I8 -> 0 | L8: =J8+K8 -> 0
A9: 3 | H9: =E9+F9-G9 -> 0 | J9: =H9+I9 -> 0 | L9: =J9+K9 -> 0
A10: 4 | H10: =E10+F10-G10 -> 0 | J10: =H10+I10 -> 0 | L10: =J10+K10 -> 0
A11: 5 | H11: =E11+F11-G11 -> 0 | J11: =H11+I11 -> 0 | L11: =J11+K11 -> 0
A12: 6 | H12: =E12+F12-G12 -> 0 | J12: =H12+I12 -> 0 | L12: =J12+K12 -> 0
A13: 7 | H13: =E13+F13-G13 -> 0 | J13: =H13+I13 -> 0 | L13: =J13+K13 -> 0
A14: 8 | H14: =E14+F14-G14 -> 0 | J14: =H14+I14 -> 0 | L14: =J14+K14 -> 0
A15: 9 | H15: =E15+F15-G15 -> 0 | J15: =H15+I15 -> 0 | L15: =J15+K15 -> 0
A16: 10 | H16: =E16+F16-G16 -> 0 | J16: =H16+I16 -> 0 | L16: =J16+K16 -> 0
A17: 11 | H17: =E17+F17-G17 -> 0 | J17: =H17+I17 -> 0 | L17: =J17+K17 -> 0
A18: 12 | H18: =E18+F18-G18 -> 0 | J18: =H18+I18 -> 0 | L18: =J18+K18 -> 0
A19: 13 | H19: =E19+F19-G19 -> 0 | J19: =H19+I19 -> 0 | L19: =J19+K19 -> 0
A20: 14 | H20: =E20+F20-G20 -> 0 | J20: =H20+I20 -> 0 | L20: =J20+K20 -> 0
A21: 15 | H21: =E21+F21-G21 -> 0 | J21: =H21+I21 -> 0 | L21: =J21+K21 -> 0
A22: 小计 | E22: =SUM(E7:E21) -> 0 | F22: =SUM(F7:F21) -> 0 | G22: =SUM(G7:G21) -> 0 | H22: =SUM(H7:H21) -> 0 | I22: =SUM(I7:I21) -> 0 | J22: =SUM(J7:J21) -> 0 | K22: =SUM(K7:K21) -> 0 | L22: =SUM(L7:L21) -> 0
B24: 审计说明：

Sheet 库存商品分析表
A1: 库存商品月发生额分析表
A2: =备忘录!$A$1 -> 被审计单位：福禄福擎网络科技有限公司 | E2: 编制人：刘喜琴 | H2: =备忘录!$C$2 -> 日期：2025/10/30
A3: =备忘录!$A$2 -> 财务报表截止日：2025/9/30 | E3: 复核人：赵玮 | H3: =备忘录!$C$3 -> 日期：2025/10/31
A4: 月份 | B4: 借方发生额合计 | E4: 贷方发生额 | I4: 期末余额
B5: 完工产品转入 | C5: 外购库存商品 | D5: 借方合计 | E5: 转入主营成本 | F5: 转入发出商品 | G5: 转入应收退货成本 | H5: 贷方小计
A6: 期初余额
A7: 1月 | D7: =SUM(B7:C7) -> 0 | H7: =SUM(E7:G7) -> 0 | I7: =I6+D7-H7 -> 0
A8: 2月 | D8: =SUM(B8:C8) -> 0 | H8: =SUM(E8:G8) -> 0 | I8: =I7+D8-H8 -> 0
A9: 3月 | D9: =SUM(B9:C9) -> 0 | H9: =SUM(E9:G9) -> 0 | I9: =I8+D9-H9 -> 0
A10: 4月 | D10: =SUM(B10:C10) -> 0 | H10: =SUM(E10:G10) -> 0 | I10: =I9+D10-H10 -> 0
A11: 5月 | D11: =SUM(B11:C11) -> 0 | H11: =SUM(E11:G11) -> 0 | I11: =I10+D11-H11 -> 0
A12: 6月 | D12: =SUM(B12:C12) -> 0 | H12: =SUM(E12:G12) -> 0 | I12: =I11+D12-H12 -> 0
A13: 7月 | D13: =SUM(B13:C13) -> 0 | H13: =SUM(E13:G13) -> 0 | I13: =I12+D13-H13 -> 0
A14: 8月 | D14: =SUM(B14:C14) -> 0 | H14: =SUM(E14:G14) -> 0 | I14: =I13+D14-H14 -> 0
A15: 9月 | D15: =SUM(B15:C15) -> 0 | H15: =SUM(E15:G15) -> 0 | I15: =I14+D15-H15 -> 0
A16: 10月 | D16: =SUM(B16:C16) -> 0 | H16: =SUM(E16:G16) -> 0 | I16: =I15+D16-H16 -> 0
A17: 11月 | D17: =SUM(B17:C17) -> 0 | H17: =SUM(E17:G17) -> 0 | I17: =I16+D17-H17 -> 0
A18: 12月 | D18: =SUM(B18:C18) -> 0 | H18: =SUM(E18:G18) -> 0 | I18: =I17+D18-H18 -> 0
A19: 合计 | B19: =SUM(B7:B18) -> 0 | C19: =SUM(C7:C18) -> 0 | D19: =SUM(D7:D18) -> 0 | E19: =SUM(E7:E18) -> 0 | F19: =SUM(F7:F18) -> 0 | G19: =SUM(G7:G18) -> 0 | H19: =SUM(H7:H18) -> 0
B21: 审计说明：

Sheet 固定资产
A1: 固定资产、累计折旧、减值准备明细表
A2: =备忘录!$A$1 -> 被审计单位：福禄福擎网络科技有限公司 | M2: 编制人：刘喜琴 | V2: =备忘录!$C$2 -> 日期：2025/10/30
A3: =备忘录!$A$2 -> 财务报表截止日：2025/9/30 | M3: 复核人：赵玮 | V3: =备忘录!$C$3 -> 日期：2025/10/31
A4: 序号 | B4: 资产名称 | C4: 资产类别 | D4: 取得时间 | E4: 使用年限 | F4: 到期日 | G4: 计量单位 | H4: 期末 数量 | I4: 原值 | M4: 累计折旧 | Q4: 减值准备 | U4: 原值调整 | W4: 累计折旧调整 | Y4: 减值准备调整 | AA4: 审定数 | AE4: 使用状态
I5: 期初原值 | J5: 本期增加 | K5: 本期减少 | L5: 期末原值 | M5: 期初累计折旧 | N5: 本期增加 | O5: 本期减少 | P5: 期末累计折旧 | Q5: 期初减值准备 | R5: 本期增加 | S5: 本期减少 | T5: 期末减值准备 | U5: 本期增加 | V5: 本期减少 | W5: 本期增加 | X5: 本期减少 | Y5: 本期增加 | Z5: 本期减少 | AA5: 原值 | AB5: 累计折旧 | AC5: 减值准备 | AD5: 净值
A6: 1 | F6: =IF(D6="",0,IF(DAY(D6)=1,IF(D6=0,0,DATE(YEAR(D6),MONTH(D6)+E6*12,DAY(D6))),IF(D6=0,0,DATE(YEAR(D6),MONTH(D6)+E6*12,DAY(D6)-1)))) -> 0 | L6: =I6+J6-K6 -> 0 | P6: =M6+N6-O6 -> 0 | T6: =Q6+R6-S6 -> 0 | AA6: =L6+U6-V6 -> 0 | AB6: =P6+W6-X6 -> 0 | AC6: =T6+Y6-Z6 -> 0 | AD6: =ROUND(AA6-AB6-AC6,2) -> 0
A7: 2 | F7: =IF(D7="",0,IF(DAY(D7)=1,IF(D7=0,0,DATE(YEAR(D7),MONTH(D7)+E7*12,DAY(D7))),IF(D7=0,0,DATE(YEAR(D7),MONTH(D7)+E7*12,DAY(D7)-1)))) -> 0 | L7: =I7+J7-K7 -> 0 | P7: =M7+N7-O7 -> 0 | T7: =Q7+R7-S7 -> 0 | AA7: =L7+U7-V7 -> 0 | AB7: =P7+W7-X7 -> 0 | AC7: =T7+Y7-Z7 -> 0 | AD7: =ROUND(AA7-AB7-AC7,2) -> 0
A8: 3 | F8: =IF(D8="",0,IF(DAY(D8)=1,IF(D8=0,0,DATE(YEAR(D8),MONTH(D8)+E8*12,DAY(D8))),IF(D8=0,0,DATE(YEAR(D8),MONTH(D8)+E8*12,DAY(D8)-1)))) -> 0 | L8: =I8+J8-K8 -> 0 | P8: =M8+N8-O8 -> 0 | T8: =Q8+R8-S8 -> 0 | AA8: =L8+U8-V8 -> 0 | AB8: =P8+W8-X8 -> 0 | AC8: =T8+Y8-Z8 -> 0 | AD8: =ROUND(AA8-AB8-AC8,2) -> 0
A9: 4 | F9: =IF(D9="",0,IF(DAY(D9)=1,IF(D9=0,0,DATE(YEAR(D9),MONTH(D9)+E9*12,DAY(D9))),IF(D9=0,0,DATE(YEAR(D9),MONTH(D9)+E9*12,DAY(D9)-1)))) -> 0 | L9: =I9+J9-K9 -> 0 | P9: =M9+N9-O9 -> 0 | T9: =Q9+R9-S9 -> 0 | AA9: =L9+U9-V9 -> 0 | AB9: =P9+W9-X9 -> 0 | AC9: =T9+Y9-Z9 -> 0 | AD9: =ROUND(AA9-AB9-AC9,2) -> 0
A10: 5 | F10: =IF(D10="",0,IF(DAY(D10)=1,IF(D10=0,0,DATE(YEAR(D10),MONTH(D10)+E10*12,DAY(D10))),IF(D10=0,0,DATE(YEAR(D10),MONTH(D10)+E10*12,DAY(D10)-1)))) -> 0 | L10: =I10+J10-K10 -> 0 | P10: =M10+N10-O10 -> 0 | T10: =Q10+R10-S10 -> 0 | AA10: =L10+U10-V10 -> 0 | AB10: =P10+W10-X10 -> 0 | AC10: =T10+Y10-Z10 -> 0 | AD10: =ROUND(AA10-AB10-AC10,2) -> 0
A11: 6 | F11: =IF(D11="",0,IF(DAY(D11)=1,IF(D11=0,0,DATE(YEAR(D11),MONTH(D11)+E11*12,DAY(D11))),IF(D11=0,0,DATE(YEAR(D11),MONTH(D11)+E11*12,DAY(D11)-1)))) -> 0 | L11: =I11+J11-K11 -> 0 | P11: =M11+N11-O11 -> 0 | T11: =Q11+R11-S11 -> 0 | AA11: =L11+U11-V11 -> 0 | AB11: =P11+W11-X11 -> 0 | AC11: =T11+Y11-Z11 -> 0 | AD11: =ROUND(AA11-AB11-AC11,2) -> 0
A12: 7 | F12: =IF(D12="",0,IF(DAY(D12)=1,IF(D12=0,0,DATE(YEAR(D12),MONTH(D12)+E12*12,DAY(D12))),IF(D12=0,0,DATE(YEAR(D12),MONTH(D12)+E12*12,DAY(D12)-1)))) -> 0 | L12: =I12+J12-K12 -> 0 | P12: =M12+N12-O12 -> 0 | T12: =Q12+R12-S12 -> 0 | AA12: =L12+U12-V12 -> 0 | AB12: =P12+W12-X12 -> 0 | AC12: =T12+Y12-Z12 -> 0 | AD12: =ROUND(AA12-AB12-AC12,2) -> 0
A13: 8 | F13: =IF(D13="",0,IF(DAY(D13)=1,IF(D13=0,0,DATE(YEAR(D13),MONTH(D13)+E13*12,DAY(D13))),IF(D13=0,0,DATE(YEAR(D13),MONTH(D13)+E13*12,DAY(D13)-1)))) -> 0 | L13: =I13+J13-K13 -> 0 | P13: =M13+N13-O13 -> 0 | T13: =Q13+R13-S13 -> 0 | AA13: =L13+U13-V13 -> 0 | AB13: =P13+W13-X13 -> 0 | AC13: =T13+Y13-Z13 -> 0 | AD13: =ROUND(AA13-AB13-AC13,2) -> 0
A14: 9 | F14: =IF(D14="",0,IF(DAY(D14)=1,IF(D14=0,0,DATE(YEAR(D14),MONTH(D14)+E14*12,DAY(D14))),IF(D14=0,0,DATE(YEAR(D14),MONTH(D14)+E14*12,DAY(D14)-1)))) -> 0 | L14: =I14+J14-K14 -> 0 | P14: =M14+N14-O14 -> 0 | T14: =Q14+R14-S14 -> 0 | AA14: =L14+U14-V14 -> 0 | AB14: =P14+W14-X14 -> 0 | AC14: =T14+Y14-Z14 -> 0 | AD14: =ROUND(AA14-AB14-AC14,2) -> 0
A15: 10 | F15: =IF(D15="",0,IF(DAY(D15)=1,IF(D15=0,0,DATE(YEAR(D15),MONTH(D15)+E15*12,DAY(D15))),IF(D15=0,0,DATE(YEAR(D15),MONTH(D15)+E15*12,DAY(D15)-1)))) -> 0 | L15: =I15+J15-K15 -> 0 | P15: =M15+N15-O15 -> 0 | T15: =Q15+R15-S15 -> 0 | AA15: =L15+U15-V15 -> 0 | AB15: =P15+W15-X15 -> 0 | AC15: =T15+Y15-Z15 -> 0 | AD15: =ROUND(AA15-AB15-AC15,2) -> 0
A16: 11 | F16: =IF(D16="",0,IF(DAY(D16)=1,IF(D16=0,0,DATE(YEAR(D16),MONTH(D16)+E16*12,DAY(D16))),IF(D16=0,0,DATE(YEAR(D16),MONTH(D16)+E16*12,DAY(D16)-1)))) -> 0 | L16: =I16+J16-K16 -> 0 | P16: =M16+N16-O16 -> 0 | T16: =Q16+R16-S16 -> 0 | AA16: =L16+U16-V16 -> 0 | AB16: =P16+W16-X16 -> 0 | AC16: =T16+Y16-Z16 -> 0 | AD16: =ROUND(AA16-AB16-AC16,2) -> 0
A17: 12 | F17: =IF(D17="",0,IF(DAY(D17)=1,IF(D17=0,0,DATE(YEAR(D17),MONTH(D17)+E17*12,DAY(D17))),IF(D17=0,0,DATE(YEAR(D17),MONTH(D17)+E17*12,DAY(D17)-1)))) -> 0 | L17: =I17+J17-K17 -> 0 | P17: =M17+N17-O17 -> 0 | T17: =Q17+R17-S17 -> 0 | AA17: =L17+U17-V17 -> 0 | AB17: =P17+W17-X17 -> 0 | AC17: =T17+Y17-Z17 -> 0 | AD17: =ROUND(AA17-AB17-AC17,2) -> 0
... A34: 29 | F34: =IF(D34="",0,IF(DAY(D34)=1,IF(D34=0,0,DATE(YEAR(D34),MONTH(D34)+E34*12,DAY(D34))),IF(D34=0,0,DATE(YEAR(D34),MONTH(D34)+E34*12,DAY(D34)-1)))) -> 0 | L34: =I34+J34-K34 -> 0 | P34: =M34+N34-O34 -> 0 | T34: =Q34+R34-S34 -> 0 | AA34: =L34+U34-V34 -> 0 | AB34: =P34+W34-X34 -> 0 | AC34: =T34+Y34-Z34 -> 0 | AD34: =ROUND(AA34-AB34-AC34,2) -> 0
A35: 合计 | I35: =ROUND(SUM(I6:I34),2) -> 0 | J35: =ROUND(SUM(J6:J34),2) -> 0 | K35: =ROUND(SUM(K6:K34),2) -> 0 | L35: =ROUND(SUM(L6:L34),2) -> 0 | M35: =ROUND(SUM(M6:M34),2) -> 0 | N35: =ROUND(SUM(N6:N34),2) -> 0 | O35: =ROUND(SUM(O6:O34),2) -> 0 | P35: =ROUND(SUM(P6:P34),2) -> 0 | ... AD35: =ROUND(SUM(AD6:AD34),2) -> 0
B37: 审计说明：

Sheet 固定资产测算表
A1: 固定资产折旧测算（未计提减值情况下适用）
A2: =备忘录!$A$1 -> 被审计单位：福禄福擎网络科技有限公司 | H2: 编制人：刘喜琴 | N2: =备忘录!$C$2 -> 日期：2025/10/30
A3: =备忘录!$A$2 -> 财务报表截止日：2025/9/30 | H3: 复核人：赵玮 | N3: =备忘录!$C$3 -> 日期：2025/10/31
A4: 期初日期 | C4: 45658 | D4: 期末日期 | E4: 45930
A5: 序号 | B5: 资产名称 | C5: 类别名称 | D5: 管理部门 | E5: 审定原值 | F5: 未审 累计折旧 | G5: 开始使用 日期 | H5: 使用年限 | I5: 残值率 | J5: 固定资产卡片记录的年折旧额 | K5: 使用月限 | L5: 测算到期日 | M5: 已提折旧月份 | N5: 本期折 旧月份 | O5: 测算月折旧 | P5: 测算当期折旧费用 | Q5: 当期折旧额与固定资产卡片核对差异 | R5: 累计折旧费用 | S5: 累计折旧额差异
A6: 1 | B6: =固定资产!B6 -> 0 | C6: =固定资产!C6 -> 0 | E6: =固定资产!AA6 -> 0 | F6: =固定资产!P6 -> 0 | G6: =固定资产!D6 -> 0 | H6: =固定资产!E6 -> 0 | K6: =IF(H6=0,0,IF(RIGHT(H6,1)<>"年",H6*12,IF(LEN(H6)=3,VALUE(LEFT(H6,2))*12,IF(LEN(H6)=2,VALUE(LEFT(H6,1))*12,"??")))) -> 0 | L6: =IF(DAY(G6)=1,IF(G6=0,0,DATE(YEAR(G6),MONTH(G6)+K6,DAY(G6))),IF(G6=0,0,DATE(YEAR(G6),MONTH(G6)+K6,DAY(G6)-1))) -> 0 | M6: =MIN(IF(AND(DAY($E$4)=30,DAY(G6)=31),IF(OR(G6=0,G6=$E$4),0,IF(L6>$E$4,VALUE(DATEDIF(G6,MIN($E$4,L6),"m"))+1,VALUE(DATEDIF(G6,MIN($E$4,L6),"m")+2))),IF(OR(G6=0,G6=$E$4),0,IF(L6>$E$4,DATEDIF(G6,MIN($E$4,L6),"m"),VALUE(DATEDIF(G6,MIN($E$4,L6),"m")+1)))),K6) -> 0 | N6: =IF(AND(YEAR(G6)=YEAR($E$4),DAY($E$4)=30,DAY(G6)=31),IF(OR(G6=0,L6<$C$4),0,IF(AND(G6<$C$4,L6>$E$4),VALUE(DATEDIF($C$4,$E$4,"m")+2),IF(AND(G6<$C$4,L6<=$E$4),VALUE(DATEDIF($C$4,L6,"m")+2),IF(AND(G6>=$C$4,L6>$E$4),VALUE(DATEDIF(G6,$E$4,"m")+1),IF(AND(G6>=$C$4,L6<=$E$4),VALUE(DATEDIF(G6,L6,"m")+2),))))),IF(OR(G6=0,L6<$C$4),0,IF(AND(G6<$C$4,L6>$E$4),VALUE(DATEDIF($C$4,$E$4,"m")+1),IF(AND(G6<$C$4,L6<=$E$4),VALUE(DATEDIF($C$4,L6,"m")+1),IF(AND(G6>=$C$4,L6>$E$4),VALUE(DATEDIF(G6,$E$4,"m")),IF(AND(G6>=$C$4,L6<=$E$4),VALUE(DATEDIF(G6,L6,"m")+1),)))))) -> 0 | O6: =IF(K6=0,0,ROUND(((1-I6)/K6)*E6,4)) -> 0 | P6: =ROUND(O6*N6,2) -> 0 | Q6: =IF(J6="","",ROUND(J6-P6,2)) | R6: =ROUND(O6*M6,2) -> 0 | S6: =ROUND(F6-R6,2) -> 0
A7: 2 | B7: =固定资产!B7 -> 0 | C7: =固定资产!C7 -> 0 | E7: =固定资产!AA7 -> 0 | F7: =固定资产!P7 -> 0 | G7: =固定资产!D7 -> 0 | H7: =固定资产!E7 -> 0 | K7: =IF(H7=0,0,IF(RIGHT(H7,1)<>"年",H7*12,IF(LEN(H7)=3,VALUE(LEFT(H7,2))*12,IF(LEN(H7)=2,VALUE(LEFT(H7,1))*12,"??")))) -> 0 | L7: =IF(DAY(G7)=1,IF(G7=0,0,DATE(YEAR(G7),MONTH(G7)+K7,DAY(G7))),IF(G7=0,0,DATE(YEAR(G7),MONTH(G7)+K7,DAY(G7)-1))) -> 0 | M7: =MIN(IF(AND(DAY($E$4)=30,DAY(G7)=31),IF(OR(G7=0,G7=$E$4),0,IF(L7>$E$4,VALUE(DATEDIF(G7,MIN($E$4,L7),"m"))+1,VALUE(DATEDIF(G7,MIN($E$4,L7),"m")+2))),IF(OR(G7=0,G7=$E$4),0,IF(L7>$E$4,DATEDIF(G7,MIN($E$4,L7),"m"),VALUE(DATEDIF(G7,MIN($E$4,L7),"m")+1)))),K7) -> 0 | N7: =IF(AND(YEAR(G7)=YEAR($E$4),DAY($E$4)=30,DAY(G7)=31),IF(OR(G7=0,L7<$C$4),0,IF(AND(G7<$C$4,L7>$E$4),VALUE(DATEDIF($C$4,$E$4,"m")+2),IF(AND(G7<$C$4,L7<=$E$4),VALUE(DATEDIF($C$4,L7,"m")+2),IF(AND(G7>=$C$4,L7>$E$4),VALUE(DATEDIF(G7,$E$4,"m")+1),IF(AND(G7>=$C$4,L7<=$E$4),VALUE(DATEDIF(G7,L7,"m")+2),))))),IF(OR(G7=0,L7<$C$4),0,IF(AND(G7<$C$4,L7>$E$4),VALUE(DATEDIF($C$4,$E$4,"m")+1),IF(AND(G7<$C$4,L7<=$E$4),VALUE(DATEDIF($C$4,L7,"m")+1),IF(AND(G7>=$C$4,L7>$E$4),VALUE(DATEDIF(G7,$E$4,"m")),IF(AND(G7>=$C$4,L7<=$E$4),VALUE(DATEDIF(G7,L7,"m")+1),)))))) -> 0 | O7: =IF(K7=0,0,ROUND(((1-I7)/K7)*E7,4)) -> 0 | P7: =ROUND(O7*N7,2) -> 0 | Q7: =IF(J7="","",ROUND(J7-P7,2)) | R7: =ROUND(O7*M7,2) -> 0 | S7: =ROUND(F7-R7,2) -> 0
A8: 3 | B8: =固定资产!B8 -> 0 | C8: =固定资产!C8 -> 0 | E8: =固定资产!AA8 -> 0 | F8: =固定资产!P8 -> 0 | G8: =固定资产!D8 -> 0 | H8: =固定资产!E8 -> 0 | K8: =IF(H8=0,0,IF(RIGHT(H8,1)<>"年",H8*12,IF(LEN(H8)=3,VALUE(LEFT(H8,2))*12,IF(LEN(H8)=2,VALUE(LEFT(H8,1))*12,"??")))) -> 0 | L8: =IF(DAY(G8)=1,IF(G8=0,0,DATE(YEAR(G8),MONTH(G8)+K8,DAY(G8))),IF(G8=0,0,DATE(YEAR(G8),MONTH(G8)+K8,DAY(G8)-1))) -> 0 | M8: =MIN(IF(AND(DAY($E$4)=30,DAY(G8)=31),IF(OR(G8=0,G8=$E$4),0,IF(L8>$E$4,VALUE(DATEDIF(G8,MIN($E$4,L8),"m"))+1,VALUE(DATEDIF(G8,MIN($E$4,L8),"m")+2))),IF(OR(G8=0,G8=$E$4),0,IF(L8>$E$4,DATEDIF(G8,MIN($E$4,L8),"m"),VALUE(DATEDIF(G8,MIN($E$4,L8),"m")+1)))),K8) -> 0 | N8: =IF(AND(YEAR(G8)=YEAR($E$4),DAY($E$4)=30,DAY(G8)=31),IF(OR(G8=0,L8<$C$4),0,IF(AND(G8<$C$4,L8>$E$4),VALUE(DATEDIF($C$4,$E$4,"m")+2),IF(AND(G8<$C$4,L8<=$E$4),VALUE(DATEDIF($C$4,L8,"m")+2),IF(AND(G8>=$C$4,L8>$E$4),VALUE(DATEDIF(G8,$E$4,"m")+1),IF(AND(G8>=$C$4,L8<=$E$4),VALUE(DATEDIF(G8,L8,"m")+2),))))),IF(OR(G8=0,L8<$C$4),0,IF(AND(G8<$C$4,L8>$E$4),VALUE(DATEDIF($C$4,$E$4,"m")+1),IF(AND(G8<$C$4,L8<=$E$4),VALUE(DATEDIF($C$4,L8,"m")+1),IF(AND(G8>=$C$4,L8>$E$4),VALUE(DATEDIF(G8,$E$4,"m")),IF(AND(G8>=$C$4,L8<=$E$4),VALUE(DATEDIF(G8,L8,"m")+1),)))))) -> 0 | O8: =IF(K8=0,0,ROUND(((1-I8)/K8)*E8,4)) -> 0 | P8: =ROUND(O8*N8,2) -> 0 | Q8: =IF(J8="","",ROUND(J8-P8,2)) | R8: =ROUND(O8*M8,2) -> 0 | S8: =ROUND(F8-R8,2) -> 0
A9: 4 | B9: =固定资产!B9 -> 0 | C9: =固定资产!C9 -> 0 | E9: =固定资产!AA9 -> 0 | F9: =固定资产!P9 -> 0 | G9: =固定资产!D9 -> 0 | H9: =固定资产!E9 -> 0 | K9: =IF(H9=0,0,IF(RIGHT(H9,1)<>"年",H9*12,IF(LEN(H9)=3,VALUE(LEFT(H9,2))*12,IF(LEN(H9)=2,VALUE(LEFT(H9,1))*12,"??")))) -> 0 | L9: =IF(DAY(G9)=1,IF(G9=0,0,DATE(YEAR(G9),MONTH(G9)+K9,DAY(G9))),IF(G9=0,0,DATE(YEAR(G9),MONTH(G9)+K9,DAY(G9)-1))) -> 0 | M9: =MIN(IF(AND(DAY($E$4)=30,DAY(G9)=31),IF(OR(G9=0,G9=$E$4),0,IF(L9>$E$4,VALUE(DATEDIF(G9,MIN($E$4,L9),"m"))+1,VALUE(DATEDIF(G9,MIN($E$4,L9),"m")+2))),IF(OR(G9=0,G9=$E$4),0,IF(L9>$E$4,DATEDIF(G9,MIN($E$4,L9),"m"),VALUE(DATEDIF(G9,MIN($E$4,L9),"m")+1)))),K9) -> 0 | N9: =IF(AND(YEAR(G9)=YEAR($E$4),DAY($E$4)=30,DAY(G9)=31),IF(OR(G9=0,L9<$C$4),0,IF(AND(G9<$C$4,L9>$E$4),VALUE(DATEDIF($C$4,$E$4,"m")+2),IF(AND(G9<$C$4,L9<=$E$4),VALUE(DATEDIF($C$4,L9,"m")+2),IF(AND(G9>=$C$4,L9>$E$4),VALUE(DATEDIF(G9,$E$4,"m")+1),IF(AND(G9>=$C$4,L9<=$E$4),VALUE(DATEDIF(G9,L9,"m")+2),))))),IF(OR(G9=0,L9<$C$4),0,IF(AND(G9<$C$4,L9>$E$4),VALUE(DATEDIF($C$4,$E$4,"m")+1),IF(AND(G9<$C$4,L9<=$E$4),VALUE(DATEDIF($C$4,L9,"m")+1),IF(AND(G9>=$C$4,L9>$E$4),VALUE(DATEDIF(G9,$E$4,"m")),IF(AND(G9>=$C$4,L9<=$E$4),VALUE(DATEDIF(G9,L9,"m")+1),)))))) -> 0 | O9: =IF(K9=0,0,ROUND(((1-I9)/K9)*E9,4)) -> 0 | P9: =ROUND(O9*N9,2) -> 0 | Q9: =IF(J9="","",ROUND(J9-P9,2)) | R9: =ROUND(O9*M9,2) -> 0 | S9: =ROUND(F9-R9,2) -> 0
A10: 5 | B10: =固定资产!B10 -> 0 | C10: =固定资产!C10 -> 0 | E10: =固定资产!AA10 -> 0 | F10: =固定资产!P10 -> 0 | G10: =固定资产!D10 -> 0 | H10: =固定资产!E10 -> 0 | K10: =IF(H10=0,0,IF(RIGHT(H10,1)<>"年",H10*12,IF(LEN(H10)=3,VALUE(LEFT(H10,2))*12,IF(LEN(H10)=2,VALUE(LEFT(H10,1))*12,"??")))) -> 0 | L10: =IF(DAY(G10)=1,IF(G10=0,0,DATE(YEAR(G10),MONTH(G10)+K10,DAY(G10))),IF(G10=0,0,DATE(YEAR(G10),MONTH(G10)+K10,DAY(G10)-1))) -> 0 | M10: =MIN(IF(AND(DAY($E$4)=30,DAY(G10)=31),IF(OR(G10=0,G10=$E$4),0,IF(L10>$E$4,VALUE(DATEDIF(G10,MIN($E$4,L10),"m"))+1,VALUE(DATEDIF(G10,MIN($E$4,L10),"m")+2))),IF(OR(G10=0,G10=$E$4),0,IF(L10>$E$4,DATEDIF(G10,MIN($E$4,L10),"m"),VALUE(DATEDIF(G10,MIN($E$4,L10),"m")+1)))),K10) -> 0 | N10: =IF(AND(YEAR(G10)=YEAR($E$4),DAY($E$4)=30,DAY(G10)=31),IF(OR(G10=0,L10<$C$4),0,IF(AND(G10<$C$4,L10>$E$4),VALUE(DATEDIF($C$4,$E$4,"m")+2),IF(AND(G10<$C$4,L10<=$E$4),VALUE(DATEDIF($C$4,L10,"m")+2),IF(AND(G10>=$C$4,L10>$E$4),VALUE(DATEDIF(G10,$E$4,"m")+1),IF(AND(G10>=$C$4,L10<=$E$4),VALUE(DATEDIF(G10,L10,"m")+2),))))),IF(OR(G10=0,L10<$C$4),0,IF(AND(G10<$C$4,L10>$E$4),VALUE(DATEDIF($C$4,$E$4,"m")+1),IF(AND(G10<$C$4,L10<=$E$4),VALUE(DATEDIF($C$4,L10,"m")+1),IF(AND(G10>=$C$4,L10>$E$4),VALUE(DATEDIF(G10,$E$4,"m")),IF(AND(G10>=$C$4,L10<=$E$4),VALUE(DATEDIF(G10,L10,"m")+1),)))))) -> 0 | O10: =IF(K10=0,0,ROUND(((1-I10)/K10)*E10,4)) -> 0 | P10: =ROUND(O10*N10,2) -> 0 | Q10: =IF(J10="","",ROUND(J10-P10,2)) | R10: =ROUND(O10*M10,2) -> 0 | S10: =ROUND(F10-R10,2) -> 0
A11: 6 | B11: =固定资产!B11 -> 0 | C11: =固定资产!C11 -> 0 | E11: =固定资产!AA11 -> 0 | F11: =固定资产!P11 -> 0 | G11: =固定资产!D11 -> 0 | H11: =固定资产!E11 -> 0 | K11: =IF(H11=0,0,IF(RIGHT(H11,1)<>"年",H11*12,IF(LEN(H11)=3,VALUE(LEFT(H11,2))*12,IF(LEN(H11)=2,VALUE(LEFT(H11,1))*12,"??")))) -> 0 | L11: =IF(DAY(G11)=1,IF(G11=0,0,DATE(YEAR(G11),MONTH(G11)+K11,DAY(G11))),IF(G11=0,0,DATE(YEAR(G11),MONTH(G11)+K11,DAY(G11)-1))) -> 0 | M11: =MIN(IF(AND(DAY($E$4)=30,DAY(G11)=31),IF(OR(G11=0,G11=$E$4),0,IF(L11>$E$4,VALUE(DATEDIF(G11,MIN($E$4,L11),"m"))+1,VALUE(DATEDIF(G11,MIN($E$4,L11),"m")+2))),IF(OR(G11=0,G11=$E$4),0,IF(L11>$E$4,DATEDIF(G11,MIN($E$4,L11),"m"),VALUE(DATEDIF(G11,MIN($E$4,L11),"m")+1)))),K11) -> 0 | N11: =IF(AND(YEAR(G11)=YEAR($E$4),DAY($E$4)=30,DAY(G11)=31),IF(OR(G11=0,L11<$C$4),0,IF(AND(G11<$C$4,L11>$E$4),VALUE(DATEDIF($C$4,$E$4,"m")+2),IF(AND(G11<$C$4,L11<=$E$4),VALUE(DATEDIF($C$4,L11,"m")+2),IF(AND(G11>=$C$4,L11>$E$4),VALUE(DATEDIF(G11,$E$4,"m")+1),IF(AND(G11>=$C$4,L11<=$E$4),VALUE(DATEDIF(G11,L11,"m")+2),))))),IF(OR(G11=0,L11<$C$4),0,IF(AND(G11<$C$4,L11>$E$4),VALUE(DATEDIF($C$4,$E$4,"m")+1),IF(AND(G11<$C$4,L11<=$E$4),VALUE(DATEDIF($C$4,L11,"m")+1),IF(AND(G11>=$C$4,L11>$E$4),VALUE(DATEDIF(G11,$E$4,"m")),IF(AND(G11>=$C$4,L11<=$E$4),VALUE(DATEDIF(G11,L11,"m")+1),)))))) -> 0 | O11: =IF(K11=0,0,ROUND(((1-I11)/K11)*E11,4)) -> 0 | P11: =ROUND(O11*N11,2) -> 0 | Q11: =IF(J11="","",ROUND(J11-P11,2)) | R11: =ROUND(O11*M11,2) -> 0 | S11: =ROUND(F11-R11,2) -> 0
A12: 7 | B12: =固定资产!B12 -> 0 | C12: =固定资产!C12 -> 0 | E12: =固定资产!AA12 -> 0 | F12: =固定资产!P12 -> 0 | G12: =固定资产!D12 -> 0 | H12: =固定资产!E12 -> 0 | K12: =IF(H12=0,0,IF(RIGHT(H12,1)<>"年",H12*12,IF(LEN(H12)=3,VALUE(LEFT(H12,2))*12,IF(LEN(H12)=2,VALUE(LEFT(H12,1))*12,"??")))) -> 0 | L12: =IF(DAY(G12)=1,IF(G12=0,0,DATE(YEAR(G12),MONTH(G12)+K12,DAY(G12))),IF(G12=0,0,DATE(YEAR(G12),MONTH(G12)+K12,DAY(G12)-1))) -> 0 | M12: =MIN(IF(AND(DAY($E$4)=30,DAY(G12)=31),IF(OR(G12=0,G12=$E$4),0,IF(L12>$E$4,VALUE(DATEDIF(G12,MIN($E$4,L12),"m"))+1,VALUE(DATEDIF(G12,MIN($E$4,L12),"m")+2))),IF(OR(G12=0,G12=$E$4),0,IF(L12>$E$4,DATEDIF(G12,MIN($E$4,L12),"m"),VALUE(DATEDIF(G12,MIN($E$4,L12),"m")+1)))),K12) -> 0 | N12: =IF(AND(YEAR(G12)=YEAR($E$4),DAY($E$4)=30,DAY(G12)=31),IF(OR(G12=0,L12<$C$4),0,IF(AND(G12<$C$4,L12>$E$4),VALUE(DATEDIF($C$4,$E$4,"m")+2),IF(AND(G12<$C$4,L12<=$E$4),VALUE(DATEDIF($C$4,L12,"m")+2),IF(AND(G12>=$C$4,L12>$E$4),VALUE(DATEDIF(G12,$E$4,"m")+1),IF(AND(G12>=$C$4,L12<=$E$4),VALUE(DATEDIF(G12,L12,"m")+2),))))),IF(OR(G12=0,L12<$C$4),0,IF(AND(G12<$C$4,L12>$E$4),VALUE(DATEDIF($C$4,$E$4,"m")+1),IF(AND(G12<$C$4,L12<=$E$4),VALUE(DATEDIF($C$4,L12,"m")+1),IF(AND(G12>=$C$4,L12>$E$4),VALUE(DATEDIF(G12,$E$4,"m")),IF(AND(G12>=$C$4,L12<=$E$4),VALUE(DATEDIF(G12,L12,"m")+1),)))))) -> 0 | O12: =IF(K12=0,0,ROUND(((1-I12)/K12)*E12,4)) -> 0 | P12: =ROUND(O12*N12,2) -> 0 | Q12: =IF(J12="","",ROUND(J12-P12,2)) | R12: =ROUND(O12*M12,2) -> 0 | S12: =ROUND(F12-R12,2) -> 0
A13: 8 | B13: =固定资产!B13 -> 0 | C13: =固定资产!C13 -> 0 | E13: =固定资产!AA13 -> 0 | F13: =固定资产!P13 -> 0 | G13: =固定资产!D13 -> 0 | H13: =固定资产!E13 -> 0 | K13: =IF(H13=0,0,IF(RIGHT(H13,1)<>"年",H13*12,IF(LEN(H13)=3,VALUE(LEFT(H13,2))*12,IF(LEN(H13)=2,VALUE(LEFT(H13,1))*12,"??")))) -> 0 | L13: =IF(DAY(G13)=1,IF(G13=0,0,DATE(YEAR(G13),MONTH(G13)+K13,DAY(G13))),IF(G13=0,0,DATE(YEAR(G13),MONTH(G13)+K13,DAY(G13)-1))) -> 0 | M13: =MIN(IF(AND(DAY($E$4)=30,DAY(G13)=31),IF(OR(G13=0,G13=$E$4),0,IF(L13>$E$4,VALUE(DATEDIF(G13,MIN($E$4,L13),"m"))+1,VALUE(DATEDIF(G13,MIN($E$4,L13),"m")+2))),IF(OR(G13=0,G13=$E$4),0,IF(L13>$E$4,DATEDIF(G13,MIN($E$4,L13),"m"),VALUE(DATEDIF(G13,MIN($E$4,L13),"m")+1)))),K13) -> 0 | N13: =IF(AND(YEAR(G13)=YEAR($E$4),DAY($E$4)=30,DAY(G13)=31),IF(OR(G13=0,L13<$C$4),0,IF(AND(G13<$C$4,L13>$E$4),VALUE(DATEDIF($C$4,$E$4,"m")+2),IF(AND(G13<$C$4,L13<=$E$4),VALUE(DATEDIF($C$4,L13,"m")+2),IF(AND(G13>=$C$4,L13>$E$4),VALUE(DATEDIF(G13,$E$4,"m")+1),IF(AND(G13>=$C$4,L13<=$E$4),VALUE(DATEDIF(G13,L13,"m")+2),))))),IF(OR(G13=0,L13<$C$4),0,IF(AND(G13<$C$4,L13>$E$4),VALUE(DATEDIF($C$4,$E$4,"m")+1),IF(AND(G13<$C$4,L13<=$E$4),VALUE(DATEDIF($C$4,L13,"m")+1),IF(AND(G13>=$C$4,L13>$E$4),VALUE(DATEDIF(G13,$E$4,"m")),IF(AND(G13>=$C$4,L13<=$E$4),VALUE(DATEDIF(G13,L13,"m")+1),)))))) -> 0 | O13: =IF(K13=0,0,ROUND(((1-I13)/K13)*E13,4)) -> 0 | P13: =ROUND(O13*N13,2) -> 0 | Q13: =IF(J13="","",ROUND(J13-P13,2)) | R13: =ROUND(O13*M13,2) -> 0 | S13: =ROUND(F13-R13,2) -> 0
A14: 9 | B14: =固定资产!B14 -> 0 | C14: =固定资产!C14 -> 0 | E14: =固定资产!AA14 -> 0 | F14: =固定资产!P14 -> 0 | G14: =固定资产!D14 -> 0 | H14: =固定资产!E14 -> 0 | K14: =IF(H14=0,0,IF(RIGHT(H14,1)<>"年",H14*12,IF(LEN(H14)=3,VALUE(LEFT(H14,2))*12,IF(LEN(H14)=2,VALUE(LEFT(H14,1))*12,"??")))) -> 0 | L14: =IF(DAY(G14)=1,IF(G14=0,0,DATE(YEAR(G14),MONTH(G14)+K14,DAY(G14))),IF(G14=0,0,DATE(YEAR(G14),MONTH(G14)+K14,DAY(G14)-1))) -> 0 | M14: =MIN(IF(AND(DAY($E$4)=30,DAY(G14)=31),IF(OR(G14=0,G14=$E$4),0,IF(L14>$E$4,VALUE(DATEDIF(G14,MIN($E$4,L14),"m"))+1,VALUE(DATEDIF(G14,MIN($E$4,L14),"m")+2))),IF(OR(G14=0,G14=$E$4),0,IF(L14>$E$4,DATEDIF(G14,MIN($E$4,L14),"m"),VALUE(DATEDIF(G14,MIN($E$4,L14),"m")+1)))),K14) -> 0 | N14: =IF(AND(YEAR(G14)=YEAR($E$4),DAY($E$4)=30,DAY(G14)=31),IF(OR(G14=0,L14<$C$4),0,IF(AND(G14<$C$4,L14>$E$4),VALUE(DATEDIF($C$4,$E$4,"m")+2),IF(AND(G14<$C$4,L14<=$E$4),VALUE(DATEDIF($C$4,L14,"m")+2),IF(AND(G14>=$C$4,L14>$E$4),VALUE(DATEDIF(G14,$E$4,"m")+1),IF(AND(G14>=$C$4,L14<=$E$4),VALUE(DATEDIF(G14,L14,"m")+2),))))),IF(OR(G14=0,L14<$C$4),0,IF(AND(G14<$C$4,L14>$E$4),VALUE(DATEDIF($C$4,$E$4,"m")+1),IF(AND(G14<$C$4,L14<=$E$4),VALUE(DATEDIF($C$4,L14,"m")+1),IF(AND(G14>=$C$4,L14>$E$4),VALUE(DATEDIF(G14,$E$4,"m")),IF(AND(G14>=$C$4,L14<=$E$4),VALUE(DATEDIF(G14,L14,"m")+1),)))))) -> 0 | O14: =IF(K14=0,0,ROUND(((1-I14)/K14)*E14,4)) -> 0 | P14: =ROUND(O14*N14,2) -> 0 | Q14: =IF(J14="","",ROUND(J14-P14,2)) | R14: =ROUND(O14*M14,2) -> 0 | S14: =ROUND(F14-R14,2) -> 0
A15: 10 | B15: =固定资产!B15 -> 0 | C15: =固定资产!C15 -> 0 | E15: =固定资产!AA15 -> 0 | F15: =固定资产!P15 -> 0 | G15: =固定资产!D15 -> 0 | H15: =固定资产!E15 -> 0 | K15: =IF(H15=0,0,IF(RIGHT(H15,1)<>"年",H15*12,IF(LEN(H15)=3,VALUE(LEFT(H15,2))*12,IF(LEN(H15)=2,VALUE(LEFT(H15,1))*12,"??")))) -> 0 | L15: =IF(DAY(G15)=1,IF(G15=0,0,DATE(YEAR(G15),MONTH(G15)+K15,DAY(G15))),IF(G15=0,0,DATE(YEAR(G15),MONTH(G15)+K15,DAY(G15)-1))) -> 0 | M15: =MIN(IF(AND(DAY($E$4)=30,DAY(G15)=31),IF(OR(G15=0,G15=$E$4),0,IF(L15>$E$4,VALUE(DATEDIF(G15,MIN($E$4,L15),"m"))+1,VALUE(DATEDIF(G15,MIN($E$4,L15),"m")+2))),IF(OR(G15=0,G15=$E$4),0,IF(L15>$E$4,DATEDIF(G15,MIN($E$4,L15),"m"),VALUE(DATEDIF(G15,MIN($E$4,L15),"m")+1)))),K15) -> 0 | N15: =IF(AND(YEAR(G15)=YEAR($E$4),DAY($E$4)=30,DAY(G15)=31),IF(OR(G15=0,L15<$C$4),0,IF(AND(G15<$C$4,L15>$E$4),VALUE(DATEDIF($C$4,$E$4,"m")+2),IF(AND(G15<$C$4,L15<=$E$4),VALUE(DATEDIF($C$4,L15,"m")+2),IF(AND(G15>=$C$4,L15>$E$4),VALUE(DATEDIF(G15,$E$4,"m")+1),IF(AND(G15>=$C$4,L15<=$E$4),VALUE(DATEDIF(G15,L15,"m")+2),))))),IF(OR(G15=0,L15<$C$4),0,IF(AND(G15<$C$4,L15>$E$4),VALUE(DATEDIF($C$4,$E$4,"m")+1),IF(AND(G15<$C$4,L15<=$E$4),VALUE(DATEDIF($C$4,L15,"m")+1),IF(AND(G15>=$C$4,L15>$E$4),VALUE(DATEDIF(G15,$E$4,"m")),IF(AND(G15>=$C$4,L15<=$E$4),VALUE(DATEDIF(G15,L15,"m")+1),)))))) -> 0 | O15: =IF(K15=0,0,ROUND(((1-I15)/K15)*E15,4)) -> 0 | P15: =ROUND(O15*N15,2) -> 0 | Q15: =IF(J15="","",ROUND(J15-P15,2)) | R15: =ROUND(O15*M15,2) -> 0 | S15: =ROUND(F15-R15,2) -> 0
A16: 11 | B16: =固定资产!B16 -> 0 | C16: =固定资产!C16 -> 0 | E16: =固定资产!AA16 -> 0 | F16: =固定资产!P16 -> 0 | G16: =固定资产!D16 -> 0 | H16: =固定资产!E16 -> 0 | K16: =IF(H16=0,0,IF(RIGHT(H16,1)<>"年",H16*12,IF(LEN(H16)=3,VALUE(LEFT(H16,2))*12,IF(LEN(H16)=2,VALUE(LEFT(H16,1))*12,"??")))) -> 0 | L16: =IF(DAY(G16)=1,IF(G16=0,0,DATE(YEAR(G16),MONTH(G16)+K16,DAY(G16))),IF(G16=0,0,DATE(YEAR(G16),MONTH(G16)+K16,DAY(G16)-1))) -> 0 | M16: =MIN(IF(AND(DAY($E$4)=30,DAY(G16)=31),IF(OR(G16=0,G16=$E$4),0,IF(L16>$E$4,VALUE(DATEDIF(G16,MIN($E$4,L16),"m"))+1,VALUE(DATEDIF(G16,MIN($E$4,L16),"m")+2))),IF(OR(G16=0,G16=$E$4),0,IF(L16>$E$4,DATEDIF(G16,MIN($E$4,L16),"m"),VALUE(DATEDIF(G16,MIN($E$4,L16),"m")+1)))),K16) -> 0 | N16: =IF(AND(YEAR(G16)=YEAR($E$4),DAY($E$4)=30,DAY(G16)=31),IF(OR(G16=0,L16<$C$4),0,IF(AND(G16<$C$4,L16>$E$4),VALUE(DATEDIF($C$4,$E$4,"m")+2),IF(AND(G16<$C$4,L16<=$E$4),VALUE(DATEDIF($C$4,L16,"m")+2),IF(AND(G16>=$C$4,L16>$E$4),VALUE(DATEDIF(G16,$E$4,"m")+1),IF(AND(G16>=$C$4,L16<=$E$4),VALUE(DATEDIF(G16,L16,"m")+2),))))),IF(OR(G16=0,L16<$C$4),0,IF(AND(G16<$C$4,L16>$E$4),VALUE(DATEDIF($C$4,$E$4,"m")+1),IF(AND(G16<$C$4,L16<=$E$4),VALUE(DATEDIF($C$4,L16,"m")+1),IF(AND(G16>=$C$4,L16>$E$4),VALUE(DATEDIF(G16,$E$4,"m")),IF(AND(G16>=$C$4,L16<=$E$4),VALUE(DATEDIF(G16,L16,"m")+1),)))))) -> 0 | O16: =IF(K16=0,0,ROUND(((1-I16)/K16)*E16,4)) -> 0 | P16: =ROUND(O16*N16,2) -> 0 | Q16: =IF(J16="","",ROUND(J16-P16,2)) | R16: =ROUND(O16*M16,2) -> 0 | S16: =ROUND(F16-R16,2) -> 0
A17: 12 | B17: =固定资产!B17 -> 0 | C17: =固定资产!C17 -> 0 | E17: =固定资产!AA17 -> 0 | F17: =固定资产!P17 -> 0 | G17: =固定资产!D17 -> 0 | H17: =固定资产!E17 -> 0 | K17: =IF(H17=0,0,IF(RIGHT(H17,1)<>"年",H17*12,IF(LEN(H17)=3,VALUE(LEFT(H17,2))*12,IF(LEN(H17)=2,VALUE(LEFT(H17,1))*12,"??")))) -> 0 | L17: =IF(DAY(G17)=1,IF(G17=0,0,DATE(YEAR(G17),MONTH(G17)+K17,DAY(G17))),IF(G17=0,0,DATE(YEAR(G17),MONTH(G17)+K17,DAY(G17)-1))) -> 0 | M17: =MIN(IF(AND(DAY($E$4)=30,DAY(G17)=31),IF(OR(G17=0,G17=$E$4),0,IF(L17>$E$4,VALUE(DATEDIF(G17,MIN($E$4,L17),"m"))+1,VALUE(DATEDIF(G17,MIN($E$4,L17),"m")+2))),IF(OR(G17=0,G17=$E$4),0,IF(L17>$E$4,DATEDIF(G17,MIN($E$4,L17),"m"),VALUE(DATEDIF(G17,MIN($E$4,L17),"m")+1)))),K17) -> 0 | N17: =IF(AND(YEAR(G17)=YEAR($E$4),DAY($E$4)=30,DAY(G17)=31),IF(OR(G17=0,L17<$C$4),0,IF(AND(G17<$C$4,L17>$E$4),VALUE(DATEDIF($C$4,$E$4,"m")+2),IF(AND(G17<$C$4,L17<=$E$4),VALUE(DATEDIF($C$4,L17,"m")+2),IF(AND(G17>=$C$4,L17>$E$4),VALUE(DATEDIF(G17,$E$4,"m")+1),IF(AND(G17>=$C$4,L17<=$E$4),VALUE(DATEDIF(G17,L17,"m")+2),))))),IF(OR(G17=0,L17<$C$4),0,IF(AND(G17<$C$4,L17>$E$4),VALUE(DATEDIF($C$4,$E$4,"m")+1),IF(AND(G17<$C$4,L17<=$E$4),VALUE(DATEDIF($C$4,L17,"m")+1),IF(AND(G17>=$C$4,L17>$E$4),VALUE(DATEDIF(G17,$E$4,"m")),IF(AND(G17>=$C$4,L17<=$E$4),VALUE(DATEDIF(G17,L17,"m")+1),)))))) -> 0 | O17: =IF(K17=0,0,ROUND(((1-I17)/K17)*E17,4)) -> 0 | P17: =ROUND(O17*N17,2) -> 0 | Q17: =IF(J17="","",ROUND(J17-P17,2)) | R17: =ROUND(O17*M17,2) -> 0 | S17: =ROUND(F17-R17,2) -> 0
... A34: 29 | B34: =固定资产!B34 -> 0 | C34: =固定资产!C34 -> 0 | E34: =固定资产!AA34 -> 0 | F34: =固定资产!P34 -> 0 | G34: =固定资产!D34 -> 0 | H34: =固定资产!E34 -> 0 | K34: =IF(H34=0,0,IF(RIGHT(H34,1)<>"年",H34*12,IF(LEN(H34)=3,VALUE(LEFT(H34,2))*12,IF(LEN(H34)=2,VALUE(LEFT(H34,1))*12,"??")))) -> 0 | L34: =IF(DAY(G34)=1,IF(G34=0,0,DATE(YEAR(G34),MONTH(G34)+K34,DAY(G34))),IF(G34=0,0,DATE(YEAR(G34),MONTH(G34)+K34,DAY(G34)-1))) -> 0 | M34: =MIN(IF(AND(DAY($E$4)=30,DAY(G34)=31),IF(OR(G34=0,G34=$E$4),0,IF(L34>$E$4,VALUE(DATEDIF(G34,MIN($E$4,L34),"m"))+1,VALUE(DATEDIF(G34,MIN($E$4,L34),"m")+2))),IF(OR(G34=0,G34=$E$4),0,IF(L34>$E$4,DATEDIF(G34,MIN($E$4,L34),"m"),VALUE(DATEDIF(G34,MIN($E$4,L34),"m")+1)))),K34) -> 0 | N34: =IF(AND(YEAR(G34)=YEAR($E$4),DAY($E$4)=30,DAY(G34)=31),IF(OR(G34=0,L34<$C$4),0,IF(AND(G34<$C$4,L34>$E$4),VALUE(DATEDIF($C$4,$E$4,"m")+2),IF(AND(G34<$C$4,L34<=$E$4),VALUE(DATEDIF($C$4,L34,"m")+2),IF(AND(G34>=$C$4,L34>$E$4),VALUE(DATEDIF(G34,$E$4,"m")+1),IF(AND(G34>=$C$4,L34<=$E$4),VALUE(DATEDIF(G34,L34,"m")+2),))))),IF(OR(G34=0,L34<$C$4),0,IF(AND(G34<$C$4,L34>$E$4),VALUE(DATEDIF($C$4,$E$4,"m")+1),IF(AND(G34<$C$4,L34<=$E$4),VALUE(DATEDIF($C$4,L34,"m")+1),IF(AND(G34>=$C$4,L34>$E$4),VALUE(DATEDIF(G34,$E$4,"m")),IF(AND(G34>=$C$4,L34<=$E$4),VALUE(DATEDIF(G34,L34,"m")+1),)))))) -> 0 | O34: =IF(K34=0,0,ROUND(((1-I34)/K34)*E34,4)) -> 0 | P34: =ROUND(O34*N34,2) -> 0 | Q34: =IF(J34="","",ROUND(J34-P34,2)) | R34: =ROUND(O34*M34,2) -> 0 | S34: =ROUND(F34-R34,2) -> 0
A35: 合计 | E35: =SUM(E6:E34) -> 0 | F35: =SUM(F6:F34) -> 0 | J35: =SUM(J6:J34) -> 0 | O35: =SUM(O6:O34) -> 0 | P35: =SUM(P6:P34) -> 0 | Q35: =SUM(Q6:Q34) -> 0 | R35: =SUM(R6:R34) -> 0 | S35: =SUM(S6:S34) -> 0
B37: 审计说明：

Sheet 无形资产
A1: 无形资产明细表
A2: =备忘录!$A$1 -> 被审计单位：福禄福擎网络科技有限公司 | H2: 编制人：刘喜琴 | K2: =备忘录!$C$2 -> 日期：2025/10/30
A3: =备忘录!$A$2 -> 财务报表截止日：2025/9/30 | H3: 复核人：赵玮 | K3: =备忘录!$C$3 -> 日期：2025/10/31
B4: 一、原值
A5: 序号 | B5: 无形资产名称 | C5: 无形资产 类别 | D5: 未审数 | J5: 期初数调整金额 | K5: 本期审计调整 | M5: 审定数
D6: 期初数 | E6: 本期借方 | F6: 本期贷方 | G6: 期末数 | H6: 企业调整 | I6: 期末报表列报 | K6: 借方调整 | L6: 贷方调整 | M6: 期初数 | N6: 本期借方 | O6: 本期贷方 | P6: 期末数
A7: 1 | G7: =ROUND(D7+E7-F7,2) -> 0 | I7: =ROUND(SUM(G7:H7),2) -> 0 | M7: =ROUND(D7+J7,2) -> 0 | N7: =ROUND(E7+K7,2) -> 0 | O7: =ROUND(F7+L7,2) -> 0 | P7: =ROUND(M7+N7-O7,2) -> 0
A8: 2 | G8: =ROUND(D8+E8-F8,2) -> 0 | I8: =ROUND(SUM(G8:H8),2) -> 0 | M8: =ROUND(D8+J8,2) -> 0 | N8: =ROUND(E8+K8,2) -> 0 | O8: =ROUND(F8+L8,2) -> 0 | P8: =ROUND(M8+N8-O8,2) -> 0
B9: 合计 | C9: —— | D9: =ROUND(SUM(D7:D8),2) -> 0 | E9: =ROUND(SUM(E7:E8),2) -> 0 | F9: =ROUND(SUM(F7:F8),2) -> 0 | G9: =ROUND(SUM(G7:G8),2) -> 0 | H9: =ROUND(SUM(H7:H8),2) -> 0 | I9: =ROUND(SUM(I7:I8),2) -> 0 | J9: =ROUND(SUM(J7:J8),2) -> 0 | K9: =ROUND(SUM(K7:K8),2) -> 0 | ... P9: =ROUND(SUM(P7:P8),2) -> 0
B11: 二、累计摊销
A12: 序号 | B12: 无形资产名称 | C12: 无形资产 类别 | D12: 未审数 | J12: 期初数调整金额 | K12: 本期审计调整 | M12: 审定数
D13: 期初数 | E13: 本期借方 | F13: 本期贷方 | G13: 期末数 | H13: 企业调整 | I13: 期末报表列报 | K13: 借方调整 | L13: 贷方调整 | M13: 期初数 | N13: 本期借方 | O13: 本期贷方 | P13: 期末数
A14: 1 | G14: =ROUND(D14-E14+F14,2) -> 0 | I14: =ROUND(SUM(G14:H14),2) -> 0 | M14: =ROUND(D14+J14,2) -> 0 | N14: =ROUND(E14+K14,2) -> 0 | O14: =ROUND(F14+L14,2) -> 0 | P14: =ROUND(M14-N14+O14,2) -> 0
A15: 2 | G15: =D15-E15+F15 -> 0 | I15: =SUM(G15:H15) -> 0 | M15: =ROUND(D15+J15,2) -> 0 | N15: =ROUND(E15+K15,2) -> 0 | O15: =ROUND(F15+L15,2) -> 0 | P15: =ROUND(M15-N15+O15,2) -> 0
B16: 合计 | C16: —— | D16: =ROUND(SUM(D14:D15),2) -> 0 | E16: =ROUND(SUM(E14:E15),2) -> 0 | F16: =ROUND(SUM(F14:F15),2) -> 0 | G16: =ROUND(SUM(G14:G15),2) -> 0 | H16: =ROUND(SUM(H14:H15),2) -> 0 | I16: =ROUND(SUM(I14:I15),2) -> 0 | J16: =ROUND(SUM(J14:J15),2) -> 0 | K16: =ROUND(SUM(K14:K15),2) -> 0 | ... P16: =ROUND(SUM(P14:P15),2) -> 0
B18: 三、减值准备
A19: 序号 | B19: 无形资产名称 | C19: 无形资产 类别 | D19: 未审数 | J19: 期初数调整金额 | K19: 本期审计调整 | M19: 审定数
D20: 期初数 | E20: 本期借方 | F20: 本期贷方 | G20: 期末数 | H20: 企业调整 | I20: 期末报表列报 | K20: 借方调整 | L20: 贷方调整 | M20: 期初数 | N20: 本期借方 | O20: 本期贷方 | P20: 期末数
A21: 1 | G21: =ROUND(D21-E21+F21,2) -> 0 | I21: =ROUND(SUM(G21:H21),2) -> 0 | M21: =ROUND(D21+J21,2) -> 0 | N21: =ROUND(E21+K21,2) -> 0 | O21: =ROUND(F21+L21,2) -> 0 | P21: =ROUND(M21-N21+O21,2) -> 0
A22: 2 | G22: =ROUND(D22-E22+F22,2) -> 0 | I22: =ROUND(SUM(G22:H22),2) -> 0 | M22: =ROUND(D22+J22,2) -> 0 | N22: =ROUND(E22+K22,2) -> 0 | O22: =ROUND(F22+L22,2) -> 0 | P22: =ROUND(M22-N22+O22,2) -> 0
B23: 合计 | C23: —— | D23: =ROUND(SUM(D21:D22),2) -> 0 | E23: =ROUND(SUM(E21:E22),2) -> 0 | F23: =ROUND(SUM(F21:F22),2) -> 0 | G23: =ROUND(SUM(G21:G22),2) -> 0 | H23: =ROUND(SUM(H21:H22),2) -> 0 | I23: =ROUND(SUM(I21:I22),2) -> 0 | J23: =ROUND(SUM(J21:J22),2) -> 0 | K23: =ROUND(SUM(K21:K22),2) -> 0 | ... P23: =ROUND(SUM(P21:P22),2) -> 0
A25: 四、账面净值 | B25: 净值合计 | D25: =ROUND(D9-D16-D23,2) -> 0 | E25: =ROUND(E9-E16-E23,2) -> 0 | F25: =ROUND(F9-F16-F23,2) -> 0 | G25: =ROUND(G9-G16-G23,2) -> 0 | H25: =ROUND(H9-H16-H23,2) -> 0 | I25: =ROUND(I9-I16-I23,2) -> 0 | J25: =ROUND(J9-J16-J23,2) -> 0 | K25: =ROUND(K9-K16-K23,2) -> 0 | ... P25: =ROUND(P9-P16-P23,2) -> 0
D27: 审计说明：
C29: 软件
C30: 土地使用权
C31: 专利权
C32: 非专有技术
C33: 商标权
C34: 著作权
C35: 特许经营权

Sheet 无形资产测算表
A1: 无形资产累计摊销计算表（未计提减值情况下适用）
A2: =备忘录!$A$1 -> 被审计单位：福禄福擎网络科技有限公司 | H2: 编制人：刘喜琴 | N2: =备忘录!$C$2 -> 日期：2025/10/30
A3: =备忘录!$A$2 -> 财务报表截止日：2025/9/30 | H3: 复核人：赵玮 | N3: =备忘录!$C$3 -> 日期：2025/10/31
A4: 期初： | B4: 45658 | C4: 摊销期末： | D4: 45930
A5: 无形资产名称 | B5: 原值 | C5: 累计摊销 | D5: 开始使用日期 | E5: 使用期限（年） | F5: 账面月摊销额 | G5: 当期摊销额 | H5: 摊销期限（月） | I5: 测算到期日 | J5: 已摊销月份 | K5: 剩余摊销月份 | L5: 本期摊销月份 | M5: 月摊销 | N5: 当期摊销费用 | O5: 月摊销额差异 | P5: 累计摊销 | Q5: 当期摊销额差异 | R5: 累计摊销额差异
H6: =IF(E6=0,0,IF(RIGHT(E6,1)<>"年",E6*12,IF(LEN(E6)=3,VALUE(LEFT(E6,2))*12,IF(LEN(E6)=2,VALUE(LEFT(E6,1))*12,"??")))) -> 0 | I6: =IF(DAY(D6)=1,IF(D6=0,0,DATE(YEAR(D6),MONTH(D6)+H6-1,DAY(D6))),IF(D6=0,0,DATE(YEAR(D6),MONTH(D6)+H6-1,DAY(D6)-1))) -> 0 | J6: =IF(D6="",0,MIN(IF(AND(DAY($D$4)=30,DAY(D6)=31),IF(OR(D6=0,D6=$D$4),0,IF(I6>$D$4,VALUE(DATEDIF(D6,MIN($D$4,I6),"m"))+1,VALUE(DATEDIF(D6,MIN($D$4,I6),"m")+2))),IF(OR(D6=0,D6=$D$4),0,IF(I6>$D$4,DATEDIF(D6,MIN($D$4,I6),"m"),VALUE(DATEDIF(D6,MIN($D$4,I6),"m")+1)))),H6)) -> 0 | K6: =IF(J6="",0,H6-J6) -> 0 | L6: =IF(AND(YEAR(D6)=YEAR($D$4),DAY($D$4)=30,DAY(D6)=31),IF(OR(D6=0,I6<$B$4),0,IF(AND(D6<$B$4,I6>$D$4),VALUE(DATEDIF($B$4,$D$4,"m")+2),IF(AND(D6<$B$4,I6<=$D$4),VALUE(DATEDIF($B$4,I6,"m")+2),IF(AND(D6>=$B$4,I6>$D$4),VALUE(DATEDIF(D6,$D$4,"m")+1),IF(AND(D6>=$B$4,I6<=$D$4),VALUE(DATEDIF(D6,I6,"m")+2),))))),IF(OR(D6=0,I6<$B$4),0,IF(AND(D6<$B$4,I6>$D$4),VALUE(DATEDIF($B$4,$D$4,"m")+1),IF(AND(D6<$B$4,I6<=$D$4),VALUE(DATEDIF($B$4,I6,"m")+1),IF(AND(D6>=$B$4,I6>$D$4),VALUE(DATEDIF(D6,$D$4,"m")+1),IF(AND(D6>=$B$4,I6<=$D$4),VALUE(DATEDIF(D6,I6,"m")+1),)))))) -> 0 | M6: =IF(H6=0,0,ROUND(((1-0)/H6)*B6,4)) -> 0 | N6: =L6*M6 -> 0 | O6: =M6-F6 -> 0 | P6: =M6*J6 -> 0 | Q6: =G6-N6 -> 0 | R6: =C6-P6 -> 0
H7: =IF(E7=0,0,IF(RIGHT(E7,1)<>"年",E7*12,IF(LEN(E7)=3,VALUE(LEFT(E7,2))*12,IF(LEN(E7)=2,VALUE(LEFT(E7,1))*12,"??")))) -> 0 | I7: =IF(DAY(D7)=1,IF(D7=0,0,DATE(YEAR(D7),MONTH(D7)+H7-1,DAY(D7))),IF(D7=0,0,DATE(YEAR(D7),MONTH(D7)+H7-1,DAY(D7)-1))) -> 0 | J7: =IF(D7="",0,MIN(IF(AND(DAY($D$4)=30,DAY(D7)=31),IF(OR(D7=0,D7=$D$4),0,IF(I7>$D$4,VALUE(DATEDIF(D7,MIN($D$4,I7),"m"))+1,VALUE(DATEDIF(D7,MIN($D$4,I7),"m")+2))),IF(OR(D7=0,D7=$D$4),0,IF(I7>$D$4,DATEDIF(D7,MIN($D$4,I7),"m"),VALUE(DATEDIF(D7,MIN($D$4,I7),"m")+1)))),H7)) -> 0 | K7: =IF(J7="",0,H7-J7) -> 0 | L7: =IF(AND(YEAR(D7)=YEAR($D$4),DAY($D$4)=30,DAY(D7)=31),IF(OR(D7=0,I7<$B$4),0,IF(AND(D7<$B$4,I7>$D$4),VALUE(DATEDIF($B$4,$D$4,"m")+2),IF(AND(D7<$B$4,I7<=$D$4),VALUE(DATEDIF($B$4,I7,"m")+2),IF(AND(D7>=$B$4,I7>$D$4),VALUE(DATEDIF(D7,$D$4,"m")+1),IF(AND(D7>=$B$4,I7<=$D$4),VALUE(DATEDIF(D7,I7,"m")+2),))))),IF(OR(D7=0,I7<$B$4),0,IF(AND(D7<$B$4,I7>$D$4),VALUE(DATEDIF($B$4,$D$4,"m")+1),IF(AND(D7<$B$4,I7<=$D$4),VALUE(DATEDIF($B$4,I7,"m")+1),IF(AND(D7>=$B$4,I7>$D$4),VALUE(DATEDIF(D7,$D$4,"m")+1),IF(AND(D7>=$B$4,I7<=$D$4),VALUE(DATEDIF(D7,I7,"m")+1),)))))) -> 0 | M7: =IF(H7=0,0,ROUND(((1-0)/H7)*B7,4)) -> 0 | N7: =L7*M7 -> 0 | O7: =M7-F7 -> 0 | P7: =M7*J7 -> 0 | Q7: =G7-N7 -> 0 | R7: =C7-P7 -> 0
A8: 合计 | B8: =SUM(B6:B7) -> 0 | C8: =SUM(C6:C7) -> 0 | D8: —— | E8: —— | F8: =SUM(F6:F7) -> 0 | G8: =SUM(G6:G7) -> 0 | H8: —— | I8: —— | J8: —— | K8: —— | L8: —— | M8: =SUM(M6:M7) -> 0 | N8: =SUM(N6:N7) -> 0 | O8: =SUM(O6:O7) -> 0 | P8: =SUM(P6:P7) -> 0 | Q8: =SUM(Q6:Q7) -> 0 | R8: =SUM(R6:R7) -> 0
B10: 审计说明：

Sheet 应收账款
A1: 应收账款明细表
A2: =备忘录!$A$1 -> 被审计单位：福禄福擎网络科技有限公司 | F2: 编制人：刘喜琴 | K2: =备忘录!$C$2 -> 日期：2025/10/30
A3: =备忘录!$A$2 -> 财务报表截止日：2025/9/30 | F3: 复核人：赵玮 | K3: =备忘录!$C$3 -> 日期：2025/10/31
A4: 序号 | B4: 科目名称 | C4: 核算项目1 | D4: 核算项目2 | E4: 账面数据 | J4: 期末报表列报 | K4: 审计调整 | L4: 期末审定余额 | M4: 余额核对 (√) | N4: 核对确认金额 | O4: 备注 | P4: 重要客户/供应商账龄划分（√） | Q4: 1个月以内 | R4: 2-3月 | S4: 4-6月 | T4: 6个月以上 | U4: 重要客户/供应商背调(√) | V4: 背景调查
E5: 期初金额（取数为：科目余额表期初借方-贷方） | F5: 本期借方 | G5: 本期贷方 | H5: 期末金额 | I5: 企业调整 | V5: 法定代表人 | W5: 成立日期 | X5: 注册地址 | Y5: 注册资本（万元） | Z5: 行业 | AA5: 股权结构 | AB5: 企业规模 | AC5: 员工人数 | AD5: 纳税人资质 | AE5: 经营范围
A6: 1 | H6: =ROUND(E6+F6-G6,2) -> 0 | J6: =H6+I6 -> 0 | L6: =J6+K6 -> 0
A7: 2 | H7: =ROUND(E7+F7-G7,2) -> 0 | J7: =H7+I7 -> 0 | L7: =J7+K7 -> 0
A8: 3 | H8: =ROUND(E8+F8-G8,2) -> 0 | J8: =H8+I8 -> 0 | L8: =J8+K8 -> 0
A9: 4 | H9: =ROUND(E9+F9-G9,2) -> 0 | J9: =H9+I9 -> 0 | L9: =J9+K9 -> 0
A10: 5 | H10: =ROUND(E10+F10-G10,2) -> 0 | J10: =H10+I10 -> 0 | L10: =J10+K10 -> 0
A11: 6 | H11: =ROUND(E11+F11-G11,2) -> 0 | J11: =H11+I11 -> 0 | L11: =J11+K11 -> 0
A12: 7 | H12: =ROUND(E12+F12-G12,2) -> 0 | J12: =H12+I12 -> 0 | L12: =J12+K12 -> 0
A13: 8 | H13: =ROUND(E13+F13-G13,2) -> 0 | J13: =H13+I13 -> 0 | L13: =J13+K13 -> 0
A14: 9 | H14: =ROUND(E14+F14-G14,2) -> 0 | J14: =H14+I14 -> 0 | L14: =J14+K14 -> 0
A15: 10 | H15: =ROUND(E15+F15-G15,2) -> 0 | J15: =H15+I15 -> 0 | L15: =J15+K15 -> 0
A16: 11 | H16: =ROUND(E16+F16-G16,2) -> 0 | J16: =H16+I16 -> 0 | L16: =J16+K16 -> 0
A17: 12 | H17: =ROUND(E17+F17-G17,2) -> 0 | J17: =H17+I17 -> 0 | L17: =J17+K17 -> 0
... A32: 27 | H32: =ROUND(E32+F32-G32,2) -> 0 | J32: =H32+I32 -> 0 | L32: =J32+K32 -> 0
A33: 账面余额总计 | E33: =ROUND(SUM(E6:E32),2) -> 0 | F33: =ROUND(SUM(F6:F32),2) -> 0 | G33: =ROUND(SUM(G6:G32),2) -> 0 | H33: =ROUND(SUM(H6:H32),2) -> 0 | I33: =ROUND(SUM(I6:I32),2) -> 0 | J33: =H33+I33 -> 0 | K33: =ROUND(SUM(K6:K32),2) -> 0 | L33: =J33+K33 -> 0 | N33: =ROUND(SUM(N6:N32),2) -> 0
A34: 坏账准备 | H34: =E34+G34-F34 -> 0 | J34: =H34+I34 -> 0 | L34: =J34+K34 -> 0
A35: 账面价值总计 | E35: =ROUND(E33-E34,2) -> 0 | H35: =ROUND(H33-H34,2) -> 0 | J35: =H35+I35 -> 0 | K35: =ROUND(K33-K34,2) -> 0 | L35: =J35+K35 -> 0
B37: 审计说明：

Sheet 预付账款
B1: 预付账款明细表
A2: =备忘录!$A$1 -> 被审计单位：福禄福擎网络科技有限公司 | F2: 编制人：刘喜琴 | L2: =备忘录!$C$2 -> 日期：2025/10/30
A3: =备忘录!$A$2 -> 财务报表截止日：2025/9/30 | F3: 复核人：赵玮 | L3: =备忘录!$C$3 -> 日期：2025/10/31
A4: 序号 | B4: 科目名称 | C4: 核算项目1 | D4: 核算项目2 | E4: 账面数据 | J4: 期末报表列报 | K4: 审计调整 | L4: 期末审定余额 | M4: 余额核对 (√) | N4: 核对确认金额 | O4: 备注 | P4: 重要客户/供应商账龄划分（√） | Q4: 1个月以内 | R4: 2-3月 | S4: 4-6月 | T4: 6个月以上 | U4: 重要客户/供应商背调(√) | V4: 背景调查
E5: 期初金额（取数为：科目余额表期初借方-贷方） | F5: 本期借方 | G5: 本期贷方 | H5: 期末金额 | I5: 企业调整 | V5: 法定代表人 | W5: 成立日期 | X5: 注册地址 | Y5: 注册资本（万元） | Z5: 行业 | AA5: 股权结构 | AB5: 企业规模 | AC5: 员工人数 | AD5: 纳税人资质 | AE5: 经营范围
A6: 1 | H6: =ROUND(E6+F6-G6,2) -> 0 | J6: =H6+I6 -> 0 | L6: =J6+K6 -> 0
A7: 2 | H7: =ROUND(E7+F7-G7,2) -> 0 | J7: =H7+I7 -> 0 | L7: =J7+K7 -> 0
A8: 3 | H8: =ROUND(E8+F8-G8,2) -> 0 | J8: =H8+I8 -> 0 | L8: =J8+K8 -> 0
A9: 4 | H9: =ROUND(E9+F9-G9,2) -> 0 | J9: =H9+I9 -> 0 | L9: =J9+K9 -> 0
A10: 5 | H10: =ROUND(E10+F10-G10,2) -> 0 | J10: =H10+I10 -> 0 | L10: =J10+K10 -> 0
A11: 6 | H11: =ROUND(E11+F11-G11,2) -> 0 | J11: =H11+I11 -> 0 | L11: =J11+K11 -> 0
A12: 7 | H12: =ROUND(E12+F12-G12,2) -> 0 | J12: =H12+I12 -> 0 | L12: =J12+K12 -> 0
A13: 8 | H13: =ROUND(E13+F13-G13,2) -> 0 | J13: =H13+I13 -> 0 | L13: =J13+K13 -> 0
A14: 9 | H14: =ROUND(E14+F14-G14,2) -> 0 | J14: =H14+I14 -> 0 | L14: =J14+K14 -> 0
A15: 10 | H15: =ROUND(E15+F15-G15,2) -> 0 | J15: =H15+I15 -> 0 | L15: =J15+K15 -> 0
A16: 11 | H16: =ROUND(E16+F16-G16,2) -> 0 | J16: =H16+I16 -> 0 | L16: =J16+K16 -> 0
A17: 12 | H17: =ROUND(E17+F17-G17,2) -> 0 | J17: =H17+I17 -> 0 | L17: =J17+K17 -> 0
... A30: 25 | H30: =ROUND(E30+F30-G30,2) -> 0 | J30: =H30+I30 -> 0 | L30: =J30+K30 -> 0
